Workbook

Sheet START HERE
A1: AI Automation Managed Services — Phase 2 Scope Definition / MVP Design
A3: Purpose | B3: Use this workbook after Phase 1 Discovery to convert client answers into a controlled MVP scope.
A4: Core question | B4: What exactly will we build first, what is excluded, and what must stay under human control?
A5: Main workflow | B5: 1) Transfer relevant Phase 1 findings → 2) Decide scope → 3) Define MVP → 4) Set automation boundaries → 5) Produce final scope summary.
A6: MVP meaning | B6: Minimum Viable Product: the smallest useful and safe first automation version that solves the main client problem without unnecessary complexity.
A7: Important rule | B7: Do not include everything the client mentioned. Include only what is valuable, safe, feasible, and needed for the first version.
A9: Color guide
A11: Grey | B11: Fixed guidance / reference fields — normally do not edit.
A12: Green | B12: Client/discovery input — copied or summarized from Phase 1.
A13: Yellow | B13: Internal package / automation decision support.
A14: Blue | B14: PM decision fields — fill after analysis.
A16: Recommended step-by-step use
A18: 1 | B18: Open 'Phase1 to Phase2 Handoff' and summarize the strongest findings from Phase 1.
A19: 2 | B19: Use 'Phase2 Scope Builder' to decide Yes / Later / No for each requirement.
A20: 3 | B20: Use 'MVP Definition' to write the first version of the solution in plain language.
A21: 4 | B21: Use 'Automation Boundary' to define what AI may classify, draft, send, or escalate.
A22: 5 | B22: Use 'Priority Scoring' if there are too many possible features.
A23: 6 | B23: Complete 'Final Scope Summary' as the project-ready output.
A26: We planned this PM flow:
A28: Phase 1 — Discovery / Analysis
A29: Understand client needs, channels, risks, pain points, possible package direction.
A31: Phase 2 — Scope Definition / MVP Design
A32: Convert discovery answers into a clear first project scope.
A34: Phase 3 — Solution Blueprint
A35: Design workflow logic, tools, data fields, routing, approvals, security.
A37: Phase 4 — MVP Build
A38: Build the first safe automation version.
A40: Phase 5 — Testing / Validation
A41: Test real cases, edge cases, errors, wrong classifications, approvals.
A43: Phase 6 — Go-live / Managed Service
... A48: By MVP Decision (Phase2 Scope Builder col F)
A49: Status | B49: Meaning | C49: Count
A50: Yes | B50: Included in MVP. | C50: =COUNTIF('Phase2 Scope Builder'!F2:F100,"Yes") -> 10
A51: Later | B51: Deferred to a later phase. | C51: =COUNTIF('Phase2 Scope Builder'!F2:F100,"Later") -> 3
A52: No | B52: Excluded from project. | C52: =COUNTIF('Phase2 Scope Builder'!F2:F100,"No") -> 1
A53: Needs clarification | B53: Open question — needs client confirmation. | C53: =COUNTIF('Phase2 Scope Builder'!F2:F100,"Needs clarification") -> 0
A55: By Completeness (Phase2 Scope Builder col N)
A56: Status | B56: Meaning | C56: Count
A57: Empty | B57: No fields filled yet. | C57: =COUNTIF('Phase2 Scope Builder'!N2:N100,"Empty") -> 85
A58: Partial | B58: Some required fields still missing. | C58: =COUNTIF('Phase2 Scope Builder'!N2:N100,"Partial") -> 0
...

Sheet Scope Decision Helper
A1: Scope Decision Helper — one requirement at a time
A2: Use this for a single candidate requirement when you're unsure whether to include it in MVP, defer it, or exclude it. Fill the 9 yellow inputs; the blue cells suggest MVP Decision, Package Direction, Approval rule, Risk flag, and a top caution. PM judgment still final — this just removes the staring-at-a-blank-cell moment.
A4: INPUTS — about this one requirement
A5: # | B5: Question | C5: Allowed values | D5: Answer
A6: Q1 | B6: Q1. Requirement (short label) | C6: Free text — e.g., 'Draft replies to booking questions'
A7: Q2 | B7: Q2. Business Value (1-5, 5 = critical to client) | C7: 1 / 2 / 3 / 4 / 5 | D7: 3
A8: Q3 | B8: Q3. Risk Level from Phase 1 | C8: Low / Medium / High / Critical | D8: Medium
A9: Q4 | B9: Q4. Feasibility (1-5, 5 = easy, APIs ready) | C9: 1 / 2 / 3 / 4 / 5 | D9: 3
A10: Q5 | B10: Q5. Complexity (1-5, 5 = very complex) | C10: 1 / 2 / 3 / 4 / 5 | D10: 3
A11: Q6 | B11: Q6. Sensitive topic? (health, legal, financial, emotional) | C11: Yes / No | D11: No
A12: Q7 | B12: Q7. Phase 1 flagged it as MVP-relevant? | C12: Yes / Later / No / Unknown | D12: Unknown
A13: Q8 | B13: Q8. AI autonomy desired | C13: Classify only / Classify + draft / Draft + auto-send / Multi-step agent | D13: Classify + draft
A14: Q9 | B14: Q9. Time pressure to deliver | C14: None / Some / High | D14: Some
A16: SUGGESTED DECISIONS (auto-calculated)
A17: # | B17: Indicator | C17: Suggested Value (formula) | D17: Reasoning hint
A18: O1 | B18: Suggested MVP Decision | C18: =IF(D8="Critical","No (Risk too high)",IF(AND(D11="Yes",D13="Draft + auto-send"),"No (sensitive + auto-send unsafe)",IF(D12="No","No (Phase 1 excluded)",IF(D12="Unknown","Needs clarification",IF(D9<=2,"Later (low feasibility)",IF(AND(D7>=4,D10<=3,D9>=3),"Yes (high value, manageable)",IF(AND(D7>=3,D9>=3),"Yes (workable)","Later (defer to Phase 2+)"))))))) -> Needs clarification | D18: Risk Critical → No. Phase 1 Unknown → Needs clarification. Low feasibility → Later. High value + manageable → Yes.
A19: O2 | B19: Suggested Package Direction | C19: =IF(D13="Multi-step agent","Agentic (with guardrails)",IF(D13="Draft + auto-send",IF(D11="Yes","Pro (with strict approval)","Pro to Managed"),IF(D13="Classify + draft","Pro","Basic"))) -> Pro | D19: Multi-step → Agentic. Auto-send → Pro/Managed. Drafts → Pro. Classify only → Basic.
A20: O3 | B20: Approval rule (product flag) | C20: =IF(OR(D11="Yes",D8="High",D8="Critical"),"Always (every outbound action)",IF(D13="Classify only","Not required (read-only)",IF(D13="Draft + auto-send","Category-based (safe vs sensitive)","Required (drafts reviewed before send)"))) -> Required (drafts reviewed before send) | D20: Sensitive or high-risk → always approve. Classify-only → no approval needed.
A21: O4 | B21: Risk flag | C21: =IF(D8="Critical","BLOCK — needs PM/client escalation before scoping.",IF(AND(D8="High",D13<>"Classify only"),"HIGH RISK — limit to classify+escalate in MVP.",IF(AND(D11="Yes",D13="Multi-step agent"),"HIGH RISK — agentic on sensitive data needs strict allow-list.",IF(D8="Medium","Watch — review approval and audit before go-live.","Standard caution.")))) -> Watch — review approval and audit before go-live. | D21: Surfaces blockers and high-risk combinations early.
A22: O5 | B22: Top caution | C22: =IF(D9<=2,"Feasibility low — confirm API/access before committing.",IF(AND(D10>=4,D7<=3),"Complexity high vs value — consider deferring or simplifying.",IF(AND(D11="Yes",D13="Classify only"),"Safe path: classify + escalate only, no AI advice.",IF(D14="High","Time pressure — narrow MVP to one channel/category first.","No major caution flagged.")))) -> No major caution flagged. | D22: The single biggest watch-out for this requirement.
A25: How to use this with the Scope Builder:
A26: 1) Fill the 9 yellow inputs for one candidate requirement.
A27: 2) Read the 5 blue suggestions.
A28: 3) Open Phase2 Scope Builder, add a new row with the requirement and PM-confirm the values (Risk, MVP Decision, Package, Approval, Status). The Helper does not write to the Scope Builder automatically.
A29: 4) Use Priority Scoring for cross-comparison when you have many candidates.
A31: Caveat: the Helper is decision support, not authority. PM judgment overrides whenever local context (client trust, contract scope, existing tools) changes the picture.

Sheet Phase1 to Phase2 Handoff
A1: Phase 1 Finding / Flag | B1: Client Answer / Evidence (GREEN) | C1: Risk Level (GREEN) | D1: Possible Package Direction (YELLOW) | E1: Phase 2 Question to Decide (BLUE) | F1: Decision Owner | G1: Notes
A2: Channels used | B2: Example: Gmail, Instagram, website form | C2: Medium | D2: Pro | E2: Which channels enter MVP first? | F2: PM + Client | G2: Start with highest-value / easiest channel.
A3: Main pain point | B3: Example: too much time answering booking questions | C3: Low | D3: Basic | E3: Which pain must MVP solve first? | F3: PM | G3: Avoid solving secondary problems in first version.
A4: Sensitive data | B4: Example: clients sometimes share personal/health details | C4: High | D4: Managed | E4: Which messages require human-only handling? | F4: PM + Client | G4: No direct AI advice for sensitive topics.
A5: Approval preference | B5: Example: client wants to approve all outgoing replies | C5: Medium | D5: Pro | E5: Can AI create drafts only? | F5: Client | G5: Human approval protects quality.
A6: Reporting need | B6: Example: client wants weekly overview of missed inquiries | C6: Low | D6: Managed | E6: Is reporting in MVP or later? | F6: PM | G6: Could be Managed package driver.

Sheet Phase2 Scope Builder
A1: ID | B1: Requirement / Need from Phase 1 | C1: Source / Evidence | D1: Business Value | E1: Risk Level | F1: MVP Decision | G1: Package Direction | H1: Automation Method Candidate | I1: Human Approval Required? | J1: Scope Boundary / Constraint | K1: Output / Decision | L1: Next Action | M1: Status | N1: Completeness Status (AUTO)
A2: 1 | B2: Classify website form inquiries | C2: Website form sends subject + message | D2: Reduce manual sorting | E2: Low | F2: Yes | G2: Basic | H2: AI classification | I2: No | J2: Only classify, no auto-send | K2: Build as MVP core | L2: Define categories | M2: Open | N2: =IF(COUNTA(B2,E2,F2,K2,L2,M2)=0,"Empty",IF(COUNTA(B2,E2,F2,K2,L2,M2)<6,"Partial","Complete")) -> Complete
A3: 2 | B3: Route spam/test messages | C3: Many low-value messages | D3: Reduce inbox noise | E3: Low | F3: Yes | G3: Basic | H3: Rule-based automation | I3: No | J3: Move to review folder, do not delete | K3: Include in MVP | L3: Create folder labels | M3: Open | N3: =IF(COUNTA(B3,E3,F3,K3,L3,M3)=0,"Empty",IF(COUNTA(B3,E3,F3,K3,L3,M3)<6,"Partial","Complete")) -> Complete
A4: 3 | B4: Draft replies to booking questions | C4: Client loses time replying | D4: Save response time | E4: Medium | F4: Yes | G4: Pro | H4: AI draft reply | I4: Yes | J4: Draft only; human sends | K4: Include if approved | L4: Collect approved answer templates | M4: Open | N4: =IF(COUNTA(B4,E4,F4,K4,L4,M4)=0,"Empty",IF(COUNTA(B4,E4,F4,K4,L4,M4)<6,"Partial","Complete")) -> Complete
A5: 4 | B5: Instagram DM intake | C5: Client receives social messages | D5: No missed leads | E5: Medium | F5: Later | G5: Pro | H5: AI classification | I5: Yes | J5: Depends on Meta access/API | K5: Phase 2 or later | L5: Check account/API feasibility | M5: Open | N5: =IF(COUNTA(B5,E5,F5,K5,L5,M5)=0,"Empty",IF(COUNTA(B5,E5,F5,K5,L5,M5)<6,"Partial","Complete")) -> Complete
A6: 5 | B6: Auto-send replies to sensitive topics | C6: Sensitive content possible | D6: Risk reduction | E6: High | F6: No | G6: Not applicable | H6: Manual only | I6: Always | J6: Never auto-send | K6: Excluded | L6: Document boundary | M6: Decided | N6: =IF(COUNTA(B6,E6,F6,K6,L6,M6)=0,"Empty",IF(COUNTA(B6,E6,F6,K6,L6,M6)<6,"Partial","Complete")) -> Complete
A7: 6 | B7: [Lead Pipeline] Score and route inbound leads by source and value | C7: CRM / web form / email submissions | D7: Faster follow-up; no missed high-value leads | E7: Medium | F7: Yes | G7: Pro | H7: AI classification + CRM logging | I7: Conditional | J7: CRM enrichment only; no auto-send of proposals or follow-up sequences | K7: Leads routed and logged; owner notified per category | L7: Map lead categories and routing rules | M7: Open | N7: =IF(COUNTA(B7,E7,F7,K7,L7,M7)=0,"Empty",IF(COUNTA(B7,E7,F7,K7,L7,M7)<6,"Partial","Complete")) -> Complete
A8: 7 | B8: [Document Processing] Extract invoice data and log to accounting | C8: Supplier invoices received by email (PDF attachments) | D8: Saves 3–4 h/week on manual data entry | E8: Medium | F8: Yes | G8: Basic | H8: AI classification | I8: Yes | J8: Extract and log only; human confirms before posting to accounting system | K8: Invoice fields extracted and logged; mismatches flagged for review | L8: Define required extraction fields and acceptable error threshold | M8: Open | N8: =IF(COUNTA(B8,E8,F8,K8,L8,M8)=0,"Empty",IF(COUNTA(B8,E8,F8,K8,L8,M8)<6,"Partial","Complete")) -> Complete
A9: 8 | B9: [Content & Marketing] Repurpose blog post into platform-specific draft formats | C9: Client produces weekly long-form post or article | D9: Saves 2 h/week; extends reach without extra writing effort | E9: Low | F9: Yes | G9: Pro | H9: AI draft reply | I9: Yes | J9: Draft only; no auto-publish; one source format per run in MVP | K9: Draft posts for Instagram, LinkedIn, and newsletter ready for owner review | L9: Agree on approved tone guide and platform templates | M9: Open | N9: =IF(COUNTA(B9,E9,F9,K9,L9,M9)=0,"Empty",IF(COUNTA(B9,E9,F9,K9,L9,M9)<6,"Partial","Complete")) -> Complete
A10: 9 | B10: [Internal Ops] Route approval requests with automated reminder | C10: Staff submit requests by email or intake form | D10: Reduces approval delays from days to hours | E10: Low | F10: Yes | G10: Basic | H10: Rule-based automation | I10: Yes | J10: Routing and notification only; no auto-approve under any circumstance | K10: Request logged; approver notified; reminder sent if no reply within 24h | L10: Define routing rules, approver list, and reminder timing | M10: Open | N10: =IF(COUNTA(B10,E10,F10,K10,L10,M10)=0,"Empty",IF(COUNTA(B10,E10,F10,K10,L10,M10)<6,"Partial","Complete")) -> Complete
A11: 10 | B11: [Reporting] Weekly KPI digest pulled from CRM and calendar | C11: Existing CRM and calendar data sources | D11: Saves 1 h/week; ensures consistent management visibility | E11: Low | F11: Later | G11: Managed | H11: Monitoring/reporting | I11: No | J11: Read-only data access only; no write actions | K11: Weekly email digest with agreed KPIs sent to defined recipients | L11: Agree on KPIs, recipients, and report cadence | M11: Open | N11: =IF(COUNTA(B11,E11,F11,K11,L11,M11)=0,"Empty",IF(COUNTA(B11,E11,F11,K11,L11,M11)<6,"Partial","Complete")) -> Complete
A12: 11 | B12: [Finance & Admin] Send payment reminders for overdue invoices | C12: Accounting tool export or spreadsheet (Bexio / Banana / CSV) | D12: Reduces overdue accounts; replaces manual follow-up | E12: Medium | F12: Yes | G12: Managed | H12: Rule-based automation | I12: Conditional | J12: Reminder only; no payment processing or accounting write-back | K12: Reminder sent at day 7 and day 14 after due date | L12: Define overdue threshold and approved reminder text | M12: Open | N12: =IF(COUNTA(B12,E12,F12,K12,L12,M12)=0,"Empty",IF(COUNTA(B12,E12,F12,K12,L12,M12)<6,"Partial","Complete")) -> Complete
A13: 12 | B13: [Scheduling] Propose available calendar slots in reply to meeting request | C13: Incoming email or form requesting an appointment | D13: Removes scheduling back-and-forth; faster booking confirmation | E13: Low | F13: Later | G13: Agentic | H13: Agentic calendar action | I13: Yes | J13: Read-only calendar access in MVP; no auto-booking or event creation | K13: Draft reply with 3 available slots ready for human to review and send | L13: Confirm calendar API access and permission scope | M13: Open | N13: =IF(COUNTA(B13,E13,F13,K13,L13,M13)=0,"Empty",IF(COUNTA(B13,E13,F13,K13,L13,M13)<6,"Partial","Complete")) -> Complete
... A15: 14 | B15: [E-commerce] Send order confirmation and shipping update notifications | C15: E-commerce platform order events / webhooks | D15: Reduces WISMO inquiries; improves customer experience | E15: Low | F15: Yes | G15: Basic | H15: Rule-based automation | I15: No | J15: Outbound notification only; no order modification or refund logic | K15: Order confirmation and shipping update sent automatically on trigger | L15: Confirm webhook access and notification templates | M15: Open | N15: =IF(COUNTA(B15,E15,F15,K15,L15,M15)=0,"Empty",IF(COUNTA(B15,E15,F15,K15,L15,M15)<6,"Partial","Complete")) -> Complete
N16: =IF(COUNTA(B16,E16,F16,K16,L16,M16)=0,"Empty",IF(COUNTA(B16,E16,F16,K16,L16,M16)<6,"Partial","Complete")) -> Empty
N17: =IF(COUNTA(B17,E17,F17,K17,L17,M17)=0,"Empty",IF(COUNTA(B17,E17,F17,K17,L17,M17)<6,"Partial","Complete")) -> Empty
N18: =IF(COUNTA(B18,E18,F18,K18,L18,M18)=0,"Empty",IF(COUNTA(B18,E18,F18,K18,L18,M18)<6,"Partial","Complete")) -> Empty
N19: =IF(COUNTA(B19,E19,F19,K19,L19,M19)=0,"Empty",IF(COUNTA(B19,E19,F19,K19,L19,M19)<6,"Partial","Complete")) -> Empty
N20: =IF(COUNTA(B20,E20,F20,K20,L20,M20)=0,"Empty",IF(COUNTA(B20,E20,F20,K20,L20,M20)<6,"Partial","Complete")) -> Empty
N21: =IF(COUNTA(B21,E21,F21,K21,L21,M21)=0,"Empty",IF(COUNTA(B21,E21,F21,K21,L21,M21)<6,"Partial","Complete")) -> Empty
N22: =IF(COUNTA(B22,E22,F22,K22,L22,M22)=0,"Empty",IF(COUNTA(B22,E22,F22,K22,L22,M22)<6,"Partial","Complete")) -> Empty
N23: =IF(COUNTA(B23,E23,F23,K23,L23,M23)=0,"Empty",IF(COUNTA(B23,E23,F23,K23,L23,M23)<6,"Partial","Complete")) -> Empty
N24: =IF(COUNTA(B24,E24,F24,K24,L24,M24)=0,"Empty",IF(COUNTA(B24,E24,F24,K24,L24,M24)<6,"Partial","Complete")) -> Empty
N25: =IF(COUNTA(B25,E25,F25,K25,L25,M25)=0,"Empty",IF(COUNTA(B25,E25,F25,K25,L25,M25)<6,"Partial","Complete")) -> Empty
N26: =IF(COUNTA(B26,E26,F26,K26,L26,M26)=0,"Empty",IF(COUNTA(B26,E26,F26,K26,L26,M26)<6,"Partial","Complete")) -> Empty
N27: =IF(COUNTA(B27,E27,F27,K27,L27,M27)=0,"Empty",IF(COUNTA(B27,E27,F27,K27,L27,M27)<6,"Partial","Complete")) -> Empty
... N100: =IF(COUNTA(B100,E100,F100,K100,L100,M100)=0,"Empty",IF(COUNTA(B100,E100,F100,K100,L100,M100)<6,"Partial","Complete")) -> Empty

Sheet MVP Definition
A1: Phase 2 Output — MVP Definition
A3: MVP Element | B3: Instruction | C3: Example | D3: Your Phase 2 Decision (EDIT)
A4: MVP Goal | B4: Write one clear sentence describing the first useful automation version. | C4: Example: Reduce manual checking of Gmail and website inquiries by classifying messages, logging them, and preparing human-approved replies.
A5: Primary Business Problem | B5: What problem must be solved first? | C5: Example: Client loses time sorting and answering repeated booking questions.
A6: Included Channels | B6: Only channels in first version. | C6: Example: Gmail + website form. Instagram later.
A7: Included Message Categories | B7: Categories handled in MVP. | C7: Example: Booking, price question, spam/test, general inquiry.
A8: Included Automations | B8: Concrete automations included. | C8: Example: classify, route, create CRM item, draft reply.
A9: Human Approval Points | B9: Where human must approve before action. | C9: Example: all outgoing replies must be reviewed.
A10: Explicit Exclusions | B10: What is not included now. | C10: Example: WhatsApp, payment handling, automatic sending, sensitive advice.
A11: Success Criteria | B11: How we know MVP works. | C11: Example: 90%+ correct routing in test set; zero auto-sent sensitive replies.
A12: Package Direction | B12: Internal direction only, not final offer. | C12: Example: Basic now, Pro later.

Sheet In-Out Scope Matrix
A1: Item / Feature | B1: In Scope | C1: Out of Scope | D1: Later | E1: Reason / Boundary | F1: Client Confirmation Needed?
A2: Gmail intake | B2: Yes | E2: Core MVP channel | F2: No
A3: Website form intake | B3: Yes | E3: Core MVP channel | F3: No
A4: Instagram DM intake | D4: Yes | E4: Needs API/access check | F4: Yes
A5: Automatic email sending | C5: Yes | E5: Not in first version due to approval risk | F5: Yes
A6: AI draft replies | B6: Yes | E6: Draft only, human sends | F6: Yes
A7: Sensitive advice replies | C7: Yes | E7: Human-only | F7: Yes

Sheet Automation Boundary
A1: Message / Task Type | B1: AI May Classify? | C1: AI May Summarize? | D1: AI May Draft? | E1: AI May Send? | F1: AI May Update CRM? | G1: Human Approval Rule | H1: Escalation / Boundary Note
A2: Booking request | B2: Yes | C2: Yes | D2: Yes | E2: No | F2: Yes | G2: Human approves reply | H2: No autonomous booking in MVP unless approved.
A3: Price question | B3: Yes | C3: Yes | D3: Yes | E3: No | F3: Yes | G3: Human approves reply | H3: Use approved FAQ only.
A4: Spam/Test | B4: Yes | C4: No | D4: No | E4: No | F4: Yes | G4: No approval needed for folder routing | H4: Move to review folder; do not delete.
A5: Complaint | B5: Yes | C5: Yes | D5: No | E5: No | F5: Yes | G5: Always human | H5: Mark urgent / review.
A6: Sensitive personal/health/legal/financial topic | B6: Yes | C6: Maybe | D6: No | E6: No | F6: Yes | G6: Always human | H6: No advice; escalate to business owner.

Sheet Priority Scoring
A1: Priority Scoring — rank candidate features for MVP
A2: Score each candidate feature on 5 dimensions (1-5). The score, class, and suggested MVP decision are calculated automatically. Lower complexity is better — that dimension is subtracted, not added. Empty rows are blank (no fake scores).
A4: ID | B4: Feature / Requirement | C4: Business Value (1-5) | D4: Urgency (1-5) | E4: Risk Reduction (1-5) | F4: Complexity (1-5) (subtracts!) | G4: Data/API Feasibility (1-5) | H4: Priority Score (auto) | I4: Priority Class (auto) | J4: MVP Decision (your call) | K4: Suggested MVP (auto)
A5: 1 | B5: Classify Gmail inquiries | C5: 5 | D5: 5 | E5: 3 | F5: 2 | G5: 5 | H5: =IF(B5="","",ROUND((C5+D5+E5+G5)-F5,1)) -> 16 | I5: =IF(H5="","",IF(H5>=14,"Must have",IF(H5>=10,"Should have",IF(H5>=7,"Could have","Won't have now")))) -> Must have | J5: Yes | K5: =IF(I5="","",IF(OR(I5="Must have",I5="Should have"),"Yes",IF(I5="Could have","Later","No"))) -> Yes
A6: 2 | B6: Classify Instagram DMs | C6: 4 | D6: 3 | E6: 3 | F6: 4 | G6: 2 | H6: =IF(B6="","",ROUND((C6+D6+E6+G6)-F6,1)) -> 8 | I6: =IF(H6="","",IF(H6>=14,"Must have",IF(H6>=10,"Should have",IF(H6>=7,"Could have","Won't have now")))) -> Could have | J6: Later | K6: =IF(I6="","",IF(OR(I6="Must have",I6="Should have"),"Yes",IF(I6="Could have","Later","No"))) -> Later
A7: 3 | B7: AI draft replies | C7: 4 | D7: 4 | E7: 3 | F7: 3 | G7: 4 | H7: =IF(B7="","",ROUND((C7+D7+E7+G7)-F7,1)) -> 12 | I7: =IF(H7="","",IF(H7>=14,"Must have",IF(H7>=10,"Should have",IF(H7>=7,"Could have","Won't have now")))) -> Should have | J7: Yes | K7: =IF(I7="","",IF(OR(I7="Must have",I7="Should have"),"Yes",IF(I7="Could have","Later","No"))) -> Yes
A8: 4 | B8: Auto-send replies (sensitive) | C8: 3 | D8: 2 | E8: 1 | F8: 4 | G8: 4 | H8: =IF(B8="","",ROUND((C8+D8+E8+G8)-F8,1)) -> 6 | I8: =IF(H8="","",IF(H8>=14,"Must have",IF(H8>=10,"Should have",IF(H8>=7,"Could have","Won't have now")))) -> Won't have now | J8: No | K8: =IF(I8="","",IF(OR(I8="Must have",I8="Should have"),"Yes",IF(I8="Could have","Later","No"))) -> No
H9: =IF(B9="","",ROUND((C9+D9+E9+G9)-F9,1)) | I9: =IF(H9="","",IF(H9>=14,"Must have",IF(H9>=10,"Should have",IF(H9>=7,"Could have","Won't have now")))) | K9: =IF(I9="","",IF(OR(I9="Must have",I9="Should have"),"Yes",IF(I9="Could have","Later","No")))
H10: =IF(B10="","",ROUND((C10+D10+E10+G10)-F10,1)) | I10: =IF(H10="","",IF(H10>=14,"Must have",IF(H10>=10,"Should have",IF(H10>=7,"Could have","Won't have now")))) | K10: =IF(I10="","",IF(OR(I10="Must have",I10="Should have"),"Yes",IF(I10="Could have","Later","No")))
H11: =IF(B11="","",ROUND((C11+D11+E11+G11)-F11,1)) | I11: =IF(H11="","",IF(H11>=14,"Must have",IF(H11>=10,"Should have",IF(H11>=7,"Could have","Won't have now")))) | K11: =IF(I11="","",IF(OR(I11="Must have",I11="Should have"),"Yes",IF(I11="Could have","Later","No")))
H12: =IF(B12="","",ROUND((C12+D12+E12+G12)-F12,1)) | I12: =IF(H12="","",IF(H12>=14,"Must have",IF(H12>=10,"Should have",IF(H12>=7,"Could have","Won't have now")))) | K12: =IF(I12="","",IF(OR(I12="Must have",I12="Should have"),"Yes",IF(I12="Could have","Later","No")))
H13: =IF(B13="","",ROUND((C13+D13+E13+G13)-F13,1)) | I13: =IF(H13="","",IF(H13>=14,"Must have",IF(H13>=10,"Should have",IF(H13>=7,"Could have","Won't have now")))) | K13: =IF(I13="","",IF(OR(I13="Must have",I13="Should have"),"Yes",IF(I13="Could have","Later","No")))
H14: =IF(B14="","",ROUND((C14+D14+E14+G14)-F14,1)) | I14: =IF(H14="","",IF(H14>=14,"Must have",IF(H14>=10,"Should have",IF(H14>=7,"Could have","Won't have now")))) | K14: =IF(I14="","",IF(OR(I14="Must have",I14="Should have"),"Yes",IF(I14="Could have","Later","No")))
H15: =IF(B15="","",ROUND((C15+D15+E15+G15)-F15,1)) | I15: =IF(H15="","",IF(H15>=14,"Must have",IF(H15>=10,"Should have",IF(H15>=7,"Could have","Won't have now")))) | K15: =IF(I15="","",IF(OR(I15="Must have",I15="Should have"),"Yes",IF(I15="Could have","Later","No")))
H16: =IF(B16="","",ROUND((C16+D16+E16+G16)-F16,1)) | I16: =IF(H16="","",IF(H16>=14,"Must have",IF(H16>=10,"Should have",IF(H16>=7,"Could have","Won't have now")))) | K16: =IF(I16="","",IF(OR(I16="Must have",I16="Should have"),"Yes",IF(I16="Could have","Later","No")))
H17: =IF(B17="","",ROUND((C17+D17+E17+G17)-F17,1)) | I17: =IF(H17="","",IF(H17>=14,"Must have",IF(H17>=10,"Should have",IF(H17>=7,"Could have","Won't have now")))) | K17: =IF(I17="","",IF(OR(I17="Must have",I17="Should have"),"Yes",IF(I17="Could have","Later","No")))
H18: =IF(B18="","",ROUND((C18+D18+E18+G18)-F18,1)) | I18: =IF(H18="","",IF(H18>=14,"Must have",IF(H18>=10,"Should have",IF(H18>=7,"Could have","Won't have now")))) | K18: =IF(I18="","",IF(OR(I18="Must have",I18="Should have"),"Yes",IF(I18="Could have","Later","No")))
H19: =IF(B19="","",ROUND((C19+D19+E19+G19)-F19,1)) | I19: =IF(H19="","",IF(H19>=14,"Must have",IF(H19>=10,"Should have",IF(H19>=7,"Could have","Won't have now")))) | K19: =IF(I19="","",IF(OR(I19="Must have",I19="Should have"),"Yes",IF(I19="Could have","Later","No")))
H20: =IF(B20="","",ROUND((C20+D20+E20+G20)-F20,1)) | I20: =IF(H20="","",IF(H20>=14,"Must have",IF(H20>=10,"Should have",IF(H20>=7,"Could have","Won't have now")))) | K20: =IF(I20="","",IF(OR(I20="Must have",I20="Should have"),"Yes",IF(I20="Could have","Later","No")))
... H34: =IF(B34="","",ROUND((C34+D34+E34+G34)-F34,1)) | I34: =IF(H34="","",IF(H34>=14,"Must have",IF(H34>=10,"Should have",IF(H34>=7,"Could have","Won't have now")))) | K34: =IF(I34="","",IF(OR(I34="Must have",I34="Should have"),"Yes",IF(I34="Could have","Later","No")))
A37: How the formulas work
A38: Priority Score | D38: Formula: (Business Value + Urgency + Risk Reduction + Feasibility) − Complexity. Range: −4 to 20.
A39: Priority Class — Must have | D39: Score ≥ 14. Strong candidate for MVP.
A40: Priority Class — Should have | D40: Score 10-13. Solid candidate.
A41: Priority Class — Could have | D41: Score 7-9. Optional / nice-to-have.
A42: Priority Class — Won't have now | D42: Score < 7. Defer or exclude.
A43: Suggested MVP | D43: Must/Should → 'Yes'. Could → 'Later'. Won't → 'No'. You can override in the MVP Decision column.
A44: Complexity | D44: This is the only dimension that REDUCES the score. High complexity = harder = lower priority.
A47: Tip: enter the feature name in column B first — that activates the formulas. Leaving B blank keeps the row empty (no fake '0' score).

Sheet Final Scope Summary
A1: Final Phase 2 Scope Summary
A3: Client / Project Name | C3: Date | D3: 2026-06-23
A4: MVP Package Direction | C4: Prepared by
A5: MVP Goal
A6: Included Channels
A7: Included Automations
A8: Human Approval Rules
A9: Out of Scope
A10: Key Risks / Boundaries
A11: Success Criteria
A12: Next Phase Trigger | B12: Proceed to Phase 3 Solution Blueprint when client confirms this scope.
A14: Scope at a Glance (auto-computed)
A15: In Scope (MVP=Yes) | D15: =COUNTIF('Phase2 Scope Builder'!F2:F100,"Yes") -> 10
A16: Deferred (MVP=Later) | D16: =COUNTIF('Phase2 Scope Builder'!F2:F100,"Later") -> 3
A17: Excluded (MVP=No) | D17: =COUNTIF('Phase2 Scope Builder'!F2:F100,"No") -> 1
A18: Needs client confirmation | D18: =COUNTIF('Phase2 Scope Builder'!F2:F100,"Needs clarification") -> 0
A19: High-risk items (Risk=High or Critical) | D19: =COUNTIF('Phase2 Scope Builder'!E2:E100,"High")+COUNTIF('Phase2 Scope Builder'!E2:E100,"Critical") -> 1
A20: Items requiring human approval | D20: =COUNTIF('Phase2 Scope Builder'!I2:I100,"Always")+COUNTIF('Phase2 Scope Builder'!I2:I100,"Yes") -> 8
A21: Total scope items defined | D21: =COUNTA('Phase2 Scope Builder'!B2:B100) -> 14

Sheet Lists
A1: Risk Level | C1: MVP Decision | E1: Package Direction | G1: Automation Method | I1: Human Approval | K1: Status | M1: Priority
A2: Low | C2: Yes | E2: Basic | G2: Rule-based automation | I2: Yes | K2: Open | M2: Must have
A3: Medium | C3: Later | E3: Pro | G3: AI classification | I3: No | K3: Decided | M3: Should have
A4: High | C4: No | E4: Managed | G4: AI summary | I4: Conditional | K4: Blocked | M4: Could have
A5: Critical | C5: Needs clarification | E5: Agentic | G5: AI draft reply | I5: Always | K5: Needs client confirmation | M5: Won't have now
E6: Mixed | G6: Human approval workflow
E7: Not applicable | G7: CRM logging
G8: Monitoring/reporting
G9: Agentic calendar action
G10: Agentic CRM action
G11: Manual only
