Workbook

Sheet START HERE
A1: AI Automation Managed Services — Phase 6: Go-live & Managed Service
A3: Purpose | B3: Launch the tested MVP safely, monitor real operation, maintain service quality, and improve the automation over time.
A4: Input from Phase 5 | B4: Go/No-Go decision, validated test cases, known defects, approval rules, final tested MVP, client acceptance notes.
A5: Main output | B5: Live automation + monitoring plan + support model + monthly review/improvement loop.
A6: How to use | B6: 1) Fill Phase5 to Phase6 Handoff. 2) Complete Go-live Checklist. 3) Define Monitoring & Support. 4) Track issues in Operations Log. 5) Use Monthly Review for managed service improvements.
A7: Color guide | B7: Grey = fixed guidance. Green = fill during go-live/operation. Blue = PM/managed-service analysis. Yellow = decision/risk note.
A8: Important | B8: Phase 6 is not 'finished and forgotten'. It is the operational service layer: monitoring, client support, quality control, reporting, and controlled improvements.
A10: Phase 6 Sheet Map
A11: Sheet | B11: Use
A12: Phase5 to Phase6 Handoff | B12: Transfer final testing status and launch prerequisites.
A13: Go-live Checklist | B13: Confirm readiness before production activation.
A14: Launch Plan | B14: Plan launch date, responsibilities, rollback, client communication.
A15: Monitoring & Support | B15: Define what is monitored, frequency, owner, alert route, SLA.
A16: Operations Log | B16: Track live issues, failed runs, misclassifications, client requests.
A17: Monthly Review | B17: Review performance and decide improvements.
A18: Improvement Backlog | B18: Controlled list of changes after go-live.
A19: Client Handover | B19: Access, documentation, training, ownership, acceptance.
A20: Final Phase6 Summary | B20: Executive summary of launched managed service.
A24: We planned this PM flow:
A26: Phase 1 — Discovery / Analysis
A27: Understand client needs, channels, risks, pain points, possible package direction.
A29: Phase 2 — Scope Definition / MVP Design
A30: Convert discovery answers into a clear first project scope.
A32: Phase 3 — Solution Blueprint
A33: Design workflow logic, tools, data fields, routing, approvals, security.
A35: Phase 4 — MVP Build
A36: Build the first safe automation version.
A38: Phase 5 — Testing / Validation
A39: Test real cases, edge cases, errors, wrong classifications, approvals.
A41: Phase 6 — Go-live / Managed Service
... A46: Go-live Checklist — by Status
A47: Status | B47: Meaning | C47: Count
A48: Not Started | B48: Not begun. | C48: =COUNTIF('Go-live Checklist'!D2:D50,"Not Started") -> 15
A49: In Progress | B49: In progress. | C49: =COUNTIF('Go-live Checklist'!D2:D50,"In Progress") -> 0
A50: Done | B50: Complete. | C50: =COUNTIF('Go-live Checklist'!D2:D50,"Done") -> 0
A51: Blocked | B51: Blocked. | C51: =COUNTIF('Go-live Checklist'!D2:D50,"Blocked") -> 0
A52: Waiting Client | B52: Waiting on client action. | C52: =COUNTIF('Go-live Checklist'!D2:D50,"Waiting Client") -> 0
A54: Operations Log — by Status
A55: Status | B55: Meaning | C55: Count
A56: Not Started | B56: Logged but not triaged. | C56: =COUNTIF('Operations Log'!G2:G200,"Not Started") -> 0
...

Sheet Operations Issue Triage Helper
A1: Operations Issue Triage Helper — one incident or request at a time
A2: Use this when a live issue, error, misclassification, or client request comes in. Fill the 6 yellow inputs; the blue cells suggest priority, rollback decision, client communication, owner, and top corrective action. Then log the issue in the Operations Log with those values.
A4: INPUTS — about this one issue
A5: # | B5: Question | C5: Allowed values | D5: Answer
A6: Q1 | B6: Q1. Issue type | C6: Failed Run / Wrong Classification / Wrong Processing Result / Client Request / Security/Access / API/Tool Limit / Enhancement / Other | D6: Failed Run
A7: Q2 | B7: Q2. Impact scope | C7: Single message / Single category / Whole channel / All workflows | D7: Single message
A8: Q3 | B8: Q3. Frequency | C8: One-off / Sporadic / Persistent (repeating) | D8: One-off
A9: Q4 | B9: Q4. Safety / data impact | C9: None / Minor / Major / Critical (legal, sensitive data harm, trust) | D9: None
A10: Q5 | B10: Q5. Cause known? | C10: Yes (root cause clear) / Partially / No (investigating) | D10: Partially
A11: Q6 | B11: Q6. Client awareness | C11: Not noticed / Noticed not complained / Complained / Asked us directly | D11: Not noticed
A13: SUGGESTED RESPONSE (auto-calculated)
A14: # | B14: Indicator | C14: Suggested Value (formula) | D14: Reasoning hint
A15: O1 | B15: Priority | C15: =IF(OR(D9="Critical",D7="All workflows"),"P1 (immediate)",IF(AND(D9="Major",D8="Persistent"),"P1 (immediate)",IF(AND(D8="Persistent",D7="Whole channel"),"P1 (immediate)",IF(OR(D9="Major",D11="Complained",D11="Asked us"),"P2 (within 24 hours)",IF(AND(D8="Sporadic",D9="Minor"),"P3 (this week)",IF(AND(D8="One-off",D9="None"),"P4 (next monthly review)","P3 (this week)")))))) -> P4 (next monthly review) | D15: Critical safety / all-workflows → P1. Client complained / Major → P2. Sporadic minor → P3.
A16: O2 | B16: Rollback decision | C16: =IF(D9="Critical","ROLLBACK now — pause production until safe.",IF(AND(D9="Major",D8="Persistent"),"Consider rollback — isolate impact while fixing.",IF(D7="All workflows","Consider rollback — broad impact justifies pause.","Not needed — fix forward."))) -> Not needed — fix forward. | D16: Critical → Rollback now. Major + persistent → Consider. Otherwise fix forward.
A17: O3 | B17: Client communication | C17: =IF(OR(D9="Critical",D11="Complained"),"Apologize + remediation plan + timeline.",IF(D9="Major","Apologize + remediation plan; explain impact.",IF(D11="Asked us","Inform — answer their question with what you know so far.",IF(D11="Noticed not complained","Inform proactively — explain the fix and timeline.",IF(AND(D9="None",D8="One-off"),"None needed — fix silently and log.","Optional — note in next monthly review."))))) -> None needed — fix silently and log. | D17: Apologize for Critical/Major or client complaints. Inform if client noticed. Silent for minor one-offs.
A18: O4 | B18: Owner | C18: =IF(OR(D6="Security/Access",D6="API/Tool Limit",D6="Wrong Classification / Wrong Processing Result",D6="Failed Run"),"Service Provider",IF(OR(D6="Client Request",D6="Enhancement"),"Shared (PM + Client owner)","Service Provider (review with client)")) -> Service Provider | D18: Most operational issues → Service Provider. Client requests/enhancements → Shared.
A19: O5 | B19: Top corrective action | C19: =IF(D9="Critical","Pause affected route; document incident; client comms within 1 hour; root-cause analysis before resume.",IF(AND(D10="No",D8="Persistent"),"Investigate before acting — log occurrences, capture payload/audit, replicate in test.",IF(D6="Wrong Classification / Wrong Processing Result","Capture the message + AI response; tune prompt or add fallback rule; retest before deploy.",IF(D6="Failed Run","Check audit log + error route; confirm retry safe; ensure no duplicate or wrong action.",IF(D6="Security/Access","Rotate or revoke credential; verify no exposure; document new process.",IF(D6="API/Tool Limit","Check usage report; adjust schedule/model/budget; notify client if package change needed.",IF(OR(D6="Client Request",D6="Enhancement"),"Log in Improvement Backlog with business value, risk, package impact; decide at next monthly review.","Log in Operations Log; assign owner; schedule fix and retest."))))))) -> Check audit log + error route; confirm retry safe; ensure no duplicate or wrong action. | D19: Single concrete next step tailored to issue type and cause.
A22: How to use this with the Operations Log / Improvement Backlog:
A23: 1) When a live issue, error, or client request comes in, fill the 6 yellow inputs.
A24: 2) Read the 5 blue suggestions.
A25: 3) For operational issues → log in Operations Log with the suggested Priority, Owner, Status. Transfer the corrective action.
A26: 4) For enhancements / client requests → log in Improvement Backlog with the suggested Priority and a note about package impact.
A28: Caveat: this is decision support. Live judgement may override — e.g., client trust, contract terms, or 'this is the third time this happened' may warrant escalating priority.

Sheet Lists
A1: Status | B1: Go Decision | C1: Priority | D1: Risk | E1: Package | F1: Frequency | G1: Owner Role | H1: Issue Type
A2: Not Started | B2: Go | C2: Low | D2: Low | E2: Basic | F2: Real-time | G2: Client Owner | H2: Failed Run
A3: In Progress | B3: Conditional Go | C3: Medium | D3: Medium | E3: Pro | F3: Hourly | G3: Service Provider | H3: Wrong Classification
A4: Done | B4: No-Go | C4: High | D4: High | E4: Managed | F4: Daily | G4: Shared | H4: Client Request
A5: Blocked | C5: Critical | D5: Critical | E5: Agentic | F5: Weekly | G5: External Vendor | H5: Security/Access
A6: Waiting Client | E6: Mixed | F6: Monthly | H6: API/Tool Limit
F7: On demand | H7: Enhancement

Sheet Phase5 to Phase6 Handoff
A1: Item | B1: Phase 5 Result / Evidence (EDIT) | C1: Open Issue? (EDIT) | D1: Required Before Go-live (EDIT) | E1: Owner (EDIT) | F1: Go-live Impact | G1: PM Decision / Notes (POST)
A2: Go/No-Go result | F2: Defines whether launch is possible
A3: Critical defects | F3: Critical defects must be closed or accepted
A4: AI classification quality | F4: Confirms whether AI route is safe enough
A5: Approval/escalation tests | F5: Confirms human-control behavior
A6: Error monitoring tests | F6: Confirms failure notifications work
A7: Client acceptance | F7: Client confirms tested workflow is acceptable
A8: Known limitations | F8: Must be documented before launch
A9: Rollback requirement | F9: Needed if production launch fails

Sheet Go-live Checklist
A1: Category | B1: Checklist Item | C1: Why it matters | D1: Status (EDIT) | E1: Owner (EDIT) | F1: Due Date (EDIT) | G1: Evidence / Link (EDIT) | H1: Go-live Blocker? (EDIT) | I1: PM Notes (POST) | J1: Completeness Status (AUTO)
A2: Access | B2: Client-owned accounts connected with approved access | C2: Avoids dependency on private accounts | D2: Not Started | J2: =IF(COUNTA(A2,B2,D2,E2,F2,H2)=0,"Empty",IF(COUNTA(A2,B2,D2,E2,F2,H2)<6,"Partial","Complete")) -> Partial
A3: Access | B3: API keys/secrets not hardcoded in scenario | C3: Prevents exposed credentials | D3: Not Started | J3: =IF(COUNTA(A3,B3,D3,E3,F3,H3)=0,"Empty",IF(COUNTA(A3,B3,D3,E3,F3,H3)<6,"Partial","Complete")) -> Partial
A4: Access | B4: Revocation/rotation process documented | C4: Allows emergency access control | D4: Not Started | J4: =IF(COUNTA(A4,B4,D4,E4,F4,H4)=0,"Empty",IF(COUNTA(A4,B4,D4,E4,F4,H4)<6,"Partial","Complete")) -> Partial
A5: Scenario | B5: Production scenario duplicated/backed up before launch | C5: Allows rollback | D5: Not Started | J5: =IF(COUNTA(A5,B5,D5,E5,F5,H5)=0,"Empty",IF(COUNTA(A5,B5,D5,E5,F5,H5)<6,"Partial","Complete")) -> Partial
A6: Scenario | B6: Test data removed from production CRM/logs | C6: Keeps client data clean | D6: Not Started | J6: =IF(COUNTA(A6,B6,D6,E6,F6,H6)=0,"Empty",IF(COUNTA(A6,B6,D6,E6,F6,H6)<6,"Partial","Complete")) -> Partial
A7: Scenario | B7: Triggers/schedule configured correctly | C7: Ensures automation runs as intended | D7: Not Started | J7: =IF(COUNTA(A7,B7,D7,E7,F7,H7)=0,"Empty",IF(COUNTA(A7,B7,D7,E7,F7,H7)<6,"Partial","Complete")) -> Partial
A8: Safety | B8: Human approval active where required | C8: Prevents unsafe auto-replies/actions | D8: Not Started | J8: =IF(COUNTA(A8,B8,D8,E8,F8,H8)=0,"Empty",IF(COUNTA(A8,B8,D8,E8,F8,H8)<6,"Partial","Complete")) -> Partial
A9: Safety | B9: Fallback route for unknown/low-confidence cases active | C9: Prevents wrong routing | D9: Not Started | J9: =IF(COUNTA(A9,B9,D9,E9,F9,H9)=0,"Empty",IF(COUNTA(A9,B9,D9,E9,F9,H9)<6,"Partial","Complete")) -> Partial
A10: Safety | B10: Sensitive/urgent escalation route active | C10: Protects high-risk cases | D10: Not Started | J10: =IF(COUNTA(A10,B10,D10,E10,F10,H10)=0,"Empty",IF(COUNTA(A10,B10,D10,E10,F10,H10)<6,"Partial","Complete")) -> Partial
A11: Monitoring | B11: Error handler and alerts active | C11: Enables fast issue response | D11: Not Started | J11: =IF(COUNTA(A11,B11,D11,E11,F11,H11)=0,"Empty",IF(COUNTA(A11,B11,D11,E11,F11,H11)<6,"Partial","Complete")) -> Partial
A12: Monitoring | B12: Audit log writing correctly | C12: Enables traceability | D12: Not Started | J12: =IF(COUNTA(A12,B12,D12,E12,F12,H12)=0,"Empty",IF(COUNTA(A12,B12,D12,E12,F12,H12)<6,"Partial","Complete")) -> Partial
A13: Client | B13: Client knows how to review/approve items | C13: Supports adoption | D13: Not Started | J13: =IF(COUNTA(A13,B13,D13,E13,F13,H13)=0,"Empty",IF(COUNTA(A13,B13,D13,E13,F13,H13)<6,"Partial","Complete")) -> Partial
... A16: Documentation | B16: Known limitations documented | C16: Avoids false expectations | D16: Not Started | J16: =IF(COUNTA(A16,B16,D16,E16,F16,H16)=0,"Empty",IF(COUNTA(A16,B16,D16,E16,F16,H16)<6,"Partial","Complete")) -> Partial
J17: =IF(COUNTA(A17,B17,D17,E17,F17,H17)=0,"Empty",IF(COUNTA(A17,B17,D17,E17,F17,H17)<6,"Partial","Complete")) -> Empty
J18: =IF(COUNTA(A18,B18,D18,E18,F18,H18)=0,"Empty",IF(COUNTA(A18,B18,D18,E18,F18,H18)<6,"Partial","Complete")) -> Empty
J19: =IF(COUNTA(A19,B19,D19,E19,F19,H19)=0,"Empty",IF(COUNTA(A19,B19,D19,E19,F19,H19)<6,"Partial","Complete")) -> Empty
J20: =IF(COUNTA(A20,B20,D20,E20,F20,H20)=0,"Empty",IF(COUNTA(A20,B20,D20,E20,F20,H20)<6,"Partial","Complete")) -> Empty
J21: =IF(COUNTA(A21,B21,D21,E21,F21,H21)=0,"Empty",IF(COUNTA(A21,B21,D21,E21,F21,H21)<6,"Partial","Complete")) -> Empty
J22: =IF(COUNTA(A22,B22,D22,E22,F22,H22)=0,"Empty",IF(COUNTA(A22,B22,D22,E22,F22,H22)<6,"Partial","Complete")) -> Empty
J23: =IF(COUNTA(A23,B23,D23,E23,F23,H23)=0,"Empty",IF(COUNTA(A23,B23,D23,E23,F23,H23)<6,"Partial","Complete")) -> Empty
J24: =IF(COUNTA(A24,B24,D24,E24,F24,H24)=0,"Empty",IF(COUNTA(A24,B24,D24,E24,F24,H24)<6,"Partial","Complete")) -> Empty
J25: =IF(COUNTA(A25,B25,D25,E25,F25,H25)=0,"Empty",IF(COUNTA(A25,B25,D25,E25,F25,H25)<6,"Partial","Complete")) -> Empty
J26: =IF(COUNTA(A26,B26,D26,E26,F26,H26)=0,"Empty",IF(COUNTA(A26,B26,D26,E26,F26,H26)<6,"Partial","Complete")) -> Empty
J27: =IF(COUNTA(A27,B27,D27,E27,F27,H27)=0,"Empty",IF(COUNTA(A27,B27,D27,E27,F27,H27)<6,"Partial","Complete")) -> Empty
J28: =IF(COUNTA(A28,B28,D28,E28,F28,H28)=0,"Empty",IF(COUNTA(A28,B28,D28,E28,F28,H28)<6,"Partial","Complete")) -> Empty
... J50: =IF(COUNTA(A50,B50,D50,E50,F50,H50)=0,"Empty",IF(COUNTA(A50,B50,D50,E50,F50,H50)<6,"Partial","Complete")) -> Empty

Sheet Launch Plan
A1: Launch Element | B1: Decision / Plan (EDIT) | C1: Owner (EDIT) | D1: Date / Time (EDIT) | E1: Dependencies | F1: Rollback Plan (EDIT) | G1: Client Communication (EDIT) | H1: PM Notes (POST)
A2: Launch date/time | E2: No critical blockers; client acceptance
A3: Production activation method | E3: Scenario schedule/webhook activation defined
A4: First live monitoring window | E4: Service provider available during first live run
A5: Client notification before launch | E5: Client knows what will happen and when
A6: Rollback trigger | E6: Define what failure requires rollback
A7: Rollback steps | E7: Backup scenario exists
A8: Post-launch review meeting | E8: At least first operational review scheduled

Sheet Monitoring & Support
A1: Monitoring Item | B1: What to Check | C1: Frequency (EDIT) | D1: Owner Role (EDIT) | E1: Alert Trigger / Threshold (EDIT) | F1: Alert Channel (EDIT) | G1: Response Target (EDIT) | H1: Escalation Rule (EDIT) | I1: Notes
A2: Scenario execution | B2: Failed or incomplete runs | C2: Daily | D2: Service Provider | E2: Any failed run | F2: Email/Make notification | G2: Same business day | H2: Escalate if repeated
A3: AI classification quality | B3: Wrong category or low-confidence pattern | C3: Weekly | D3: Service Provider | E3: More than 2 wrong cases/week | F3: Monthly review / email | G3: Next review cycle | H3: Update prompt/rules
A4: Human approval queue | B4: Items waiting too long | C4: Daily | D4: Client Owner | E4: Items older than agreed limit | F4: Email/CRM status | G4: Client-defined | H4: Notify client owner
A5: CRM/logging | B5: Records created correctly | C5: Weekly | D5: Service Provider | E5: Missing records or wrong fields | F5: Email | G5: Same business day | H5: Fix mapping
A6: Sensitive escalation | B6: Urgent/sensitive messages routed correctly | C6: Weekly | D6: Shared | E6: Any missed escalation | F6: Immediate alert | G6: Immediate review | H6: Pause risky route if needed
A7: API usage/costs | B7: Unusual usage or credit consumption | C7: Weekly/Monthly | D7: Service Provider | E7: Above budget/normal range | F7: Email/report | G7: Next review cycle | H7: Adjust schedule/model
A8: Client feedback | B8: Complaints, confusion, new needs | C8: Monthly | D8: Shared | E8: Client feedback received | F8: Meeting/email | G8: Monthly | H8: Add to improvement backlog

Sheet Operations Log
A1: Date | B1: Issue / Event Type | C1: Description | D1: Impact | E1: Priority | F1: Owner | G1: Status | H1: Root Cause | I1: Corrective Action | J1: Preventive Action | K1: Client Informed? | L1: Closed Date

Sheet Monthly Review
A1: Review Period | B1: Metric / Topic | C1: Target / Expectation | D1: Actual Result (EDIT) | E1: Status (EDIT) | F1: Insight / Interpretation (POST) | G1: Decision / Improvement (POST) | H1: Owner | I1: Due Date
B2: Number of failed runs | C2: 0 critical / low failed-run rate
B3: Wrong classifications | C3: Low and decreasing
B4: Messages routed to human review | C4: Useful, not excessive
B5: Average response/approval delay | C5: Within client expectation
B6: Client time saved | C6: Clear positive value
B7: New recurring request types | C7: Identify improvement needs
B8: Cost / API usage | C8: Within agreed budget
B9: Client feedback | C9: Positive or actionable

Sheet Improvement Backlog
A1: ID | B1: Improvement Request | C1: Source | D1: Business Value | E1: Risk / Complexity | F1: Package Impact | G1: Priority | H1: Status | I1: MVP or Later | J1: Owner | K1: Decision | L1: Notes | M1: Completeness Status (AUTO)
A2: IMP-001 | M2: =IF(COUNTA(B2,D2,E2,G2,H2,I2)=0,"Empty",IF(COUNTA(B2,D2,E2,G2,H2,I2)<6,"Partial","Complete")) -> Empty
A3: IMP-002 | M3: =IF(COUNTA(B3,D3,E3,G3,H3,I3)=0,"Empty",IF(COUNTA(B3,D3,E3,G3,H3,I3)<6,"Partial","Complete")) -> Empty
A4: IMP-003 | M4: =IF(COUNTA(B4,D4,E4,G4,H4,I4)=0,"Empty",IF(COUNTA(B4,D4,E4,G4,H4,I4)<6,"Partial","Complete")) -> Empty
A5: IMP-004 | M5: =IF(COUNTA(B5,D5,E5,G5,H5,I5)=0,"Empty",IF(COUNTA(B5,D5,E5,G5,H5,I5)<6,"Partial","Complete")) -> Empty
A6: IMP-005 | M6: =IF(COUNTA(B6,D6,E6,G6,H6,I6)=0,"Empty",IF(COUNTA(B6,D6,E6,G6,H6,I6)<6,"Partial","Complete")) -> Empty
A7: IMP-006 | M7: =IF(COUNTA(B7,D7,E7,G7,H7,I7)=0,"Empty",IF(COUNTA(B7,D7,E7,G7,H7,I7)<6,"Partial","Complete")) -> Empty
A8: IMP-007 | M8: =IF(COUNTA(B8,D8,E8,G8,H8,I8)=0,"Empty",IF(COUNTA(B8,D8,E8,G8,H8,I8)<6,"Partial","Complete")) -> Empty
A9: IMP-008 | M9: =IF(COUNTA(B9,D9,E9,G9,H9,I9)=0,"Empty",IF(COUNTA(B9,D9,E9,G9,H9,I9)<6,"Partial","Complete")) -> Empty
A10: IMP-009 | M10: =IF(COUNTA(B10,D10,E10,G10,H10,I10)=0,"Empty",IF(COUNTA(B10,D10,E10,G10,H10,I10)<6,"Partial","Complete")) -> Empty
A11: IMP-010 | M11: =IF(COUNTA(B11,D11,E11,G11,H11,I11)=0,"Empty",IF(COUNTA(B11,D11,E11,G11,H11,I11)<6,"Partial","Complete")) -> Empty
A12: IMP-011 | M12: =IF(COUNTA(B12,D12,E12,G12,H12,I12)=0,"Empty",IF(COUNTA(B12,D12,E12,G12,H12,I12)<6,"Partial","Complete")) -> Empty
A13: IMP-012 | M13: =IF(COUNTA(B13,D13,E13,G13,H13,I13)=0,"Empty",IF(COUNTA(B13,D13,E13,G13,H13,I13)<6,"Partial","Complete")) -> Empty
... A21: IMP-020 | M21: =IF(COUNTA(B21,D21,E21,G21,H21,I21)=0,"Empty",IF(COUNTA(B21,D21,E21,G21,H21,I21)<6,"Partial","Complete")) -> Empty
M22: =IF(COUNTA(B22,D22,E22,G22,H22,I22)=0,"Empty",IF(COUNTA(B22,D22,E22,G22,H22,I22)<6,"Partial","Complete")) -> Empty
M23: =IF(COUNTA(B23,D23,E23,G23,H23,I23)=0,"Empty",IF(COUNTA(B23,D23,E23,G23,H23,I23)<6,"Partial","Complete")) -> Empty
M24: =IF(COUNTA(B24,D24,E24,G24,H24,I24)=0,"Empty",IF(COUNTA(B24,D24,E24,G24,H24,I24)<6,"Partial","Complete")) -> Empty
M25: =IF(COUNTA(B25,D25,E25,G25,H25,I25)=0,"Empty",IF(COUNTA(B25,D25,E25,G25,H25,I25)<6,"Partial","Complete")) -> Empty
M26: =IF(COUNTA(B26,D26,E26,G26,H26,I26)=0,"Empty",IF(COUNTA(B26,D26,E26,G26,H26,I26)<6,"Partial","Complete")) -> Empty
M27: =IF(COUNTA(B27,D27,E27,G27,H27,I27)=0,"Empty",IF(COUNTA(B27,D27,E27,G27,H27,I27)<6,"Partial","Complete")) -> Empty
M28: =IF(COUNTA(B28,D28,E28,G28,H28,I28)=0,"Empty",IF(COUNTA(B28,D28,E28,G28,H28,I28)<6,"Partial","Complete")) -> Empty
M29: =IF(COUNTA(B29,D29,E29,G29,H29,I29)=0,"Empty",IF(COUNTA(B29,D29,E29,G29,H29,I29)<6,"Partial","Complete")) -> Empty
M30: =IF(COUNTA(B30,D30,E30,G30,H30,I30)=0,"Empty",IF(COUNTA(B30,D30,E30,G30,H30,I30)<6,"Partial","Complete")) -> Empty
M31: =IF(COUNTA(B31,D31,E31,G31,H31,I31)=0,"Empty",IF(COUNTA(B31,D31,E31,G31,H31,I31)<6,"Partial","Complete")) -> Empty
M32: =IF(COUNTA(B32,D32,E32,G32,H32,I32)=0,"Empty",IF(COUNTA(B32,D32,E32,G32,H32,I32)<6,"Partial","Complete")) -> Empty
M33: =IF(COUNTA(B33,D33,E33,G33,H33,I33)=0,"Empty",IF(COUNTA(B33,D33,E33,G33,H33,I33)<6,"Partial","Complete")) -> Empty
... M100: =IF(COUNTA(B100,D100,E100,G100,H100,I100)=0,"Empty",IF(COUNTA(B100,D100,E100,G100,H100,I100)<6,"Partial","Complete")) -> Empty

Sheet Client Handover
A1: Handover Area | B1: What is Delivered / Explained | C1: Client Owner (EDIT) | D1: Service Provider Owner (EDIT) | E1: Status (EDIT) | F1: Evidence / Link (EDIT) | G1: Notes
A2: Workflow overview | B2: Explain what automation does and does not do | E2: Not Started
A3: Review/approval process | B3: Show where client reviews AI drafts or escalated items | E3: Not Started
A4: Access ownership | B4: Confirm client owns business-critical accounts | E4: Not Started
A5: Support process | B5: Explain how to report issues/change requests | E5: Not Started
A6: Monitoring/reporting | B6: Explain monitoring frequency and monthly review | E6: Not Started
A7: Limitations | B7: Explain exclusions and known limitations | E7: Not Started
A8: Emergency fallback | B8: Explain what happens if automation fails | E8: Not Started
A9: Acceptance confirmation | B9: Client confirms launch acceptance | E9: Not Started

Sheet Final Phase6 Summary
A1: Field | B1: Summary / Decision (EDIT) | C1: Notes
A2: Client / Project
A3: Package Direction | C3: Basic / Pro / Managed / Agentic / Mixed
A4: Go-live Date
A5: Live Channels
A6: Live Automations
A7: Human Approval Points
A8: Monitoring Model
A9: Support Model
A10: Known Limitations
A11: Next Review Date
A12: Next Improvement Priorities
A13: Final Phase 6 Status | C13: Launched / Conditional / Not Launched
A15: Phase 6 at a Glance (auto-computed)
A16: Go-live checklist items — Done | D16: =COUNTIF('Go-live Checklist'!D2:D50,"Done") -> 0
A17: Go-live blockers — Yes | D17: =COUNTIF('Go-live Checklist'!H2:H50,"Yes") -> 0
A18: Client Handover items — Done | D18: =COUNTIF('Client Handover'!E2:E100,"Done") -> 0
A19: Operations Log — issues recorded | D19: =COUNTA('Operations Log'!A2:A200) -> 0
A20: Operations Log — open (Not Started + In Progress) | D20: =COUNTIF('Operations Log'!G2:G200,"Not Started")+COUNTIF('Operations Log'!G2:G200,"In Progress") -> 0
A21: Operations Log — closed (Done) | D21: =COUNTIF('Operations Log'!G2:G200,"Done") -> 0
A22: Improvement Backlog — recorded | D22: =COUNTA('Improvement Backlog'!A2:A100) -> 20
A23: Improvement Backlog — Done | D23: =COUNTIF('Improvement Backlog'!H2:H100,"Done") -> 0
A24: Improvement Backlog — MVP scope | D24: =COUNTIF('Improvement Backlog'!I2:I100,"MVP") -> 0
A25: Improvement Backlog — Later | D25: =COUNTIF('Improvement Backlog'!I2:I100,"Later") -> 0
A26: Monthly Review — Action Needed items | D26: =COUNTIF('Monthly Review'!E2:E100,"Action Needed") -> 0
