Workbook

Sheet START HERE
B2: AI Automation Pricing Calculator - SAFE VERSION
B4: Purpose | C4: Clean, Excel-safe pricing workbook. It avoids advanced lookup formulas, tables, and data-validation objects that can sometimes trigger Excel repair messages.
B5: How to use | C5: Use Package Reference to select the package. Then manually copy the base low/high values into Quote Calculator yellow cells.
B6: Yellow cells | C6: Editable input cells.
B7: Blue cells | C7: Calculated output cells.
B8: Grey/reference sheets | C8: Internal reference and examples.
B9: Why this safe version | C9: Previous workbook likely had a compatibility/repair issue caused by advanced formulas or workbook metadata. This version uses simple formulas only.
B10: Client sharing | C10: Do not send internal pricing logic to client. Use Client Quote Summary as a clean external view.
B11: Version | C11: safe v4 - editable reference lists + auto lookup
B12: Created | C12: 2026-06-23
B13: Recommended workflow | C13: 1) pick package → 2) copy base ranges → 3) enter complexity → 4) review calculated quote → 5) copy client summary.
B14: Audit note | C14: Use 'Quote Calculator FIXED' for commercial quotes. Original calculator is retained as legacy/comparison.

Sheet Product Catalogue
A1: VortexDeep — Product Catalogue
A2: Three levels: AREA › SUB-AREA (job) › AUTOMATION (the thing we build & price). Representative, not exhaustive — the list expands. Each automation shows the task PATTERN it uses (patterns recur across areas — that's our reusable IP). ★ = shortlist ready for the website.
A4: PATTERNS (the verbs): | B4: Capture · Classify & route · Draft & reply · Extract & validate · Schedule & book · Summarise & report · Monitor & alert · Sync & log
A6: Area | B6: Sub-area (job) | C6: Automation | D6: Pattern(s) | E6: ★ Site
A7: Communication & Customers
B8: Communication & Intake
C9: Pull every enquiry (form, email, voicemail) into one list | D9: Capture | E9: ★
C10: Sort by topic, urgency and language | D10: Classify & route | E10: ★
C11: Draft a holding reply for each, for your approval | D11: Draft & reply | E11: ★
C12: Route each to the right person or inbox | D12: Classify & route
C13: Flag anything urgent or unusual | D13: Monitor & alert
C14: Log every enquiry with its outcome | D14: Sync & log
B15: Customer Support
C16: Auto-answer repeat questions (order status, returns, how-to) | D16: Draft & reply | E16: ★
C17: Detect and surface urgent tickets first | D17: Classify & route | E17: ★
C18: Draft replies from your knowledge base | D18: Draft & reply | E18: ★
C19: Escalate anything the AI is unsure about | D19: Monitor & alert
C20: Tag and log resolved tickets | D20: Sync & log
B21: Scheduling & Booking
C22: Take booking requests any time and offer real slots | D22: Schedule & book | E22: ★
C23: Send confirmations and reminders | D23: Schedule & book | E23: ★
C24: Prevent double-bookings | D24: Schedule & book | E24: ★
C25: Reschedule / cancel on request | D25: Schedule & book
C26: Chase no-show risks the day before | D26: Monitor & alert
C27: Coordinate group or multi-person slots | D27: Schedule & book
B28: Feedback & Reviews
C29: Collect feedback from email, reviews and surveys in one place | D29: Capture | E29: ★
C30: Sort praise vs complaints vs questions | D30: Classify & route | E30: ★
C31: Draft a reply to each, for approval | D31: Draft & reply | E31: ★
C32: Alert on negative reviews fast | D32: Monitor & alert
C33: Summarise themes each week | D33: Summarise & report
A34: Sales & Growth
B35: Lead & Sales Pipeline
C36: Capture leads from forms, events and referrals | D36: Capture | E36: ★
C37: Score and prioritise the promising ones | D37: Classify & route | E37: ★
C38: Draft first-touch and follow-up messages | D38: Draft & reply | E38: ★
C39: Nudge stalled deals before they go cold | D39: Monitor & alert | E39: ★
C40: Keep the CRM updated automatically | D40: Sync & log
C41: Weekly pipeline summary | D41: Summarise & report
B42: Content & Marketing
...

Sheet Package Reference
B2: Package Pricing Reference
B3: EDITABLE RANGE: update package names, price ranges, scope notes and access model here. Quote Calculator reads columns A:E by package name.
B5: Package | C5: Setup Low | D5: Setup High | E5: Monthly Low | F5: Monthly High | G5: Typical scope | H5: Best for | I5: Access model | J5: Internal note | K5: Commercial label | L5: Typical use by automation type
B6: Basic Intake | C6: 750 | D6: 1800 | E6: 150 | F6: 450 | G6: Email/forms intake, rule-based routing, booking link, simple folders/labels | H6: Simple intake, low complexity | I6: Results/dashboard only | J6: Keep scope tight | K6: AI Intake Basic | L6: Communication & Intake; Document routing (no AI extraction); E-commerce order notifications; Finance reminders. Rule-based only — no AI required.
B7: Basic+ AI Triage | C7: 1500 | D7: 3500 | E7: 300 | F7: 750 | G7: AI classification, CRM/Notion log, folder routing, draft support | H7: MG Red Shift-style workflow | I7: Results/dashboard + workflow summary | J7: Good first AI package | K7: AI Intake Triage Basic+ | L7: Communication & Intake (AI classify); Lead & Sales Pipeline (CRM log); Document Processing (AI field extraction); Customer Support (ticket triage); E-commerce (AI categorisation).
B8: Pro Multi-Channel | C8: 3500 | D8: 7500 | E8: 750 | F8: 1500 | G8: Email + social media, AI classification, drafts, approval workflow | H8: Multiple channels, repeated questions | I8: Dashboard + workflow chart | J8: Needs fallback and approval gates | K8: AI Workflow Pro | L8: Communication & Intake (multi-source); Content & Marketing (AI draft + publish review); Lead & Sales Pipeline (multi-source pipeline); Document Processing (multi-source); Customer Support (multi-channel triage).
B9: Managed Operations | C9: 7500 | D9: 15000 | E9: 1500 | F9: 3500 | G9: CRM, monitoring, reports, monthly improvements, support | H9: Ongoing operational support | I9: Dashboard, reports, limited logic visibility | J9: Define support limits | K9: Managed AI Operations | L9: Reporting & Analytics (KPI digests, management reports); Finance & Admin (reconciliation, overdue reminders); Internal Ops & Approvals (ongoing routing); Scheduling & Booking (managed flows). Any category requiring ongoing monitoring and improvement.
B10: Agentic Automation | C10: 12000 | D10: 30000 | E10: 2500 | F10: 6000 | G10: Calendar/CRM actions, multi-step decisions, audit and governance | H10: Complex controlled actions | I10: Approval console + blueprint summary | J10: Quote individually | K10: Agentic AI Operations | L10: Scheduling & Booking (AI slot proposals, calendar actions); Lead & Sales Pipeline (autonomous follow-up sequences); Finance & Admin (exception detection + action); Internal Ops (conditional approval chains). Any category needing multi-step AI decisions with audit.
B11: Build-and-Transfer | C11: 4500 | D11: 15000 | E11: 0 | F11: 1000 | G11: Automation built in client workspace and handed over | H11: Client wants ownership | I11: Full access/export/documentation | J11: LEGACY — do not select as package. Use a scope package in C5 and set Access model = Build-and-transfer in C6. | K11: Build & Transfer | L11: All automation categories — applies when client requires full IP and operational ownership post-handover, regardless of automation type.

Sheet Complexity Reference
B2: Complexity Adders & Multipliers | L2: Support Model Lookup - Editable
B4: Factor | C4: Setup Low | D4: Setup High | E4: Monthly Low | F4: Monthly High | G4: Rule | H4: When to apply | I4: Notes | J4: Example | L4: Support Model | M4: Monthly Multiplier | N4: Setup Handover Multiplier | O4: Typical Use | P4: Client Access | Q4: Support Responsibility | R4: Pricing Note | S4: Internal Note
B5: Extra data sources / triggers | C5: 500 | D5: 1500 | E5: 100 | F5: 300 | G5: per source / trigger | H5: Additional data source, trigger, or inbound channel beyond the scope included in the package | I5: Email inbox, social DM, document upload trigger, API feed, scheduled database poll | J5: invoice email trigger + webhook + Instagram DM = 3 sources | L5: No support | M5: 0 | N5: 1 | O5: Build-and-transfer with no monthly support | P5: Full handover | Q5: None after handover | R5: 0x monthly | S5: Legacy setup multiplier normalized to 1. Setup premium now belongs to Access Models / fixed calculator.
B6: AI generation steps | C6: 500 | D6: 2000 | E6: 150 | F6: 500 | G6: per workflow type | H6: AI generates any output: reply drafts, extracted document fields, summarised text, repurposed content | I6: Each distinct AI generation type adds complexity — count per type, not per execution | J6: invoice field extraction + booking reply draft = 2 generation steps | L6: Light support | M6: 0.5 | N6: 1 | O6: Client owns automation, occasional help | P6: Full/limited | Q6: Limited fixes | R6: 0.5x monthly | S6: Legacy setup multiplier normalized to 1. Setup premium now belongs to Access Models / fixed calculator.
B7: CRM integration | C7: 750 | D7: 2500 | E7: 200 | F7: 600 | G7: per CRM | H7: Notion/Airtable/HubSpot records | I7: Status and field mapping | J7: Notion DB | L7: Normal managed support | M7: 1 | N7: 1 | O7: Default managed service | P7: Dashboard/results | Q7: Normal monitoring/support | R7: 1.0x monthly | S7: Default.
B8: Approval workflow | C8: 750 | D8: 2000 | E8: 150 | F8: 500 | G8: per approval path | H8: Human review needed | I8: Important for sensitive sectors | J8: approve before send | L8: High-responsibility maintenance | M8: 1.5 | N8: 1 | O8: Important business workflow | P8: Dashboard/results + stronger control | Q8: Higher reliability support | R8: 1.5x monthly | S8: Setup premium should be explicit via access model/manual add, not hidden in support model.
B9: Reporting layer | C9: 500 | D9: 2000 | E9: 250 | F9: 900 | G9: yes/no | H9: Dashboards, summaries, KPI reports | I9: Managed service | J9: monthly report | L9: Premium transfer support | M9: 2 | N9: 1 | O9: Transferred asset but you still maintain | P9: Full handover | Q9: Ongoing maintenance | R9: 2.0x monthly | S9: Use Access Models / fixed calculator for transfer setup premium.
B10: Sensitive data | C10: 0 | D10: 0 | E10: 0 | F10: 0 | G10: x1.3 to x1.7 | H10: Health/legal/finance/high privacy | I10: Apply mainly to setup and monthly | J10: therapist | L10: Critical support | M10: 3 | N10: 1 | O10: Complex/agentic/high-risk system | P10: Full/controlled | Q10: High responsibility | R10: Up to 3.0x monthly | S10: Use manual setup add/urgency multiplier for critical setup impact.
B11: Urgency | C11: 0 | D11: 0 | E11: 0 | F11: 0 | G11: x1.2 to x1.5 | H11: Fast delivery required | I11: Apply to setup | J11: launch this week
B12: Full handover | C12: 0 | D12: 0 | E12: 0 | F12: 0 | G12: x1.5 to x3.0 | H12: Client receives scenario/blueprint | I12: Build-and-transfer | J12: own Make workspace
B14: Monthly support model | C14: Monthly multiplier | D14: Typical monthly logic | E14: Use when | F14: Client receives | G14: You remain responsible for | H14: Example | I14: Pricing note | J14: Internal decision
B15: No support | C15: 0 | D15: No recurring fee | E15: Build-and-transfer with no support | F15: Delivered automation only | G15: Nothing after handover | H15: client self-maintains | I15: 0x monthly | J15: Use rarely
B16: Light support | C16: 0.5 | D16: Ad-hoc checks / small fixes | E16: Client owns automation but may need help | F16: Occasional support | G16: Limited support only | H16: quarterly help | I16: 0.5x to 1.0x monthly | J16: Define hours
B17: Normal managed support | C17: 1 | D17: Standard monitoring and minor improvements | E17: Managed service default | F17: Reports/support | G17: Normal reliability support | H17: Basic+/Pro managed | I17: 1.0x monthly | J17: Default
B18: High-responsibility maintenance | C18: 1.5 | D18: Strong monitoring, quick fixes, change support | E18: Client owns or depends heavily on system | F18: Higher support availability | G18: Higher operational responsibility | H18: mission-critical workflow | I18: 1.5x to 3.0x monthly | J18: Premium
B19: Premium transfer support | C19: 2 | D19: Transferred asset + ongoing maintenance | E19: Build-and-transfer but you still maintain it | F19: Full asset + managed care | G19: Ongoing maintenance despite transfer | H19: client owns Make, you maintain | I19: 2.0x typical | J19: Charge clearly
B20: Critical support | C20: 3 | D20: High urgency / high responsibility | E20: Complex agentic systems | F20: Priority support | G20: Major ongoing responsibility | H20: Calendar/CRM agent with SLA-like expectation | I20: Up to 3.0x monthly | J20: Custom quote

Sheet Quote Calculator
B2: Quote Calculator — Package / Access Model / Support Model (v8)
B4: Step | C4: Field | D4: Value | E4: Explanation | G4: Client-facing summary | K4: Available Packages | M4: Available Access Models | O4: Available Support Models | R4: Support model | U4: Meaning
B5: 1 | C5: Client / project name | E5: EDIT | G5: Project | H5: =D5 -> 0 | K5: ='Package Reference'!B6 -> Basic Intake | M5: ='Access Models'!B6 -> Managed service | O5: ='Complexity Reference'!L5 -> No support | R5: No support | U5: build-and-transfer, client owns risk
B6: 2 | C6: Selected package | D6: Basic Intake | E6: EDIT: scope package only — excludes Build-and-Transfer (use Access model C6 = Build-and-transfer for handover projects) | G6: Package | H6: =D6 -> Basic Intake | K6: ='Package Reference'!B7 -> Basic+ AI Triage | M6: ='Access Models'!B7 -> Logic visibility | O6: ='Complexity Reference'!L6 -> Light support | R6: Light support | U6: occasional checks/fixes
B7: 3 | C7: Access / ownership model | D7: Managed service | E7: EDIT: controls setup/handover premium only (not monthly) | G7: Access model | H7: =D7 -> Managed service | K7: ='Package Reference'!B8 -> Pro Multi-Channel | M7: ='Access Models'!B8 -> Limited admin | O7: ='Complexity Reference'!L7 -> Normal managed support | R7: Normal managed support | U7: default for business workflow
B8: 4 | C8: Support model | D8: Normal managed support | E8: EDIT: controls monthly maintenance cost only (not setup) | G8: Support model | H8: =D8 -> Normal managed support | K8: ='Package Reference'!B9 -> Managed Operations | M8: ='Access Models'!B9 -> Client-owned workspace | O8: ='Complexity Reference'!L8 -> High-responsibility maintenance | R8: High-responsibility support | U8: stronger monitoring, faster response
G9: Setup range | H9: ="CHF "&ROUND(D35,0)&" - CHF "&ROUND(D36,0) -> CHF 2250 - CHF 6300 | K9: ='Package Reference'!B10 -> Agentic Automation | M9: ='Access Models'!B10 -> Build-and-transfer | O9: ='Complexity Reference'!L9 -> Premium transfer support | R9: Agentic Automation | U9: Premium transfer support
B10: 5 | C10: Base setup low | D10: =IFERROR(VLOOKUP(D6,'Package Reference'!$B$6:$F$10,2,FALSE()),0) -> 750 | E10: CALC from Package Reference | G10: Monthly range | H10: ="CHF "&ROUND(D37,0)&" - CHF "&ROUND(D38,0) -> CHF 500 - CHF 1550 | O10: ='Complexity Reference'!L10 -> Critical support | R10: Critical support | U10: for operationally sensitive workflows
B11: 6 | C11: Base setup high | D11: =IFERROR(VLOOKUP(D6,'Package Reference'!$B$6:$F$10,3,FALSE()),0) -> 1800 | E11: CALC from Package Reference | G11: Recommended setup | H11: ="CHF "&ROUND(D39,0) -> CHF 4300
B12: 7 | C12: Base monthly low | D12: =IFERROR(VLOOKUP(D6,'Package Reference'!$B$6:$F$10,4,FALSE()),0) -> 150 | E12: CALC from Package Reference | G12: Recommended monthly | H12: ="CHF "&ROUND(D40,0) -> CHF 1000
B13: 8 | C13: Base monthly high | D13: =IFERROR(VLOOKUP(D6,'Package Reference'!$B$6:$F$10,5,FALSE()),0) -> 450 | E13: CALC from Package Reference | G13: Notes | H13: Prices exclude third-party tool/API usage unless agreed.
B14: 9 | C14: Auto access setup multiplier | D14: =IFERROR(VLOOKUP(D7,'Access Models'!$B$6:$L$10,10,FALSE()),1) -> 1 | E14: CALC from Access Models col J — access model controls setup premium, not support model | G14: List sources | H14: Package Ref A4:A9 | Access Models A4:A8 | Complexity Ref K4:K9
B15: 10 | C15: Auto monthly support multiplier | D15: =IFERROR(VLOOKUP(D8,'Complexity Reference'!$L$5:$N$10,2,FALSE()),1) -> 1 | E15: CALC from support model (monthly multiplier only)
B17: 11 | C17: Extra data sources / triggers count | D17: 0 | E17: EDIT: count each additional data source, trigger, or inbound channel beyond the base package. In Make.com: each separate webhook endpoint, app trigger, API source, or scheduled data pull. E.g. Instagram DM = 1, invoice email inbox = 1, API poll = 1. Do NOT count the primary source included in the selected package. | G17: Extra data sources / triggers — examples | H17: Each distinct inbound source beyond the base package (separate webhook endpoint, app trigger or API feed).
B18: 12 | C18: AI generation steps count | D18: 1 | E18: EDIT: count each distinct AI generation step — any HTTP module calling OpenAI or Claude for any purpose. Count per generation TYPE, not per execution. E.g. booking reply draft = 1. Invoice field extraction + booking reply draft = 2. Content repurposing call = 1. | G18: Example values:
B19: 13 | C19: CRM integrations count | D19: 1 | E19: EDIT: count each external CRM or database system connected via Make.com (Notion, HubSpot, Airtable, Google Sheets used as a CRM, etc.). Count per SYSTEM, not per module. Notion with 3 Notion modules = still 1. Notion + HubSpot = 2. | G19: Primary source included in package = 0
B20: 14 | C20: Approval workflows count | D20: 1 | E20: EDIT: count each route where Make.com pauses and a human must review and approve before the automation sends or acts. SEEKER draft reviewed by human before reply = 1. Auto folder-move with no human gate = 0. Multiple gated routes = count each gate separately. | G20: Website form on a separate webhook = 1
B21: 15 | C21: Reporting layer count | D21: 0 | E21: EDIT: 0 or 1. Use 1 only if the automation writes structured output to a reporting layer: Google Sheets analytics view, Notion summary dashboard, or similar. Test-folder logging does NOT count. Standard Notion CRM entries do NOT count as reporting. | G21: Website form + Instagram DM = 2; or invoice email + webhook = 2
B22: 16 | C22: Sensitive data multiplier | D22: 1 | E22: EDIT: normal = 1.0. Increase if handling sensitive data: 1.3 for confidential business info (contracts, financials, HR); 1.5 for GDPR-sensitive or EU-only data; 1.7 for health records or personal identity data. Always discuss data handling explicitly with the client before applying. | G22: Website + Instagram + invoice email = 3; or 3 distinct API sources = 3
B23: 17 | C23: Urgency multiplier | D23: 1 | E23: EDIT: normal = 1.0. Use 1.2 for 2–3 week delivery. Use 1.3–1.5 for hard deadlines within days (compressed build, testing and handover). Never exceed 1.5.
B24: 18 | C24: Manual setup multiplier override | E24: OPTIONAL EDIT: leave blank to use the access model auto-value (from the col L lookup). Override only when the auto value does not fit — e.g. Managed service selected but this project has unusually complex API credential setup or multi-environment staging. | G24: AI generation steps — examples | H24: Each distinct HTTP module calling OpenAI / Claude (count per draft type, any email volume).
B25: 19 | C25: Manual monthly support multiplier override | E25: OPTIONAL EDIT: leave blank to use the support model auto-value. Override only when the auto value does not reflect the agreed SLA — e.g. Normal support selected but client has a faster-response agreement that is not yet in the reference table. | G25: Example values:
B26: 20 | C26: Manual custom setup add | D26: 0 | E26: EDIT: add one-time costs not covered by the package adder prices. — Make.com plan upgrade (if client account needs a higher ops tier) — Third-party API onboarding or account setup fee — Domain / DNS configuration — First-month OpenAI / Claude credit (if client pre-funds a budget) OPERATIONAL PASS-THROUGH: Make.com operations and API token costs are variable and best invoiced monthly with actuals. Use this field for a one-time estimate only if the client needs a total upfront budget figure. | G26: Classify or route only, no AI generation call = 0
B27: 21 | C27: Manual custom monthly add | D27: 0 | E27: EDIT: add ongoing monthly operational costs not covered by the support multiplier. These are direct pass-through costs you pay to providers: — Make.com operations budget: CHF 15–30/month simple (< 500 ops/day); CHF 30–60/month moderate (500–2,000 ops/day); CHF 60–120/month complex multi-branch scenario — OpenAI / Claude API tokens: CHF 10–20/month for ~200–500 AI drafts; CHF 20–40/month for ~500–2,000 AI drafts Best practice: leave C26 = 0 in the quote and invoice these monthly with actuals. Only fix a value here if the client requires a total-cost-of-ownership budget upfront. | G27: One AI generation type (reply draft, field extraction, or content call) = 1
G28: Booking reply draft + invoice field extraction = 2; or repurposing + reply = 2
C29: Effective setup/access multiplier | D29: =IF(D24="",D14,D24) -> 1 | E29: CALC
C30: Effective monthly support multiplier | D30: =IF(D25="",D15,D25) -> 1 | E30: CALC | G30: CRM integrations — Make.com context | H30: Each external database / CRM connected (Notion, HubSpot, Airtable, Google Sheets as CRM). Count per system, not per module.
C31: Setup subtotal low (before multipliers) | D31: =D10+D17*IFERROR(VLOOKUP("Extra channel",'Complexity Reference'!$B$5:$F$9,2,FALSE()),0)+D18*IFERROR(VLOOKUP("AI draft workflow",'Complexity Reference'!$B$5:$F$9,2,FALSE()),0)+D19*IFERROR(VLOOKUP("CRM integration",'Complexity Reference'!$B$5:$F$9,2,FALSE()),0)+D20*IFERROR(VLOOKUP("Approval workflow",'Complexity Reference'!$B$5:$F$9,2,FALSE()),0)+D21*IFERROR(VLOOKUP("Reporting layer",'Complexity Reference'!$B$5:$F$9,2,FALSE()),0)+D26 -> 2250 | E31: CALC | G31: Example values:
C32: Setup subtotal high (before multipliers) | D32: =D11+D17*IFERROR(VLOOKUP("Extra channel",'Complexity Reference'!$B$5:$F$9,3,FALSE()),0)+D18*IFERROR(VLOOKUP("AI draft workflow",'Complexity Reference'!$B$5:$F$9,3,FALSE()),0)+D19*IFERROR(VLOOKUP("CRM integration",'Complexity Reference'!$B$5:$F$9,3,FALSE()),0)+D20*IFERROR(VLOOKUP("Approval workflow",'Complexity Reference'!$B$5:$F$9,3,FALSE()),0)+D21*IFERROR(VLOOKUP("Reporting layer",'Complexity Reference'!$B$5:$F$9,3,FALSE()),0)+D26 -> 6300 | E32: CALC | G32: Folder routing only, no CRM = 0
C33: Monthly subtotal low (before support multiplier) | D33: =D12+D17*IFERROR(VLOOKUP("Extra channel",'Complexity Reference'!$B$5:$F$9,4,FALSE()),0)+D18*IFERROR(VLOOKUP("AI draft workflow",'Complexity Reference'!$B$5:$F$9,4,FALSE()),0)+D19*IFERROR(VLOOKUP("CRM integration",'Complexity Reference'!$B$5:$F$9,4,FALSE()),0)+D20*IFERROR(VLOOKUP("Approval workflow",'Complexity Reference'!$B$5:$F$9,4,FALSE()),0)+D21*IFERROR(VLOOKUP("Reporting layer",'Complexity Reference'!$B$5:$F$9,4,FALSE()),0)+D27 -> 500 | E33: CALC | G33: Notion only (any number of Notion modules) = 1
C34: Monthly subtotal high (before support multiplier) | D34: =D13+D17*IFERROR(VLOOKUP("Extra channel",'Complexity Reference'!$B$5:$F$9,5,FALSE()),0)+D18*IFERROR(VLOOKUP("AI draft workflow",'Complexity Reference'!$B$5:$F$9,5,FALSE()),0)+D19*IFERROR(VLOOKUP("CRM integration",'Complexity Reference'!$B$5:$F$9,5,FALSE()),0)+D20*IFERROR(VLOOKUP("Approval workflow",'Complexity Reference'!$B$5:$F$9,5,FALSE()),0)+D21*IFERROR(VLOOKUP("Reporting layer",'Complexity Reference'!$B$5:$F$9,5,FALSE()),0)+D27 -> 1550 | E34: CALC | G34: Notion + HubSpot = 2
C35: Calculated setup low | D35: =ROUND(D31*D22*D23*D29,0) -> 2250 | E35: CALC
C36: Calculated setup high | D36: =ROUND(D32*D22*D23*D29,0) -> 6300 | E36: CALC | G36: Approval workflows — Make.com context | H36: Each route where Make.com pauses and a human must review / approve before it sends or acts.
C37: Calculated monthly low | D37: =ROUND(D33*D22*D30,0) -> 500 | E37: CALC | G37: Example values:
C38: Calculated monthly high | D38: =ROUND(D34*D22*D30,0) -> 1550 | E38: CALC | G38: Auto folder-move only, no human gate = 0
C39: Recommended setup quote | D39: =ROUND((D35+D36)/2,-2) -> 4300 | E39: CALC | G39: SEEKER draft reviewed by human before reply = 1
C40: Recommended monthly quote | D40: =ROUND((D37+D38)/2,-2) -> 1000 | E40: CALC | G40: SEEKER gated + LEAD CRM entry requires approval = 2
C42: Quote Sanity Check (auto) | G42: Reporting layer — Make.com context
C43: Check | D43: Status | E43: Detail | G43: Example values:
C44: Package name matches Reference | D44: =IF(D6="","empty",IF(D10=0,"FAIL","OK")) -> OK | E44: =IF(D6="","Pick a package from column J (5 scope packages only).",IF(D10=0,IF(LOWER(D6)="build-and-transfer","Build-and-Transfer is an access model — select scope package in C5 and set C6 = Build-and-transfer.","Package name doesn't match Package Reference — use column J list."),"Package found in Reference.")) -> Package found in Reference. | G44: Test-folder log only = 0
...

Sheet ROI App
B2: ROI Automation Calculator
B4: Field | C4: Value | D4: Unit / Notes | G4: CASE STUDY | J4: CASE STUDY
B5: 1. CLIENT INPUTS | G5: MG1 | J5: MG2
B6: Hard ROI — Time Savings
B7: Employees Involved | C7: 2 | D7: people | G7: 4 | H7: people | J7: 2 | K7: people
B8: Hours Lost / Week | C8: 5 | D8: hours / week | G8: 2 | H8: hours / week | J8: 2 | K8: hours / week
B9: Hourly Rate (Gross) | C9: 100 | D9: CHF / hour | G9: 80 | H9: CHF / hour | J9: 80 | K9: CHF / hour
B11: Hard ROI — Error Reduction
B12: Mistakes / Week | C12: 5 | D12: mistakes / week | G12: 1 | H12: mistakes / week | J12: 1 | K12: mistakes / week
B13: Cost per Mistake | C13: 200 | D13: CHF / mistake | G13: 75 | H13: CHF / mistake | J13: 125 | K13: CHF / mistake
B15: Soft ROI — Lost Revenue
B16: Lost Leads / Month | C16: 10 | D16: leads / month | G16: 1 | H16: leads / month | J16: 2 | K16: leads / month
B17: Avg Value per Lead | C17: 1500 | D17: CHF / lead | G17: 1000 | H17: CHF / lead | J17: 125 | K17: CHF / lead
B19: Investment & Ongoing Costs
B20: One-Time Setup Cost | C20: 20000 | D20: CHF total | G20: 3500 | H20: CHF total | J20: 2500 | K20: CHF total
B21: Monthly Managed AI Ops Cost | C21: 2350 | D21: CHF / month — paste from Quote Calculator C39 (Recommended monthly quote) | G21: 1600 | H21: CHF / month | J21: 800 | K21: CHF / month
B23: 2. CALCULATED ROI | G23: ROI | J23: ROI
B25: Monthly Cost of Time | C25: =C7*C8*C9*4 -> 4000 | D25: CHF | G25: =G7*G8*G9*4 -> 2560 | H25: CHF | J25: =J7*J8*J9*4 -> 1280 | K25: CHF
B26: Monthly Cost of Errors | C26: =C12*C13*4 -> 4000 | D26: CHF | G26: =G12*G13*4 -> 300 | H26: CHF | J26: =J12*J13*4 -> 500 | K26: CHF
B27: Monthly Lost Revenue | C27: =C16*C17 -> 15000 | D27: CHF | G27: =G16*G17 -> 1000 | H27: CHF | J27: =J16*J17 -> 250 | K27: CHF
B28: Monthly Gross Benefit | C28: =SUM(C25:C27) -> 23000 | D28: CHF — cost of inaction | G28: =SUM(G25:G27) -> 3860 | H28: CHF — cost of inaction | J28: =SUM(J25:J27) -> 2030 | K28: CHF — cost of inaction
B29: (−) Monthly Managed AI Ops | C29: =C21 -> 2350 | D29: CHF | G29: =G21 -> 1600 | H29: CHF | J29: =J21 -> 800 | K29: CHF
B30: Net Monthly Benefit | C30: =C28-C29 -> 20650 | D30: CHF | G30: =G28-G29 -> 2260 | H30: CHF | J30: =J28-J29 -> 1230 | K30: CHF
B31: Annual Net Benefit | C31: =C30*12 -> 247800 | D31: CHF | G31: =G30*12 -> 27120 | H31: CHF | J31: =J30*12 -> 14760 | K31: CHF
B32: Total Year 1 Investment | C32: =C20+C21*12 -> 48200 | D32: CHF — setup + 12× monthly managed | G32: =G20+G21*12 -> 22700 | H32: CHF | J32: =J20+J21*12 -> 12100 | K32: CHF
B33: Payback Period | C33: =IF(C30<=0,"N/A",C20/C30) -> 0.968523 | D33: Months | G33: =IF(G30<=0,"N/A",G20/G30) -> 1.5486726 | H33: Months | J33: =IF(J30<=0,"N/A",J20/J30) -> 2.0325203 | K33: Months
B34: First-Year Net ROI | C34: =IF(C32=0,"N/A",(C31-C20)/C32) -> 4.7261411 | D34: % — net Y1 return ÷ total Y1 investment (setup + 12× monthly) | G34: =IF(G32=0,"N/A",(G31-G20)/G32) -> 1.0405286 | H34: % | J34: =IF(J32=0,"N/A",(J31-J20)/J32) -> 1.0132231 | K34: %
B35: Year 2+ Annual ROI | C35: =IF(C21=0,"N/A",C30*12/(C21*12)) -> 8.787234 | G35: =IF(G21=0,"N/A",G30*12/(G21*12)) -> 1.4125 | H35: % | J35: =IF(J21=0,"N/A",J30*12/(J21*12)) -> 1.5375 | K35: %
B37: 3. NEGOTIATION VIEW
B38: Value Ceiling (monthly) | C38: =IF(C20+C28=0,"N/A",(C28*12-C20)/12) -> 21333.333 | D38: CHF/month — max fee where client still breaks even in Year 1 | G38: =IF(G20+G28=0,"N/A",(G28*12-G20)/12) -> 3568.3333 | H38: CHF/month | J38: =IF(J20+J28=0,"N/A",(J28*12-J20)/12) -> 1821.6667 | K38: CHF/month
B39: Headroom — value kept by client | C39: =IF(C38="N/A","N/A",C38-C21) -> 18983.333 | D39: CHF/month below the ceiling. Use this when client says fee is high. | G39: =IF(G38="N/A","N/A",G38-G21) -> 1968.3333 | H39: CHF/month | J39: =IF(J38="N/A","N/A",J38-J21) -> 1021.6667 | K39: CHF/month
B41: Staffing alternative comparison
B42: Equiv. manual staffing cost | C42: 0 | D42: CHF/month — est. cost of person doing this manually. Rule of thumb CH: CHF 70k salary ≈ CHF 8,300/month fully loaded. Even 1 day/week ≈ CHF 2,000+. | G42: 0 | H42: CHF/month | J42: 0 | K42: CHF/month
B43: Automation saving vs. staffing | C43: =IF(C42=0,"(enter staffing cost above)",C42-C21) -> (enter staffing cost above) | D43: CHF/month saved vs. hiring. Negative = staffing is cheaper. | G43: =IF(G42=0,"(enter staffing cost above)",G42-G21) -> (enter staffing cost above) | H43: CHF/month | J43: =IF(J42=0,"(enter staffing cost above)",J42-J21) -> (enter staffing cost above) | K43: CHF/month
B44: Talking point — monthly fee objection: "Think of it like Krankenkasse. The best months are the ones where you never needed to call us. That's not money wasted — that's the system working. You pay for the guarantee of continuity, not for the number of incidents. And unlike Krankenkasse, here you can calculate the return."
B46: Tip: Monthly Managed AI Ops (C20) should match 'Recommended monthly quote' from Quote Calculator tab. First-Year Net ROI divides by total Year 1 spend (setup + 12× monthly). Year 2+ ROI shows the recurring return once setup is fully amortised.

Sheet ROI App_v1
B2: ROI Automation Calculator
B3: Field | C3: Value | D3: Unit / Notes
B4: 1. CLIENT INPUTS | G4: MGREDSHIFT
B5: Hard ROI — Time Savings
B6: Employees Involved | C6: 2 | D6: people | G6: 4 | H6: people
B7: Hours Lost / Week | C7: 5 | D7: hours / week | G7: 2 | H7: hours / week
B8: Hourly Rate (Gross) | C8: 100 | D8: CHF / hour | G8: 80 | H8: CHF / hour
B10: Hard ROI — Error Reduction
B11: Mistakes / Week | C11: 5 | D11: mistakes / week | G11: 1 | H11: mistakes / week
B12: Cost per Mistake | C12: 200 | D12: CHF / mistake | G12: 75 | H12: CHF / mistake
B14: Soft ROI — Lost Revenue
B15: Lost Leads / Month | C15: 10 | D15: leads / month | G15: 1 | H15: leads / month
B16: Avg Value per Lead | C16: 1500 | D16: CHF / lead | G16: 1000 | H16: CHF / lead
B18: Investment & Ongoing Costs
B19: One-Time Setup Cost | C19: 20000 | D19: CHF total | G19: 3500 | H19: CHF total
B20: Monthly Managed AI Ops Cost | C20: 2350 | D20: CHF / month — paste from Quote Calculator C39 (Recommended monthly quote) | G20: 1600 | H20: CHF / month
B22: 2. CALCULATED ROI | G22: ROI
B24: Monthly Cost of Time | C24: =C6*C7*C8*4 -> 4000 | D24: CHF | G24: =G6*G7*G8*4 -> 2560 | H24: CHF
B25: Monthly Cost of Errors | C25: =C11*C12*4 -> 4000 | D25: CHF | G25: =G11*G12*4 -> 300 | H25: CHF
B26: Monthly Lost Revenue | C26: =C15*C16 -> 15000 | D26: CHF | G26: =G15*G16 -> 1000 | H26: CHF
B27: Monthly Gross Benefit | C27: =SUM(C24:C26) -> 23000 | D27: CHF — cost of inaction | G27: =SUM(G24:G26) -> 3860 | H27: CHF — cost of inaction
B28: (−) Monthly Managed AI Ops | C28: =C20 -> 2350 | D28: CHF | G28: =G20 -> 1600 | H28: CHF
B29: Net Monthly Benefit | C29: =C27-C28 -> 20650 | D29: CHF | G29: =G27-G28 -> 2260 | H29: CHF
B30: Annual Net Benefit | C30: =C29*12 -> 247800 | D30: CHF | G30: =G29*12 -> 27120 | H30: CHF
B31: Total Year 1 Investment | C31: =C19+C20*12 -> 48200 | D31: CHF — setup + 12× monthly managed | G31: =G19+G20*12 -> 22700 | H31: CHF
B32: Payback Period | C32: =IF(C29<=0,"N/A",C19/C29) -> 0.968523 | D32: Months | G32: =IF(G29<=0,"N/A",G19/G29) -> 1.5486726 | H32: Months
B33: First-Year Net ROI | C33: =IF(C31=0,"N/A",(C30-C19)/C31) -> 4.7261411 | D33: % — net Y1 return ÷ total Y1 investment (setup + 12× monthly) | G33: =IF(G31=0,"N/A",(G30-G19)/G31) -> 1.0405286 | H33: %
B34: Year 2+ Annual ROI | C34: =IF(C20=0,"N/A",C29*12/(C20*12)) -> 8.787234 | G34: =IF(G20=0,"N/A",G29*12/(G20*12)) -> 1.4125 | H34: %
B35: Tip: Monthly Managed AI Ops (C20) should match 'Recommended monthly quote' from Quote Calculator tab. First-Year Net ROI divides by total Year 1 spend (setup + 12× monthly). Year 2+ ROI shows the recurring return once setup is fully amortised.

Sheet ROI App_v0
B2: ROI Automation Calculator
B3: Field | C3: Value | D3: Unit / Notes
B4: 1. CLIENT INPUTS | G4: MGREDSHIFT
B5: Hard ROI — Time Savings
B6: Employees Involved | C6: 2 | D6: people | G6: 4 | H6: people
B7: Hours Lost / Week | C7: 5 | D7: hours / week | G7: 2 | H7: hours / week
B8: Hourly Rate (Gross) | C8: 100 | D8: CHF / hour | G8: 80 | H8: CHF / hour
B10: Hard ROI — Error Reduction
B11: Mistakes / Week | C11: 5 | D11: mistakes / week | G11: 1 | H11: mistakes / week
B12: Cost per Mistake | C12: 200 | D12: CHF / mistake | G12: 75 | H12: CHF / mistake
B14: Soft ROI — Lost Revenue
B15: Lost Leads / Month | C15: 10 | D15: leads / month | G15: 1 | H15: leads / month
B16: Avg Value per Lead | C16: 1500 | D16: CHF / lead | G16: 1000 | H16: CHF / lead
B18: Investment & Ongoing Costs
B19: One-Time Setup Cost | C19: 20000 | D19: CHF total | G19: 3500 | H19: CHF total
B20: Monthly Managed AI Ops Cost | C20: 2350 | D20: CHF / month — paste from Quote Calculator C39 (Recommended monthly quote) | G20: 1600 | H20: CHF / month
B22: 2. CALCULATED ROI | G22: ROI
B24: Monthly Cost of Time | C24: =C6*C7*C8*4 -> 4000 | D24: CHF | G24: =G6*G7*G8*4 -> 2560 | H24: CHF
B25: Monthly Cost of Errors | C25: =C11*C12*4 -> 4000 | D25: CHF | G25: =G11*G12*4 -> 300 | H25: CHF
B26: Monthly Lost Revenue | C26: =C15*C16 -> 15000 | D26: CHF | G26: =G15*G16 -> 1000 | H26: CHF
B27: Monthly Gross Benefit | C27: =SUM(C24:C26) -> 23000 | D27: CHF — cost of inaction | G27: =SUM(G24:G26) -> 3860 | H27: CHF — cost of inaction
B28: (−) Monthly Managed AI Ops | C28: =C20 -> 2350 | D28: CHF | G28: =G20 -> 1600 | H28: CHF
B29: Net Monthly Benefit | C29: =C27-C28 -> 20650 | D29: CHF | G29: =G27-G28 -> 2260 | H29: CHF
B30: Annual Net Benefit | C30: =C29*12 -> 247800 | D30: CHF | G30: =G29*12 -> 27120 | H30: CHF
B31: Payback Period | C31: =IF(C29<=0,"N/A",C19/C29) -> 0.968523 | D31: Months | G31: =IF(G29<=0,"N/A",G19/G29) -> 1.5486726 | H31: Months
B32: First-Year Net ROI | C32: =IF(C19=0,"N/A",(C29*12-C19)/C19) -> 11.39 | D32: % (over Year 1) | G32: =IF(G19=0,"N/A",(G29*12-G19)/G19) -> 6.7485714 | H32: % (over Year 1)
B34: Tip: Monthly Managed AI Ops (C20) should match 'Recommended monthly quote' from the Quote Calculator tab (cell C39). Yellow = edit, light blue = calculated.

Sheet Example Quotes
B2: Example Quote Ranges
B4: Example | C4: Package | D4: Setup Low | E4: Setup High | F4: Monthly Low | G4: Monthly High | H4: Why | I4: Access model | J4: Notes | K4: Client label
B5: MG Red Shift v4.0 — AI-drafted SEEKER reply (base) | C5: Basic+ AI Triage | D5: 1500 | E5: 3000 | F5: 250 | G5: 600 | H5: AI classification, Notion DB, folder routing, SEEKER draft support | I5: Managed / hybrid | J5: No automatic sending; AI draft held for review | K5: AI Intake Triage Basic+
B6: Therapist Gmail + booking link | C6: Basic Intake | D6: 1200 | E6: 2500 | F6: 250 | G6: 500 | H6: Email/form intake, booking triage, no direct advice | I6: Managed / hybrid | J6: Human approval | K6: AI Intake Basic
B7: Therapist Instagram + Gmail + drafts | C7: Pro Multi-Channel | D7: 3500 | E7: 7500 | F7: 750 | G7: 1500 | H7: Multiple channels and draft approval workflow | I7: Managed | J7: Sensitive data needs strict boundaries | K7: AI Workflow Pro
B8: Small agency CRM + reporting | C8: Managed Operations | D8: 7500 | E8: 15000 | F8: 1500 | G8: 3500 | H8: CRM, monitoring, reporting, improvement backlog | I8: Managed | J8: Recurring service value | K8: Managed AI Operations
B9: Calendar/CRM agent | C9: Agentic Automation | D9: 12000 | E9: 30000 | F9: 2500 | G9: 6000 | H9: Controlled multi-step actions with approvals | I9: Controlled access | J9: Quote individually | K9: Agentic AI Operations
B10: Client full handover | C10: Build-and-Transfer | D10: 4500 | E10: 15000 | F10: 0 | G10: 1000 | H10: Transfers Make logic and documentation | I10: Client-owned | J10: Price 1.5x to 3x setup | K10: Build & Transfer
B11: MG Red Shift v4.1 — template SEEKER reply | C11: Basic+ AI Triage | D11: 1300 | E11: 2700 | F11: 200 | G11: 500 | H11: Same triage; SEEKER reply is a prepared template (no AI generation). Simplest of the three. | I11: Managed / hybrid | J11: Template reply; no AI draft | K11: AI Intake Triage Basic+
B12: MG Red Shift v4.2 + v4.1 — dual intake (email + webform) | C12: Basic+ AI Triage | D12: 2000 | E12: 4500 | F12: 400 | G12: 900 | H12: v4.1 process across two intake paths (email then webform): extra source + duplicated classify/route. | I12: Managed / hybrid | J12: No automatic sending; two channels | K12: AI Intake Triage Basic+

Sheet Access Models
B2: Access & Ownership Pricing Logic
B3: these five models are the granular access variants that implement the three policy tiers (Managed / Licence / Full transfer). See IP & Licensing Policy.
B5: Model | C5: Client receives | D5: You retain | E5: Pricing effect | F5: Monthly effect | G5: Risk | H5: Use when | I5: Client wording | J5: Internal note | K5: Default setup multiplier | L5: Typical range | M5: Pricing use in FIXED calculator | N5: Policy tier
B6: Managed service | C6: Results, dashboards, reports, approval queue | D6: Make logic, prompts, reusable blueprints | E6: Normal | F6: x1.0 monthly | G6: Low | H6: Default | I6: We manage the automation and provide outputs/support. | J6: Best default model | K6: 1 | L6: x1.0 | M6: Managed service: no handover premium. | N6: Managed (default)
B7: Logic visibility | C7: Workflow summary, Mermaid/chart, status rules | D7: Implementation details and reusable logic | E7: Normal or small add-on | F7: x1.0 monthly | G7: Low | H7: Client wants transparency | I7: You receive workflow documentation without internal implementation. | J7: Good trust-building option | K7: 1.1 | L7: x1.0–x1.15 | M7: Transparency/documentation premium. | N7: Licence
B8: Limited admin | C8: Dashboard, approvals, run summaries | D8: Scenario edit rights and blueprint export | E8: +10–25% | F8: x1.1–1.25 monthly | G8: Medium | H8: Client needs stronger control | I8: You can review outcomes while we manage the system. | J8: Managed clients | K8: 1.2 | L8: x1.10–x1.25 | M8: Limited admin/client controls. | N8: Licence
B9: Client-owned workspace | C9: Automation runs in client workspace | D9: Methodology and reusable templates | E9: +25–75% | F9: x0.5–1.5 monthly depending support | G9: Medium | H9: Compliance/enterprise | I9: Built in your workspace; support remains available. | J9: Higher setup | K9: 1.5 | L9: x1.25–x1.75 | M9: Client-owned workspace/setup burden. | N9: Licence
B10: Build-and-transfer | C10: Full Make scenario, export, documentation | D10: General know-how only | E10: x1.5–x3 setup | F10: x0–x3 monthly depending support | G10: High | H10: INTERNAL INFORMATION ONLY — not a client-facing offer | I10: We build and hand over the automation asset. | J10: Documented for internal clarity; not sold. See IP & Licensing Policy. | K10: 2 | L10: x1.5–x3.0 | M10: Build-and-transfer default; override if needed. | N10: Full transfer — internal info only
C12: Client | D12: VD | E12: what it means?
C13: Approvals | E13: You review and OK an action before it happens.
C14: Dashboards | E14: A live screen showing what the automation is doing and its status.
C15: Results | E15: The finished output of a run (sorted messages, extracted data, etc.).
C16: Reports | E16: Periodic summaries (daily/weekly) of what was processed.
C17: Approval Queue | E17: The list of items waiting for your yes/no before they're sent or done.
C18: Charts (Mermaid, <other>) | E18: A visual diagram of how the workflow flows — for understanding, not editing.
C19: Status Rules | E19: The plain rules that decide what counts as done, pending, or failed.
C20: Run Summaries | E20: A short recap of each run: how many handled, flagged, errored.
C21: Scenarios (Make, n8n, <other>) | E21: The actual automation build (the connected steps) inside Make/n8n.
C22: Logic (Make, n8n, <other>) | E22: The decision rules inside the scenario — how it classifies and routes.
C23: Prompts (Make, n8n, <other>) | E23: The exact instructions given to the AI at each step.
D24: Blueprints (Make, n8n, <other>) | E24: A reusable export of a scenario that lets it be rebuilt. We retain this.
C25: Documentation | E25: Written explanation of what the automation does and how to operate it.
C26: Export? | E26: Whether a copy of the scenario file can be taken out of the tool.
D27: reusable blueprints | E27: Our library of scenario templates reused across clients. Ours only.
D28: reusable logic | E28: Our library of decision patterns reused across clients. Ours only.
D29: implementation details | E29: The specific technical wiring and config behind the scenario. Ours only.
D30: scenario edit rights | E30: Permission to change the automation's build (granted only in Limited admin).
D31: blueprint exports | E31: The ability to export the blueprint file. Ours only.
D32: methodology | E32: Our process for discovering, scoping and building automations. Never shared.
D33: reusable templates | E33: Our standard building blocks used across projects. Ours only.
D34: general know-how | E34: Generic experience we keep after any engagement.

Sheet Access & Licence Pricing
B2: Access & Licence Pricing
B3: Three access tiers. Managed (default) = we run and improve it. Licence (option) = client holds a bounded right-to-use; we keep the build and the methodology. Full transfer = internal information only, not a client-facing offer (shown for internal clarity). Setup/Monthly are live-linked to 'Package Reference' midpoints. See IP & Licensing Policy.
B5: INPUTS (edit)
B6: Licence % of managed-year | C6: 0.5 | D6: share of the managed year the licence keeps (maintain-vs-improve split). 40–60% typical.
B7: Licence setup multiplier | C7: 1.3 | D7: one-time uplift for documentation + handover so they can run it themselves.
B8: Buy-out: years of recurring to capitalise | C8: 2.5 | D8: buy-out one-time = setup + (years × 12 × monthly). Protects the recurring you give up.
B10: Package | C10: Managed setup | D10: Managed / mo | E10: Licence setup | F10: Licence / year | G10: Licence / mo (equiv) | H10: Full transfer one-time (internal info only) | I10: Transfer / mo
B11: ='Package Reference'!B6 -> Basic Intake | C11: =ROUND(('Package Reference'!C6+'Package Reference'!D6)/2,0) -> 1275 | D11: =ROUND(('Package Reference'!E6+'Package Reference'!F6)/2,0) -> 300 | E11: =ROUND(C11*$C$7,0) -> 1658 | F11: =ROUND(D11*12*$C$6,0) -> 1800 | G11: =ROUND(F11/12,0) -> 150 | H11: =ROUND(C11+$C$8*12*D11,0) -> 10275 | I11: 0
B12: ='Package Reference'!B7 -> Basic+ AI Triage | C12: =ROUND(('Package Reference'!C7+'Package Reference'!D7)/2,0) -> 2500 | D12: =ROUND(('Package Reference'!E7+'Package Reference'!F7)/2,0) -> 525 | E12: =ROUND(C12*$C$7,0) -> 3250 | F12: =ROUND(D12*12*$C$6,0) -> 3150 | G12: =ROUND(F12/12,0) -> 263 | H12: =ROUND(C12+$C$8*12*D12,0) -> 18250 | I12: 0
B13: ='Package Reference'!B8 -> Pro Multi-Channel | C13: =ROUND(('Package Reference'!C8+'Package Reference'!D8)/2,0) -> 5500 | D13: =ROUND(('Package Reference'!E8+'Package Reference'!F8)/2,0) -> 1125 | E13: =ROUND(C13*$C$7,0) -> 7150 | F13: =ROUND(D13*12*$C$6,0) -> 6750 | G13: =ROUND(F13/12,0) -> 563 | H13: =ROUND(C13+$C$8*12*D13,0) -> 39250 | I13: 0
B14: ='Package Reference'!B9 -> Managed Operations | C14: =ROUND(('Package Reference'!C9+'Package Reference'!D9)/2,0) -> 11250 | D14: =ROUND(('Package Reference'!E9+'Package Reference'!F9)/2,0) -> 2500 | E14: =ROUND(C14*$C$7,0) -> 14625 | F14: =ROUND(D14*12*$C$6,0) -> 15000 | G14: =ROUND(F14/12,0) -> 1250 | H14: =ROUND(C14+$C$8*12*D14,0) -> 86250 | I14: 0
B15: ='Package Reference'!B10 -> Agentic Automation | C15: =ROUND(('Package Reference'!C10+'Package Reference'!D10)/2,0) -> 21000 | D15: =ROUND(('Package Reference'!E10+'Package Reference'!F10)/2,0) -> 4250 | E15: =ROUND(C15*$C$7,0) -> 27300 | F15: =ROUND(D15*12*$C$6,0) -> 25500 | G15: =ROUND(F15/12,0) -> 2125 | H15: =ROUND(C15+$C$8*12*D15,0) -> 148500 | I15: 0
B17: How to read it:
B18: • Managed (default): you run and improve it. Setup + monthly per the package. Recurring, you keep the IP.
B19: • Licence (no managed service): they run it; you licence the right-to-use and keep the IP. Setup ×1.3 (handover/docs) + an annual licence = licence% × the managed year. Still recurring.
B20: • Full transfer (INTERNAL INFORMATION ONLY — not offered as a path): if ever considered, one-time = setup + years×12×monthly, so we're paid for the recurring we give up. We keep only general know-how.
B21: Licence % = the maintain-vs-improve split: 40% if your monthly is mostly active improvement, 60% if mostly keeping-it-running. Default 50%.
B22: Figures use Package Reference midpoints; for a specific deal use the Quote Calculator's setup/monthly in place of the midpoint.
B24: Policy source-of-truth: VortexDeep_IP_and_Licensing_Policy_v01. Full transfer is documented, not sold.

Sheet Front-Door Tools — Pricing
B2: Front-Door Tools — Pricing (AISR & AIWSC)
B3: Follows each tool's OWN process docs — they do NOT share one ladder. AISR sells as 3 packages (with prices you've already set). AIWSC keeps two axes apart: DEPTH (mode numbers) and AUTHORIZATION (named). For both, the scan/report is the free front door; fixes and ongoing are paid. AISR figures are yours (documented); AIWSC figures are indicative (no documented price yet) — adjust.
B5: AISR — AI Search Readiness · pipeline & 3 packages (prices per AISR-Process.docx)
B6: Pipeline: | C6: 1 Audit (free, no AI) → 2 Fill facts → 3 Test/teaser (free) → 4 Fix (paid) → 5 Verify → Managed (paid). Client sees only a TEASER; the full report, fixes and implementation stay behind payment.
B7: Package | C7: Price (CHF) | D7: Price (CHF) | E7: Price (CHF) | F7: What the client gets | G7: Access | H7: Recurring | I7: Note
C8: min | D8: max | E8: note | G8: / AI | H8: ?
B9: Free teaser | C9: 0 | D9: 250 | E9: - | F9: Audit + readiness score + 2–3 real AI errors | G9: read-only; cents of API | H9: no | I9: Wins the project — your Fit Check
B10: Fix | C10: 2500 | D10: 5000 | E10: one-time | F10: Full readiness report + implemented fixes + before/after | G10: approved on-site edits | H10: no | I10: The full report lives here, not in the teaser
B11: Managed | C11: 500 | D11: 1000 | E11: month | F11: Repeat testing + small approved fixes over time | G11: ongoing | H11: yes | I11: Off-site citation work is the effective half
B12: Source: your AISR-Process.docx (documented prices). Free = steps 1–3; Paid = full report + fixes + verify + managed.
B14: AIWSC — Website Security Check · two axes: DEPTH (numbered) × AUTHORIZATION (named)
B15: Your AIWSC-Scanning-Policy.docx is explicit: keep depth and authorization apart — mixing them into one number line causes confusion.
B16: DEPTH — the mode numbers (on every report & filename)
B17: Mode | F17: Reads | G17: Permission | H17: Command
B18: mode-00 triage | F18: Public records only: DNS + certificate | G18: None needed (internal) | H18: triage --client <domain>
B19: mode-05 inspect | F19: The delivered page(s) you name: headers, cookies, version + above | G19: None needed (internal) | H19: inspect --client <domain-or-URL>
B20: mode-10 scan | F20: Full light scan: above + the tool's own checks (e.g. redirect test) | G20: Needs authorization | H20: scan --client <domain>
B21: mode-15 scan --deeper | F21: Above + sensitive-file exposure probe (.env / .git) | G21: Needs auth covering ACTIVE testing | H21: scan --client <domain> --deeper
B22: AUTHORIZATION — named, not numbered (who said yes)
B23: self-owned | C23: a domain we control — self-attested
B24: built-by-VD | C24: site we built/maintain — consent as a standing clause in the contract
B25: client | C25: the site owner's written consent (self-serve: prove ownership = the consent)
B26: Same depth (e.g. mode-10) can run under any authorization — depth and authorization are independent.
B28: COMMERCIAL — free front door, paid fixes (AIWSC has no documented price yet; figures indicative)
B29: Tier | C29: Price (CHF) | D29: Price (CHF) | E29: Price (CHF) | F29: What the client gets | G29: Depth | H29: Recurring | I29: Note
C30: min | D30: max | E30: note | G30: / auth | H30: ?
B31: Free scan | C31: 0 | D31: 0 | E31: - | F31: Light scan + plain-language report, self-serve, ownership-verified | G31: mode 00–10 · owner-initiated | H31: no | I31: The front door (no cold outreach)
B32: Fix | C32: 1500 | D32: 3500 | E32: one-time | F32: Agreed remediation (certs, headers, email auth, updates) + re-scan proof | G32: approved changes · client consent | H32: no | I32: Where the work is paid
B33: Deep check | C33: 300 | D33: 800 | E33: add-on | F33: mode-15 active exposure probe (.env/.git) | G33: needs ACTIVE-testing auth | H33: no | I33: Only inside a proper engagement
B34: Managed | C34: 300 | D34: 700 | E34: month | F34: Periodic re-scan + monitoring | G34: scoped standing consent | H34: yes | I34: Or refer deep manual pentest to a partner
B36: GUARDRAILS (from your own docs)
B37: • Read-only & invited only: read what a site already exposes; never alter/break in; never scan strangers uninvited.
B38: • Authority = ownership OR written consent. Building a site doesn't grant it — but lets consent be a standing contract clause.
B39: • AIWSC is a scan-level assessment, NOT a manual penetration test — refer true pentests to a specialist partner.
B40: • Have a Swiss lawyer review the standing-clause wording and any outreach before the first client.
B41: • SECURITY: API_KEYS.txt is still committed in VDt_02_aisr — rotate those keys and make the repo private.
B43: MARKET COMPARISON (2026) — where VortexDeep sits vs typical providers
B44: Market figures are USD/EUR; treat as rough CHF parity (USD ≈ 0.85 CHF, EUR ≈ 0.94 CHF). VD is deliberately at the accessible / SME end — below agencies. The edge is honesty + human-in-the-loop, not being cheapest.
B45: AISR — AI Search Readiness (AEO / GEO)
B46: Tier | C46: VD (CHF) | D46: VD (CHF) | E46: VD (CHF) | F46: Typical market (2026) | G46: TM (USD) | H46: TM (USD) | I46: TM (USD) | J46: Where VD sits
...

Sheet Client Quote Summary
B2: Client-Facing Quote Summary Template
B4: Project name | C4: Enter project name
B5: Package direction | C5: Enter package direction
B6: One-line scope | C6: Example: AI intake triage for website/email inquiries with classification, routing, Notion logging, and draft support.
B7: Included | C7: List included channels, categories, automations, and approvals.
B8: Not included | C8: List postponed or excluded items.
B9: Setup fee | C9: Enter setup fee or range.
B10: Monthly managed service | C10: Enter monthly fee or range.
B11: Access model | C11: Managed service / hybrid / client-owned / build-and-transfer.
B12: Client responsibilities | C12: Provide access, approve test cases, review drafts, confirm go-live.
B13: Provider responsibilities | C13: Build, test, monitor, support, update rules/prompts as agreed.
B14: Approval points | C14: Scope approval, blueprint approval, go-live approval.
B15: Notes | C15: Prices exclude third-party software/API usage unless agreed otherwise.
... B20: Build-and-transfer note | C20: If full automation ownership is transferred, setup and monthly support may be multiplied depending on access and responsibility.

Sheet MGRS - EMAIL Logic
B2: MGREDSHIFT v4.0 vs Direct Email Intake Expansion
B3: Access model applies to every product — Managed / Licence / Full transfer (internal). See Access Models · Access & Licence Pricing · IP & Licensing Policy.
B5: Area | C5: Existing MGREDSHIFT v4.0 | D5: Expansion for other clients | E5: Pricing effect | F5: Why it matters
B6: Input source | C6: Website contact form via webhook only. | D6: Add direct inbox trigger, e.g. Gmail/IMAP/Outlook “watch emails”. | E6: Counts as +1 intake channel/source. | F6: Direct emails do not use the website form structure and may never reach the existing webhook scenario.
B7: Message structure | C7: Structured form fields: name, email, phone, subject, message. | D7: Normalize unstructured email into the same internal fields: source_type, sender, subject, body, phone/WhatsApp, detected country. | E7: Small setup increase. | F7: Without normalization, the classifier receives inconsistent inputs and misses cases.
B8: Router / pre-branch | C8: Classifier runs after webhook input and router acts on LEAD / SEEKER / SPAM / TEST. | D8: Add small source router/pre-branch: website_form vs direct_email, then merge both into the same classification logic. | E8: Small to medium setup increase. | F8: Keeps one central classifier while allowing several input channels.
B9: Classification logic | C9: Good for website enquiries. Foreign distributor requests are handled when they arrive through the form. | D9: Add fallback terms for direct emails: India, Gujarat, +91, WhatsApp, distributor, reseller, agency, purchase in [country]. | E9: Usually included in the add-on. | F9: Direct emails often use broken wording, so keyword fallback improves SEEKER detection.
B10: Deduplication | C10: Less critical when each form submission is unique. | D10: Use email message ID / thread ID / timestamp to avoid duplicated processing. | E10: Part of realistic business version. | F10: Inbox triggers can re-read, forward, or re-process messages if not controlled.
B11: Routing and logging | C11: Folder routing + Notion logging + manual review. | D11: Add email labels/folders, status logging, error route and optional reply draft path. | E11: Moves from simple branch to managed workflow. | F11: Client sees a reliable operational process, not only an AI classification.
B12: Recommended classification | C12: Basic+ AI Triage. | D12: Still Basic+ if one inbox and same logic; low Pro if multiple inboxes, email-specific drafts or social channels are added. | E12: Use change request if added later. | F12: Scope expansion changes responsibility, testing and support needs.
B13: Practical conclusion | C13: For MG Red Shift, modification may not be needed now because direct foreign requests can be handled manually. | D13: For client projects, direct email intake should be discussed in discovery and priced as an optional intake-source add-on. | E13: Default quote: CHF 900–1’500 setup + CHF 150–300/month. | F13: This protects against underpricing and makes scope boundaries clear.

Sheet AUDIT Pricing
B2: Pricing Calculator Audit
B3: Workbook | C3: AI_Automation_PM_Helper_Pricing_Calculator_v6_Streamlined_MJS_updated_email_intake.xlsx
B4: Audit focus | C4: Quote Calculator, C5 package + C6 support model, Build-and-Transfer pricing, workbook consistency
B6: Verdict | C6: Status | D6: Detail | E6: Impact | F6: Recommended fix | G6: Priority
B7: Overall | C7: PARTLY OK | D7: Standard managed packages calculate logically for the current inputs. | E7: Usable for Basic/Pro/Managed quotes with care. | F7: Keep package selection and support model, but add stronger checks. | G7: Medium
B8: C5 + C6 combination | C8: TECHNICALLY OK | D8: C5 drives base package via Package Reference; C6 drives support/setup multipliers via Complexity Reference. | E8: Combination works mathematically. | F8: Keep, but separate package/support/access model more clearly. | G8: Medium
B9: Build-and-Transfer | C9: FAIL | D9: Build-and-Transfer has base setup/monthly = 0 in Package Reference, so calculator can return 0 or too-low setup. | E9: Underpricing risk, especially if counts are not entered. | F9: Treat Build-and-Transfer as access/ownership model OR give it a non-zero base. | G9: High
B10: Support multiplier logic | C10: WARN | D10: For Build-and-Transfer, Normal managed support uses setup multiplier 1.0, while No support uses 1.5, so 'normal support' can make setup cheaper than 'no support'. | E10: Commercially inconsistent. | F10: Move handover/setup multiplier to a separate access model field. | G10: High
B11: Hard-coded adders | C11: WARN | D11: Quote formulas C29:C32 use hard-coded adder amounts instead of reading Complexity Reference A:E. | E11: Changing reference prices will not update calculator. | F11: Use lookups / SUMPRODUCT against Complexity Reference. | G11: High
B12: Dropdowns | C12: WARN | D12: C5/C6 dropdowns are fixed text lists, not dynamic ranges from reference sheets. | E12: If reference names change, dropdowns can go stale. | F12: Use data validation references to Package Reference and Complexity Reference ranges. | G12: Medium
B13: Example Quotes | C13: WARN | D13: Example Build-and-Transfer quote is CHF 4'500–15'000 / 0–1'000 monthly, but calculator can output lower values. | E13: Inconsistent client guidance. | F13: Align reference, calculator and examples. | G13: High
B14: ROI App | C14: NOTE | D14: ROI math is coherent, but setup/monthly costs are manual, not linked to Quote Calculator. | E14: Manual copy errors possible. | F14: Link ROI inputs to Quote Calculator cells or clearly mark as manual scenario input. | G14: Low
B15: Client Quote Summary | C15: NOTE | D15: Client summary is manual and not linked to calculator outputs. | E15: Manual quote-copy risk. | F15: Optional: formula-link key outputs. | G15: Low
B16: Pricing Logic tabs | C16: NOTE | D16: Direct Email Intake Branch pricing is documented but not connected to Quote Calculator. | E16: Email-intake scope can be missed or double-counted. | F16: Add an optional Direct Email Branch add-on or map it clearly to Extra Channel + Draft + Approval counts. | G16: Medium
B18: Current Quote Calculator inputs | C18: Value
B19: Selected package (C5) | C19: Basic+ AI Triage
B20: Support model (C6) | C20: Normal managed support
B21: Extra channels count (C15) | C21: 0
B22: AI draft workflows count (C16) | C22: 1
B23: CRM integrations count (C17) | C23: 1
B24: Approval workflows count (C18) | C24: 1
B25: Reporting layer count (C19) | C25: 0
B26: Sensitive data multiplier (C20) | C26: 1
B27: Urgency multiplier (C21) | C27: 1
B29: Current calculated result | C29: Setup low | D29: Setup high | E29: Monthly low | F29: Monthly high | G29: Recommended
B30: Basic+ AI Triage + Normal managed support | C30: 3500 | D30: 10000 | E30: 800 | F30: 2350 | G30: Setup 6800 / Monthly 1600
B32: Build-and-Transfer test with current counts | C32: Setup low | D32: Setup high | E32: Monthly low | F32: Monthly high | G32: Recommended
B33: No support | C33: 3000 | D33: 9750 | E33: 0 | F33: 0 | G33: Setup 6400 / Monthly 0
B34: Light support | C34: 3000 | D34: 9750 | E34: 250 | F34: 800 | G34: Setup 6400 / Monthly 500
B35: Normal managed support | C35: 2000 | D35: 6500 | E35: 500 | F35: 1600 | G35: Setup 4300 / Monthly 1100
B36: High-responsibility maintenance | C36: 3000 | D36: 9750 | E36: 750 | F36: 2400 | G36: Setup 6400 / Monthly 1600
B37: Premium transfer support | C37: 4000 | D37: 13000 | E37: 1000 | F37: 3200 | G37: Setup 8500 / Monthly 2100
B38: Critical support | C38: 6000 | D38: 19500 | E38: 1500 | F38: 4800 | G38: Setup 12800 / Monthly 3200
B40: Build-and-Transfer zero-count test | C40: Setup low | D40: Setup high | E40: Monthly low | F40: Monthly high | G40: Recommended
B41: No support | C41: 0 | D41: 0 | E41: 0 | F41: 0 | G41: Setup 0 / Monthly 0
B42: Light support | C42: 0 | D42: 0 | E42: 0 | F42: 0 | G42: Setup 0 / Monthly 0
B43: Normal managed support | C43: 0 | D43: 0 | E43: 0 | F43: 0 | G43: Setup 0 / Monthly 0
