Workbook

Sheet START HERE
A1: Phase 4 — MVP Build
A2: Convert the approved Phase 3 blueprint into a controlled, testable first automation build. Build only the approved MVP, not the final scaled system.
A4: Step | B4: Activity | C4: Instruction | D4: Use Sheet
A5: 1 | B5: Transfer design | C5: Copy final Phase 3 decisions into the handoff sheet. | D5: Phase3 to Phase4 Handoff
A6: 2 | B6: Break into tasks | C6: Create concrete build items and dependencies. | D6: Build Backlog
A7: 3 | B7: Configure modules | C7: Build trigger, normalizer, AI classifier, router, CRM, notification/draft, audit and error handler. | D7: Module Build Plan
A8: 4 | B8: Secure access | C8: Set up connections safely. Never store secrets in workbook or hardcoded modules. | D8: Credentials & Access
A9: 5 | B9: Configure prompts | C9: Define schema, categories, confidence and fallback rules. | D9: AI Prompt Config
A10: 6 | B10: Prepare tests | C10: Create seed cases for formal Phase 5 validation. | D10: Test Seed Cases
A11: 7 | B11: Checklist | C11: Confirm MVP build is ready before testing. | D11: Build Checklist
A14: We planned this PM flow:
A16: Phase 1 — Discovery / Analysis
A17: Understand client needs, channels, risks, pain points, possible package direction.
A19: Phase 2 — Scope Definition / MVP Design
A20: Convert discovery answers into a clear first project scope.
A22: Phase 3 — Solution Blueprint
A23: Design workflow logic, tools, data fields, routing, approvals, security.
A25: Phase 4 — MVP Build
A26: Build the first safe automation version.
A28: Phase 5 — Testing / Validation
A29: Test real cases, edge cases, errors, wrong classifications, approvals.
A31: Phase 6 — Go-live / Managed Service
... A36: Build Backlog — by Status
A37: Status | B37: Meaning | C37: Count
A38: Not Started | B38: Build not begun. | C38: =COUNTIF('Build Backlog'!F5:F16,"Not Started") -> 12
A39: In Progress | B39: Build in progress. | C39: =COUNTIF('Build Backlog'!F5:F16,"In Progress") -> 0
A40: Done | B40: Build complete. | C40: =COUNTIF('Build Backlog'!F5:F16,"Done") -> 0
A41: Blocked | B41: Cannot proceed — needs resolution. | C41: =COUNTIF('Build Backlog'!F5:F16,"Blocked") -> 0
A43: Module Build Plan — by Status
A44: Status | B44: Meaning | C44: Count
A45: Not Started | B45: Module not built yet. | C45: =COUNTIF('Module Build Plan'!H5:H14,"Not Started") -> 10
A46: In Progress | B46: Module being built. | C46: =COUNTIF('Module Build Plan'!H5:H14,"In Progress") -> 0
A47: Done | B47: Module ready. | C47: =COUNTIF('Module Build Plan'!H5:H14,"Done") -> 0
A48: Blocked | B48: Module blocked. | C48: =COUNTIF('Module Build Plan'!H5:H14,"Blocked") -> 0
A50: Build Checklist — by Pass status
A51: Status | B51: Meaning | C51: Count
A52: Pass | B52: Checklist item verified. | C52: =COUNTIF('Build Checklist'!C5:C16,"Pass") -> 0
A53: Pending | B53: Not yet verified. | C53: =COUNTIF('Build Checklist'!C5:C16,"Pending") -> 0
A54: Fail | B54: Failed — needs rebuild or fix. | C54: =COUNTIF('Build Checklist'!C5:C16,"Fail") -> 0
A55: N/A | B55: Not applicable for this project. | C55: =COUNTIF('Build Checklist'!C5:C16,"N/A") -> 0
...

Sheet Build Item Readiness Helper
A1: Build Item Readiness Helper — should I build this now?
A2: Use this BEFORE starting any build item. Fill the 6 yellow inputs about the item; the blue cells suggest whether to build now, the priority, mandatory pre-build checks, Phase 5 test priority, and the top safety boundary. PM judgment still final.
A4: INPUTS — about this one build item
A5: # | B5: Question | C5: Allowed values | D5: Answer
A6: Q1 | B6: Q1. Build item category | C6: Module / Credential / Prompt / Audit-error / Test / Other | D6: Module
A7: Q2 | B7: Q2. Dependency status | C7: All met / Some pending / Blocked | D7: All met
A8: Q3 | B8: Q3. Risk level (from Phase 3 blueprint) | C8: Low / Medium / High | D8: Medium
A9: Q4 | B9: Q4. AI involvement in this item | C9: None / Classify only / Generate content / Take action | D9: Classify only
A10: Q5 | B10: Q5. Security touch points | C10: Routine / OAuth setup / Secret handling / Sensitive data | D10: Routine
A11: Q6 | B11: Q6. Phase 3 blueprint approval status | C11: Yes / Partial / No / Unknown | D11: Yes
A13: SUGGESTED VERDICT (auto-calculated)
A14: # | B14: Indicator | C14: Suggested Value (formula) | D14: Reasoning hint
A15: O1 | B15: Build verdict | C15: =IF(D11="No","BLOCK — not approved in Phase 3; escalate.",IF(D11="Unknown","HOLD — confirm Phase 3 approval before building.",IF(D7="Blocked","BLOCK — dependency is blocked; escalate.",IF(D7="Some pending","HOLD — build prerequisites first.",IF(D11="Partial","HOLD — confirm partial blueprint covers this item.","GO — proceed with build."))))) -> GO — proceed with build. | D15: Phase 3 must be Yes and dependencies met. Anything else → Hold or Block.
A16: O2 | B16: Priority recommendation | C16: =IF(OR(D6="Credential",D6="Audit-error"),"P1 (foundational — do early)",IF(AND(D8="High",D9<>"None"),"P1 (high-risk AI — do early, test hard)",IF(AND(D6="Test",D8="Low"),"P3 (later — low-risk tests)","P2 (standard sprint priority)"))) -> P2 (standard sprint priority) | D16: Credentials and audit-error are foundational. High-risk AI items also P1.
A17: O3 | B17: Mandatory pre-build checks | C17: =IF(D10="Secret handling","Use Make connection/keychain; never hardcode keys; rotate plan documented.",IF(D10="OAuth setup","Confirm client owns account; minimum-required scopes only; revocation path noted.",IF(D10="Sensitive data","Human approval required at every outbound action; no AI advice; minimal retention.",IF(D6="Prompt","Lock schema, allowed categories, confidence threshold, fallback rule before build.",IF(D6="Module","Confirm trigger source ID; no auto-delete; error route attached.","Standard: log inputs/outputs; fallback to Human Review on uncertainty."))))) -> Confirm trigger source ID; no auto-delete; error route attached. | D17: Single most-important pre-build action for this combination.
A18: O4 | B18: Phase 5 test priority | C18: =IF(OR(D8="High",D9="Take action",D10="Sensitive data"),"MUST TEST (high-impact failure modes)",IF(AND(D8="Low",D9="None"),"Smoke only (basic happy path)","Standard test set (happy + 1-2 edge cases)")) -> Standard test set (happy + 1-2 edge cases) | D18: High risk / agentic / sensitive → must test. Low-risk passive → smoke only.
A19: O5 | B19: Top safety boundary | C19: =IF(AND(D9="Take action",D10="Sensitive data"),"Irreversible action on sensitive data: require allow-list + approval + kill-switch + audit.",IF(AND(D9="Generate content",D10="Sensitive data"),"AI content on sensitive topic: never auto-send; escalate; no AI advice.",IF(D9="Take action","Agentic step: explicit allow-list of actions + audit log + manual approval for non-routine cases.",IF(D10="Sensitive data","Sensitive data: minimum-data retention; access restricted to owner.",IF(D6="Credential","Never paste secrets in workbook or exports; sanitize before sharing.","Standard: write audit row each run; no destructive actions on error."))))) -> Standard: write audit row each run; no destructive actions on error. | D19: The biggest single safety rule for this build item.
A22: How to use this with the Build Backlog:
A23: 1) Pick one B-### item from the Build Backlog.
A24: 2) Fill the 6 yellow inputs.
A25: 3) Read the 5 blue suggestions; transfer Priority and Risk into the backlog row.
A26: 4) Use Mandatory pre-build checks as a sanity gate before starting work.
A28: Caveat: this is decision support. Real PM judgment (client trust, contract scope, team availability) may override the recommendation.

Sheet Phase3 to Phase4 Handoff
A1: Phase 3 → Phase 4 Handoff
A2: Use this to preserve scope. Build decisions must come from the approved Phase 3 blueprint.
A4: Handoff Area | B4: Approved Phase 3 Decision | C4: Build Impact | D4: Owner | E4: Status | F4: Open Issue / Comment
A5: MVP goal | C5: Defines what the first build must achieve | E5: Not Started
A6: Included data sources / channels | C6: Defines triggers/connections to configure | E6: Not Started
A7: Included processing categories | C7: Defines classifier labels, extraction schema, or routing rules | E7: Not Started
A8: Excluded functions | C8: Defines what must not be built yet | E8: Not Started
A9: Human approval points | C9: Defines draft/review/not-send logic | E9: Not Started
A10: Tool stack | C10: Defines Make apps and external services | E10: Not Started
A11: Data fields | C11: Defines CRM/log/audit fields | E11: Not Started
A12: Security/access rules | C12: Defines credentials, ownership and permissions | E12: Not Started
A13: Error handling rules | C13: Defines fallback notifications and no-destructive-actions logic | E13: Not Started

Sheet Build Backlog
A1: Phase 4 Build Backlog
A2: Main MVP implementation task list. Use Status/Priority/Dependency to control the build.
A4: ID | B4: Build Item | C4: Description | D4: Source Decision | E4: Priority | F4: Status | G4: Owner | H4: Dependency | I4: Risk | J4: Done Criteria | K4: Notes | L4: Completeness Status (AUTO)
A5: B-001 | B5: Create scenario shell | C5: Create project scenario with naming convention and version. | D5: Phase3 blueprint | E5: High | F5: Not Started | H5: None | I5: Low | J5: Scenario created and named correctly | L5: =IF(COUNTA(B5,D5,E5,F5,I5,J5)=0,"Empty",IF(COUNTA(B5,D5,E5,F5,I5,J5)<6,"Partial","Complete")) -> Complete
A6: B-002 | B6: Configure trigger/input | C6: Configure webhook/email/form trigger based on approved MVP. | D6: Included channels | E6: High | F6: Not Started | H6: B-001 | I6: Medium | J6: Trigger receives exact intended payload | L6: =IF(COUNTA(B6,D6,E6,F6,I6,J6)=0,"Empty",IF(COUNTA(B6,D6,E6,F6,I6,J6)<6,"Partial","Complete")) -> Complete
A7: B-003 | B7: Normalize input fields | C7: Map incoming data to standard fields. | D7: Data field map | E7: High | F7: Not Started | H7: B-002 | I7: Medium | J7: All required fields present | L7: =IF(COUNTA(B7,D7,E7,F7,I7,J7)=0,"Empty",IF(COUNTA(B7,D7,E7,F7,I7,J7)<6,"Partial","Complete")) -> Complete
A8: B-004 | B8: Configure AI classifier | C8: Build AI classification step with strict JSON output. | D8: Routing rules | E8: High | F8: Not Started | H8: B-003 | I8: Medium | J8: Classifier returns valid JSON and labels | L8: =IF(COUNTA(B8,D8,E8,F8,I8,J8)=0,"Empty",IF(COUNTA(B8,D8,E8,F8,I8,J8)<6,"Partial","Complete")) -> Complete
A9: B-005 | B9: Add validation/fallback | C9: Handle invalid or low-confidence AI response. | D9: Error rules | E9: High | F9: Not Started | H9: B-004 | I9: High | J9: Unknown/invalid routes to Human Review | L9: =IF(COUNTA(B9,D9,E9,F9,I9,J9)=0,"Empty",IF(COUNTA(B9,D9,E9,F9,I9,J9)<6,"Partial","Complete")) -> Complete
A10: B-006 | B10: Build router paths | C10: Route each category to correct action. | D10: Routing rules | E10: High | F10: Not Started | H10: B-004 | I10: Medium | J10: Each category has safe path | L10: =IF(COUNTA(B10,D10,E10,F10,I10,J10)=0,"Empty",IF(COUNTA(B10,D10,E10,F10,I10,J10)<6,"Partial","Complete")) -> Complete
A11: B-007 | B11: Create CRM/log record | C11: Create Notion/Airtable/CRM record. | D11: Data field map | E11: High | F11: Not Started | H11: B-006 | I11: Medium | J11: Record contains key fields/status | L11: =IF(COUNTA(B11,D11,E11,F11,I11,J11)=0,"Empty",IF(COUNTA(B11,D11,E11,F11,I11,J11)<6,"Partial","Complete")) -> Complete
A12: B-008 | B12: Create draft/notification | C12: Prepare draft or notification without unsafe auto-send. | D12: Approval rules | E12: Medium | F12: Not Started | H12: B-006 | I12: Medium | J12: Human receives clear draft/task | L12: =IF(COUNTA(B12,D12,E12,F12,I12,J12)=0,"Empty",IF(COUNTA(B12,D12,E12,F12,I12,J12)<6,"Partial","Complete")) -> Complete
A13: B-009 | B13: Move/label message | C13: Move or label exact source message only. | D13: Tool stack | E13: Medium | F13: Not Started | H13: B-006 | I13: High | J13: No wrong message moved | L13: =IF(COUNTA(B13,D13,E13,F13,I13,J13)=0,"Empty",IF(COUNTA(B13,D13,E13,F13,I13,J13)<6,"Partial","Complete")) -> Complete
A14: B-010 | B14: Add audit log | C14: Log classification, action and status. | D14: Monitoring | E14: High | F14: Not Started | H14: B-006 | I14: Medium | J14: Each run writes audit row | L14: =IF(COUNTA(B14,D14,E14,F14,I14,J14)=0,"Empty",IF(COUNTA(B14,D14,E14,F14,I14,J14)<6,"Partial","Complete")) -> Complete
A15: B-011 | B15: Add error handler | C15: Notify on failure and avoid destructive actions. | D15: Error rules | E15: High | F15: Not Started | H15: B-006 | I15: High | J15: Failure creates alert/status Error | L15: =IF(COUNTA(B15,D15,E15,F15,I15,J15)=0,"Empty",IF(COUNTA(B15,D15,E15,F15,I15,J15)<6,"Partial","Complete")) -> Complete
A16: B-012 | B16: Prepare test seed cases | C16: Prepare cases for Phase 5 testing. | D16: Test plan | E16: Medium | F16: Not Started | H16: B-004 | I16: Low | J16: All categories have sample messages | L16: =IF(COUNTA(B16,D16,E16,F16,I16,J16)=0,"Empty",IF(COUNTA(B16,D16,E16,F16,I16,J16)<6,"Partial","Complete")) -> Complete

Sheet Module Build Plan
A1: Scenario / Module Build Plan
A2: Translate the workflow into concrete modules. One row per Make/app module or component.
A4: Step | B4: Module / Component | C4: Purpose | D4: Input | E4: Output | F4: Configuration Needed | G4: Safety Rule | H4: Status | I4: Test Ref | J4: Notes | K4: Completeness Status (AUTO)
A5: 1 | B5: Trigger | C5: Receive trigger input | D5: Trigger payload (message, document, event, or data record) | E5: Raw payload | F5: Connection, trigger filter, exact ID capture | G5: Never lose source ID | H5: Not Started | I5: TC-001 | K5: =IF(COUNTA(B5,C5,D5,E5,F5,G5,H5,I5)=0,"Empty",IF(COUNTA(B5,C5,D5,E5,F5,G5,H5,I5)<8,"Partial","Complete")) -> Complete
A6: 2 | B6: Normalizer / Mapper | C6: Standardize fields | D6: Raw payload | E6: Standard fields | F6: Map source fields into standard format (channel, type, content, timestamp) | G6: Required fields cannot be empty | H6: Not Started | I6: TC-002 | K6: =IF(COUNTA(B6,C6,D6,E6,F6,G6,H6,I6)=0,"Empty",IF(COUNTA(B6,C6,D6,E6,F6,G6,H6,I6)<8,"Partial","Complete")) -> Complete
A7: 3 | B7: AI Classifier | C7: Classify input / extract structured data | D7: Standard fields | E7: JSON classification | F7: Prompt, schema, temperature, model | G7: No free text outside JSON | H7: Not Started | I7: TC-003 | K7: =IF(COUNTA(B7,C7,D7,E7,F7,G7,H7,I7)=0,"Empty",IF(COUNTA(B7,C7,D7,E7,F7,G7,H7,I7)<8,"Partial","Complete")) -> Complete
A8: 4 | B8: JSON Parser / Validator | C8: Validate AI output | D8: Classifier result | E8: Parsed fields | F8: Schema, required values, fallback | G8: Invalid → Human Review | H8: Not Started | I8: TC-004 | K8: =IF(COUNTA(B8,C8,D8,E8,F8,G8,H8,I8)=0,"Empty",IF(COUNTA(B8,C8,D8,E8,F8,G8,H8,I8)<8,"Partial","Complete")) -> Complete
A9: 5 | B9: Router | C9: Select action path | D9: Parsed classification | E9: Selected path | F9: Route filters per category | G9: No category without fallback | H9: Not Started | I9: TC-005 | K9: =IF(COUNTA(B9,C9,D9,E9,F9,G9,H9,I9)=0,"Empty",IF(COUNTA(B9,C9,D9,E9,F9,G9,H9,I9)<8,"Partial","Complete")) -> Complete
A10: 6 | B10: CRM/Database Create | C10: Log record / entry | D10: Mapped fields | E10: CRM item | F10: Database/table fields | G10: Store minimum necessary data | H10: Not Started | I10: TC-006 | K10: =IF(COUNTA(B10,C10,D10,E10,F10,G10,H10,I10)=0,"Empty",IF(COUNTA(B10,C10,D10,E10,F10,G10,H10,I10)<8,"Partial","Complete")) -> Complete
A11: 7 | B11: Draft/Notify | C11: Prepare next action | D11: Input + classification or extraction result | E11: Draft/task/alert | F11: Template, recipient, approval flow | G11: No auto-send unless approved | H11: Not Started | I11: TC-007 | K11: =IF(COUNTA(B11,C11,D11,E11,F11,G11,H11,I11)=0,"Empty",IF(COUNTA(B11,C11,D11,E11,F11,G11,H11,I11)<8,"Partial","Complete")) -> Complete
A12: 8 | B12: Move/Label Message | C12: Organise or route source item | D12: Exact source item ID (message ID, document ID, record ID) | E12: Folder/label update | F12: Folder names, ID mapping | G12: Use exact message ID only | H12: Not Started | I12: TC-008 | K12: =IF(COUNTA(B12,C12,D12,E12,F12,G12,H12,I12)=0,"Empty",IF(COUNTA(B12,C12,D12,E12,F12,G12,H12,I12)<8,"Partial","Complete")) -> Complete
A13: 9 | B13: Audit Log | C13: Record execution | D13: All prior outputs | E13: Audit row | F13: Log table/sheet fields | G13: Every run logged | H13: Not Started | I13: TC-009 | K13: =IF(COUNTA(B13,C13,D13,E13,F13,G13,H13,I13)=0,"Empty",IF(COUNTA(B13,C13,D13,E13,F13,G13,H13,I13)<8,"Partial","Complete")) -> Complete
A14: 10 | B14: Error Handler | C14: Catch failures | D14: Error event | E14: Alert + error log | F14: Error route, notification recipient | G14: No deletion on error | H14: Not Started | I14: TC-010 | K14: =IF(COUNTA(B14,C14,D14,E14,F14,G14,H14,I14)=0,"Empty",IF(COUNTA(B14,C14,D14,E14,F14,G14,H14,I14)<8,"Partial","Complete")) -> Complete

Sheet Credentials & Access
A1: Credentials & Access Register
A2: Record access setup without storing secrets. Never paste API keys or passwords into this workbook.
A4: Service / Tool | B4: Credential Type | C4: Owner | D4: Stored Where | E4: Access Level | F4: Rotation / Revocation Plan | G4: Status | H4: Do NOT Store Here | I4: Notes
A5: Make.com | B5: Workspace access | C5: Provider or client | D5: Make team/workspace | E5: Admin/Editor/Viewer | F5: Remove user or transfer scenario ownership | G5: Not Started | H5: Passwords, API keys
A6: Gmail / Google Workspace | B6: OAuth connection | C6: Client preferred | D6: Make connection / OAuth | E6: Minimum required scopes | F6: Client can revoke OAuth access | G6: Not Started | H6: Passwords
A7: Instagram / Meta | B7: OAuth / Business integration | C7: Client | D7: Meta Business / Make connection | E7: Page messaging access only | F7: Remove app/business permission | G7: Not Started | H7: Access tokens
A8: OpenAI | B8: API key | C8: Provider or client | D8: Make secure connection/keychain or backend proxy | E8: Limited project key | F8: Rotate key if exposed; monitor usage | G8: Not Started | H8: Raw key
A9: CRM / Notion / Airtable | B9: OAuth/API connection | C9: Client preferred | D9: Make connection | E9: Create/update only where needed | F9: Revoke integration from workspace | G9: Not Started | H9: Raw key
A10: Calendar / Booking | B10: OAuth connection | C10: Client | D10: Make connection / native integration | E10: Read availability / create draft booking if approved | F10: Revoke OAuth app | G10: Not Started | H10: Passwords

Sheet AI Prompt Config
A1: AI Prompt / Rule Configuration
A2: Define AI behavior as a controlled build asset: prompts, schema, categories, confidence, fallback and approvals.
A4: Prompt ID | B4: Use Case | C4: Model / Tool | D4: Input Fields | E4: Required Output Schema | F4: Allowed Categories | G4: Temperature | H4: Confidence Threshold | I4: Fallback Rule | J4: Human Approval? | K4: Status | L4: Notes
A5: P-001 | B5: Message classification | C5: OpenAI / Make AI | D5: subject, message, channel | E5: classification, confidence, urgency, reason, suggested_action, requires_human_review | F5: Client-specific taxonomy | G5: 0 | H5: 0.80 | I5: Below threshold → Human Review | J5: Yes | K5: Not Started
A6: P-002 | B6: Reply draft | C6: OpenAI / Make AI | D6: message, category, FAQ, tone | E6: draft_subject, draft_body, risk_note | F6: Safe categories only | G6: 0.2 | H6: 0.85 | I6: If sensitive → no draft, escalate | J6: Yes | K6: Not Started
A7: P-003 | B7: Summary for CRM | C7: OpenAI / Make AI | D7: message, classification | E7: one_sentence_summary, client_need | F7: All non-spam categories | G7: 0 | H7: 0.80 | I7: Invalid → raw message note | J7: No | K7: Not Started
A8: P-004 | B8: Urgency detection | C8: OpenAI / Make AI | D8: message | E8: urgency, escalation_reason | F8: normal, important, urgent | G8: 0 | H8: 0.90 | I8: Urgent → notify human immediately | J8: Yes | K8: Not Started
A9: P-005 | B9: Document field extraction | C9: OpenAI / Make AI | D9: document_text, field_schema, document_type | E9: extracted_fields, confidence, missing_fields, validation_status | F9: Defined field schema per document type (invoice, contract, form) | G9: 0 | H9: 0.85 | I9: Missing required field → flag for human review; do not post to system | J9: Yes | K9: Not Started | L9: Validate extracted fields before any downstream write; error route mandatory.
A10: P-006 | B10: Content repurposing / draft generation | C10: OpenAI / Make AI | D10: source_content, target_platform, tone_guide, character_limit | E10: draft_content, platform_format, risk_note | F10: Approved target platforms only | G10: 0.3 | I10: Human review required before any publish action; never auto-publish | J10: Yes | K10: Not Started | L10: One source per run; draft only — never publish without explicit human approval.

Sheet Audit & Error Build
A1: Audit Log and Error Handling Build
A2: Build logging and error handling as part of MVP, not afterthought.
A4: Item | B4: What to Build | C4: Required Fields / Logic | D4: Reason | E4: Status | F4: Owner | G4: Notes
A5: Audit log row | B5: Write one log row per run | C5: timestamp, source_id, channel, classification, confidence, action_taken, status | D5: Supports monitoring and client trust | E5: Not Started
A6: Error log row | B6: Write one row per failed run | C6: timestamp, scenario, module, error_message, source_id, recovery_status | D6: Supports support/debugging | E6: Not Started
A7: Failure notification | B7: Send alert to provider/admin | C7: error summary, affected client, run link, next action | D7: Prevents silent failures | E7: Not Started
A8: Fallback route | B8: Route unknown/invalid cases to Human Review | C8: invalid JSON, missing field, low confidence, unrecognized category | D8: Avoids unsafe automation | E8: Not Started
A9: No destructive action rule | B9: Do not delete source messages automatically | C9: move/label instead of delete | D9: Protects client data | E9: Not Started
A10: Exact message matching | B10: Use source ID or correlation ID | C10: no latest-unread matching in production | D10: Avoids wrong message moved/replied | E10: Not Started

Sheet Test Seed Cases
A1: Test Seed Cases for Phase 5
A2: Prepare representative messages during build. These become the starting point for formal Phase 5 testing.
A4: Test ID | B4: Category | C4: Sample Input Message | D4: Expected Classification | E4: Expected Action | F4: Risk | G4: AI Draft? | H4: Auto-Send? | I4: Notes
A5: TC-001 | B5: Lead / Booking | C5: Hello, I would like to book an appointment next week. | D5: BOOKING / LEAD | E5: Create CRM item + draft booking reply | F5: Low | G5: Yes | H5: No
A6: TC-002 | B6: Price question | C6: Can you tell me your prices? | D6: PRICE_QUESTION | E6: Create draft FAQ reply | F6: Low | G6: Yes | H6: No
A7: TC-003 | B7: Sensitive message | C7: I have a personal problem and need advice now. | D7: SENSITIVE / HUMAN_REVIEW | E7: Escalate to human, no advice | F7: High | G7: No | H7: No
A8: TC-004 | B8: Complaint | C8: I did not receive an answer and I am unhappy. | D8: COMPLAINT | E8: Human review + important flag | F8: Medium | G8: Maybe | H8: No
A9: TC-005 | B9: Spam | C9: Buy followers cheap now. | D9: SPAM | E9: Move to spam-review folder | F9: Low | G9: No | H9: No
A10: TC-006 | B10: Unclear | C10: Hi | D10: UNKNOWN / HUMAN_REVIEW | E10: Human review | F10: Medium | G10: No | H10: No
A11: TC-007 | B11: Test message | C11: This is a test form submission. | D11: TEST | E11: Route to test folder/log | F11: Low | G11: No | H11: No
A12: TC-008 | B12: Document Processing | C12: [Invoice PDF received] Supplier: ABC GmbH, CHF 4'850, due 2026-07-15 | D12: INVOICE / DOCUMENT | E12: Extract fields → validate → log to accounting; flag mismatches for review | F12: Medium | G12: Yes (field extraction) | H12: No | I12: Example for document extraction automation — adapt field schema per project
A13: TC-009 | B13: Content & Marketing | C13: [Source article submitted] Product launch blog post (800 words); targets: Instagram, LinkedIn, newsletter | D13: CONTENT_REPURPOSE | E13: Generate platform-specific drafts → route to human review → publish only after approval | F13: Low | G13: Yes | H13: No | I13: Example for content repurposing — never auto-publish; human approval required before every post
A14: TC-010 | B14: Internal Ops / Approval | C14: [Approval request submitted] Purchase: CHF 1'200, office equipment, submitted by T. Müller | D14: APPROVAL_REQUEST | E14: Route to approver → send notification + log; reminder if no reply within 24h | F14: Low | G14: No | H14: No | I14: Example for approval routing automation — no auto-approve under any circumstance

Sheet Build Checklist
A1: Phase 4 Build Completion Checklist
A2: Complete this before starting formal Phase 5 testing.
A4: Check ID | B4: Checklist Item | C4: Pass? | D4: Evidence / Link / Comment | E4: Owner | F4: Date
A5: C-001 | B5: Scenario/workflow name and version are clear
A6: C-002 | B6: Trigger receives the correct source message/payload
A7: C-003 | B7: No hardcoded API keys or passwords are visible in modules
A8: C-004 | B8: Client-owned connections are used where appropriate
A9: C-005 | B9: AI classifier returns strict valid JSON
A10: C-006 | B10: Low-confidence/invalid outputs route to Human Review
A11: C-007 | B11: No unsafe automatic sending is enabled unless approved
A12: C-008 | B12: CRM/database record is created correctly
A13: C-009 | B13: Audit log is written for each run
A14: C-010 | B14: Error handler creates alert and error log
A15: C-011 | B15: Exact message ID/correlation logic is confirmed
A16: C-012 | B16: Test seed cases are prepared for Phase 5
A18: Build at a Glance (auto-computed)
A19: Backlog items defined | G19: =COUNTA('Build Backlog'!A5:A16) -> 12
A20: Backlog items — Done | G20: =COUNTIF('Build Backlog'!F5:F16,"Done") -> 0
A21: Modules planned | G21: =COUNTA('Module Build Plan'!A5:A14) -> 10
A22: Modules — Done | G22: =COUNTIF('Module Build Plan'!H5:H14,"Done") -> 0
A23: Credentials registered | G23: =COUNTA('Credentials & Access'!A5:A10) -> 6
A24: Credentials — Verified | G24: =COUNTIF('Credentials & Access'!G5:G10,"Verified") -> 0
A25: AI prompts defined | G25: =COUNTA('AI Prompt Config'!A5:A12) -> 6
A26: AI prompts — Done | G26: =COUNTIF('AI Prompt Config'!K5:K12,"Done") -> 0
A27: Audit/Error items defined | G27: =COUNTA('Audit & Error Build'!A5:A12) -> 6
A28: Test seed cases prepared | G28: =COUNTA('Test Seed Cases'!A5:A12) -> 8
A29: Build Checklist items — Pass | G29: =COUNTIF('Build Checklist'!C5:C16,"Pass") -> 0
A30: Build Checklist items — Pending/Fail | G30: =COUNTIF('Build Checklist'!C5:C16,"Pending")+COUNTIF('Build Checklist'!C5:C16,"Fail") -> 0

Sheet Change Log
A1: Build Change Log
A2: Track changes to prompts, routing, module settings and security decisions during implementation.
A4: Change ID | B4: Date | C4: Area | D4: Change Description | E4: Reason | F4: Impact | G4: Approved By | H4: Status
A5: CH-001
A6: CH-002
A7: CH-003
