Workbook

Sheet START HERE
A1: AI Automation Managed Services - Phase 1 Discovery Master
A3: Purpose | B3: Use this workbook as one broad master template for first client discovery. It covers the full Phase 1 scope, but clearly marks which columns are filled live during the interview and which are completed later by the PM.
A5: Step | B5: What to do | C5: Where | E5: Colour | F5: Meaning | G5: When to edit
A6: 1 | B6: Before the interview: read the fixed grey guidance columns and choose which rows are relevant for the client. | C6: Phase1 Master | E6: Grey | F6: Fixed/reference guidance | G6: Normally do not edit
A7: 2 | B7: During the interview: fill only the green columns first. Do not over-design the solution yet. | C7: Client Answer / Notes, Initial Risk Level, Initial MVP Relevance, Open Questions | E7: Green | F7: Live interview input | G7: Fill during client call
A8: 3 | B8: After the interview: complete the blue PM analysis columns. | C8: PM Interpretation, Output / Decision, Final Product Flag, Final MVP Relevance, Required Action / Next Step | E8: Blue | F8: PM analysis / decision | G8: Fill after interview
A9: 4 | B9: Use the yellow optional column only when you already see a clear product configuration flag. | C9: Draft Product Flag | E9: Yellow | F9: Optional early configuration flag | G9: Fill if already clear
A10: 5 | B10: Use Example Rows if you are unsure how answers should look. | C10: Example Rows
A12: MVP = Minimum Viable Product: the smallest useful and safe first automation version that solves the main problem without building the full future system.
A14: Internal package logic added
A15: Use the package logic only internally during Phase 1. Do not treat Basic/Pro/Managed/Agentic as final offers during discovery. During the interview, collect facts first. After the interview, use Package Decision Helper to fill Internal Package Indication and Automation Method Candidate in Phase1 Master. Package direction should support MVP definition, risk boundaries, and solution architecture. It can be Basic, Pro, Managed, Agentic, Mixed, Later, or Not applicable.
A19: We planned this PM flow: | C19: We now have:
A21: Phase 1 — Discovery / Analysis | C21: Phase 1 — Discovery / Analysis
A22: Understand client needs, channels, risks, pain points, possible package direction. | C22: Client needs, risks, flags, internal package direction.
A24: Phase 2 — Scope Definition / MVP Design | C24: Phase 2 — Scope / MVP Design
A25: Convert discovery answers into a clear first project scope. | C25: What to build now, later, or exclude.
A27: Phase 3 — Solution Blueprint | C27: Phase 3 — Solution Blueprint
A28: Design workflow logic, tools, data fields, routing, approvals, security. | C28: Workflow, tools, data, routing, approvals, security.
A30: Phase 4 — MVP Build | C30: Phase 4 — MVP Build
A31: Build the first safe automation version. | C31: Build backlog, modules, prompts, credentials, audit/error setup.
A33: Phase 5 — Testing / Validation | C33: Phase 5 — Testing / Validation
A34: Test real cases, edge cases, errors, wrong classifications, approvals. | C34: Test cases, AI validation, escalation, defects, Go/No-Go.
A36: Phase 6 — Go-live / Managed Service | C36: Phase 6 — Go-live / Managed Service
A37: Launch, monitor, maintain, improve, report. | C37: Launch, monitoring, operations, monthly review, improvements.
C39: This gives you a complete reusable framework:
C40: client interview → scope → blueprint → build → test → launch/manage
C41: The next logical step would be to create one short Master Overview / Index Excel or PDF that links all six phases and explains when to use each file.
A43: NEW IN v3 — Streamlined Discovery Flow
A44: Step | B44: Sheet | C44: Use when | E44: What you get
A45: 0 — Before the call | B45: Client Pre-Interview | C45: Send to client 2–3 days before the discovery call. | E45: Easy facts pre-filled: channels, tools, volumes, sensitive data, success picture.
A46: 1 — During the call | B46: Interview Script | C46: Use on the live call instead of Phase1 Master. | E46: ~20 questions, conversational order, with branch/skip cues. Faster, less fatigue.
A47: 2 — Right after the call | B47: Quick Diagnostic | C47: Fill 9 inputs based on interview answers. | E47: Auto-suggested package direction, MVP scope hint, approval rule, risk caution.
A48: 3 — Consolidation | B48: Phase1 Master | C48: Transfer all answers, complete the PM (blue) and Package (pink) columns. | E48: Canonical record for the project. Drives Phase 2 scope.
A50: Discovery Progress (auto-computed from Phase1 Master)
A51: Status | B51: Meaning | E51: Count
A52: Empty | B52: No live answer yet — row not yet covered in interview. | E52: =COUNTIF('Phase1 Master'!S2:S67,"Empty") -> 66
A53: Live partial | B53: Some live fields missing (Client Answer / Risk / MVP). | E53: =COUNTIF('Phase1 Master'!S2:S67,"Live partial") -> 0
A54: Live OK - PM pending | B54: Live edit done; PM analysis not started. | E54: =COUNTIF('Phase1 Master'!S2:S67,"Live OK - PM pending") -> 0
A55: PM partial | B55: PM analysis started but missing fields. | E55: =COUNTIF('Phase1 Master'!S2:S67,"PM partial") -> 0
A56: Complete | B56: All required live + PM fields filled. | E56: =COUNTIF('Phase1 Master'!S2:S67,"Complete") -> 0
...

Sheet Client Pre-Interview EN
A1: Pre-Interview Questionnaire — for the Client
A2: Please answer in your own words — short bullet points are fine. There are no wrong answers. We use this to come prepared, so the call can focus on the harder questions rather than basic facts. Takes about 10 minutes.
A4: # | B4: Question | C4: Hint / Examples (read if unsure) | D4: Your Answer
A5: 1 | B5: Business basics — What does your business do, and who are your typical clients? | C5: 1–2 sentences. E.g., 'Solo therapist, private clients, mostly adults in Zurich.'
A6: 2 | B6: Main pain — What is the main problem or repetitive task you want help with? | C6: What eats your time today? E.g., 'Replying to the same booking and price questions every day.'
A7: 3 | B7: Success picture — What would 'success' look like 3 months after we go live? | C7: E.g., 'Faster replies, no missed bookings, less admin in the evening, daily summary by email.'
A8: 4 | B8: Channels — Where do client messages arrive today? | C8: Tick all that apply: Email/Gmail, Instagram DM, Facebook Messenger, WhatsApp, Website form, Phone/SMS, LinkedIn, Other.
A9: 5 | B9: Volume — Roughly how many client messages per week, total? | C9: Pick one: under 20 / 20–100 / 100–500 / more than 500.
A10: 6 | B10: Common types — What types of messages do you get most often? | C10: E.g., new booking, price questions, cancellations/reschedules, complaints, general questions, spam.
A11: 7 | B11: Document tasks — Do you handle repetitive document tasks regularly? | C11: E.g., extracting data from supplier invoices, summarising contracts, processing application forms, categorising receipts. If yes, roughly how many per week?
A12: 8 | B12: Content production — Do you create or manage content regularly? | C12: E.g., writing social media posts, sending email newsletters, publishing blog articles. On which platforms? How often?
A13: 9 | B13: Internal operations — Are there internal process steps that take up time? | C13: E.g., routing requests for sign-off, assigning tasks to team members, onboarding new staff or clients, sending project status updates. Which step takes the longest?
A14: 10 | B14: Sensitive content — Do messages ever contain sensitive personal information (health, legal, financial, emotional)? | C14: Yes / Sometimes / No. If yes, briefly describe the type.
A15: 11 | B15: Human-only tasks — Which tasks should ALWAYS stay human, never automated? | C15: E.g., therapy advice, complaints, urgent emotional cases, legal questions.
A16: 12 | B16: AI comfort level — How comfortable are you with AI replying to clients? | C16: Pick one: (a) Never auto-send — I want to approve every reply. (b) Auto-send only safe replies (e.g., price list, booking link). (c) Auto-send most replies, escalate only edge cases.
... A19: 15 | B19: Anything else — Anything we should know before the call? | C19: Privacy rules, deadlines, previous bad experiences with automation, anything sensitive.
A21: Tip: send this as a Google Doc, PDF, or just copy/paste the questions into an email. If a client cannot answer a question, leave it blank — we will cover it on the call.

Sheet CPI DE
A1: Vorab-Fragebogen — für den Kunden
A2: Bitte beantworten Sie die Fragen in eigenen Worten — kurze Stichpunkte reichen. Es gibt keine falschen Antworten. Wir nutzen diese Informationen zur Vorbereitung, damit wir uns im Gespräch auf die wichtigen Themen konzentrieren können. Dauert etwa 10 Minuten.
A4: # | B4: Frage | C4: Hinweis / Beispiel (lesen falls unklar) | D4: Ihre Antwort
A5: 1 | B5: Geschäftsgrundlagen — Was macht Ihr Unternehmen, und wer sind Ihre typischen Kunden? | C5: 1–2 Sätze. Z.B. 'Selbstständige Therapeutin, Privatkunden, hauptsächlich Erwachsene in Zürich.'
A6: 2 | B6: Hauptproblem — Was ist das grösste Problem oder die wiederkehrende Aufgabe, bei der Sie Unterstützung möchten? | C6: Was kostet Sie heute am meisten Zeit? Z.B. 'Täglich die gleichen Fragen zu Buchungen und Preisen beantworten.'
A7: 3 | B7: Erfolgsbild — Wie würde 'Erfolg' für Sie 3 Monate nach dem Go-live aussehen? | C7: Z.B. 'Schnellere Antworten, keine verpassten Buchungen, weniger Administration am Abend, tägliche Zusammenfassung per E-Mail.'
A8: 4 | B8: Kanäle — Wo kommen heute die Kundennachrichten an? | C8: Alles Zutreffende ankreuzen: E-Mail/Gmail, Instagram DM, Facebook Messenger, WhatsApp, Webformular, Telefon/SMS, LinkedIn, Anderes.
A9: 5 | B9: Volumen — Wie viele Kundennachrichten erhalten Sie ungefähr pro Woche, insgesamt? | C9: Eines auswählen: unter 20 / 20–100 / 100–500 / mehr als 500.
A10: 6 | B10: Häufige Typen — Welche Arten von Nachrichten erhalten Sie am häufigsten? | C10: Z.B. neue Buchungen, Preisfragen, Stornierungen/Umbuchungen, Reklamationen, allgemeine Fragen, Spam.
A11: 7 | B11: Dokumentaufgaben — Bearbeiten Sie regelmässig wiederkehrende Dokumentaufgaben? | C11: Z.B. Daten aus Lieferantenrechnungen extrahieren, Verträge zusammenfassen, Antragsformulare verarbeiten, Belege kategorisieren. Falls ja, ungefähr wie viele pro Woche?
A12: 8 | B12: Inhaltserstellung — Erstellen oder verwalten Sie regelmässig Inhalte? | C12: Z.B. Instagram-Posts verfassen, E-Mail-Newsletter versenden, Blogartikel schreiben. Auf welchen Plattformen? Wie oft?
A13: 9 | B13: Interne Abläufe — Gibt es interne Prozessschritte, die regelmässig Zeit kosten? | C13: Z.B. Freigaben einholen, Aufgaben an Teammitglieder zuweisen, neue Mitarbeitende oder Kunden einführen, Projektstatus kommunizieren. Welcher Schritt dauert am längsten?
A14: 10 | B14: Sensible Inhalte — Enthalten Nachrichten manchmal sensible persönliche Informationen (Gesundheit, Recht, Finanzen, Emotionen)? | C14: Ja / Manchmal / Nein. Falls ja, bitte kurz die Art beschreiben.
A15: 11 | B15: Aufgaben nur für Menschen — Welche Aufgaben sollen IMMER von Menschen erledigt werden, niemals automatisiert? | C15: Z.B. Therapieberatung, Reklamationen, dringende emotionale Fälle, Rechtsfragen.
A16: 12 | B16: Komfortniveau mit AI — Wie wohl fühlen Sie sich damit, wenn AI auf Kunden antwortet? | C16: Eines auswählen: (a) Nie automatisch senden — ich möchte jede Antwort freigeben. (b) Nur sichere Antworten automatisch senden (z.B. Preisliste, Buchungslink). (c) Die meisten Antworten automatisch senden, nur Ausnahmefälle eskalieren.
... A19: 15 | B19: Sonstiges — Gibt es etwas, das wir vor dem Gespräch wissen sollten? | C19: Datenschutzregeln, Fristen, frühere schlechte Erfahrungen mit Automatisierung, sensible Themen.
A21: Tipp: Senden Sie diesen Fragebogen als Google Doc, PDF oder kopieren Sie die Fragen einfach in eine E-Mail. Wenn der Kunde eine Frage nicht beantworten kann, einfach leer lassen — wir besprechen das dann im Gespräch.

Sheet Interview Script EN
A1: Interview Script — Conversational Flow
A2: Use this on the live call instead of Phase1 Master. Same questions, but ordered as a real conversation, with branching cues. After the call, copy answers into Phase1 Master and use Quick Diagnostic to point to package direction.
A4: Step | B4: Block (talk track) | C4: Core Question (always ask) | D4: Branch / Skip Rule | E4: Quick Notes (LIVE) | F4: Open Questions (LIVE)
A5: 1 | B5: Warm-up | C5: Quick recap: did the pre-interview questionnaire feel clear? Anything we should add up front?
A6: 2 | B6: Business & success | C6: Walk me through the main pain point and what 'success in 3 months' looks like for you. | D6: If client struggles to define success → ask for one concrete daily/weekly outcome (e.g., 'no missed booking before noon').
A7: 3 | B7: Business & success | C7: Which tasks should stay human-owned and never be automated? | D7: Always ask. Note exact wording — this becomes the guardrail list.
A8: 4 | B8: Channels & volume | C8: Confirm the channels: which one carries the highest volume? Which is the most business-critical (revenue)? | D8: Volume ≠ value. If they differ, MVP should follow the critical channel first.
A9: 5 | B9: Channels & volume | C9: Who owns each account (Gmail, Instagram, etc.)? Are credentials shared? | D9: If passwords are shared → flag security task in Required Action.
A10: 6 | B10: Current workflow | C10: Walk me through what happens today from message arrival → reply. | D10: Listen for 'check phone twice a day' or 'I forget on weekends' — these are MVP triggers.
A11: 7 | B11: Current workflow | C11: Where are messages or leads recorded today — any CRM, spreadsheet, notebook? | D11: If no CRM → simple Notion/Airtable likely needed. If full CRM exists → integration scope.
A12: 8 | B12: Operations Mapping | C12: Apart from incoming messages — does the client also deal with any of these: processing documents regularly, creating content, managing internal approvals or workflows, tracking finance or admin tasks? | D12: Branching question. For each YES → follow up with the relevant step below. If all NO → skip steps 9–11 and continue from step 12.
A13: 9 | B13: Operations Mapping | C13: Documents: walk me through the flow — what arrives, what needs to happen to it, and where does the result go? | D13: Skip if step 8 = No for documents. Capture: document type, volume, source, action needed, destination.
A14: 10 | B14: Operations Mapping | C14: Content: what do you create regularly, on which platforms, and where is the biggest bottleneck — drafting, scheduling, repurposing, or approval? | D14: Skip if step 8 = No for content. Capture: content types, platforms, current time cost, any existing approval step.
A15: 11 | B15: Operations Mapping | C15: Internal ops: which process causes the most manual work — approvals, task assignment, onboarding, or something else? | D15: Skip if step 8 = No for internal ops / finance. Capture: process name, who routes it, how delays happen, tools used.
A16: 12 | B16: Message types | C16: What are the most common categories? Which are high-value leads vs spam/noise? | D16: Goal: get a draft taxonomy (5–7 categories max for MVP).
A17: 13 | B17: Sensitive cases | C17: Can messages contain sensitive personal data (health, legal, finance, emotional)? | D17: If YES → ask: what must AI never answer directly? What are urgent keywords? Who is notified? Skip the next two only if NO and confirmed.
... A28: 24 | B28: Wrap-up | C28: Confirm: who is the decision-maker, what's the timeline, what blocks us from starting? | D28: Note in Required Action / Next Step.
A30: Pacing: ~40–55 min for the 24 steps. Operations Mapping (steps 8–11) can be skipped in full if the client’s primary need is communication intake only. After the call: (1) transfer notes to Phase1 Master, (2) fill Quick Diagnostic to get package direction, (3) finalize Output / Decision columns.

Sheet IS DE
A1: Interview-Leitfaden — Gesprächsablauf
A2: Verwenden Sie diesen Leitfaden im Live-Gespräch anstelle des Phase1 Master. Gleiche Fragen, aber als echtes Gespräch geordnet, mit Verzweigungshinweisen. Nach dem Gespräch: Antworten in Phase1 Master übertragen und Quick Diagnostic für die Paketrichtung nutzen.
A4: Schritt | B4: Block (Gesprächsführung) | C4: Kernfrage (immer stellen) | D4: Verzweigung / Skip-Regel | E4: Schnellnotizen (LIVE) | F4: Offene Fragen (LIVE)
A5: 1 | B5: Aufwärmen | C5: Kurzer Rückblick: War der Vorab-Fragebogen verständlich? Gibt es etwas, das wir vorab ergänzen sollten?
A6: 2 | B6: Geschäft & Erfolg | C6: Erzählen Sie mir vom Hauptproblem und wie 'Erfolg in 3 Monaten' für Sie aussieht. | D6: Wenn der Kunde Mühe hat, Erfolg zu definieren → nach einem konkreten täglichen/wöchentlichen Ergebnis fragen (z.B. 'keine verpasste Buchung vor Mittag').
A7: 3 | B7: Geschäft & Erfolg | C7: Welche Aufgaben sollen menschlich bleiben und niemals automatisiert werden? | D7: Immer fragen. Exakten Wortlaut notieren — das wird zur Guardrail-Liste.
A8: 4 | B8: Kanäle & Volumen | C8: Bestätigen Sie die Kanäle: Welcher hat das höchste Volumen? Welcher ist geschäftskritisch (Umsatz)? | D8: Volumen ≠ Wert. Wenn unterschiedlich, sollte das MVP zuerst dem kritischen Kanal folgen.
A9: 5 | B9: Kanäle & Volumen | C9: Wer besitzt jedes Konto (Gmail, Instagram usw.)? Werden Zugangsdaten geteilt? | D9: Falls Passwörter geteilt werden → Sicherheitsaufgabe in Required Action markieren.
A10: 6 | B10: Aktueller Workflow | C10: Beschreiben Sie mir den heutigen Ablauf von Nachrichteneingang bis Antwort. | D10: Achten Sie auf 'schaue zweimal täglich aufs Telefon' oder 'am Wochenende vergesse ich' — das sind MVP-Auslöser.
A11: 7 | B11: Aktueller Workflow | C11: Wo werden Nachrichten oder Leads heute erfasst — gibt es ein CRM, eine Tabelle, ein Notizbuch? | D11: Kein CRM → einfaches Notion/Airtable wahrscheinlich nötig. Vollständiges CRM → Integrations-Scope.
A12: 8 | B12: Operatives Mapping | C12: Abgesehen von eingehenden Nachrichten — trifft eines davon zu: regelmässige Dokumentverarbeitung, Inhaltserstellung, interne Freigaben oder Finanzverwaltung? | D12: Verzweigungsfrage. Für jedes JA → passendem Schritt folgen. Wenn alles Nein → Schritte 9–11 überspringen und ab Schritt 12 weitermachen.
A13: 9 | B13: Operatives Mapping | C13: Dokumente: beschreiben Sie den Ablauf — was kommt an, was muss damit passieren, und wo geht das Ergebnis hin? | D13: Überspringen wenn Schritt 8 = Nein für Dokumente. Erfassen: Dokumenttyp, Volumen, Quelle, benötigte Aktion, Zielort.
A14: 10 | B14: Operatives Mapping | C14: Inhalte: was erstellen Sie regelmässig, auf welchen Plattformen, und wo ist der grösste Engpass — Verfassen, Einplanen, Wiederverwenden oder Freigabe? | D14: Überspringen wenn Schritt 8 = Nein für Inhalte. Erfassen: Inhaltstypen, Plattformen, aktueller Zeitaufwand, bestehender Freigabeschritt.
A15: 11 | B15: Operatives Mapping | C15: Interne Abläufe: welcher Prozess verursacht die meiste manuelle Arbeit — Freigaben, Aufgabenzuweisung, Onboarding oder etwas anderes? | D15: Überspringen wenn Schritt 8 = Nein für interne Abläufe / Finanzen. Erfassen: Prozessname, wer weiterleitet, wie Verzögerungen entstehen, verwendete Tools.
A16: 12 | B16: Nachrichtentypen | C16: Was sind die häufigsten Kategorien? Welche sind wertvolle Leads vs. Spam/Rauschen? | D16: Ziel: eine Taxonomie skizzieren (max. 5–7 Kategorien fürs MVP).
A17: 13 | B17: Sensible Fälle | C17: Können Nachrichten sensible persönliche Daten enthalten (Gesundheit, Recht, Finanzen, Emotionen)? | D17: Wenn JA → fragen: Was darf AI niemals direkt beantworten? Was sind dringende Keywords? Wer wird benachrichtigt? Die nächsten beiden überspringen nur wenn NEIN und bestätigt.
... A28: 24 | B28: Abschluss | C28: Bestätigen: Wer ist die entscheidungsbefugte Person, was ist der Zeitplan, was hält uns vom Start ab? | D28: In Required Action / Next Step notieren.
A30: Tempo: ~40–55 Min. für die 24 Schritte. Operatives Mapping (Schritte 8–11) kann vollständig übersprungen werden, wenn der primäre Bedarf des Kunden reine Kommunikationsautomatisierung ist. Nach dem Gespräch: (1) Notizen in Phase1 Master übertragen, (2) Quick Diagnostic ausfüllen für die Paketrichtung, (3) Output- / Decision-Spalten finalisieren.

Sheet Quick Diagnostic
A1: Quick Diagnostic — Inputs → Suggested Package Direction
A2: Fill the 10 yellow inputs after the interview. Start with Q0 to set the primary automation type — this shapes the O2 scope hint. Formulas in the blue cells below suggest a package direction, MVP scope hints, and key cautions. This is decision support, not a final answer — PM judgment still required.
A4: INPUTS
A5: # | B5: Question | C5: Allowed values | D5: Answer
A6: Q0 | B6: Q0. Primary automation type (select dominant process) | C6: Communication & Intake / Lead & Sales Pipeline / Document & Data Processing / Content & Marketing / Internal Operations & Approvals / Reporting & Analytics / Finance & Admin / Scheduling & Booking / Customer Support & After-Sales / E-commerce & Fulfilment / Mixed | D6: Communication & Intake
A7: Q1 | B7: Q1. Volume of incoming messages per week | C7: Low (<20) / Medium (20-100) / High (100-500) / Very High (500+) | D7: Medium
A8: Q2 | B8: Q2. Number of distinct channels (Gmail, IG, WhatsApp, form...) | C8: 1 / 2-3 / 4+ | D8: 2-3
A9: Q3 | B9: Q3. Sensitive personal data involved? | C9: Yes / Sometimes / No | D9: No
A10: Q4 | B10: Q4. Wants AI to DRAFT replies (human approves)? | C10: Yes / No | D10: Yes
A11: Q5 | B11: Q5. Wants AI to AUTO-SEND replies (no human)? | C11: No / Safe categories only / Yes | D11: No
A12: Q6 | B12: Q6. Calendar / booking actions desired? | C12: None / Read-only / Propose slots / Auto-book | D12: None
A13: Q7 | B13: Q7. Wants ongoing monitoring & reporting (daily/weekly)? | C13: Yes / No | D13: No
A14: Q8 | B14: Q8. Wants multi-step AI agent actions (CRM update + follow-up etc.)? | C14: Yes / No | D14: No
A15: Q9 | B15: Q9. Highest acceptable consequence of an automation error? | C15: Low (mild annoyance) / Medium (lost lead) / High (legal/trust/health) | D15: Medium
A17: SUGGESTED DIRECTION (auto-calculated)
A18: # | B18: Indicator | C18: Suggested Value (formula) | D18: Reasoning hint
A19: O1 | B19: Suggested package direction | C19: =IF(OR(D14="Yes",D12="Auto-book"),"Agentic (with strict guardrails)",IF(OR(D13="Yes",D7="Very High",D7="High"),"Managed",IF(OR(D10="Yes",D8="2-3",D8="4+",D12="Propose slots"),"Pro","Basic"))) -> Pro | D19: From Q0/Q5/Q6/Q7/Q8/Q1. Higher autonomy → Agentic; reporting need → Managed; drafts/multi-channel → Pro.
A20: O2 | B20: MVP scope hint | C20: =IF(D6="Document & Data Processing","Extract → validate → log → route documents. AI extracts fields; human confirms before posting.",IF(D6="Content & Marketing","Generate → review → schedule. AI drafts content; human approves before publishing.",IF(OR(D6="Internal Operations & Approvals",D6="Finance & Admin"),"Route → assign → notify → approve. Human approves all actions; audit log required.",IF(D9="Yes","Triage + classify + escalate sensitive cases. No AI advice. Human review queue.",IF(D10="Yes","Classify + AI draft replies + human approval queue + CRM log.",IF(OR(D8="2-3",D8="4+"),"Multi-channel intake → single CRM/log; start with highest-value channel.","Single-channel intake → folder routing + CRM log + simple notifications.")))))) -> Classify + AI draft replies + human approval queue + CRM log. | D20: From Q0/Q3/Q4/Q2. Scope adapts to type: Documents→extract+log+route; Content→generate+review+publish; Ops/Finance→route+assign+notify+approve. Communication/other → existing logic applies.
A21: O3 | B21: Approval rule (product flag) | C21: =IF(OR(D9="Yes",D15="High"),"human_approval_required = true (all outbound).",IF(D11="Yes","human_approval_required = false (with audit log).",IF(D11="Safe categories only","human_approval_required = category_based.","human_approval_required = true (default)."))) -> human_approval_required = true (default). | D21: From Q3/Q5/Q9. Sensitive or high-risk → always require approval.
A22: O4 | B22: Top risk caution | C22: =IF(AND(D9="Yes",D11<>"No"),"HIGH RISK: sensitive data + auto-send. Require approval and audit log.",IF(D9="Yes","Sensitive content → classify + escalate, never AI-advise.",IF(D15="High","High-consequence domain → strict approval and fallback rules.","Standard caution: no auto-delete, fallback to Human Review when unsure."))) -> Standard caution: no auto-delete, fallback to Human Review when unsure. | D22: From Q3/Q5/Q9. Surfaces the single biggest risk to address in Phase 2.
A23: O5 | B23: Channel scope hint | C23: =IF(D8="4+","Pick top 1-2 channels for MVP; rest as phase 2.",IF(D8="2-3","Include 1-2 channels in MVP; others later.","Single channel — full coverage possible in MVP.")) -> Include 1-2 channels in MVP; others later. | D23: From Q2. Limits MVP complexity when many channels.
A24: O6 | B24: Reporting need | C24: =IF(D13="Yes","Daily/weekly summary + KPI dashboard required.","Reporting optional — propose in Phase 6 if useful.") -> Reporting optional — propose in Phase 6 if useful. | D24: From Q7. Drives whether Managed level applies.
A25: O7 | B25: Agentic boundary | C25: =IF(D14="Yes","Agentic scope requires: explicit allow-list of actions, audit log, approval for sensitive categories, kill-switch.",IF(D12="Auto-book","Auto-book → start with tentative-only events + approval; full auto-book in phase 2.","No agentic actions required for MVP.")) -> No agentic actions required for MVP. | D25: From Q6/Q8. Defines guardrails if any agentic actions appear.
A28: Package direction legend (cross-reference Internal Package Logic sheet):
A29: • Basic — rule-based intake, low risk, mostly admin tasks.
A30: • Pro — AI classification + draft replies, human approval queue.
A31: • Managed — ongoing service: CRM, monitoring, reporting, optimization.
A32: • Agentic — bounded multi-step AI actions (calendar, CRM updates) with strict guardrails.
A33: • Mixed — combination is normal; e.g. Pro for intake + Managed for reporting.
A35: Workflow: Pre-Interview Questionnaire → Interview Script (live call) → Quick Diagnostic → transfer to Phase1 Master (post-interview columns) → Phase 2 scope.

Sheet Phase1 Master
A1: Phase | B1: Area | C1: Checkpoint / Question | D1: Why this matters | E1: Example Answer | F1: Client Answer / Notes (LIVE EDIT) | G1: Initial Risk Level (LIVE EDIT) | H1: Initial MVP Relevance (LIVE EDIT) | I1: Open Questions (LIVE EDIT) | J1: Draft Product Flag (OPTIONAL) | K1: PM Interpretation (POST) | L1: Output / Decision (POST) | M1: Final Product Flag (POST) | N1: Final MVP Relevance (POST) | O1: Required Action / Next Step (POST) | P1: Internal Package Indication (POST) | Q1: Automation Method Candidate (POST) | R1: Package Notes / Boundary (POST) | S1: Completeness Status (AUTO)
A2: 1 Discovery | B2: Business Context | C2: What does the business do and who are its clients? | D2: Defines service logic, risk level, and message types. | E2: Therapist serving private clients; bookings and questions come via Instagram and Gmail. | S2: =IF(COUNTA(F2,G2,H2)=0,"Empty",IF(COUNTA(F2,G2,H2)<3,"Live partial",IF(COUNTA(K2,L2,N2,O2)=0,"Live OK - PM pending",IF(COUNTA(K2,L2,N2,O2)<4,"PM partial","Complete")))) -> Empty
A3: 1 Discovery | B3: Business Context | C3: What is the main pain or tedious task today? | D3: Identifies the real business problem and expected value. | E3: Too much time checking messages and repeating booking/price answers. | S3: =IF(COUNTA(F3,G3,H3)=0,"Empty",IF(COUNTA(F3,G3,H3)<3,"Live partial",IF(COUNTA(K3,L3,N3,O3)=0,"Live OK - PM pending",IF(COUNTA(K3,L3,N3,O3)<4,"PM partial","Complete")))) -> Empty
A4: 1 Discovery | B4: Business Context | C4: What would success look like after automation? | D4: Defines measurable outcome and acceptance criteria. | E4: Fewer missed messages, faster booking replies, daily summary, less manual checking. | S4: =IF(COUNTA(F4,G4,H4)=0,"Empty",IF(COUNTA(F4,G4,H4)<3,"Live partial",IF(COUNTA(K4,L4,N4,O4)=0,"Live OK - PM pending",IF(COUNTA(K4,L4,N4,O4)<4,"PM partial","Complete")))) -> Empty
A5: 1 Discovery | B5: Business Context | C5: Which tasks should remain human-owned? | D5: Prevents over-automation and protects sensitive service quality. | E5: Therapy advice, complaints, urgent emotional messages. | S5: =IF(COUNTA(F5,G5,H5)=0,"Empty",IF(COUNTA(F5,G5,H5)<3,"Live partial",IF(COUNTA(K5,L5,N5,O5)=0,"Live OK - PM pending",IF(COUNTA(K5,L5,N5,O5)<4,"PM partial","Complete")))) -> Empty
A6: 1 Discovery | B6: Channels | C6: Which channels are used for incoming messages? | D6: Determines technical integrations and source-of-truth design. | E6: Gmail, Instagram DM, website form. | S6: =IF(COUNTA(F6,G6,H6)=0,"Empty",IF(COUNTA(F6,G6,H6)<3,"Live partial",IF(COUNTA(K6,L6,N6,O6)=0,"Live OK - PM pending",IF(COUNTA(K6,L6,N6,O6)<4,"PM partial","Complete")))) -> Empty
A7: 1 Discovery | B7: Channels | C7: Which channel has the highest message volume? | D7: Helps choose MVP priority. | E7: Instagram has 60% of inquiries; Gmail has serious bookings. | S7: =IF(COUNTA(F7,G7,H7)=0,"Empty",IF(COUNTA(F7,G7,H7)<3,"Live partial",IF(COUNTA(K7,L7,N7,O7)=0,"Live OK - PM pending",IF(COUNTA(K7,L7,N7,O7)<4,"PM partial","Complete")))) -> Empty
A8: 1 Discovery | B8: Channels | C8: Which channel is most business-critical? | D8: High-value channels should be included early. | E8: Gmail contains existing clients and booking confirmations. | S8: =IF(COUNTA(F8,G8,H8)=0,"Empty",IF(COUNTA(F8,G8,H8)<3,"Live partial",IF(COUNTA(K8,L8,N8,O8)=0,"Live OK - PM pending",IF(COUNTA(K8,L8,N8,O8)<4,"PM partial","Complete")))) -> Empty
A9: 1 Discovery | B9: Channels | C9: Who owns/administers each account? | D9: Defines access, security, and onboarding requirements. | E9: Client owns Gmail and Instagram; no Make account yet. | S9: =IF(COUNTA(F9,G9,H9)=0,"Empty",IF(COUNTA(F9,G9,H9)<3,"Live partial",IF(COUNTA(K9,L9,N9,O9)=0,"Live OK - PM pending",IF(COUNTA(K9,L9,N9,O9)<4,"PM partial","Complete")))) -> Empty
A10: 1 Discovery | B10: Current Workflow | C10: What happens today when a message arrives? | D10: Maps current process and gaps. | E10: Client checks manually twice per day and replies from phone. | S10: =IF(COUNTA(F10,G10,H10)=0,"Empty",IF(COUNTA(F10,G10,H10)<3,"Live partial",IF(COUNTA(K10,L10,N10,O10)=0,"Live OK - PM pending",IF(COUNTA(K10,L10,N10,O10)<4,"PM partial","Complete")))) -> Empty
A11: 1 Discovery | B11: Current Workflow | C11: Where are messages or leads recorded today? | D11: Determines whether CRM/logging is needed. | E11: No CRM; some notes in Gmail, some in notebook. | S11: =IF(COUNTA(F11,G11,H11)=0,"Empty",IF(COUNTA(F11,G11,H11)<3,"Live partial",IF(COUNTA(K11,L11,N11,O11)=0,"Live OK - PM pending",IF(COUNTA(K11,L11,N11,O11)<4,"PM partial","Complete")))) -> Empty
A12: 1 Discovery | B12: Current Workflow | C12: Are messages ever missed or answered late? | D12: Identifies impact and value of automation. | E12: Yes, especially Instagram DMs on weekends. | S12: =IF(COUNTA(F12,G12,H12)=0,"Empty",IF(COUNTA(F12,G12,H12)<3,"Live partial",IF(COUNTA(K12,L12,N12,O12)=0,"Live OK - PM pending",IF(COUNTA(K12,L12,N12,O12)<4,"PM partial","Complete")))) -> Empty
A13: 1 Discovery | B13: Current Workflow | C13: Are there existing templates or FAQs? | D13: Good source for safe AI drafts and rule-based replies. | E13: Price list and standard booking instructions exist. | S13: =IF(COUNTA(F13,G13,H13)=0,"Empty",IF(COUNTA(F13,G13,H13)<3,"Live partial",IF(COUNTA(K13,L13,N13,O13)=0,"Live OK - PM pending",IF(COUNTA(K13,L13,N13,O13)<4,"PM partial","Complete")))) -> Empty
... A67: 1 Discovery | B67: MVP Candidate | C67: What is the first safe useful outcome? | D67: Defines MVP output. | E67: Classified messages, CRM log, draft replies, human review queue. | S67: =IF(COUNTA(F67,G67,H67)=0,"Empty",IF(COUNTA(F67,G67,H67)<3,"Live partial",IF(COUNTA(K67,L67,N67,O67)=0,"Live OK - PM pending",IF(COUNTA(K67,L67,N67,O67)<4,"PM partial","Complete")))) -> Empty

Sheet Field Guide
A1: Column | B1: Type | C1: Edit timing | D1: How to use | E1: Example
A2: Phase | B2: Fixed | C2: Do not edit normally | D2: Shows the PM phase. | E2: 1 Discovery
A3: Area | B3: Fixed | C3: Do not edit normally | D3: Groups questions by topic. | E3: Channels
A4: Checkpoint / Question | B4: Fixed | C4: Ask during interview | D4: Main question to ask the client. | E4: Which channels are used for incoming messages?
A5: Why this matters | B5: Fixed | C5: Read as guidance | D5: Explains why the question affects scope/risk. | E5: Determines technical integrations.
A6: Example Answer | B6: Fixed | C6: Read as guidance | D6: Shows what a typical client answer may look like. | E6: Gmail, Instagram, website form.
A7: Client Answer / Notes | B7: Live input | C7: During interview | D7: Write raw client answer. Keep it factual. | E7: Uses Gmail daily and Instagram DMs mostly for booking.
A8: Initial Risk Level | B8: Live input | C8: During interview | D8: Quick risk estimate: Low, Medium, High, Unknown. | E8: Medium
A9: Initial MVP Relevance | B9: Live input | C9: During interview | D9: First guess whether it belongs in first version: Yes, Later, No, Unknown. | E9: Yes
A10: Open Questions | B10: Live input | C10: During interview | D10: Write anything that needs clarification. | E10: Need to check Instagram API access.
A11: Draft Product Flag | B11: Optional | C11: During or after interview | D11: Early configuration marker if clear. | E11: channels = gmail, instagram_later
A12: PM Interpretation | B12: PM analysis | C12: After interview | D12: Your conclusion as project manager. | E12: Main problem is split intake and missed booking requests.
... A20: Package Notes / Boundary (POST) | B20: After interview | C20: Clarify why a package/method fits and what must be excluded or delayed. | D20: Auto-send excluded; draft only first. | E20: Important for safety and scope control.

Sheet Product Flags
A1: Flag Group | B1: Flag Name | C1: Possible Values | D1: Meaning | E1: Example
A2: Business | B2: business_type | C2: therapist | retail | consultant | service | trade | custom | D2: Defines client/business domain. | E2: business_type = therapist
A3: Channels | B3: channels | C3: gmail | website | instagram | facebook | whatsapp | linkedin | other | D3: Channels to include or postpone. | E3: channels = gmail, website, instagram_later
A4: AI Control | B4: ai_classification_enabled | C4: true | false | D4: AI can classify messages. | E4: ai_classification_enabled = true
A5: AI Control | B5: ai_draft_enabled | C5: true | false | D5: AI may draft replies. | E5: ai_draft_enabled = true
A6: AI Control | B6: auto_reply_enabled | C6: true | false | limited | D6: AI/automation may send without approval. | E6: auto_reply_enabled = false
A7: Human Control | B7: human_approval_required | C7: true | false | category_based | D7: Human approval requirement. | E7: human_approval_required = true
A8: Risk | B8: sensitive_data_level | C8: low | medium | high | D8: Expected sensitivity of message content. | E8: sensitive_data_level = high
A9: Risk | B9: urgent_escalation_enabled | C9: true | false | D9: Urgent cases trigger alert. | E9: urgent_escalation_enabled = true
A10: Booking | B10: booking_enabled | C10: true | false | later | D10: Booking flow included. | E10: booking_enabled = true
A11: Booking | B11: calendar_access | C11: none | read_only | write_with_approval | write | D11: Calendar integration scope. | E11: calendar_access = read_only
A12: CRM | B12: crm_required | C12: none | simple | full | D12: Lead/client storage need. | E12: crm_required = simple
... A16: Package | B16: package_candidate | C16: basic | ai_assisted | managed | agentic | D16: Likely package level. | E16: package_candidate = ai_assisted

Sheet Example Rows
A1: Phase | B1: Area | C1: Checkpoint / Question | D1: Why this matters | E1: Example Answer | F1: Client Answer / Notes (LIVE EDIT) | G1: Initial Risk Level (LIVE EDIT) | H1: Initial MVP Relevance (LIVE EDIT) | I1: Open Questions (LIVE EDIT) | J1: Draft Product Flag (OPTIONAL) | K1: PM Interpretation (POST) | L1: Output / Decision (POST) | M1: Final Product Flag (POST) | N1: Final MVP Relevance (POST) | O1: Required Action / Next Step (POST) | P1: Internal Package Indication (POST) | Q1: Automation Method Candidate (POST) | R1: Package Notes / Boundary (POST)
A2: 1 Discovery | B2: Channels | C2: Which channels are used for incoming messages? | D2: Determines technical integrations and source-of-truth design. | E2: Gmail, Instagram DM, website form. | F2: Client uses Gmail and Instagram daily; website form is rare but important. | G2: Medium | H2: Yes | I2: Need to check if Instagram is business account. | J2: channels = gmail, instagram, website | K2: Main problem is split intake across channels. | L2: MVP includes Gmail + website first; Instagram after API/access check. | M2: channels = gmail, website, instagram_later | N2: Yes | O2: Check access rights and ask client for sample messages. | P2: Pro | Q2: AI classification + draft replies | R2: No auto-send; therapist approval required.
A3: 1 Discovery | B3: Automation Boundary | C3: Can AI send replies automatically? | D3: Determines risk and package level. | E3: No automatic replies in first version. | F3: Client does not want auto-send. AI may prepare drafts only. | G3: Medium | H3: Yes | J3: auto_reply_enabled = false | K3: Human trust/control is important; first version must be draft-only. | L3: Set no auto-send rule in MVP and add approval status. | M3: human_approval_required = true; auto_reply_enabled = false | N3: Yes | O3: Define approved draft review location. | P3: Basic | Q3: Email/form intake + CRM log | R3: Start with Gmail and website form only.
A4: 1 Discovery | B4: Sensitive Cases | C4: Can messages contain sensitive personal data? | D4: Determines compliance and human-review rules. | E4: Yes, clients may describe personal or health problems. | F4: Yes, sometimes people describe emotional or health-related problems. | G4: High | H4: Yes | I4: Need approved escalation text for urgent cases. | J4: sensitive_data_level = high | K4: Sensitive content means AI must classify/escalate, not advise. | L4: All sensitive/urgent categories go to Human Review. No therapeutic advice. | M4: sensitive_data_level = high; urgent_escalation_enabled = true | N4: Yes | O4: Prepare escalation keywords and approved fallback message. | P4: Managed | Q4: CRM status tracking + weekly report | R4: Add monitoring after MVP is stable.
A5: 1 Discovery | B5: MVP Candidate | C5: Which problem should be solved first? | D5: Creates initial MVP focus. | E5: Triage incoming messages and identify bookings. | F5: Main need: reduce checking work and avoid missed bookings. | G5: Medium | H5: Yes | J5: package_candidate = basic | K5: MVP should focus on intake triage, not full agentic automation. | L5: Build basic intake + classification + CRM log + draft review. | M5: package_candidate = basic | N5: Yes | O5: Create Phase 2 scope with Gmail/website workflow. | P5: Agentic Later | Q5: Calendar slot proposal | R5: Only after approval workflow and audit log exist.

Sheet Internal Package Logic
A1: INTERNAL ONLY — Flexible Package / Solution Direction
A3: Package Direction | B3: Internal Meaning | C3: Typical Discovery Triggers | D3: Typical Automation Methods | E3: Good MVP Candidate When | F3: Human Control Level | G3: Typical Exclusions / Boundaries | H3: Example Product Flags
A4: Basic | B4: Simple intake automation; mostly rule-based workflows. | C4: One or two channels; low message volume; repeated admin questions; client wants quick time saving. | D4: Email/form intake, labels/folders, booking link, CRM/Notion log, simple notifications. | E4: Main problem is missed or delayed admin handling; sensitive risk is low to medium. | F4: Human handles final replies unless predefined reply is very safe. | G4: No autonomous advice, no complex social media, no advanced CRM/reporting. | H4: package=basic; channels=email,forms; booking_enabled=true; auto_reply=limited
A5: Pro | B5: AI-assisted intake with classification, summaries, and reply drafts. | C5: Multiple channels; many repeated questions; social media messages; client wants AI support but still wants approval. | D5: AI classification, AI summary, AI draft reply, FAQ matching, urgency flag, human approval queue. | E5: Client receives many similar messages and wants faster review without losing control. | F5: Human approval required before external sending by default. | G5: No fully autonomous sensitive replies; no uncontrolled calendar/CRM changes. | H5: package=pro; ai_classification=true; reply_drafts=true; human_approval_required=true
A6: Managed | B6: Operational service with monitoring, CRM, reporting, and continuous improvement. | C6: Client wants ongoing support, follow-up control, reporting, no missed leads, monthly optimization. | D6: CRM pipeline, status tracking, audit log, daily/weekly summaries, failed-run monitoring, improvement backlog. | E6: Client needs reliability and visibility, not only one-time setup. | F6: Human approval depends on category; operations monitored by service provider. | G6: No agentic actions unless separately approved; no hidden data processing. | H6: package=managed; crm_required=true; monitoring=true; reporting=true
A7: Agentic | B7: Advanced automation where AI can perform bounded multi-step actions. | C7: Client asks AI to check calendars, update CRM, propose times, execute follow-ups, or adapt workflow dynamically. | D7: Calendar lookup, slot proposal, CRM update, follow-up sequence, multi-step agent with guardrails. | E7: Only after stable categories, clear rules, and strict approval/fallback logic exist. | F7: Strict approval and audit by default; limited autonomy only in safe categories. | G7: No medical/legal/financial advice; no unsupervised sensitive decisions; no destructive actions. | H7: package=agentic; agentic_actions=calendar_only; approval_required=true; audit_log=true

Sheet Automation Methods
A1: INTERNAL ONLY — Automation Method Catalogue
A3: Automation Type | B3: Method | C3: What It Does | D3: Best Used For | E3: Package Direction | F3: Risk Level | G3: Human Approval Needed? | H3: Example
A4: Traditional | B4: Rule-based routing | C4: Uses fixed IF/THEN rules to move, label, notify, or create records. | D4: Stable repeated tasks with clear rules. | E4: Basic | F4: Low | G4: Usually no, unless reply is sent. | H4: If subject contains booking, create booking task.
A5: Traditional | B5: Form/email capture | C5: Receives messages and stores them in one place. | D5: Website forms, Gmail/Outlook intake. | E5: Basic | F5: Low | G5: No. | H5: Website form → Notion/CRM item.
A6: Traditional | B6: Booking link automation | C6: Sends or prepares a standard booking link. | D6: Simple appointment request handling. | E6: Basic | F6: Low-Medium | G6: Maybe, depending on business. | H6: Booking request → draft reply with Calendly link.
A7: AI | B7: AI classification | C7: LLM classifies message into predefined business categories. | D7: Mixed inquiries, unclear wording, multiple message types. | E7: Pro | F7: Medium | G7: Recommended for sensitive businesses. | H7: Classify as NEW_BOOKING / PRICE / COMPLAINT / URGENT.
A8: AI | B8: AI summary | C8: Summarizes long messages for quick human review. | D8: Long emails, multi-message threads, social DMs. | E8: Pro | F8: Medium | G8: No for summary only. | H8: Summarize inquiry into 3 bullets.
A9: AI | B9: AI draft reply | C9: Creates a reply draft using approved tone/rules. | D9: Repeated answers where human wants faster response. | E9: Pro | F9: Medium-High | G9: Yes by default. | H9: Draft reply to price question, therapist approves.
A10: Managed | B10: CRM/status tracking | C10: Creates and updates records with workflow status. | D10: Lead tracking, client follow-up, internal tasks. | E10: Managed | F10: Medium | G10: Depends on action. | H10: Create CRM item with status Pending Approval.
A11: Managed | B11: Monitoring/reporting | C11: Tracks failures, volumes, categories, response times. | D11: Ongoing managed service and improvement. | E11: Managed | F11: Low-Medium | G11: No. | H11: Weekly report: leads, spam, pending replies.
A12: Agentic | B12: Calendar action | C12: Checks calendar and proposes time slots or creates tentative event. | D12: Appointment-heavy businesses. | E12: Agentic | F12: High | G12: Yes unless explicitly approved for safe cases. | H12: Find 3 free slots and prepare reply.
A13: Agentic | B13: Multi-step agent | C13: Uses tools and adapts steps to reach a defined goal. | D13: Complex workflows with changing conditions. | E13: Agentic | F13: High | G13: Strictly yes at first. | H13: Agent reviews inquiry, checks CRM, proposes next action.

Sheet Package Decision Helper
A1: INTERNAL ONLY — Discovery Answer → Package Direction Helper
A3: Discovery Signal | B3: What It Usually Means | C3: Likely Package Direction | D3: Possible MVP Inclusion | E3: Automation Method Candidate | F3: PM Caution | G3: Example PM Decision
A4: Only email/forms, repeated simple requests | B4: Low complexity; quick operational gain possible. | C4: Basic | D4: Yes | E4: Rule-based routing + CRM log | F4: Avoid overbuilding. | G4: Start with intake classification and folder routing.
A5: Social DMs + email + website form | B5: Multi-channel intake problem. | C5: Pro | D5: Yes or Later | E5: AI classification + draft replies | F5: Check API feasibility and permissions. | G5: Include Gmail/forms first; social media in phase 2 if needed.
A6: Client wants no missed leads and follow-up visibility | B6: Process control problem, not only automation. | C6: Managed | D6: Yes | E6: CRM/status tracking + reporting | F6: Define owner and status rules. | G6: Add CRM pipeline and weekly report.
A7: Client asks AI to answer clients directly | B7: Possible, but risky depending on domain. | C7: Pro / Agentic | D7: Later | E7: AI drafts first, auto-send only safe categories | F7: Need approval and liability boundary. | G7: Start with drafts requiring approval.
A8: Client asks AI to check calendar or book appointments | B8: Tool/action workflow. | C8: Agentic | D8: Later, or controlled MVP | E8: Calendar action + approval workflow | F8: Avoid autonomous booking at start. | G8: AI proposes slots; human approves.
A9: Sensitive data possible: health/legal/finance | B9: High-risk domain. | C9: Managed / Agentic only with guardrails | D9: Yes for triage, not direct advice | E9: Classification + escalation + audit log | F9: No AI advice; human review required. | G9: Classify and escalate sensitive messages only.
A10: Client wants monthly improvement and support | B10: Managed service opportunity. | C10: Managed | D10: Yes | E10: Monitoring/reporting + optimization backlog | F10: Define SLA and support scope. | G10: Offer managed support after MVP.
