Workbook

Sheet START HERE
B2: AI Automation Pricing Calculator — VortexDeep
B3: Updated workbook. This sheet is the map; the Quote Calculator is the engine.
B5: Purpose | C5: Define WHAT we offer, PRICE a build, and show the three ACCESS MODELS a client can hold it under.
B6: The engine | C6: Quote Calculator — pick package + access model + support model, set the complexity counts, read setup/monthly and (new) all three access options.
B7: Cell colours | C7: Yellow = you edit. Blue = calculated (don't type over). Plain/grey = reference & internal.
B8: Access models | C8: Managed (default) · Licence (client-facing ownership, we keep the IP) · Full transfer (INTERNAL ONLY). Full policy: IP_and_Licensing_Policy doc.
B9: Client sharing | C9: Do NOT send internal logic/pricing sheets to clients. Share only the Client Quote Summary.
B10: v28 · updated 2026-09 · adds Break-Even & Runway sheet; fixes a formula bug in Quote Calculator F31:F34 (Extra data sources / AI generation steps adders were silently computing to 0 in v27 due to a label mismatch against Complexity Reference). | C10: v27 · updated 2026-08 · supersedes the old 'safe v4' notes.
B12: SHEET MAP
B13: Group | C13: Sheet | D13: What it's for
B14: Offer | C14: Product Catalogue | D14: What we sell: Area › Sub-area › Automation (+ front-door tools). Mirrors vortexdeep.ch.
B15: Engine | C15: Quote Calculator | D15: Price one build. The live calculator — start here for a quote.
B16: Engine ref | C16: Package Reference | D16: The 5 scope packages and their base setup/monthly ranges.
B17: Engine ref | C17: Complexity Reference | D17: Adders & support multipliers the calculator pulls in.
B18: Access | C18: Access Models | D18: The 5 access variants + what client gets / we keep + 'what it means'.
B19: Access | C19: Access Support Matrix | D19: The three tiers and where each is priced.
B20: Access | C20: Access & Licence Pricing | D20: Managed / Licence / Full-transfer numbers per package.
B21: Company | C21: Break-Even & Runway | D21: NEW in v28 — founder draw + fixed costs vs. blended client revenue -> break-even client count. Tests the deck's own '6-8 clients' claim.
B22: Examples | C22: Example Quotes | D22: Worked example quotes (kept for reference).
B23: Examples | C23: Example Quotes — 3 options | D23: Each build shown under all three access models (split min/max).
B24: Front door | C24: Front-Door Tools — Pricing | D24: AISR & AIWSC tiers + market comparison (non-core services).
... B29: Internal | C29: ROI App / _v1 / _v0 | D29: ROI calculators (client value framing).
B31: WORKFLOW
B32: 1) In Quote Calculator, pick Package + Access model + Support model (yellow cells).
B33: 2) Set the complexity counts (extra channels, AI steps, CRM, approvals, reporting) + any multipliers.
B34: 3) Read Setup / Monthly ranges — and the new 'Three access models (derived)' block for Licence & Transfer.
B35: 4) Copy the agreed numbers into Client Quote Summary to share.

Sheet Product Catalogue
B2: VortexDeep — Product Catalogue
B3: Three levels: AREA › SUB-AREA (job) › AUTOMATION (the thing we build & price). Representative, not exhaustive — the list expands. Each automation shows the task PATTERN it uses (patterns recur across areas — that's our reusable IP). ★ = shortlist ready for the website.
B5: PATTERNS (the verbs):
B6: Capture · Classify & route · Draft & reply · Extract & validate · Schedule & book · Summarise & report · Monitor & alert · Sync & log
B8: Area | C8: Sub-area (job) | D8: Automation | E8: Pattern(s) | F8: ★ Site
B9: Communication & Customers
C10: Communication & Intake
D11: Pull every enquiry (form, email, voicemail) into one list | E11: Capture | F11: ★
D12: Sort by topic, urgency and language | E12: Classify & route | F12: ★
D13: Draft a holding reply for each, for your approval | E13: Draft & reply | F13: ★
D14: Route each to the right person or inbox | E14: Classify & route
D15: Flag anything urgent or unusual | E15: Monitor & alert
D16: Log every enquiry with its outcome | E16: Sync & log
C17: Customer Support
D18: Auto-answer repeat questions (order status, returns, how-to) | E18: Draft & reply | F18: ★
D19: Detect and surface urgent tickets first | E19: Classify & route | F19: ★
D20: Draft replies from your knowledge base | E20: Draft & reply | F20: ★
D21: Escalate anything the AI is unsure about | E21: Monitor & alert
D22: Tag and log resolved tickets | E22: Sync & log
C23: Scheduling & Booking
D24: Take booking requests any time and offer real slots | E24: Schedule & book | F24: ★
D25: Send confirmations and reminders | E25: Schedule & book | F25: ★
D26: Prevent double-bookings | E26: Schedule & book | F26: ★
D27: Reschedule / cancel on request | E27: Schedule & book
D28: Chase no-show risks the day before | E28: Monitor & alert
D29: Coordinate group or multi-person slots | E29: Schedule & book
C30: Feedback & Reviews
D31: Collect feedback from email, reviews and surveys in one place | E31: Capture | F31: ★
D32: Sort praise vs complaints vs questions | E32: Classify & route | F32: ★
D33: Draft a reply to each, for approval | E33: Draft & reply | F33: ★
D34: Alert on negative reviews fast | E34: Monitor & alert
D35: Summarise themes each week | E35: Summarise & report
B36: Sales & Growth
C37: Lead & Sales Pipeline
D38: Capture leads from forms, events and referrals | E38: Capture | F38: ★
D39: Score and prioritise the promising ones | E39: Classify & route | F39: ★
D40: Draft first-touch and follow-up messages | E40: Draft & reply | F40: ★
D41: Nudge stalled deals before they go cold | E41: Monitor & alert | F41: ★
D42: Keep the CRM updated automatically | E42: Sync & log
D43: Weekly pipeline summary | E43: Summarise & report
...

Sheet Quote Calculator
B2: Quote Calculator — Package / Access Model / Support Model (v8)
B4: Step | C4: Field | F4: Value | G4: Explanation | M4: Client-facing summary | Q4: Available Packages | S4: Available Access Models | U4: Available Support Models | X4: Support model | AA4: Meaning
B5: 1 | C5: Client / project name | G5: EDIT | M5: Project | N5: =F5 -> 0 | Q5: ='Package Reference'!B6 -> Basic Intake | S5: ='Access Models'!B6 -> Managed service | U5: ='Complexity Reference'!L5 -> No support | X5: No support | AA5: build-and-transfer, client owns risk
B6: 2 | C6: Selected package | F6: Basic Intake | G6: EDIT: scope package only — excludes Build-and-Transfer (use Access model C6 = Build-and-transfer for handover projects) | M6: Package | N6: =F6 -> Basic Intake | Q6: ='Package Reference'!B7 -> Basic+ AI Triage | S6: ='Access Models'!B7 -> Logic visibility | U6: ='Complexity Reference'!L6 -> Light support | X6: Light support | AA6: occasional checks/fixes
B7: 3 | C7: Access / ownership model | F7: Managed service | G7: EDIT: controls setup/handover premium only (not monthly) | M7: Access model | N7: =F7 -> Managed service | Q7: ='Package Reference'!B8 -> Pro Multi-Channel | S7: ='Access Models'!B8 -> Limited admin | U7: ='Complexity Reference'!L7 -> Normal managed support | X7: Normal managed support | AA7: default for business workflow
B8: 4 | C8: Support model | F8: Normal managed support | G8: EDIT: controls monthly maintenance cost only (not setup) | M8: Support model | N8: =F8 -> Normal managed support | Q8: ='Package Reference'!B9 -> Managed Operations | S8: ='Access Models'!B9 -> Client-owned workspace | U8: ='Complexity Reference'!L8 -> High-responsibility maintenance | X8: High-responsibility support | AA8: stronger monitoring, faster response
M9: Setup range | N9: ="CHF "&ROUND(F35,0)&" - CHF "&ROUND(F36,0) -> CHF 2750 - CHF 8300 | Q9: ='Package Reference'!B10 -> Agentic Automation | S9: ='Access Models'!B10 -> Build-and-transfer | U9: ='Complexity Reference'!L9 -> Premium transfer support | X9: Agentic Automation | AA9: Premium transfer support
B10: 5 | C10: Base setup low | F10: =IFERROR(VLOOKUP(F6,'Package Reference'!$B$6:$F$10,2,FALSE()),0) -> 750 | G10: CALC from Package Reference | M10: Monthly range | N10: ="CHF "&ROUND(F37,0)&" - CHF "&ROUND(F38,0) -> CHF 650 - CHF 2050 | U10: ='Complexity Reference'!L10 -> Critical support | X10: Critical support | AA10: for operationally sensitive workflows
B11: 6 | C11: Base setup high | F11: =IFERROR(VLOOKUP(F6,'Package Reference'!$B$6:$F$10,3,FALSE()),0) -> 1800 | G11: CALC from Package Reference | M11: Recommended setup | N11: ="CHF "&ROUND(F39,0) -> CHF 5500
B12: 7 | C12: Base monthly low | F12: =IFERROR(VLOOKUP(F6,'Package Reference'!$B$6:$F$10,4,FALSE()),0) -> 150 | G12: CALC from Package Reference | M12: Recommended monthly | N12: ="CHF "&ROUND(F40,0) -> CHF 1400
B13: 8 | C13: Base monthly high | F13: =IFERROR(VLOOKUP(F6,'Package Reference'!$B$6:$F$10,5,FALSE()),0) -> 450 | G13: CALC from Package Reference | M13: Notes | N13: Prices exclude third-party tool/API usage unless agreed.
B14: 9 | C14: Auto access setup multiplier | F14: =IFERROR(VLOOKUP(F7,'Access Models'!$B$6:$L$10,10,FALSE()),1) -> 1 | G14: CALC from Access Models col J —access model controls setup premium, not support model | M14: List sources | N14: Package Ref A4:A9 | Access Models A4:A8 | Complexity Ref K4:K9
B15: 10 | C15: Auto monthly support multiplier | F15: =IFERROR(VLOOKUP(F8,'Complexity Reference'!$L$5:$N$10,2,FALSE()),1) -> 1 | G15: CALC from support model (monthly multiplier only)
B17: 11 | C17: Extra data sources / triggers count | F17: 0 | G17: EDIT: count each additional data source, trigger, or inbound channel beyond the base package. In Make.com: each separate webhook endpoint, app trigger, API source, or scheduled data pull. E.g. Instagram DM = 1, invoice email inbox = 1, API poll = 1. Do NOT count the primary source included in the selected package. | M17: Examples:
B18: 12 | C18: AI generation steps count | F18: 1 | G18: EDIT: count each distinct AI generation step — any HTTP module calling OpenAI or Claude for any purpose. Count per generation TYPE, not per execution. E.g. booking reply draft = 1. Invoice field extraction + booking reply draft = 2. Content repurposing call = 1. | M18: Extra data sources / triggers
B19: 13 | C19: CRM integrations count | F19: 1 | G19: EDIT: count each external CRM or database system connected via Make.com (Notion, HubSpot, Airtable, Google Sheets used as a CRM, etc.). Count per SYSTEM, not per module. Notion with 3 Notion modules = still 1. Notion + HubSpot = 2. | M19: Each distinct inbound source beyond the base package (separate webhook endpoint, app trigger or API feed).
B20: 14 | C20: Approval workflows count | F20: 1 | G20: EDIT: count each route where Make.com pauses and a human must review and approve before the automation sends or acts. SEEKER draft reviewed by human before reply = 1. Auto folder-move with no human gate = 0. Multiple gated routes = count each gate separately. | M20: Example values:
B21: 15 | C21: Reporting layer count | F21: 0 | G21: EDIT: 0 or 1. Use 1 only if the automation writes structured output to a reporting layer: Google Sheets analytics view, Notion summary dashboard, or similar. Test-folder logging does NOT count. Standard Notion CRM entries do NOT count as reporting. | N21: Primary source included in package = 0
B22: 16 | C22: Sensitive data multiplier | F22: 1 | G22: EDIT: normal = 1.0. Increase if handling sensitive data: 1.3 for confidential business info (contracts, financials, HR); 1.5 for GDPR-sensitive or EU-only data; 1.7 for health records or personal identity data. Always discuss data handling explicitly with the client before applying. | N22: Website form on a separate webhook = 1
B23: 17 | C23: Urgency multiplier | F23: 1 | G23: EDIT: normal = 1.0. Use 1.2 for 2–3 week delivery. Use 1.3–1.5 for hard deadlines within days (compressed build, testing and handover). Never exceed 1.5. | N23: Website form + Instagram DM = 2; or invoice email + webhook = 2
B24: 18 | C24: Manual setup multiplier override | G24: OPTIONAL EDIT: leave blank to use the access model auto-value (from the col L lookup). Override only when the auto value does not fit — e.g. Managed service selected but this project has unusually complex API credential setup or multi-environment staging. | N24: Website + Instagram + invoice email = 3; or 3 distinct API sources = 3
B25: 19 | C25: Manual monthly support multiplier override | G25: OPTIONAL EDIT: leave blank to use the support model auto-value. Override only when the auto value does not reflect the agreed SLA — e.g. Normal support selected but client has a faster-response agreement that is not yet in the reference table.
B26: 20 | C26: Manual custom setup add | F26: 0 | G26: EDIT: add one-time costs not covered by the package adder prices. — Make.com plan upgrade (if client account needs a higher ops tier) — Third-party API onboarding or account setup fee — Domain / DNS configuration — First-month OpenAI / Claude credit (if client pre-funds a budget) OPERATIONAL PASS-THROUGH: Make.com operations and API token costs are variable and best invoiced monthly with actuals. Use this field for a one-time estimate only if the client needs a total upfront budget figure. | M26: AI generation steps
B27: 21 | C27: Manual custom monthly add | F27: 0 | G27: EDIT: add ongoing monthly operational costs not covered by the support multiplier. These are direct pass-through costs you pay to providers: — Make.com operations budget: CHF 15–30/month simple (< 500 ops/day); CHF 30–60/month moderate (500–2,000 ops/day); CHF 60–120/month complex multi-branch scenario — OpenAI / Claude API tokens: CHF 10–20/month for ~200–500 AI drafts; CHF 20–40/month for ~500–2,000 AI drafts Best practice: leave C26 = 0 in the quote and invoice these monthly with actuals. Only fix a value here if the client requires a total-cost-of-ownership budget upfront. | M27: Each distinct HTTP module calling OpenAI / Claude (count per draft type, any email volume).
M28: Example values:
C29: Effective setup/access multiplier | F29: =IF(F24="",F14,F24) -> 1 | G29: CALC | N29: Classify or route only, no AI generation call = 0
C30: Effective monthly support multiplier | F30: =IF(F25="",F15,F25) -> 1 | G30: CALC | N30: One AI generation type (reply draft, field extraction, or content call) = 1
C31: Setup subtotal low (before multipliers) | F31: =F10+F17*IFERROR(VLOOKUP("Extra data sources / triggers",'Complexity Reference'!$B$5:$F$9,2,FALSE()),0)+F18*IFERROR(VLOOKUP("AI generation steps",'Complexity Reference'!$B$5:$F$9,2,FALSE()),0)+F19*IFERROR(VLOOKUP("CRM integration",'Complexity Reference'!$B$5:$F$9,2,FALSE()),0)+F20*IFERROR(VLOOKUP("Approval workflow",'Complexity Reference'!$B$5:$F$9,2,FALSE()),0)+F21*IFERROR(VLOOKUP("Reporting layer",'Complexity Reference'!$B$5:$F$9,2,FALSE()),0)+F26 -> 2750 | G31: CALC | N31: Booking reply draft + invoice field extraction = 2; or repurposing + reply = 2
C32: Setup subtotal high (before multipliers) | F32: =F11+F17*IFERROR(VLOOKUP("Extra data sources / triggers",'Complexity Reference'!$B$5:$F$9,3,FALSE()),0)+F18*IFERROR(VLOOKUP("AI generation steps",'Complexity Reference'!$B$5:$F$9,3,FALSE()),0)+F19*IFERROR(VLOOKUP("CRM integration",'Complexity Reference'!$B$5:$F$9,3,FALSE()),0)+F20*IFERROR(VLOOKUP("Approval workflow",'Complexity Reference'!$B$5:$F$9,3,FALSE()),0)+F21*IFERROR(VLOOKUP("Reporting layer",'Complexity Reference'!$B$5:$F$9,3,FALSE()),0)+F26 -> 8300 | G32: CALC
C33: Monthly subtotal low (before support multiplier) | F33: =F12+F17*IFERROR(VLOOKUP("Extra data sources / triggers",'Complexity Reference'!$B$5:$F$9,4,FALSE()),0)+F18*IFERROR(VLOOKUP("AI generation steps",'Complexity Reference'!$B$5:$F$9,4,FALSE()),0)+F19*IFERROR(VLOOKUP("CRM integration",'Complexity Reference'!$B$5:$F$9,4,FALSE()),0)+F20*IFERROR(VLOOKUP("Approval workflow",'Complexity Reference'!$B$5:$F$9,4,FALSE()),0)+F21*IFERROR(VLOOKUP("Reporting layer",'Complexity Reference'!$B$5:$F$9,4,FALSE()),0)+F27 -> 650 | G33: CALC | M33: CRM integrations — Make.com context
C34: Monthly subtotal high (before support multiplier) | F34: =F13+F17*IFERROR(VLOOKUP("Extra data sources / triggers",'Complexity Reference'!$B$5:$F$9,5,FALSE()),0)+F18*IFERROR(VLOOKUP("AI generation steps",'Complexity Reference'!$B$5:$F$9,5,FALSE()),0)+F19*IFERROR(VLOOKUP("CRM integration",'Complexity Reference'!$B$5:$F$9,5,FALSE()),0)+F20*IFERROR(VLOOKUP("Approval workflow",'Complexity Reference'!$B$5:$F$9,5,FALSE()),0)+F21*IFERROR(VLOOKUP("Reporting layer",'Complexity Reference'!$B$5:$F$9,5,FALSE()),0)+F27 -> 2050 | G34: CALC | M34: Each external database / CRM connected (Notion, HubSpot, Airtable, Google Sheets as CRM). Count per system, not per module.
C35: Calculated setup low | F35: =ROUND(F31*F22*F23*F29,0) -> 2750 | G35: CALC | M35: Example values:
C36: Calculated setup high | F36: =ROUND(F32*F22*F23*F29,0) -> 8300 | G36: CALC | N36: Folder routing only, no CRM = 0
C37: Calculated monthly low | F37: =ROUND(F33*F22*F30,0) -> 650 | G37: CALC | N37: Notion only (any number of Notion modules) = 1
C38: Calculated monthly high | F38: =ROUND(F34*F22*F30,0) -> 2050 | G38: CALC | N38: Notion + HubSpot = 2
C39: Recommended setup quote | F39: =ROUND((F35+F36)/2,-2) -> 5500 | G39: CALC
C40: Recommended monthly quote | F40: =ROUND((F37+F38)/2,-2) -> 1400 | G40: CALC | M40: Approval workflows — Make.com context
M41: Each route where Make.com pauses and a human must review / approve before it sends or acts.
C42: Quote Sanity Check (auto) | M42: Example values:
C43: Check | F43: Status | G43: Detail | N43: Auto folder-move only, no human gate = 0
...

Sheet ROI App
B2: ROI Automation Calculator
B4: Field | C4: Value | D4: Unit / Notes | G4: CASE STUDY | J4: CASE STUDY
B5: 1. CLIENT INPUTS | G5: MG1 | J5: MG2
B6: Hard ROI — Time Savings
B7: Employees Involved | C7: 2 | D7: people | G7: 4 | H7: people | J7: 2 | K7: people
B8: Hours Lost / Week | C8: 5 | D8: hours / week | G8: 2 | H8: hours / week | J8: 2 | K8: hours / week
B9: Hourly Rate (Gross) | C9: 100 | D9: CHF / hour | G9: 80 | H9: CHF / hour | J9: 80 | K9: CHF / hour
B11: Hard ROI — Error Reduction
B12: Mistakes / Week | C12: 5 | D12: mistakes / week | G12: 1 | H12: mistakes / week | J12: 1 | K12: mistakes / week
B13: Cost per Mistake | C13: 200 | D13: CHF / mistake | G13: 75 | H13: CHF / mistake | J13: 125 | K13: CHF / mistake
B15: Soft ROI — Lost Revenue
B16: Lost Leads / Month | C16: 10 | D16: leads / month | G16: 1 | H16: leads / month | J16: 2 | K16: leads / month
B17: Avg Value per Lead | C17: 1500 | D17: CHF / lead | G17: 1000 | H17: CHF / lead | J17: 125 | K17: CHF / lead
B19: Investment & Ongoing Costs
B20: One-Time Setup Cost | C20: ='Quote Calculator'!F39 -> 5500 | D20: CHF total — live-linked to Quote Calculator F39 (Recommended setup quote). Overtype with a fixed number to freeze a scenario. | G20: 3500 | H20: CHF total | J20: 2500 | K20: CHF total
B21: Monthly Managed AI Ops Cost | C21: ='Quote Calculator'!F40 -> 1400 | D21: CHF / month — live-linked to Quote Calculator F40 (Recommended monthly quote). Overtype with a fixed number to freeze a scenario. | G21: 1600 | H21: CHF / month | J21: 800 | K21: CHF / month
B23: 2. CALCULATED ROI | G23: ROI | J23: ROI
B25: Monthly Cost of Time | C25: =C7*C8*C9*4 -> 4000 | D25: CHF | G25: =G7*G8*G9*4 -> 2560 | H25: CHF | J25: =J7*J8*J9*4 -> 1280 | K25: CHF
B26: Monthly Cost of Errors | C26: =C12*C13*4 -> 4000 | D26: CHF | G26: =G12*G13*4 -> 300 | H26: CHF | J26: =J12*J13*4 -> 500 | K26: CHF
B27: Monthly Lost Revenue | C27: =C16*C17 -> 15000 | D27: CHF | G27: =G16*G17 -> 1000 | H27: CHF | J27: =J16*J17 -> 250 | K27: CHF
B28: Monthly Gross Benefit | C28: =SUM(C25:C27) -> 23000 | D28: CHF — cost of inaction | G28: =SUM(G25:G27) -> 3860 | H28: CHF — cost of inaction | J28: =SUM(J25:J27) -> 2030 | K28: CHF — cost of inaction
B29: (−) Monthly Managed AI Ops | C29: =C21 -> 1400 | D29: CHF | G29: =G21 -> 1600 | H29: CHF | J29: =J21 -> 800 | K29: CHF
B30: Net Monthly Benefit | C30: =C28-C29 -> 21600 | D30: CHF | G30: =G28-G29 -> 2260 | H30: CHF | J30: =J28-J29 -> 1230 | K30: CHF
B31: Annual Net Benefit | C31: =C30*12 -> 259200 | D31: CHF | G31: =G30*12 -> 27120 | H31: CHF | J31: =J30*12 -> 14760 | K31: CHF
B32: Total Year 1 Investment | C32: =C20+C21*12 -> 22300 | D32: CHF — setup + 12× monthly managed | G32: =G20+G21*12 -> 22700 | H32: CHF | J32: =J20+J21*12 -> 12100 | K32: CHF
B33: Payback Period | C33: =IF(C30<=0,"N/A",C20/C30) -> 0.25462963 | D33: Months | G33: =IF(G30<=0,"N/A",G20/G30) -> 1.5486726 | H33: Months | J33: =IF(J30<=0,"N/A",J20/J30) -> 2.0325203 | K33: Months
B34: First-Year Net ROI | C34: =IF(C32=0,"N/A",(C31-C20)/C32) -> 11.376682 | D34: % — net Y1 return ÷ total Y1 investment (setup + 12× monthly) | G34: =IF(G32=0,"N/A",(G31-G20)/G32) -> 1.0405286 | H34: % | J34: =IF(J32=0,"N/A",(J31-J20)/J32) -> 1.0132231 | K34: %
B35: Year 2+ Annual ROI | C35: =IF(C21=0,"N/A",C30*12/(C21*12)) -> 15.428571 | G35: =IF(G21=0,"N/A",G30*12/(G21*12)) -> 1.4125 | H35: % | J35: =IF(J21=0,"N/A",J30*12/(J21*12)) -> 1.5375 | K35: %
B37: 3. NEGOTIATION VIEW
B38: Value Ceiling (monthly) | C38: =IF(C20+C28=0,"N/A",(C28*12-C20)/12) -> 22541.667 | D38: CHF/month — max fee where client still breaks even in Year 1 | G38: =IF(G20+G28=0,"N/A",(G28*12-G20)/12) -> 3568.3333 | H38: CHF/month | J38: =IF(J20+J28=0,"N/A",(J28*12-J20)/12) -> 1821.6667 | K38: CHF/month
B39: Headroom — value kept by client | C39: =IF(C38="N/A","N/A",C38-C21) -> 21141.667 | D39: CHF/month below the ceiling. Use this when client says fee is high. | G39: =IF(G38="N/A","N/A",G38-G21) -> 1968.3333 | H39: CHF/month | J39: =IF(J38="N/A","N/A",J38-J21) -> 1021.6667 | K39: CHF/month
B41: Staffing alternative comparison
B42: Equiv. manual staffing cost | C42: 0 | D42: CHF/month — est. cost of person doing this manually. Rule of thumb CH: CHF 70k salary ≈ CHF 8,300/month fully loaded. Even 1 day/week ≈ CHF 2,000+. | G42: 0 | H42: CHF/month | J42: 0 | K42: CHF/month
B43: Automation saving vs. staffing | C43: =IF(C42=0,"(enter staffing cost above)",C42-C21) -> (enter staffing cost above) | D43: CHF/month saved vs. hiring. Negative = staffing is cheaper. | G43: =IF(G42=0,"(enter staffing cost above)",G42-G21) -> (enter staffing cost above) | H43: CHF/month | J43: =IF(J42=0,"(enter staffing cost above)",J42-J21) -> (enter staffing cost above) | K43: CHF/month
B45: Talking point — monthly fee objection: "Think of it like Krankenkasse. The best months are the ones where you never needed to call us. That's not money wasted — that's the system working. You pay for the guarantee of continuity, not for the number of incidents. And unlike Krankenkasse, here you can calculate the return."
B47: Tip: Monthly Managed AI Ops (C20) should match 'Recommended monthly quote' from Quote Calculator tab. First-Year Net ROI divides by total Year 1 spend (setup + 12× monthly). Year 2+ ROI shows the recurring return once setup is fully amortised.

Sheet ROI App_v1
B2: ROI Automation Calculator
B4: Field | C4: Value | D4: Unit / Notes
B5: 1. CLIENT INPUTS | G5: MGREDSHIFT
B6: Hard ROI — Time Savings
B7: Employees Involved | C7: 2 | D7: people | G7: 4 | H7: people
B8: Hours Lost / Week | C8: 5 | D8: hours / week | G8: 2 | H8: hours / week
B9: Hourly Rate (Gross) | C9: 100 | D9: CHF / hour | G9: 80 | H9: CHF / hour
B11: Hard ROI — Error Reduction
B12: Mistakes / Week | C12: 5 | D12: mistakes / week | G12: 1 | H12: mistakes / week
B13: Cost per Mistake | C13: 200 | D13: CHF / mistake | G13: 75 | H13: CHF / mistake
B15: Soft ROI — Lost Revenue
B16: Lost Leads / Month | C16: 10 | D16: leads / month | G16: 1 | H16: leads / month
B17: Avg Value per Lead | C17: 1500 | D17: CHF / lead | G17: 1000 | H17: CHF / lead
B19: Investment & Ongoing Costs
B20: One-Time Setup Cost | C20: 20000 | D20: CHF total | G20: 3500 | H20: CHF total
B21: Monthly Managed AI Ops Cost | C21: 2350 | D21: CHF / month — paste from Quote Calculator C39 (Recommended monthly quote) | G21: 1600 | H21: CHF / month
B23: 2. CALCULATED ROI | G23: ROI
B25: Monthly Cost of Time | C25: =C7*C8*C9*4 -> 4000 | D25: CHF | G25: =G7*G8*G9*4 -> 2560 | H25: CHF
B26: Monthly Cost of Errors | C26: =C12*C13*4 -> 4000 | D26: CHF | G26: =G12*G13*4 -> 300 | H26: CHF
B27: Monthly Lost Revenue | C27: =C16*C17 -> 15000 | D27: CHF | G27: =G16*G17 -> 1000 | H27: CHF
B28: Monthly Gross Benefit | C28: =SUM(C25:C27) -> 23000 | D28: CHF — cost of inaction | G28: =SUM(G25:G27) -> 3860 | H28: CHF — cost of inaction
B29: (−) Monthly Managed AI Ops | C29: =C21 -> 2350 | D29: CHF | G29: =G21 -> 1600 | H29: CHF
B30: Net Monthly Benefit | C30: =C28-C29 -> 20650 | D30: CHF | G30: =G28-G29 -> 2260 | H30: CHF
B31: Annual Net Benefit | C31: =C30*12 -> 247800 | D31: CHF | G31: =G30*12 -> 27120 | H31: CHF
B32: Total Year 1 Investment | C32: =C20+C21*12 -> 48200 | D32: CHF — setup + 12× monthly managed | G32: =G20+G21*12 -> 22700 | H32: CHF
B33: Payback Period | C33: =IF(C30<=0,"N/A",C20/C30) -> 0.968523 | D33: Months | G33: =IF(G30<=0,"N/A",G20/G30) -> 1.5486726 | H33: Months
B34: First-Year Net ROI | C34: =IF(C32=0,"N/A",(C31-C20)/C32) -> 4.7261411 | D34: % — net Y1 return ÷ total Y1 investment (setup + 12× monthly) | G34: =IF(G32=0,"N/A",(G31-G20)/G32) -> 1.0405286 | H34: %
B35: Year 2+ Annual ROI | C35: =IF(C21=0,"N/A",C30*12/(C21*12)) -> 8.787234 | G35: =IF(G21=0,"N/A",G30*12/(G21*12)) -> 1.4125 | H35: %
B36: Tip: Monthly Managed AI Ops (C20) should match 'Recommended monthly quote' from Quote Calculator tab. First-Year Net ROI divides by total Year 1 spend (setup + 12× monthly). Year 2+ ROI shows the recurring return once setup is fully amortised.

Sheet ROI App_v0
B2: ROI Automation Calculator
B4: Field | C4: Value | D4: Unit / Notes
B5: 1. CLIENT INPUTS | G5: MGREDSHIFT
B6: Hard ROI — Time Savings
B7: Employees Involved | C7: 2 | D7: people | G7: 4 | H7: people
B8: Hours Lost / Week | C8: 5 | D8: hours / week | G8: 2 | H8: hours / week
B9: Hourly Rate (Gross) | C9: 100 | D9: CHF / hour | G9: 80 | H9: CHF / hour
B11: Hard ROI — Error Reduction
B12: Mistakes / Week | C12: 5 | D12: mistakes / week | G12: 1 | H12: mistakes / week
B13: Cost per Mistake | C13: 200 | D13: CHF / mistake | G13: 75 | H13: CHF / mistake
B15: Soft ROI — Lost Revenue
B16: Lost Leads / Month | C16: 10 | D16: leads / month | G16: 1 | H16: leads / month
B17: Avg Value per Lead | C17: 1500 | D17: CHF / lead | G17: 1000 | H17: CHF / lead
B19: Investment & Ongoing Costs
B20: One-Time Setup Cost | C20: 20000 | D20: CHF total | G20: 3500 | H20: CHF total
B21: Monthly Managed AI Ops Cost | C21: 2350 | D21: CHF / month — paste from Quote Calculator C39 (Recommended monthly quote) | G21: 1600 | H21: CHF / month
B23: 2. CALCULATED ROI | G23: ROI
B25: Monthly Cost of Time | C25: =C7*C8*C9*4 -> 4000 | D25: CHF | G25: =G7*G8*G9*4 -> 2560 | H25: CHF
B26: Monthly Cost of Errors | C26: =C12*C13*4 -> 4000 | D26: CHF | G26: =G12*G13*4 -> 300 | H26: CHF
B27: Monthly Lost Revenue | C27: =C16*C17 -> 15000 | D27: CHF | G27: =G16*G17 -> 1000 | H27: CHF
B28: Monthly Gross Benefit | C28: =SUM(C25:C27) -> 23000 | D28: CHF — cost of inaction | G28: =SUM(G25:G27) -> 3860 | H28: CHF — cost of inaction
B29: (−) Monthly Managed AI Ops | C29: =C21 -> 2350 | D29: CHF | G29: =G21 -> 1600 | H29: CHF
B30: Net Monthly Benefit | C30: =C28-C29 -> 20650 | D30: CHF | G30: =G28-G29 -> 2260 | H30: CHF
B31: Annual Net Benefit | C31: =C30*12 -> 247800 | D31: CHF | G31: =G30*12 -> 27120 | H31: CHF
B32: Payback Period | C32: =IF(C30<=0,"N/A",C20/C30) -> 0.968523 | D32: Months | G32: =IF(G30<=0,"N/A",G20/G30) -> 1.5486726 | H32: Months
B33: First-Year Net ROI | C33: =IF(C20=0,"N/A",(C30*12-C20)/C20) -> 11.39 | D33: % (over Year 1) | G33: =IF(G20=0,"N/A",(G30*12-G20)/G20) -> 6.7485714 | H33: % (over Year 1)
B35: Tip: Monthly Managed AI Ops (C20) should match 'Recommended monthly quote' from the Quote Calculator tab (cell C39). Yellow = edit, light blue = calculated.

Sheet Package Reference
B2: Package Pricing Reference
B3: EDITABLE RANGE: update package names, price ranges, scope notes and access model here. Quote Calculator reads columns A:E by package name.
B5: Package | C5: Setup Low | D5: Setup High | E5: Monthly Low | F5: Monthly High | G5: Typical scope | H5: Best for | I5: Access model | J5: Internal note | K5: Commercial label | L5: Typical use by automation type
B6: Basic Intake | C6: 750 | D6: 1800 | E6: 150 | F6: 450 | G6: Email/forms intake, rule-based routing, booking link, simple folders/labels | H6: Simple intake, low complexity | I6: Results/dashboard only | J6: Keep scope tight | K6: AI Intake Basic | L6: Communication & Intake; Document routing (no AI extraction); E-commerce order notifications; Finance reminders. Rule-based only — no AI required.
B7: Basic+ AI Triage | C7: 1500 | D7: 3500 | E7: 300 | F7: 750 | G7: AI classification, CRM/Notion log, folder routing, draft support | H7: MG Red Shift-style workflow | I7: Results/dashboard + workflow summary | J7: Good first AI package | K7: AI Intake Triage Basic+ | L7: Communication & Intake (AI classify); Lead & Sales Pipeline (CRM log); Document Processing (AI field extraction); Customer Support (ticket triage); E-commerce (AI categorisation).
B8: Pro Multi-Channel | C8: 3500 | D8: 7500 | E8: 750 | F8: 1500 | G8: Email + social media, AI classification, drafts, approval workflow | H8: Multiple channels, repeated questions | I8: Dashboard + workflow chart | J8: Needs fallback and approval gates | K8: AI Workflow Pro | L8: Communication & Intake (multi-source); Content & Marketing (AI draft + publish review); Lead & Sales Pipeline (multi-source pipeline); Document Processing (multi-source); Customer Support (multi-channel triage).
B9: Managed Operations | C9: 7500 | D9: 15000 | E9: 1500 | F9: 3500 | G9: CRM, monitoring, reports, monthly improvements, support | H9: Ongoing operational support | I9: Dashboard, reports, limited logic visibility | J9: Define support limits | K9: Managed AI Operations | L9: Reporting & Analytics (KPI digests, management reports); Finance & Admin (reconciliation, overdue reminders); Internal Ops & Approvals (ongoing routing); Scheduling & Booking (managed flows). Any category requiring ongoing monitoring and improvement.
B10: Agentic Automation | C10: 12000 | D10: 30000 | E10: 2500 | F10: 6000 | G10: Calendar/CRM actions, multi-step decisions, audit and governance | H10: Complex controlled actions | I10: Approval console + blueprint summary | J10: Quote individually | K10: Agentic AI Operations | L10: Scheduling & Booking (AI slot proposals, calendar actions); Lead & Sales Pipeline (autonomous follow-up sequences); Finance & Admin (exception detection + action); Internal Ops (conditional approval chains). Any category needing multi-step AI decisions with audit.
B11: Build-and-Transfer | C11: 4500 | D11: 15000 | E11: 0 | F11: 1000 | G11: Automation built in client workspace and handed over | H11: Client wants ownership | I11: Full access/export/documentation | J11: LEGACY — do not select as package. Use a scope package in C5 and set Access model = Build-and-transfer in C6. | K11: Build & Transfer | L11: All automation categories — applies when client requires full IP and operational ownership post-handover, regardless of automation type.

Sheet Access Models
B2: Access & Ownership Pricing Logic
B3: these five models are the granular access variants that implement the three policy tiers (Managed / Licence / Full transfer). See IP & Licensing Policy.
B5: Model | C5: Client receives | D5: You retain | E5: Pricing effect | F5: Monthly effect | G5: Risk | H5: Use when | I5: Client wording | J5: Internal note | K5: Default setup multiplier | L5: Typical range | M5: Pricing use in FIXED calculator | N5: Policy tier
B6: Managed service | C6: Results, dashboards, reports, approval queue | D6: Make logic, prompts, reusable blueprints | E6: Normal | F6: x1.0 monthly | G6: Low | H6: Default | I6: We manage the automation and provide outputs/support. | J6: Best default model | K6: 1 | L6: x1.0 | M6: Managed service: no handover premium. | N6: Managed (default)
B7: Logic visibility | C7: Workflow summary, Mermaid/chart, status rules | D7: Implementation details and reusable logic | E7: Normal or small add-on | F7: x1.0 monthly | G7: Low | H7: Client wants transparency | I7: You receive workflow documentation without internal implementation. | J7: Good trust-building option | K7: 1.1 | L7: x1.0–x1.15 | M7: Transparency/documentation premium. | N7: Licence
B8: Limited admin | C8: Dashboard, approvals, run summaries | D8: Scenario edit rights and blueprint export | E8: +10–25% | F8: x1.1–1.25 monthly | G8: Medium | H8: Client needs stronger control | I8: You can review outcomes while we manage the system. | J8: Managed clients | K8: 1.2 | L8: x1.10–x1.25 | M8: Limited admin/client controls. | N8: Licence
B9: Client-owned workspace | C9: Automation runs in client workspace | D9: Methodology and reusable templates | E9: +25–75% | F9: x0.5–1.5 monthly depending support | G9: Medium | H9: Compliance/enterprise | I9: Built in your workspace; support remains available. | J9: Higher setup | K9: 1.5 | L9: x1.25–x1.75 | M9: Client-owned workspace/setup burden. | N9: Licence
B10: Build-and-transfer | C10: Full Make scenario, export, documentation | D10: General know-how only | E10: x1.5–x3 setup | F10: x0–x3 monthly depending support | G10: High | H10: INTERNAL INFORMATION ONLY — not a client-facing offer | I10: We build and hand over the automation asset. | J10: Documented for internal clarity; not sold. See IP & Licensing Policy. | K10: 2 | L10: x1.5–x3.0 | M10: Build-and-transfer default; override if needed. | N10: Full transfer — internal info only
C12: Client | D12: VD | E12: what it means?
C13: Approvals | E13: You review and OK an action before it happens.
C14: Dashboards | E14: A live screen showing what the automation is doing and its status.
C15: Results | E15: The finished output of a run (sorted messages, extracted data, etc.).
C16: Reports | E16: Periodic summaries (daily/weekly) of what was processed.
C17: Approval Queue | E17: The list of items waiting for your yes/no before they're sent or done.
C18: Charts (Mermaid, <other>) | E18: A visual diagram of how the workflow flows — for understanding, not editing.
C19: Status Rules | E19: The plain rules that decide what counts as done, pending, or failed.
C20: Run Summaries | E20: A short recap of each run: how many handled, flagged, errored.
C21: Scenarios (Make, n8n, <other>) | E21: The actual automation build (the connected steps) inside Make/n8n.
C22: Logic (Make, n8n, <other>) | E22: The decision rules inside the scenario — how it classifies and routes.
C23: Prompts (Make, n8n, <other>) | E23: The exact instructions given to the AI at each step.
D24: Blueprints (Make, n8n, <other>) | E24: A reusable export of a scenario that lets it be rebuilt. We retain this.
C25: Documentation | E25: Written explanation of what the automation does and how to operate it.
C26: Export? | E26: Whether a copy of the scenario file can be taken out of the tool.
D27: reusable blueprints | E27: Our library of scenario templates reused across clients. Ours only.
D28: reusable logic | E28: Our library of decision patterns reused across clients. Ours only.
D29: implementation details | E29: The specific technical wiring and config behind the scenario. Ours only.
D30: scenario edit rights | E30: Permission to change the automation's build (granted only in Limited admin).
D31: blueprint exports | E31: The ability to export the blueprint file. Ours only.
D32: methodology | E32: Our process for discovering, scoping and building automations. Never shared.
D33: reusable templates | E33: Our standard building blocks used across projects. Ours only.
D34: general know-how | E34: Generic experience we keep after any engagement.

Sheet Complexity Reference
B2: Complexity Adders & Multipliers | L2: Support Model Lookup - Editable
B4: Factor | C4: Setup Low | D4: Setup High | E4: Monthly Low | F4: Monthly High | G4: Rule | H4: When to apply | I4: Notes | J4: Example | L4: Support Model | M4: Monthly Multiplier | N4: Setup Handover Multiplier | O4: Typical Use | P4: Client Access | Q4: Support Responsibility | R4: Pricing Note | S4: Internal Note
B5: Extra data sources / triggers | C5: 500 | D5: 1500 | E5: 100 | F5: 300 | G5: per source / trigger | H5: Additional data source, trigger, or inbound channel beyond the scope included in the package | I5: Email inbox, social DM, document upload trigger, API feed, scheduled database poll | J5: invoice email trigger + webhook + Instagram DM = 3 sources | L5: No support | M5: 0 | N5: 1 | O5: Build-and-transfer with no monthly support | P5: Full handover | Q5: None after handover | R5: 0x monthly | S5: Legacy setup multiplier normalized to 1. Setup premium now belongs to Access Models / fixed calculator.
B6: AI generation steps | C6: 500 | D6: 2000 | E6: 150 | F6: 500 | G6: per workflow type | H6: AI generates any output: reply drafts, extracted document fields, summarised text, repurposed content | I6: Each distinct AI generation type adds complexity — count per type, not per execution | J6: invoice field extraction + booking reply draft = 2 generation steps | L6: Light support | M6: 0.5 | N6: 1 | O6: Client owns automation, occasional help | P6: Full/limited | Q6: Limited fixes | R6: 0.5x monthly | S6: Legacy setup multiplier normalized to 1. Setup premium now belongs to Access Models / fixed calculator.
B7: CRM integration | C7: 750 | D7: 2500 | E7: 200 | F7: 600 | G7: per CRM | H7: Notion/Airtable/HubSpot records | I7: Status and field mapping | J7: Notion DB | L7: Normal managed support | M7: 1 | N7: 1 | O7: Default managed service | P7: Dashboard/results | Q7: Normal monitoring/support | R7: 1.0x monthly | S7: Default.
B8: Approval workflow | C8: 750 | D8: 2000 | E8: 150 | F8: 500 | G8: per approval path | H8: Human review needed | I8: Important for sensitive sectors | J8: approve before send | L8: High-responsibility maintenance | M8: 1.5 | N8: 1 | O8: Important business workflow | P8: Dashboard/results + stronger control | Q8: Higher reliability support | R8: 1.5x monthly | S8: Setup premium should be explicit via access model/manual add, not hidden in support model.
B9: Reporting layer | C9: 500 | D9: 2000 | E9: 250 | F9: 900 | G9: yes/no | H9: Dashboards, summaries, KPI reports | I9: Managed service | J9: monthly report | L9: Premium transfer support | M9: 2 | N9: 1 | O9: Transferred asset but you still maintain | P9: Full handover | Q9: Ongoing maintenance | R9: 2.0x monthly | S9: Use Access Models / fixed calculator for transfer setup premium.
B10: Sensitive data | C10: 0 | D10: 0 | E10: 0 | F10: 0 | G10: x1.3 to x1.7 | H10: Health/legal/finance/high privacy | I10: Apply mainly to setup and monthly | J10: therapist | L10: Critical support | M10: 3 | N10: 1 | O10: Complex/agentic/high-risk system | P10: Full/controlled | Q10: High responsibility | R10: Up to 3.0x monthly | S10: Use manual setup add/urgency multiplier for critical setup impact.
B11: Urgency | C11: 0 | D11: 0 | E11: 0 | F11: 0 | G11: x1.2 to x1.5 | H11: Fast delivery required | I11: Apply to setup | J11: launch this week
B12: Full handover | C12: 0 | D12: 0 | E12: 0 | F12: 0 | G12: x1.5 to x3.0 | H12: Client receives scenario/blueprint | I12: Build-and-transfer | J12: own Make workspace
B14: Monthly support model | C14: Monthly multiplier | D14: Typical monthly logic | E14: Use when | F14: Client receives | G14: You remain responsible for | H14: Example | I14: Pricing note | J14: Internal decision
B15: No support | C15: 0 | D15: No recurring fee | E15: Build-and-transfer with no support | F15: Delivered automation only | G15: Nothing after handover | H15: client self-maintains | I15: 0x monthly | J15: Use rarely
B16: Light support | C16: 0.5 | D16: Ad-hoc checks / small fixes | E16: Client owns automation but may need help | F16: Occasional support | G16: Limited support only | H16: quarterly help | I16: 0.5x to 1.0x monthly | J16: Define hours
B17: Normal managed support | C17: 1 | D17: Standard monitoring and minor improvements | E17: Managed service default | F17: Reports/support | G17: Normal reliability support | H17: Basic+/Pro managed | I17: 1.0x monthly | J17: Default
B18: High-responsibility maintenance | C18: 1.5 | D18: Strong monitoring, quick fixes, change support | E18: Client owns or depends heavily on system | F18: Higher support availability | G18: Higher operational responsibility | H18: mission-critical workflow | I18: 1.5x to 3.0x monthly | J18: Premium
B19: Premium transfer support | C19: 2 | D19: Transferred asset + ongoing maintenance | E19: Build-and-transfer but you still maintain it | F19: Full asset + managed care | G19: Ongoing maintenance despite transfer | H19: client owns Make, you maintain | I19: 2.0x typical | J19: Charge clearly
B20: Critical support | C20: 3 | D20: High urgency / high responsibility | E20: Complex agentic systems | F20: Priority support | G20: Major ongoing responsibility | H20: Calendar/CRM agent with SLA-like expectation | I20: Up to 3.0x monthly | J20: Custom quote

Sheet Example Quotes
B2: Example Quote Ranges
B3: STALE — v28 fix (see START HERE) corrected the Quote Calculator's 'AI generation steps' and 'Extra data sources' adders, which had been silently computing to CHF 0 in v27. Only the MG Red Shift v4.0 row below has been re-verified and corrected (cross-checked against DOCU - Pricing Logic and AUDIT Pricing). Every other row here still reflects pre-fix arithmetic — re-run each through the live Quote Calculator with its actual counts before quoting a client from this sheet. See column K.
B6: Example | C6: Package | D6: Setup Low | E6: Setup High | F6: Monthly Low | G6: Monthly High | H6: Why | I6: Access model | J6: Notes | K6: Status
B7: MG Red Shift v4.0 — AI-drafted SEEKER reply (base) | C7: Basic+ AI Triage | D7: 3500 | E7: 10000 | F7: 800 | G7: 2350 | H7: AI classification, Notion DB, folder routing, SEEKER draft support | I7: Managed / hybrid | J7: No automatic sending; AI draft held for review. CORRECTED in v28: recomputed from Basic+ AI Triage base + AI generation(1) + CRM(1) + Approval(1), Normal managed support — matches AUDIT Pricing's own independent hand-calc (recommended ~CHF 6,800 / 1,600). Note: DOCU - Pricing Logic!F121 mislabels this package 'Basic Intake' in one worked table (B495/B579 in the same sheet correctly say Basic+ AI Triage) — that internal contradiction is unresolved, flagged separately. | K7: CORRECTED (v28)
B8: Therapist Gmail + booking link | C8: Basic Intake | D8: 1200 | E8: 2500 | F8: 250 | G8: 500 | H8: Email/form intake, booking triage, no direct advice | I8: Managed / hybrid | J8: Human approval | K8: NEEDS RE-QUOTE (predates v28 fix)
B9: Therapist Instagram + Gmail + drafts | C9: Pro Multi-Channel | D9: 3500 | E9: 7500 | F9: 750 | G9: 1500 | H9: Multiple channels and draft approval workflow | I9: Managed | J9: Sensitive data needs strict boundaries | K9: NEEDS RE-QUOTE (predates v28 fix)
B10: Small agency CRM + reporting | C10: Managed Operations | D10: 7500 | E10: 15000 | F10: 1500 | G10: 3500 | H10: CRM, monitoring, reporting, improvement backlog | I10: Managed | J10: Recurring service value | K10: NEEDS RE-QUOTE (predates v28 fix)
B11: Calendar/CRM agent | C11: Agentic Automation | D11: 12000 | E11: 30000 | F11: 2500 | G11: 6000 | H11: Controlled multi-step actions with approvals | I11: Controlled access | J11: Quote individually | K11: NEEDS RE-QUOTE (predates v28 fix)
B12: Client full handover | C12: Build-and-Transfer | D12: 4500 | E12: 15000 | F12: 0 | G12: 1000 | H12: Transfers Make logic and documentation | I12: Client-owned | J12: Price 1.5x to 3x setup | K12: NEEDS RE-QUOTE (predates v28 fix)
B13: MG Red Shift v4.1 — template SEEKER reply | C13: Basic+ AI Triage | D13: 1300 | E13: 2700 | F13: 200 | G13: 500 | H13: Same triage; SEEKER reply is a prepared template (no AI generation). Simplest of the three. | I13: Managed / hybrid | J13: Template reply; no AI draft | K13: NEEDS RE-QUOTE (predates v28 fix)
B14: MG Red Shift v4.2 + v4.1 — dual intake (email + webform) | C14: Basic+ AI Triage | D14: 2000 | E14: 4500 | F14: 400 | G14: 900 | H14: v4.1 process across two intake paths (email then webform): extra source + duplicated classify/route. | I14: Managed / hybrid | J14: No automatic sending; two channels | K14: NEEDS RE-QUOTE (predates v28 fix)

Sheet Example Quotes — 3 options
B2: Example Quotes — each build, three access options
B3: One build (scope) → three ways the client can hold it. Prices are split into min/max cells (one number each). Managed = baseline. Licence = setup ×1.30 + annual licence ≈ 50% of the managed year (you keep the IP). Full transfer = setup + ~2.5 years of the monthly you give up (INTERNAL ONLY; scales with scope). Indicative CHF — adjust multipliers in the note. STALE (v28): only the MG Red Shift v4.0 block below has been re-verified against the corrected Quote Calculator; every other block still reflects pre-fix arithmetic — see column I on each block, and re-run before quoting a client.
B5: Therapist Gmail + booking link | C5: scope: Basic Intake
B6: Option | C6: Setup min | D6: Setup max | E6: Recurring min | F6: Recurring max | G6: Unit | H6: What the client holds | I6: IP / notes
B7: Managed (default) | C7: 1200 | D7: 2500 | E7: 250 | F7: 500 | G7: / month | H7: Results + right to use; we run & improve it | I7: NEEDS RE-QUOTE (predates v28 fix)
B8: + Licence option | C8: 1560 | D8: 3250 | E8: 1500 | F8: 3000 | G8: / year | H8: Runs for them; bounded right-to-use | I8: NEEDS RE-QUOTE (predates v28 fix)
B9: + Full transfer (internal only) | C9: 8700 | D9: 17500 | E9: 0 | F9: 0 | G9: / month | H9: They OWN the build outright | I9: NEEDS RE-QUOTE (predates v28 fix)
B11: MG Red Shift v4.0 — SEEKER reply | C11: scope: Basic+ AI Triage
B12: Option | C12: Setup min | D12: Setup max | E12: Recurring min | F12: Recurring max | G12: Unit | H12: What the client holds | I12: IP / notes
B13: Managed (default) | C13: 3500 | D13: 10000 | E13: 800 | F13: 2350 | G13: / month | H13: Results + right to use; we run & improve it | I13: CORRECTED (v28)
B14: + Licence option | C14: 4550 | D14: 13000 | E14: 4800 | F14: 14100 | G14: / year | H14: Runs for them; bounded right-to-use | I14: CORRECTED (v28)
B15: + Full transfer (internal only) | C15: 27500 | D15: 80500 | E15: 0 | F15: 0 | G15: / month | H15: They OWN the build outright | I15: CORRECTED (v28)
B17: Therapist Instagram + Gmail + drafts | C17: scope: Pro Multi-Channel
B18: Option | C18: Setup min | D18: Setup max | E18: Recurring min | F18: Recurring max | G18: Unit | H18: What the client holds | I18: IP / notes
B19: Managed (default) | C19: 3500 | D19: 7500 | E19: 750 | F19: 1500 | G19: / month | H19: Results + right to use; we run & improve it | I19: NEEDS RE-QUOTE (predates v28 fix)
B20: + Licence option | C20: 4550 | D20: 9750 | E20: 4500 | F20: 9000 | G20: / year | H20: Runs for them; bounded right-to-use | I20: NEEDS RE-QUOTE (predates v28 fix)
B21: + Full transfer (internal only) | C21: 26000 | D21: 52500 | E21: 0 | F21: 0 | G21: / month | H21: They OWN the build outright | I21: NEEDS RE-QUOTE (predates v28 fix)
B23: Small agency CRM + reporting | C23: scope: Managed Operations
B24: Option | C24: Setup min | D24: Setup max | E24: Recurring min | F24: Recurring max | G24: Unit | H24: What the client holds | I24: IP / notes
B25: Managed (default) | C25: 7500 | D25: 15000 | E25: 1500 | F25: 3500 | G25: / month | H25: Results + right to use; we run & improve it | I25: NEEDS RE-QUOTE (predates v28 fix)
B26: + Licence option | C26: 9750 | D26: 19500 | E26: 9000 | F26: 21000 | G26: / year | H26: Runs for them; bounded right-to-use | I26: NEEDS RE-QUOTE (predates v28 fix)
B27: + Full transfer (internal only) | C27: 52500 | D27: 120000 | E27: 0 | F27: 0 | G27: / month | H27: They OWN the build outright | I27: NEEDS RE-QUOTE (predates v28 fix)
B29: Calendar/CRM agent | C29: scope: Agentic Automation
B30: Option | C30: Setup min | D30: Setup max | E30: Recurring min | F30: Recurring max | G30: Unit | H30: What the client holds | I30: IP / notes
B31: Managed (default) | C31: 12000 | D31: 30000 | E31: 2500 | F31: 6000 | G31: / month | H31: Results + right to use; we run & improve it | I31: NEEDS RE-QUOTE (predates v28 fix)
B32: + Licence option | C32: 15600 | D32: 39000 | E32: 15000 | F32: 36000 | G32: / year | H32: Runs for them; bounded right-to-use | I32: NEEDS RE-QUOTE (predates v28 fix)
B33: + Full transfer (internal only) | C33: 87000 | D33: 210000 | E33: 0 | F33: 0 | G33: / month | H33: They OWN the build outright | I33: NEEDS RE-QUOTE (predates v28 fix)
B35: Formula (edit to taste): Licence setup = Managed setup ×1.30 · Licence annual = Managed monthly ×12 ×0.50 · Transfer one-time = Managed setup + 2.5×12×Managed monthly · Transfer recurring = 0.
B36: Licence 'Recurring' is the annual licence (unit = /year). Managed & Transfer recurring are monthly (unit = /month). Transfer grows with scope — Basic ~9k, Agentic ~87k–210k — so it's a multiplier, kept internal-only.

Sheet Access & Licence Pricing
B2: Access & Licence Pricing
B3: Three access tiers. Managed (default) = we run and improve it. Licence (option) = client holds a bounded right-to-use; we keep the build and the methodology. Full transfer = internal information only, not a client-facing offer (shown for internal clarity). Setup/Monthly are live-linked to 'Package Reference' midpoints. See IP & Licensing Policy.
B5: INPUTS (edit)
B6: Licence % of managed-year | C6: 0.5 | D6: share of the managed year the licence keeps (maintain-vs-improve split). 40–60% typical.
B7: Licence setup multiplier | C7: 1.3 | D7: one-time uplift for documentation + handover so they can run it themselves.
B8: Buy-out: years of recurring to capitalise | C8: 2.5 | D8: buy-out one-time = setup + (years × 12 × monthly). Protects the recurring you give up.
B10: Package | C10: Managed setup | D10: Managed / mo | E10: Licence setup | F10: Licence / year | G10: Licence / mo (equiv) | H10: Full transfer one-time (internal info only) | I10: Transfer / mo
B11: ='Package Reference'!B6 -> Basic Intake | C11: =ROUND(('Package Reference'!C6+'Package Reference'!D6)/2,0) -> 1275 | D11: =ROUND(('Package Reference'!E6+'Package Reference'!F6)/2,0) -> 300 | E11: =ROUND(C11*$C$7,0) -> 1658 | F11: =ROUND(D11*12*$C$6,0) -> 1800 | G11: =ROUND(F11/12,0) -> 150 | H11: =ROUND(C11+$C$8*12*D11,0) -> 10275 | I11: 0
B12: ='Package Reference'!B7 -> Basic+ AI Triage | C12: =ROUND(('Package Reference'!C7+'Package Reference'!D7)/2,0) -> 2500 | D12: =ROUND(('Package Reference'!E7+'Package Reference'!F7)/2,0) -> 525 | E12: =ROUND(C12*$C$7,0) -> 3250 | F12: =ROUND(D12*12*$C$6,0) -> 3150 | G12: =ROUND(F12/12,0) -> 263 | H12: =ROUND(C12+$C$8*12*D12,0) -> 18250 | I12: 0
B13: ='Package Reference'!B8 -> Pro Multi-Channel | C13: =ROUND(('Package Reference'!C8+'Package Reference'!D8)/2,0) -> 5500 | D13: =ROUND(('Package Reference'!E8+'Package Reference'!F8)/2,0) -> 1125 | E13: =ROUND(C13*$C$7,0) -> 7150 | F13: =ROUND(D13*12*$C$6,0) -> 6750 | G13: =ROUND(F13/12,0) -> 563 | H13: =ROUND(C13+$C$8*12*D13,0) -> 39250 | I13: 0
B14: ='Package Reference'!B9 -> Managed Operations | C14: =ROUND(('Package Reference'!C9+'Package Reference'!D9)/2,0) -> 11250 | D14: =ROUND(('Package Reference'!E9+'Package Reference'!F9)/2,0) -> 2500 | E14: =ROUND(C14*$C$7,0) -> 14625 | F14: =ROUND(D14*12*$C$6,0) -> 15000 | G14: =ROUND(F14/12,0) -> 1250 | H14: =ROUND(C14+$C$8*12*D14,0) -> 86250 | I14: 0
B15: ='Package Reference'!B10 -> Agentic Automation | C15: =ROUND(('Package Reference'!C10+'Package Reference'!D10)/2,0) -> 21000 | D15: =ROUND(('Package Reference'!E10+'Package Reference'!F10)/2,0) -> 4250 | E15: =ROUND(C15*$C$7,0) -> 27300 | F15: =ROUND(D15*12*$C$6,0) -> 25500 | G15: =ROUND(F15/12,0) -> 2125 | H15: =ROUND(C15+$C$8*12*D15,0) -> 148500 | I15: 0
B17: How to read it:
B18: • Managed (default): you run and improve it. Setup + monthly per the package. Recurring, you keep the IP.
B19: • Licence (no managed service): they run it; you licence the right-to-use and keep the IP. Setup ×1.3 (handover/docs) + an annual licence = licence% × the managed year. Still recurring.
B20: • Full transfer (INTERNAL INFORMATION ONLY — not offered as a path): if ever considered, one-time = setup + years×12×monthly, so we're paid for the recurring we give up. We keep only general know-how.
B21: Licence % = the maintain-vs-improve split: 40% if your monthly is mostly active improvement, 60% if mostly keeping-it-running. Default 50%.
B22: Figures use Package Reference midpoints; for a specific deal use the Quote Calculator's setup/monthly in place of the midpoint.
B24: Policy source-of-truth: VortexDeep_IP_and_Licensing_Policy_v01. Full transfer is documented, not sold.

Sheet Break-Even & Runway
B2: Break-Even & Runway — company-level, not per-quote
B3: Answers the open item in claude_VD_v13_change_sheet.md: 'Is break-even at 6-8 clients supported by the pricing model?' Nothing else in VD docu computes this — the deck states it, this sheet tests it. Cell colours match the rest of the workbook: yellow = you edit, blue = calculated, don't type over.
B5: 1) ASSUMED CLIENT MIX -> blended monthly fee per active client (live from Access & Licence Pricing)
B6: Package | C6: Managed / mo (live) | D6: Mix weight (edit, must total 100%)
B7: ='Access & Licence Pricing'!B11 -> Basic Intake | C7: ='Access & Licence Pricing'!D11 -> 300 | D7: 0.3
B8: ='Access & Licence Pricing'!B12 -> Basic+ AI Triage | C8: ='Access & Licence Pricing'!D12 -> 525 | D8: 0.35
B9: ='Access & Licence Pricing'!B13 -> Pro Multi-Channel | C9: ='Access & Licence Pricing'!D13 -> 1125 | D9: 0.25
B10: ='Access & Licence Pricing'!B14 -> Managed Operations | C10: ='Access & Licence Pricing'!D14 -> 2500 | D10: 0.08
B11: ='Access & Licence Pricing'!B15 -> Agentic Automation | C11: ='Access & Licence Pricing'!D15 -> 4250 | D11: 0.02
B12: Weight total (must = 100%) | C12: =SUM(D7:D11) -> 1 | D12: =IF(ABS(SUM(D7:D11)-1)<0.001,"OK","FIX WEIGHTS — must total 100%") -> OK
B13: Blended monthly fee per active client (CHF) | C13: =SUMPRODUCT(C7:C11,D7:D11) -> 840 | D13: =CONCATENATE("Implied ARR/client: CHF ",TEXT(C13*12,"#,##0"),"/yr — deck (Slide 7) claims CHF 8,000-15,000/yr blended") -> Implied ARR/client: CHF 10,080/yr — deck (Slide 7) claims CHF 8,000-15,000/yr blended
B15: 2) MONTHLY FIXED COST BASE (edit — your own numbers; nothing to link this to yet)
B16: Founder monthly draw (CHF) | C16: 6000
B17: Other fixed monthly costs (CHF) — tools, insurance, accounting, admin | C17: 500
B18: Gross margin on delivery (%) — 1 minus your own time/subcontractor cost as a share of fee | C18: 0.85 | D18: Delivery pass-through (Make.com ops, AI API tokens per Quote Calculator C26/C27 guidance) sits outside this margin — keep it out of both sides.
B19: Total fixed monthly cost (CHF) | C19: =C16+C17 -> 6500
B20: Contribution margin per client / month (CHF) | C20: =C13*C18 -> 714
B22: 3) BREAK-EVEN
B23: Break-even client count | C23: =IF(C20<=0,"n/a",ROUNDUP(C19/C20,0)) -> 10
B24: Monthly revenue at break-even (CHF) | C24: =IF(ISNUMBER(C23),C23*C13,"n/a") -> 8400
B25: Deck check (Slides 6-7 claim ~6-8 clients) | C25: =IF(ISNUMBER(C23),IF(AND(C23>=6,C23<=8),"OK — matches deck","CHECK — model says "&C23&" clients, deck says 6-8"),"n/a") -> CHECK — model says 10 clients, deck says 6-8
B27: 4) PRE-REVENUE RUNWAY (optional)
B28: Starting cash available (CHF) — leave 0 if not modelling this | C28: 0
B29: Runway at zero clients (months) | C29: =IF(C28<=0,"enter starting cash",IF(C19<=0,"n/a — zero fixed costs",ROUND(C28/C19,1))) -> enter starting cash
B31: 5) SENSITIVITY — break-even client count at different founder draws (holds row 2 mix + row 17-18 fixed)
B32: Founder draw scenario | C32: Break-even clients
B33: Lean (CHF 4,000/mo) | C33: =IF(C20<=0,"n/a",ROUNDUP((4000+C17)/C20,0)) -> 7
B34: Base (= C16 above) | C34: =IF(C20<=0,"n/a",ROUNDUP((C16+C17)/C20,0)) -> 10
B35: Comfortable (CHF 8,000/mo) | C35: =IF(C20<=0,"n/a",ROUNDUP((8000+C17)/C20,0)) -> 12
B37: Source note: Package monthly fees pull live from 'Access & Licence Pricing' (itself live from 'Package Reference'), so this sheet updates automatically if package pricing changes or the F31:F34 adder fix changes the underlying quotes. The client-mix weights, founder draw, other fixed costs, gross margin and starting cash are this sheet's own assumptions — state them out loud before quoting this number to a jury.

Sheet Front-Door Tools — Pricing
B2: Front-Door Tools — Pricing (AISR & AIWSC)
B3: Follows each tool's OWN process docs — they do NOT share one ladder. AISR sells as 3 packages (with prices you've already set). AIWSC keeps two axes apart: DEPTH (mode numbers) and AUTHORIZATION (named). For both, the scan/report is the free front door; fixes and ongoing are paid. AISR figures are yours (documented); AIWSC figures are indicative (no documented price yet) — adjust.
B5: AISR — AI Search Readiness · pipeline & 3 packages (prices per AISR-Process.docx)
B6: Pipeline: | C6: 1 Audit (free, no AI) → 2 Fill facts → 3 Test/teaser (free) → 4 Fix (paid) → 5 Verify → Managed (paid). Client sees only a TEASER; the full report, fixes and implementation stay behind payment.
B7: Package | C7: Price (CHF) | D7: Price (CHF) | E7: Price (CHF) | F7: What the client gets | G7: Access | H7: Recurring | I7: Note
C8: min | D8: max | E8: note | G8: / AI | H8: ?
B9: Free teaser | C9: 0 | D9: 250 | E9: - | F9: Audit + readiness score + 2–3 real AI errors | G9: read-only; cents of API | H9: no | I9: Wins the project — your Fit Check
B10: Fix | C10: 2500 | D10: 5000 | E10: one-time | F10: Full readiness report + implemented fixes + before/after | G10: approved on-site edits | H10: no | I10: The full report lives here, not in the teaser
B11: Managed | C11: 500 | D11: 1000 | E11: month | F11: Repeat testing + small approved fixes over time | G11: ongoing | H11: yes | I11: Off-site citation work is the effective half
B12: Source: your AISR-Process.docx (documented prices). Free = steps 1–3; Paid = full report + fixes + verify + managed.
B14: AIWSC — Website Security Check · two axes: DEPTH (numbered) × AUTHORIZATION (named)
B15: Your AIWSC-Scanning-Policy.docx is explicit: keep depth and authorization apart — mixing them into one number line causes confusion.
B16: DEPTH — the mode numbers (on every report & filename)
B17: Mode | F17: Reads | G17: Permission | H17: Command
B18: mode-00 triage | F18: Public records only: DNS + certificate | G18: None needed (internal) | H18: triage --client <domain>
B19: mode-05 inspect | F19: The delivered page(s) you name: headers, cookies, version + above | G19: None needed (internal) | H19: inspect --client <domain-or-URL>
B20: mode-10 scan | F20: Full light scan: above + the tool's own checks (e.g. redirect test) | G20: Needs authorization | H20: scan --client <domain>
B21: mode-15 scan --deeper | F21: Above + sensitive-file exposure probe (.env / .git) | G21: Needs auth covering ACTIVE testing | H21: scan --client <domain> --deeper
B22: AUTHORIZATION — named, not numbered (who said yes)
B23: self-owned | C23: a domain we control — self-attested
B24: built-by-VD | C24: site we built/maintain — consent as a standing clause in the contract
B25: client | C25: the site owner's written consent (self-serve: prove ownership = the consent)
B26: Same depth (e.g. mode-10) can run under any authorization — depth and authorization are independent.
B28: COMMERCIAL — free front door, paid fixes (AIWSC has no documented price yet; figures indicative)
B29: Tier | C29: Price (CHF) | D29: Price (CHF) | E29: Price (CHF) | F29: What the client gets | G29: Depth | H29: Recurring | I29: Note
C30: min | D30: max | E30: note | G30: / auth | H30: ?
B31: Free scan | C31: 0 | D31: 0 | E31: - | F31: Light scan + plain-language report, self-serve, ownership-verified | G31: mode 00–10 · owner-initiated | H31: no | I31: The front door (no cold outreach)
