Workbook

Sheet START_HERE
A1: VortexDeep — Financial Model v01
A2: Working scenario, not a forecast. Built 2026-09-14 from Pricing Calculator v27 (package midpoints), pitch deck v11-1/v13 (roadmap client counts, team plan) and TalkingPoints v15. All other numbers are model placeholders to validate.
A4: HOW TO USE
A5: 1. Pick a scenario on Assumptions!B4 (Low / Base / High). Everything else flows from Assumptions and Financing_Plan.
A6: 2. Blue text = input you can edit. Black = formula. Green = link to another sheet. Yellow fill = key assumption to validate first.
A7: 3. Monthly_CF is the engine (Jul 2026 – Dec 2029). PnL, Balance_Sheet, Cap_Table and Valuation read from it. Do not type into Monthly_CF.
A8: 4. Toggle funding events on/off with the Include column on Financing_Plan (1 = in the cash flow, 0 = shown but excluded).
A9: 5. Every hardcoded number has a source or a 'placeholder — verify' note next to it. Replace placeholders before showing this to a jury.
A11: SHEET MAP
A12: Sheet | B12: What it answers | C12: Reads from
A13: Assumptions | B13: Every driver: pricing, client ramp, churn, delivery cost, salaries, overhead, tax, DSO | C13: Pricing Calculator v27 · deck roadmap · team slide
A14: Monthly_CF | B14: Monthly client ramp, revenue, costs, EBITDA, receivables, cash and runway | C14: Assumptions · Financing_Plan
A15: PnL | B15: Annual P&L 2026 (H2) – 2029, margins, ARR run-rate, break-even month and clients, peak funding need | C15: Monthly_CF
A16: Balance_Sheet | B16: Year-end balance sheet, capital structure ratios, balance check | C16: Monthly_CF · Financing_Plan
A17: Cap_Table | B17: Ownership today → after co-founder equity → after option pool → after a round | C17: Financing_Plan · Valuation
A18: Use_of_Funds | B18: Where a raise would go, and how many months of burn it buys | C18: Financing_Plan · Monthly_CF
A19: Financing_Plan | B19: Funding events feeding the cash flow, plus the staged financing framework | C19: —
A20: Funding_Sources | B20: Matrix of Swiss funding options vs. fit for VortexDeep | C20: —
A21: Valuation | B21: Three indicative methods; selected pre-money feeds Cap_Table | C21: PnL
A22: Exit | B22: Exit options, value drivers and prerequisites (minor area) | C22: Valuation
A24: MODEL HEALTH CHECKS (all should read OK)
A25: Package mix sums to 100% | B25: =IF(ABS(Assumptions!H17-1)<0.0001,"OK","CHECK") -> OK
A26: Balance sheet balances every year | B26: =IF(MAX(ABS(Balance_Sheet!B24),ABS(Balance_Sheet!C24),ABS(Balance_Sheet!D24),ABS(Balance_Sheet!E24))<1,"OK","CHECK") -> OK
A27: Use of funds allocation sums to 100% | B27: =IF(ABS(Use_of_Funds!B14-1)<0.0001,"OK","CHECK") -> OK
A28: Cap table sums to 100% at every stage | B28: =IF(MAX(ABS(Cap_Table!B16-1),ABS(Cap_Table!C16-1),ABS(Cap_Table!D16-1),ABS(Cap_Table!E16-1))<0.0001,"OK","CHECK") -> OK
A30: HEADLINE OUTPUTS (active scenario)
A31: Active scenario | B31: =Assumptions!B4 -> Base
A32: 2029 total revenue (CHF) | B32: =PnL!E12 -> 454702.31
A33: 2029 ARR run-rate, December (CHF) | B33: =PnL!E13 -> 457237.5
A34: 2029 EBITDA (CHF) | B34: =PnL!E21 -> -10411.965
A35: Sustainable break-even month | B35: =PnL!B28 -> 47331
A36: Active clients at break-even | B36: =PnL!B29 -> 29
A37: Lowest cash point (CHF) | B37: =PnL!B31 -> -31925.902
A38: Peak external funding need (CHF) | B38: =PnL!B33 -> 31925.902
A39: Selected pre-money valuation (CHF) | B39: =Valuation!B40 -> 459565.04
A41: SOURCES
A42: Pricing Calculator v27 › Package Reference (setup & monthly ranges per package) and Access & Licence Pricing.
A43: Pitch deck v11-1 slide 6 (roadmap: 1–2 / 6–8 / 15–20 / 30–40 clients), slide 7 (ARR band), slide 8 (hiring order); v13 change sheet (team layer order).
A44: TalkingPoints v15 (blended ARR/client hypothesis CHF 12–17k; bootstrap-first stance).
A45: Business Creation ICT programme, Day 3 (financial planning) and Day 5 (funding sources, financing plan).
...

Sheet Assumptions
A1: Assumptions — all drivers live here
A2: Blue = edit. Yellow = validate first. Sources/notes in column J.
A4: Active scenario | B4: Base | C4: (options →) | D4: Low | E4: Base | F4: High
A5: Scenario index | B5: =MATCH(B4,D4:F4,0) -> 2
A7: Model start month | B7: 46204 | J7: First month of the model (42 months to Dec 2029).
A8: Model end month | B8: =EDATE(B7,41) -> 47453
A10: B. PRICING — from Pricing Calculator v27 › Package Reference (midpoints of catalogue ranges)
A11: Package | B11: Setup low | C11: Setup high | D11: Setup mid | E11: Monthly low | F11: Monthly high | G11: Monthly mid | H11: Client mix % | J11: Source / note
A12: Basic Intake | B12: 750 | C12: 1800 | D12: =(B12+C12)/2 -> 1275 | E12: 150 | F12: 450 | G12: =(E12+F12)/2 -> 300 | H12: 0.2 | J12: Ranges: Pricing Calculator v27, Package Reference. Mix %: placeholder — replace with real pipeline mix.
A13: Basic+ AI Triage | B13: 1500 | C13: 3500 | D13: =(B13+C13)/2 -> 2500 | E13: 300 | F13: 750 | G13: =(E13+F13)/2 -> 525 | H13: 0.35 | J13: Ranges: Pricing Calculator v27, Package Reference. Mix %: placeholder — replace with real pipeline mix.
A14: Pro Multi-Channel | B14: 3500 | C14: 7500 | D14: =(B14+C14)/2 -> 5500 | E14: 750 | F14: 1500 | G14: =(E14+F14)/2 -> 1125 | H14: 0.25 | J14: Ranges: Pricing Calculator v27, Package Reference. Mix %: placeholder — replace with real pipeline mix.
A15: Managed Operations | B15: 7500 | C15: 15000 | D15: =(B15+C15)/2 -> 11250 | E15: 1500 | F15: 3500 | G15: =(E15+F15)/2 -> 2500 | H15: 0.15 | J15: Ranges: Pricing Calculator v27, Package Reference. Mix %: placeholder — replace with real pipeline mix.
A16: Agentic Automation | B16: 12000 | C16: 30000 | D16: =(B16+C16)/2 -> 21000 | E16: 2500 | F16: 6000 | G16: =(E16+F16)/2 -> 4250 | H16: 0.05 | J16: Ranges: Pricing Calculator v27, Package Reference. Mix %: placeholder — replace with real pipeline mix.
A17: Blended (mix-weighted) | D17: =SUMPRODUCT(D12:D16,H12:H16)/SUM(H12:H16) -> 5242.5 | G17: =SUMPRODUCT(G12:G16,H12:H16)/SUM(H12:H16) -> 1112.5 | H17: =SUM(H12:H16) -> 1 | J17: Blended monthly ×12 ≈ ARR per client. Deck slide 7 says ~8–15k, TalkingPoints v15 says 12–17k — this cell reconciles the two.
A18: Implied ARR per active client | B18: =G17*12 -> 13350
A20: B2. SETUP FEE REALISATION — % of catalogue midpoint actually invoiced (unpaid pilot, early discounts)
A21: Year | B21: 2026 | C21: 2027 | D21: 2028 | E21: 2029
A22: Realised setup fee % | B22: 0.5 | C22: 0.85 | D22: 1 | E22: 1 | J22: Placeholder. 2026 = first pilot unpaid (deck slide 10), second client discounted.
A24: C. CLIENT RAMP — year-end active managed clients (deck v11-1 slide 6: 1–2 / 6–8 / 15–20 / 30–40)
A25: Year | B25: Low | C25: Base | D25: High | E25: Selected
A26: 2026 | B26: 1 | C26: 2 | D26: 2 | E26: =INDEX(B26:D26,$B$5) -> 2 | J26: Base = midpoint of the roadmap band. Low = roughly half. High = top of band.
A27: 2027 | B27: 4 | C27: 7 | D27: 8 | E27: =INDEX(B27:D27,$B$5) -> 7
A28: 2028 | B28: 9 | C28: 17 | D28: 20 | E28: =INDEX(B28:D28,$B$5) -> 17
A29: 2029 | B29: 16 | C29: 35 | D29: 40 | E29: =INDEX(B29:D29,$B$5) -> 35
A30: Annual client churn % | B30: 0.15 | C30: 0.1 | D30: 0.08 | E30: =INDEX(B30:D30,$B$5) -> 0.1 | J30: Placeholder. Managed-service SME churn; validate after first paid year.
A32: D. DIRECT (DELIVERY) COSTS
A33: AI API & tooling per active client, CHF / month | B33: 60 | J33: Placeholder. Pricing Calculator excludes third-party API cost — this is VD's own cost of running a client.
A34: Platform subscriptions (Make/n8n, hosting), CHF / month fixed | B34: 150
A35: Subcontracted build cost, % of setup revenue | B35: 0.1 | J35: Placeholder. Freelance help on builds beyond founder capacity.
A36: Payment, bank & other variable cost, % of revenue | B36: 0.02
A38: E. PEOPLE — annual gross cost by year (CHF). Order follows Team slide v13: co-founder → client success → sales
A39: Role | B39: 2026 | C39: 2027 | D39: 2028 | E39: 2029 | J39: Note
A40: Founder draw (Maciek) | B40: 0 | C40: 30000 | D40: 60000 | E40: 84000 | J40: Placeholder. Bootstrap: no draw in 2026, ramps as revenue allows.
A41: Technical co-founder — BUILD | B41: 0 | C41: 0 | D41: 48000 | E41: 72000 | J41: Equity-only in 2027 (see Cap_Table); part-time salary from 2028.
A42: Client success / managed ops — RUN | B42: 0 | C42: 0 | D42: 30000 | E42: 72000 | J42: Starts mid-2028 when recurring base outgrows founder (deck slide 8).
A43: B2B sales & partnerships — SELL | B43: 0 | C43: 0 | D43: 0 | E43: 80000 | J43: Added at 15–20 clients (deck slide 8).
A44: Employer social charges (AHV/IV/EO, ALV, BVG, UVG), % on gross | B44: 0.15 | J44: Placeholder — verify with fiduciary; depends on pension plan and age.
A46: F. OVERHEAD — CHF per year
A47: Category | B47: 2026 | C47: 2027 | D47: 2028 | E47: 2029
A48: Legal, IP & fiduciary (contracts, licences, accounting) | B48: 4000 | C48: 8000 | D48: 10000 | E48: 12000 | J48: All placeholders. 2026 is a half year. Legal & IP counsel is 'bought in, not hired' (deck slide 8).
...

Sheet Financing_Plan
A1: Financing plan — events feeding the cash flow, and the staged framework
A2: Include = 1 puts the event into Monthly_CF. Include = 0 keeps it visible but excluded. Bootstrap-first: only founder capital is on by default.
A4: # | B4: Month | C4: Source | D4: Type | E4: Amount CHF | F4: Include (1/0) | G4: Purpose / trigger | H4: Note
A5: 1 | B5: 46204 | C5: Founder share capital (GmbH formation) | D5: Equity | E5: 20000 | F5: 1 | G5: Formation, first tooling, legal | H5: CHF 20k is the legal minimum for a Swiss GmbH — verify chosen legal form.
A6: 2 | B6: 46204 | C6: Founder additional paid-in / shareholder loan | D6: Equity | E6: 10000 | F6: 1 | G6: Buffer for 2026 H2 overhead | H6: Placeholder. Treated as equity (paid-in); reclassify as loan if structured so.
A7: 3 | B7: 46478 | C7: Non-dilutive grant (e.g. Innosuisse Innovation Cheque) | D7: Grant | E7: 15000 | F7: 0 | G7: Co-develop reusable workflow library with a research partner | H7: Placeholder — eligibility requires a Swiss research partner; verify current Innosuisse terms.
A8: 4 | B8: 46753 | C8: Angel / pre-seed round | D8: Equity | E8: 150000 | F8: 0 | G8: Accelerate: earlier delivery hire, faster CH → EU (deck slide 11) | H8: Optional. Pre-money from Valuation sheet; see Cap_Table and Use_of_Funds.
A9: 5 | B9: 46935 | C9: Bank SME credit line / start-up loan | D9: Debt | E9: 50000 | F9: 0 | G9: Working-capital bridge once 2 years of accounts exist | H9: Placeholder. Requires track record; verify with house bank / cantonal bank.
A10: 6 | B10: 47300 | C10: Loan repayment (first tranche) | D10: Repayment | E10: 25000 | F10: 0 | G10: Repay half of the credit line | H10: Linked to the debt above; only include if the loan is included.
A12: Rows 5–11 are read by Monthly_CF (row 11 is spare). Keep every month on the 1st.
A13: Total equity (included) | E13: =SUMIFS(E5:E11,D5:D11,"Equity",F5:F11,1) -> 30000
A14: Total debt drawn (included) | E14: =SUMIFS(E5:E11,D5:D11,"Debt",F5:F11,1) -> 0
A15: Total grants (included) | E15: =SUMIFS(E5:E11,D5:D11,"Grant",F5:F11,1) -> 0
A22: STAGED FINANCING FRAMEWORK — what funds each stage, and what triggers the next (Day 5 preparation)
A23: Stage | B23: Period | C23: Primary source | D23: Indicative amount | E23: Trigger to move on | F23: What it funds | G23: Dilution / control | H23: Status
A24: 0 · Validate | B24: 2026 H2 | C24: Founder capital + first setup fees | D24: =E5+E6 -> 30000 | E24: One reference case, second client signed | F24: Formation, tooling, Fit Check, legal | G24: None — 100% founder | H24: Now
A25: 1 · Convert | B25: 2027 | C25: Revenue (setup fees fund builds) ± non-dilutive grant | D25: =E7 -> 15000 | E25: 6–8 managed clients, EBITDA ≥ 0 | F25: Founder draw, first subcontracted builds, IP library | G25: None (co-founder equity only) | H25: Plan
A26: 2 · Standardise | B26: 2028 | C26: Optional angel round OR credit line | D26: =E8+E9 -> 200000 | E26: 15–20 clients, delivery hire in place | F26: Delivery hire, DACH entry, working-capital buffer | G26: ~10–20% if angel round | H26: Optional
A27: 3 · Scale | B27: 2029 | C27: Retained earnings; bank line; licensing revenue | D27: See PnL | E27: 30–40 clients, team of 4 | F27: Sales hire, productised workflows, EU pilots | G27: Keep founder control (TalkingPoints v15) | H27: Hypothesis
A29: Principle (TalkingPoints v15, validated): bootstrap-first; raising is optional and only to accelerate; keep founder control; protect the IP/licence library in any agreement.

Sheet Monthly_CF
A1: Monthly engine — Jul 2026 to Dec 2029 (active scenario)
A2: No inputs here. Change Assumptions or Financing_Plan. Clients are fractional (smooth ramp within each year); receivables = DSO/30 × monthly revenue.
A3: Month | B3: =Assumptions!$B$7 -> 46204 | C3: =EDATE(B3,1) -> 46235 | D3: =EDATE(C3,1) -> 46266 | E3: =EDATE(D3,1) -> 46296 | F3: =EDATE(E3,1) -> 46327 | G3: =EDATE(F3,1) -> 46357 | H3: =EDATE(G3,1) -> 46388 | I3: =EDATE(H3,1) -> 46419 | J3: =EDATE(I3,1) -> 46447 | ... AQ3: =EDATE(AP3,1) -> 47453
A4: Year | B4: =YEAR(B3) -> 2026 | C4: =YEAR(C3) -> 2026 | D4: =YEAR(D3) -> 2026 | E4: =YEAR(E3) -> 2026 | F4: =YEAR(F3) -> 2026 | G4: =YEAR(G3) -> 2026 | H4: =YEAR(H3) -> 2027 | I4: =YEAR(I3) -> 2027 | ... AQ4: =YEAR(AQ3) -> 2029
A5: Month of year | B5: =MONTH(B3) -> 7 | C5: =MONTH(C3) -> 8 | D5: =MONTH(D3) -> 9 | E5: =MONTH(E3) -> 10 | F5: =MONTH(F3) -> 11 | G5: =MONTH(G3) -> 12 | H5: =MONTH(H3) -> 1 | I5: =MONTH(I3) -> 2 | ... AQ5: =MONTH(AQ3) -> 12
A6: Year-start active clients | B6: =IFERROR(INDEX(Assumptions!$E$26:$E$29,MATCH(B4-1,Assumptions!$A$26:$A$29,0)),0) -> 0 | C6: =IFERROR(INDEX(Assumptions!$E$26:$E$29,MATCH(C4-1,Assumptions!$A$26:$A$29,0)),0) -> 0 | D6: =IFERROR(INDEX(Assumptions!$E$26:$E$29,MATCH(D4-1,Assumptions!$A$26:$A$29,0)),0) -> 0 | E6: =IFERROR(INDEX(Assumptions!$E$26:$E$29,MATCH(E4-1,Assumptions!$A$26:$A$29,0)),0) -> 0 | F6: =IFERROR(INDEX(Assumptions!$E$26:$E$29,MATCH(F4-1,Assumptions!$A$26:$A$29,0)),0) -> 0 | G6: =IFERROR(INDEX(Assumptions!$E$26:$E$29,MATCH(G4-1,Assumptions!$A$26:$A$29,0)),0) -> 0 | H6: =IFERROR(INDEX(Assumptions!$E$26:$E$29,MATCH(H4-1,Assumptions!$A$26:$A$29,0)),0) -> 2 | I6: =IFERROR(INDEX(Assumptions!$E$26:$E$29,MATCH(I4-1,Assumptions!$A$26:$A$29,0)),0) -> 2 | ... AQ6: =IFERROR(INDEX(Assumptions!$E$26:$E$29,MATCH(AQ4-1,Assumptions!$A$26:$A$29,0)),0) -> 17
A7: Year-end target clients | B7: =INDEX(Assumptions!$E$26:$E$29,MATCH(B4,Assumptions!$A$26:$A$29,0)) -> 2 | C7: =INDEX(Assumptions!$E$26:$E$29,MATCH(C4,Assumptions!$A$26:$A$29,0)) -> 2 | D7: =INDEX(Assumptions!$E$26:$E$29,MATCH(D4,Assumptions!$A$26:$A$29,0)) -> 2 | E7: =INDEX(Assumptions!$E$26:$E$29,MATCH(E4,Assumptions!$A$26:$A$29,0)) -> 2 | F7: =INDEX(Assumptions!$E$26:$E$29,MATCH(F4,Assumptions!$A$26:$A$29,0)) -> 2 | G7: =INDEX(Assumptions!$E$26:$E$29,MATCH(G4,Assumptions!$A$26:$A$29,0)) -> 2 | H7: =INDEX(Assumptions!$E$26:$E$29,MATCH(H4,Assumptions!$A$26:$A$29,0)) -> 7 | I7: =INDEX(Assumptions!$E$26:$E$29,MATCH(I4,Assumptions!$A$26:$A$29,0)) -> 7 | ... AQ7: =INDEX(Assumptions!$E$26:$E$29,MATCH(AQ4,Assumptions!$A$26:$A$29,0)) -> 35
A8: Months elapsed in model year | B8: =IF(B4=YEAR(Assumptions!$B$7),B5-MONTH(Assumptions!$B$7)+1,B5) -> 1 | C8: =IF(C4=YEAR(Assumptions!$B$7),C5-MONTH(Assumptions!$B$7)+1,C5) -> 2 | D8: =IF(D4=YEAR(Assumptions!$B$7),D5-MONTH(Assumptions!$B$7)+1,D5) -> 3 | E8: =IF(E4=YEAR(Assumptions!$B$7),E5-MONTH(Assumptions!$B$7)+1,E5) -> 4 | F8: =IF(F4=YEAR(Assumptions!$B$7),F5-MONTH(Assumptions!$B$7)+1,F5) -> 5 | G8: =IF(G4=YEAR(Assumptions!$B$7),G5-MONTH(Assumptions!$B$7)+1,G5) -> 6 | H8: =IF(H4=YEAR(Assumptions!$B$7),H5-MONTH(Assumptions!$B$7)+1,H5) -> 1 | I8: =IF(I4=YEAR(Assumptions!$B$7),I5-MONTH(Assumptions!$B$7)+1,I5) -> 2 | ... AQ8: =IF(AQ4=YEAR(Assumptions!$B$7),AQ5-MONTH(Assumptions!$B$7)+1,AQ5) -> 12
A9: Months in model year | B9: =IF(B4=YEAR(Assumptions!$B$7),13-MONTH(Assumptions!$B$7),12) -> 6 | C9: =IF(C4=YEAR(Assumptions!$B$7),13-MONTH(Assumptions!$B$7),12) -> 6 | D9: =IF(D4=YEAR(Assumptions!$B$7),13-MONTH(Assumptions!$B$7),12) -> 6 | E9: =IF(E4=YEAR(Assumptions!$B$7),13-MONTH(Assumptions!$B$7),12) -> 6 | F9: =IF(F4=YEAR(Assumptions!$B$7),13-MONTH(Assumptions!$B$7),12) -> 6 | G9: =IF(G4=YEAR(Assumptions!$B$7),13-MONTH(Assumptions!$B$7),12) -> 6 | H9: =IF(H4=YEAR(Assumptions!$B$7),13-MONTH(Assumptions!$B$7),12) -> 12 | I9: =IF(I4=YEAR(Assumptions!$B$7),13-MONTH(Assumptions!$B$7),12) -> 12 | ... AQ9: =IF(AQ4=YEAR(Assumptions!$B$7),13-MONTH(Assumptions!$B$7),12) -> 12
A10: Active clients (end of month) | B10: =B6+(B7-B6)*B8/B9 -> 0.33333333 | C10: =C6+(C7-C6)*C8/C9 -> 0.66666667 | D10: =D6+(D7-D6)*D8/D9 -> 1 | E10: =E6+(E7-E6)*E8/E9 -> 1.3333333 | F10: =F6+(F7-F6)*F8/F9 -> 1.6666667 | G10: =G6+(G7-G6)*G8/G9 -> 2 | H10: =H6+(H7-H6)*H8/H9 -> 2.4166667 | I10: =I6+(I7-I6)*I8/I9 -> 2.8333333 | ... AQ10: =AQ6+(AQ7-AQ6)*AQ8/AQ9 -> 35
A11: Churned clients | B11: =0 -> 0 | C11: =B10*Assumptions!$E$30/12 -> 0.0027777778 | D11: =C10*Assumptions!$E$30/12 -> 0.0055555556 | E11: =D10*Assumptions!$E$30/12 -> 0.0083333333 | F11: =E10*Assumptions!$E$30/12 -> 0.011111111 | G11: =F10*Assumptions!$E$30/12 -> 0.013888889 | H11: =G10*Assumptions!$E$30/12 -> 0.016666667 | I11: =H10*Assumptions!$E$30/12 -> 0.020138889 | J11: =I10*Assumptions!$E$30/12 -> 0.023611111 | ... AQ11: =AP10*Assumptions!$E$30/12 -> 0.27916667
A12: New clients won | B12: =B10 -> 0.33333333 | C12: =C10-B10+C11 -> 0.33611111 | D12: =D10-C10+D11 -> 0.33888889 | E12: =E10-D10+E11 -> 0.34166667 | F12: =F10-E10+F11 -> 0.34444444 | G12: =G10-F10+G11 -> 0.34722222 | H12: =H10-G10+H11 -> 0.43333333 | I12: =I10-H10+I11 -> 0.43680556 | J12: =J10-I10+J11 -> 0.44027778 | ... AQ12: =AQ10-AP10+AQ11 -> 1.7791667
A13: REVENUE
A14: Setup revenue | B14: =B12*Assumptions!$D$17*INDEX(Assumptions!$B$22:$E$22,MATCH(B4,Assumptions!$B$21:$E$21,0)) -> 873.75 | C14: =C12*Assumptions!$D$17*INDEX(Assumptions!$B$22:$E$22,MATCH(C4,Assumptions!$B$21:$E$21,0)) -> 881.03125 | D14: =D12*Assumptions!$D$17*INDEX(Assumptions!$B$22:$E$22,MATCH(D4,Assumptions!$B$21:$E$21,0)) -> 888.3125 | E14: =E12*Assumptions!$D$17*INDEX(Assumptions!$B$22:$E$22,MATCH(E4,Assumptions!$B$21:$E$21,0)) -> 895.59375 | F14: =F12*Assumptions!$D$17*INDEX(Assumptions!$B$22:$E$22,MATCH(F4,Assumptions!$B$21:$E$21,0)) -> 902.875 | G14: =G12*Assumptions!$D$17*INDEX(Assumptions!$B$22:$E$22,MATCH(G4,Assumptions!$B$21:$E$21,0)) -> 910.15625 | H14: =H12*Assumptions!$D$17*INDEX(Assumptions!$B$22:$E$22,MATCH(H4,Assumptions!$B$21:$E$21,0)) -> 1930.9875 | I14: =I12*Assumptions!$D$17*INDEX(Assumptions!$B$22:$E$22,MATCH(I4,Assumptions!$B$21:$E$21,0)) -> 1946.4602 | ... AQ14: =AQ12*Assumptions!$D$17*INDEX(Assumptions!$B$22:$E$22,MATCH(AQ4,Assumptions!$B$21:$E$21,0)) -> 9327.2812
A15: Recurring (managed service) revenue | B15: =B10/2*Assumptions!$G$17 -> 185.41667 | C15: =(B10+C10)/2*Assumptions!$G$17 -> 556.25 | D15: =(C10+D10)/2*Assumptions!$G$17 -> 927.08333 | E15: =(D10+E10)/2*Assumptions!$G$17 -> 1297.9167 | F15: =(E10+F10)/2*Assumptions!$G$17 -> 1668.75 | G15: =(F10+G10)/2*Assumptions!$G$17 -> 2039.5833 | H15: =(G10+H10)/2*Assumptions!$G$17 -> 2456.7708 | I15: =(H10+I10)/2*Assumptions!$G$17 -> 2920.3125 | J15: =(I10+J10)/2*Assumptions!$G$17 -> 3383.8542 | ... AQ15: =(AP10+AQ10)/2*Assumptions!$G$17 -> 38103.125
A16: Total revenue | B16: =B14+B15 -> 1059.1667 | C16: =C14+C15 -> 1437.2812 | D16: =D14+D15 -> 1815.3958 | E16: =E14+E15 -> 2193.5104 | F16: =F14+F15 -> 2571.625 | G16: =G14+G15 -> 2949.7396 | H16: =H14+H15 -> 4387.7583 | I16: =I14+I15 -> 4866.7727 | ... AQ16: =AQ14+AQ15 -> 47430.406
A17: DIRECT COSTS
A18: AI API & tooling | B18: =B10*Assumptions!$B$33 -> 20 | C18: =C10*Assumptions!$B$33 -> 40 | D18: =D10*Assumptions!$B$33 -> 60 | E18: =E10*Assumptions!$B$33 -> 80 | F18: =F10*Assumptions!$B$33 -> 100 | G18: =G10*Assumptions!$B$33 -> 120 | H18: =H10*Assumptions!$B$33 -> 145 | I18: =I10*Assumptions!$B$33 -> 170 | ... AQ18: =AQ10*Assumptions!$B$33 -> 2100
A19: Platform subscriptions | B19: =Assumptions!$B$34 -> 150 | C19: =Assumptions!$B$34 -> 150 | D19: =Assumptions!$B$34 -> 150 | E19: =Assumptions!$B$34 -> 150 | F19: =Assumptions!$B$34 -> 150 | G19: =Assumptions!$B$34 -> 150 | H19: =Assumptions!$B$34 -> 150 | I19: =Assumptions!$B$34 -> 150 | ... AQ19: =Assumptions!$B$34 -> 150
A20: Subcontracted build | B20: =B14*Assumptions!$B$35 -> 87.375 | C20: =C14*Assumptions!$B$35 -> 88.103125 | D20: =D14*Assumptions!$B$35 -> 88.83125 | E20: =E14*Assumptions!$B$35 -> 89.559375 | F20: =F14*Assumptions!$B$35 -> 90.2875 | G20: =G14*Assumptions!$B$35 -> 91.015625 | H20: =H14*Assumptions!$B$35 -> 193.09875 | I20: =I14*Assumptions!$B$35 -> 194.64602 | ... AQ20: =AQ14*Assumptions!$B$35 -> 932.72812
A21: Payment & variable | B21: =B16*Assumptions!$B$36 -> 21.183333 | C21: =C16*Assumptions!$B$36 -> 28.745625 | D21: =D16*Assumptions!$B$36 -> 36.307917 | E21: =E16*Assumptions!$B$36 -> 43.870208 | F21: =F16*Assumptions!$B$36 -> 51.4325 | G21: =G16*Assumptions!$B$36 -> 58.994792 | H21: =H16*Assumptions!$B$36 -> 87.755167 | I21: =I16*Assumptions!$B$36 -> 97.335453 | ... AQ21: =AQ16*Assumptions!$B$36 -> 948.60812
A22: Total direct costs | B22: =SUM(B18:B21) -> 278.55833 | C22: =SUM(C18:C21) -> 306.84875 | D22: =SUM(D18:D21) -> 335.13917 | E22: =SUM(E18:E21) -> 363.42958 | F22: =SUM(F18:F21) -> 391.72 | G22: =SUM(G18:G21) -> 420.01042 | H22: =SUM(H18:H21) -> 575.85392 | I22: =SUM(I18:I21) -> 611.98147 | ... AQ22: =SUM(AQ18:AQ21) -> 4131.3363
A23: Gross profit | B23: =B16-B22 -> 780.60833 | C23: =C16-C22 -> 1130.4325 | D23: =D16-D22 -> 1480.2567 | E23: =E16-E22 -> 1830.0808 | F23: =F16-F22 -> 2179.905 | G23: =G16-G22 -> 2529.7292 | H23: =H16-H22 -> 3811.9044 | I23: =I16-I22 -> 4254.7912 | ... AQ23: =AQ16-AQ22 -> 43299.07
A24: PEOPLE & OVERHEAD
A25: Founder draw | B25: =INDEX(Assumptions!$B$40:$E$40,MATCH(B4,Assumptions!$B$39:$E$39,0))/12*(1+Assumptions!$B$44) -> 0 | C25: =INDEX(Assumptions!$B$40:$E$40,MATCH(C4,Assumptions!$B$39:$E$39,0))/12*(1+Assumptions!$B$44) -> 0 | D25: =INDEX(Assumptions!$B$40:$E$40,MATCH(D4,Assumptions!$B$39:$E$39,0))/12*(1+Assumptions!$B$44) -> 0 | E25: =INDEX(Assumptions!$B$40:$E$40,MATCH(E4,Assumptions!$B$39:$E$39,0))/12*(1+Assumptions!$B$44) -> 0 | F25: =INDEX(Assumptions!$B$40:$E$40,MATCH(F4,Assumptions!$B$39:$E$39,0))/12*(1+Assumptions!$B$44) -> 0 | G25: =INDEX(Assumptions!$B$40:$E$40,MATCH(G4,Assumptions!$B$39:$E$39,0))/12*(1+Assumptions!$B$44) -> 0 | H25: =INDEX(Assumptions!$B$40:$E$40,MATCH(H4,Assumptions!$B$39:$E$39,0))/12*(1+Assumptions!$B$44) -> 2875 | I25: =INDEX(Assumptions!$B$40:$E$40,MATCH(I4,Assumptions!$B$39:$E$39,0))/12*(1+Assumptions!$B$44) -> 2875 | ... AQ25: =INDEX(Assumptions!$B$40:$E$40,MATCH(AQ4,Assumptions!$B$39:$E$39,0))/12*(1+Assumptions!$B$44) -> 8050
A26: Technical co-founder | B26: =INDEX(Assumptions!$B$41:$E$41,MATCH(B4,Assumptions!$B$39:$E$39,0))/12*(1+Assumptions!$B$44) -> 0 | C26: =INDEX(Assumptions!$B$41:$E$41,MATCH(C4,Assumptions!$B$39:$E$39,0))/12*(1+Assumptions!$B$44) -> 0 | D26: =INDEX(Assumptions!$B$41:$E$41,MATCH(D4,Assumptions!$B$39:$E$39,0))/12*(1+Assumptions!$B$44) -> 0 | E26: =INDEX(Assumptions!$B$41:$E$41,MATCH(E4,Assumptions!$B$39:$E$39,0))/12*(1+Assumptions!$B$44) -> 0 | F26: =INDEX(Assumptions!$B$41:$E$41,MATCH(F4,Assumptions!$B$39:$E$39,0))/12*(1+Assumptions!$B$44) -> 0 | G26: =INDEX(Assumptions!$B$41:$E$41,MATCH(G4,Assumptions!$B$39:$E$39,0))/12*(1+Assumptions!$B$44) -> 0 | H26: =INDEX(Assumptions!$B$41:$E$41,MATCH(H4,Assumptions!$B$39:$E$39,0))/12*(1+Assumptions!$B$44) -> 0 | I26: =INDEX(Assumptions!$B$41:$E$41,MATCH(I4,Assumptions!$B$39:$E$39,0))/12*(1+Assumptions!$B$44) -> 0 | ... AQ26: =INDEX(Assumptions!$B$41:$E$41,MATCH(AQ4,Assumptions!$B$39:$E$39,0))/12*(1+Assumptions!$B$44) -> 6900
A27: Client success / ops | B27: =INDEX(Assumptions!$B$42:$E$42,MATCH(B4,Assumptions!$B$39:$E$39,0))/12*(1+Assumptions!$B$44) -> 0 | C27: =INDEX(Assumptions!$B$42:$E$42,MATCH(C4,Assumptions!$B$39:$E$39,0))/12*(1+Assumptions!$B$44) -> 0 | D27: =INDEX(Assumptions!$B$42:$E$42,MATCH(D4,Assumptions!$B$39:$E$39,0))/12*(1+Assumptions!$B$44) -> 0 | E27: =INDEX(Assumptions!$B$42:$E$42,MATCH(E4,Assumptions!$B$39:$E$39,0))/12*(1+Assumptions!$B$44) -> 0 | F27: =INDEX(Assumptions!$B$42:$E$42,MATCH(F4,Assumptions!$B$39:$E$39,0))/12*(1+Assumptions!$B$44) -> 0 | G27: =INDEX(Assumptions!$B$42:$E$42,MATCH(G4,Assumptions!$B$39:$E$39,0))/12*(1+Assumptions!$B$44) -> 0 | H27: =INDEX(Assumptions!$B$42:$E$42,MATCH(H4,Assumptions!$B$39:$E$39,0))/12*(1+Assumptions!$B$44) -> 0 | I27: =INDEX(Assumptions!$B$42:$E$42,MATCH(I4,Assumptions!$B$39:$E$39,0))/12*(1+Assumptions!$B$44) -> 0 | ... AQ27: =INDEX(Assumptions!$B$42:$E$42,MATCH(AQ4,Assumptions!$B$39:$E$39,0))/12*(1+Assumptions!$B$44) -> 6900
A28: Sales & partnerships | B28: =INDEX(Assumptions!$B$43:$E$43,MATCH(B4,Assumptions!$B$39:$E$39,0))/12*(1+Assumptions!$B$44) -> 0 | C28: =INDEX(Assumptions!$B$43:$E$43,MATCH(C4,Assumptions!$B$39:$E$39,0))/12*(1+Assumptions!$B$44) -> 0 | D28: =INDEX(Assumptions!$B$43:$E$43,MATCH(D4,Assumptions!$B$39:$E$39,0))/12*(1+Assumptions!$B$44) -> 0 | E28: =INDEX(Assumptions!$B$43:$E$43,MATCH(E4,Assumptions!$B$39:$E$39,0))/12*(1+Assumptions!$B$44) -> 0 | F28: =INDEX(Assumptions!$B$43:$E$43,MATCH(F4,Assumptions!$B$39:$E$39,0))/12*(1+Assumptions!$B$44) -> 0 | G28: =INDEX(Assumptions!$B$43:$E$43,MATCH(G4,Assumptions!$B$39:$E$39,0))/12*(1+Assumptions!$B$44) -> 0 | H28: =INDEX(Assumptions!$B$43:$E$43,MATCH(H4,Assumptions!$B$39:$E$39,0))/12*(1+Assumptions!$B$44) -> 0 | I28: =INDEX(Assumptions!$B$43:$E$43,MATCH(I4,Assumptions!$B$39:$E$39,0))/12*(1+Assumptions!$B$44) -> 0 | ... AQ28: =INDEX(Assumptions!$B$43:$E$43,MATCH(AQ4,Assumptions!$B$39:$E$39,0))/12*(1+Assumptions!$B$44) -> 7666.6667
A29: Total people (incl. social charges) | B29: =SUM(B25:B28) -> 0 | C29: =SUM(C25:C28) -> 0 | D29: =SUM(D25:D28) -> 0 | E29: =SUM(E25:E28) -> 0 | F29: =SUM(F25:F28) -> 0 | G29: =SUM(G25:G28) -> 0 | H29: =SUM(H25:H28) -> 2875 | I29: =SUM(I25:I28) -> 2875 | ... AQ29: =SUM(AQ25:AQ28) -> 29516.667
A30: Overhead | B30: =INDEX(Assumptions!$B$55:$E$55,MATCH(B4,Assumptions!$B$47:$E$47,0))/12 -> 833.33333 | C30: =INDEX(Assumptions!$B$55:$E$55,MATCH(C4,Assumptions!$B$47:$E$47,0))/12 -> 833.33333 | D30: =INDEX(Assumptions!$B$55:$E$55,MATCH(D4,Assumptions!$B$47:$E$47,0))/12 -> 833.33333 | E30: =INDEX(Assumptions!$B$55:$E$55,MATCH(E4,Assumptions!$B$47:$E$47,0))/12 -> 833.33333 | F30: =INDEX(Assumptions!$B$55:$E$55,MATCH(F4,Assumptions!$B$47:$E$47,0))/12 -> 833.33333 | G30: =INDEX(Assumptions!$B$55:$E$55,MATCH(G4,Assumptions!$B$47:$E$47,0))/12 -> 833.33333 | H30: =INDEX(Assumptions!$B$55:$E$55,MATCH(H4,Assumptions!$B$47:$E$47,0))/12 -> 2000 | I30: =INDEX(Assumptions!$B$55:$E$55,MATCH(I4,Assumptions!$B$47:$E$47,0))/12 -> 2000 | ... AQ30: =INDEX(Assumptions!$B$55:$E$55,MATCH(AQ4,Assumptions!$B$47:$E$47,0))/12 -> 5833.3333
A31: EBITDA | B31: =B23-B29-B30 -> -52.725 | C31: =C23-C29-C30 -> 297.09917 | D31: =D23-D29-D30 -> 646.92333 | E31: =E23-E29-E30 -> 996.7475 | F31: =F23-F29-F30 -> 1346.5717 | G31: =G23-G29-G30 -> 1696.3958 | H31: =H23-H29-H30 -> -1063.0956 | I31: =I23-I29-I30 -> -620.20881 | ... AQ31: =AQ23-AQ29-AQ30 -> 7949.07
A32: Tax (paid in December) | B32: =IF(B5=12,MAX(0,SUMIFS($B$31:$AQ$31,$B$4:$AQ$4,B4))*Assumptions!$B$59,0) -> 0 | C32: =IF(C5=12,MAX(0,SUMIFS($B$31:$AQ$31,$B$4:$AQ$4,C4))*Assumptions!$B$59,0) -> 0 | D32: =IF(D5=12,MAX(0,SUMIFS($B$31:$AQ$31,$B$4:$AQ$4,D4))*Assumptions!$B$59,0) -> 0 | E32: =IF(E5=12,MAX(0,SUMIFS($B$31:$AQ$31,$B$4:$AQ$4,E4))*Assumptions!$B$59,0) -> 0 | F32: =IF(F5=12,MAX(0,SUMIFS($B$31:$AQ$31,$B$4:$AQ$4,F4))*Assumptions!$B$59,0) -> 0 | G32: =IF(G5=12,MAX(0,SUMIFS($B$31:$AQ$31,$B$4:$AQ$4,G4))*Assumptions!$B$59,0) -> 986.2025 | H32: =IF(H5=12,MAX(0,SUMIFS($B$31:$AQ$31,$B$4:$AQ$4,H4))*Assumptions!$B$59,0) -> 0 | I32: =IF(I5=12,MAX(0,SUMIFS($B$31:$AQ$31,$B$4:$AQ$4,I4))*Assumptions!$B$59,0) -> 0 | ... AQ32: =IF(AQ5=12,MAX(0,SUMIFS($B$31:$AQ$31,$B$4:$AQ$4,AQ4))*Assumptions!$B$59,0) -> 0
A33: Net income | B33: =B31-B32 -> -52.725 | C33: =C31-C32 -> 297.09917 | D33: =D31-D32 -> 646.92333 | E33: =E31-E32 -> 996.7475 | F33: =F31-F32 -> 1346.5717 | G33: =G31-G32 -> 710.19333 | H33: =H31-H32 -> -1063.0956 | I33: =I31-I32 -> -620.20881 | ... AQ33: =AQ31-AQ32 -> 7949.07
A34: CASH
A35: Receivables (end of month) | B35: =B16*Assumptions!$B$58/30 -> 1059.1667 | C35: =C16*Assumptions!$B$58/30 -> 1437.2812 | D35: =D16*Assumptions!$B$58/30 -> 1815.3958 | E35: =E16*Assumptions!$B$58/30 -> 2193.5104 | F35: =F16*Assumptions!$B$58/30 -> 2571.625 | G35: =G16*Assumptions!$B$58/30 -> 2949.7396 | H35: =H16*Assumptions!$B$58/30 -> 4387.7583 | I35: =I16*Assumptions!$B$58/30 -> 4866.7727 | ... AQ35: =AQ16*Assumptions!$B$58/30 -> 47430.406
A36: Change in receivables | B36: =B35 -> 1059.1667 | C36: =C35-B35 -> 378.11458 | D36: =D35-C35 -> 378.11458 | E36: =E35-D35 -> 378.11458 | F36: =F35-E35 -> 378.11458 | G36: =G35-F35 -> 378.11458 | H36: =H35-G35 -> 1438.0187 | I36: =I35-H35 -> 479.01432 | J36: =J35-I35 -> 479.01432 | ... AQ36: =AQ35-AP35 -> 1734.2812
A37: Operating cash flow | B37: =B33-B36 -> -1111.8917 | C37: =C33-C36 -> -81.015417 | D37: =D33-D36 -> 268.80875 | E37: =E33-E36 -> 618.63292 | F37: =F33-F36 -> 968.45708 | G37: =G33-G36 -> 332.07875 | H37: =H33-H36 -> -2501.1143 | I37: =I33-I36 -> -1099.2231 | ... AQ37: =AQ33-AQ36 -> 6214.7887
A38: Equity in | B38: =SUMIFS(Financing_Plan!$E$5:$E$11,Financing_Plan!$B$5:$B$11,B3,Financing_Plan!$D$5:$D$11,"Equity",Financing_Plan!$F$5:$F$11,1) -> 30000 | C38: =SUMIFS(Financing_Plan!$E$5:$E$11,Financing_Plan!$B$5:$B$11,C3,Financing_Plan!$D$5:$D$11,"Equity",Financing_Plan!$F$5:$F$11,1) -> 0 | D38: =SUMIFS(Financing_Plan!$E$5:$E$11,Financing_Plan!$B$5:$B$11,D3,Financing_Plan!$D$5:$D$11,"Equity",Financing_Plan!$F$5:$F$11,1) -> 0 | E38: =SUMIFS(Financing_Plan!$E$5:$E$11,Financing_Plan!$B$5:$B$11,E3,Financing_Plan!$D$5:$D$11,"Equity",Financing_Plan!$F$5:$F$11,1) -> 0 | F38: =SUMIFS(Financing_Plan!$E$5:$E$11,Financing_Plan!$B$5:$B$11,F3,Financing_Plan!$D$5:$D$11,"Equity",Financing_Plan!$F$5:$F$11,1) -> 0 | G38: =SUMIFS(Financing_Plan!$E$5:$E$11,Financing_Plan!$B$5:$B$11,G3,Financing_Plan!$D$5:$D$11,"Equity",Financing_Plan!$F$5:$F$11,1) -> 0 | H38: =SUMIFS(Financing_Plan!$E$5:$E$11,Financing_Plan!$B$5:$B$11,H3,Financing_Plan!$D$5:$D$11,"Equity",Financing_Plan!$F$5:$F$11,1) -> 0 | I38: =SUMIFS(Financing_Plan!$E$5:$E$11,Financing_Plan!$B$5:$B$11,I3,Financing_Plan!$D$5:$D$11,"Equity",Financing_Plan!$F$5:$F$11,1) -> 0 | ... AQ38: =SUMIFS(Financing_Plan!$E$5:$E$11,Financing_Plan!$B$5:$B$11,AQ3,Financing_Plan!$D$5:$D$11,"Equity",Financing_Plan!$F$5:$F$11,1) -> 0
A39: Debt drawn | B39: =SUMIFS(Financing_Plan!$E$5:$E$11,Financing_Plan!$B$5:$B$11,B3,Financing_Plan!$D$5:$D$11,"Debt",Financing_Plan!$F$5:$F$11,1) -> 0 | C39: =SUMIFS(Financing_Plan!$E$5:$E$11,Financing_Plan!$B$5:$B$11,C3,Financing_Plan!$D$5:$D$11,"Debt",Financing_Plan!$F$5:$F$11,1) -> 0 | D39: =SUMIFS(Financing_Plan!$E$5:$E$11,Financing_Plan!$B$5:$B$11,D3,Financing_Plan!$D$5:$D$11,"Debt",Financing_Plan!$F$5:$F$11,1) -> 0 | E39: =SUMIFS(Financing_Plan!$E$5:$E$11,Financing_Plan!$B$5:$B$11,E3,Financing_Plan!$D$5:$D$11,"Debt",Financing_Plan!$F$5:$F$11,1) -> 0 | F39: =SUMIFS(Financing_Plan!$E$5:$E$11,Financing_Plan!$B$5:$B$11,F3,Financing_Plan!$D$5:$D$11,"Debt",Financing_Plan!$F$5:$F$11,1) -> 0 | G39: =SUMIFS(Financing_Plan!$E$5:$E$11,Financing_Plan!$B$5:$B$11,G3,Financing_Plan!$D$5:$D$11,"Debt",Financing_Plan!$F$5:$F$11,1) -> 0 | H39: =SUMIFS(Financing_Plan!$E$5:$E$11,Financing_Plan!$B$5:$B$11,H3,Financing_Plan!$D$5:$D$11,"Debt",Financing_Plan!$F$5:$F$11,1) -> 0 | I39: =SUMIFS(Financing_Plan!$E$5:$E$11,Financing_Plan!$B$5:$B$11,I3,Financing_Plan!$D$5:$D$11,"Debt",Financing_Plan!$F$5:$F$11,1) -> 0 | ... AQ39: =SUMIFS(Financing_Plan!$E$5:$E$11,Financing_Plan!$B$5:$B$11,AQ3,Financing_Plan!$D$5:$D$11,"Debt",Financing_Plan!$F$5:$F$11,1) -> 0
A40: Debt repaid | B40: =SUMIFS(Financing_Plan!$E$5:$E$11,Financing_Plan!$B$5:$B$11,B3,Financing_Plan!$D$5:$D$11,"Repayment",Financing_Plan!$F$5:$F$11,1) -> 0 | C40: =SUMIFS(Financing_Plan!$E$5:$E$11,Financing_Plan!$B$5:$B$11,C3,Financing_Plan!$D$5:$D$11,"Repayment",Financing_Plan!$F$5:$F$11,1) -> 0 | D40: =SUMIFS(Financing_Plan!$E$5:$E$11,Financing_Plan!$B$5:$B$11,D3,Financing_Plan!$D$5:$D$11,"Repayment",Financing_Plan!$F$5:$F$11,1) -> 0 | E40: =SUMIFS(Financing_Plan!$E$5:$E$11,Financing_Plan!$B$5:$B$11,E3,Financing_Plan!$D$5:$D$11,"Repayment",Financing_Plan!$F$5:$F$11,1) -> 0 | F40: =SUMIFS(Financing_Plan!$E$5:$E$11,Financing_Plan!$B$5:$B$11,F3,Financing_Plan!$D$5:$D$11,"Repayment",Financing_Plan!$F$5:$F$11,1) -> 0 | G40: =SUMIFS(Financing_Plan!$E$5:$E$11,Financing_Plan!$B$5:$B$11,G3,Financing_Plan!$D$5:$D$11,"Repayment",Financing_Plan!$F$5:$F$11,1) -> 0 | H40: =SUMIFS(Financing_Plan!$E$5:$E$11,Financing_Plan!$B$5:$B$11,H3,Financing_Plan!$D$5:$D$11,"Repayment",Financing_Plan!$F$5:$F$11,1) -> 0 | I40: =SUMIFS(Financing_Plan!$E$5:$E$11,Financing_Plan!$B$5:$B$11,I3,Financing_Plan!$D$5:$D$11,"Repayment",Financing_Plan!$F$5:$F$11,1) -> 0 | ... AQ40: =SUMIFS(Financing_Plan!$E$5:$E$11,Financing_Plan!$B$5:$B$11,AQ3,Financing_Plan!$D$5:$D$11,"Repayment",Financing_Plan!$F$5:$F$11,1) -> 0
...

Sheet PnL
A1: Annual P&L — active scenario
A2: 2026 is a half year (Jul–Dec). All values CHF. Read from Monthly_CF.
A3: Year | B3: 2026 (H2) | C3: 2027 | D3: 2028 | E3: 2029 | F3: Total
A4: year key | B4: 2026 | C4: 2027 | D4: 2028 | E4: 2029
A5: CLIENTS
A6: New clients won | B6: =SUMIFS(Monthly_CF!$B$12:$AQ$12,Monthly_CF!$B$4:$AQ$4,B$4) -> 2.0416667 | C6: =SUMIFS(Monthly_CF!$B$12:$AQ$12,Monthly_CF!$B$4:$AQ$4,C$4) -> 5.4291667 | D6: =SUMIFS(Monthly_CF!$B$12:$AQ$12,Monthly_CF!$B$4:$AQ$4,D$4) -> 11.158333 | E6: =SUMIFS(Monthly_CF!$B$12:$AQ$12,Monthly_CF!$B$4:$AQ$4,E$4) -> 20.525 | F6: =SUM(B6:E6) -> 39.154167
A7: Active clients (year-end) | B7: =INDEX(Monthly_CF!$B$10:$AQ$10,MATCH(DATE(B$4,12,1),Monthly_CF!$B$3:$AQ$3,0)) -> 2 | C7: =INDEX(Monthly_CF!$B$10:$AQ$10,MATCH(DATE(C$4,12,1),Monthly_CF!$B$3:$AQ$3,0)) -> 7 | D7: =INDEX(Monthly_CF!$B$10:$AQ$10,MATCH(DATE(D$4,12,1),Monthly_CF!$B$3:$AQ$3,0)) -> 17 | E7: =INDEX(Monthly_CF!$B$10:$AQ$10,MATCH(DATE(E$4,12,1),Monthly_CF!$B$3:$AQ$3,0)) -> 35 | F7: =E7 -> 35
A8: Blended ARR per active client | B8: =Assumptions!$B$18 -> 13350 | C8: =Assumptions!$B$18 -> 13350 | D8: =Assumptions!$B$18 -> 13350 | E8: =Assumptions!$B$18 -> 13350
A9: REVENUE
A10: Setup revenue | B10: =SUMIFS(Monthly_CF!$B$14:$AQ$14,Monthly_CF!$B$4:$AQ$4,B$4) -> 5351.7188 | C10: =SUMIFS(Monthly_CF!$B$14:$AQ$14,Monthly_CF!$B$4:$AQ$4,C$4) -> 24193.045 | D10: =SUMIFS(Monthly_CF!$B$14:$AQ$14,Monthly_CF!$B$4:$AQ$4,D$4) -> 58497.562 | E10: =SUMIFS(Monthly_CF!$B$14:$AQ$14,Monthly_CF!$B$4:$AQ$4,E$4) -> 107602.31 | F10: =SUM(B10:E10) -> 195644.64
A11: Recurring revenue | B11: =SUMIFS(Monthly_CF!$B$15:$AQ$15,Monthly_CF!$B$4:$AQ$4,B$4) -> 6675 | C11: =SUMIFS(Monthly_CF!$B$15:$AQ$15,Monthly_CF!$B$4:$AQ$4,C$4) -> 60075 | D11: =SUMIFS(Monthly_CF!$B$15:$AQ$15,Monthly_CF!$B$4:$AQ$4,D$4) -> 160200 | E11: =SUMIFS(Monthly_CF!$B$15:$AQ$15,Monthly_CF!$B$4:$AQ$4,E$4) -> 347100 | F11: =SUM(B11:E11) -> 574050
A12: Total revenue | B12: =SUMIFS(Monthly_CF!$B$16:$AQ$16,Monthly_CF!$B$4:$AQ$4,B$4) -> 12026.719 | C12: =SUMIFS(Monthly_CF!$B$16:$AQ$16,Monthly_CF!$B$4:$AQ$4,C$4) -> 84268.045 | D12: =SUMIFS(Monthly_CF!$B$16:$AQ$16,Monthly_CF!$B$4:$AQ$4,D$4) -> 218697.56 | E12: =SUMIFS(Monthly_CF!$B$16:$AQ$16,Monthly_CF!$B$4:$AQ$4,E$4) -> 454702.31 | F12: =SUM(B12:E12) -> 769694.64
A13: ARR run-rate (December recurring × 12) | B13: =INDEX(Monthly_CF!$B$15:$AQ$15,MATCH(DATE(B$4,12,1),Monthly_CF!$B$3:$AQ$3,0))*12 -> 24475 | C13: =INDEX(Monthly_CF!$B$15:$AQ$15,MATCH(DATE(C$4,12,1),Monthly_CF!$B$3:$AQ$3,0))*12 -> 90668.75 | D13: =INDEX(Monthly_CF!$B$15:$AQ$15,MATCH(DATE(D$4,12,1),Monthly_CF!$B$3:$AQ$3,0))*12 -> 221387.5 | E13: =INDEX(Monthly_CF!$B$15:$AQ$15,MATCH(DATE(E$4,12,1),Monthly_CF!$B$3:$AQ$3,0))*12 -> 457237.5
A14: MARGIN
A15: Direct costs | B15: =SUMIFS(Monthly_CF!$B$22:$AQ$22,Monthly_CF!$B$4:$AQ$4,B$4) -> 2095.7063 | C15: =SUMIFS(Monthly_CF!$B$22:$AQ$22,Monthly_CF!$B$4:$AQ$4,C$4) -> 9294.6654 | D15: =SUMIFS(Monthly_CF!$B$22:$AQ$22,Monthly_CF!$B$4:$AQ$4,D$4) -> 20963.708 | E15: =SUMIFS(Monthly_CF!$B$22:$AQ$22,Monthly_CF!$B$4:$AQ$4,E$4) -> 40914.277 | F15: =SUM(B15:E15) -> 73268.357
A16: Gross profit | B16: =SUMIFS(Monthly_CF!$B$23:$AQ$23,Monthly_CF!$B$4:$AQ$4,B$4) -> 9931.0125 | C16: =SUMIFS(Monthly_CF!$B$23:$AQ$23,Monthly_CF!$B$4:$AQ$4,C$4) -> 74973.38 | D16: =SUMIFS(Monthly_CF!$B$23:$AQ$23,Monthly_CF!$B$4:$AQ$4,D$4) -> 197733.86 | E16: =SUMIFS(Monthly_CF!$B$23:$AQ$23,Monthly_CF!$B$4:$AQ$4,E$4) -> 413788.03 | F16: =SUM(B16:E16) -> 696426.28
A17: Gross margin % | B17: =IF(B12=0,0,B16/B12) -> 0.8257458 | C17: =IF(C12=0,0,C16/C12) -> 0.88970119 | D17: =IF(D12=0,0,D16/D12) -> 0.90414293 | E17: =IF(E12=0,0,E16/E12) -> 0.91001964 | F17: =IF(F12=0,0,F16/F12) -> 0.90480854
A18: OPERATING RESULT
A19: People (incl. social charges) | B19: =SUMIFS(Monthly_CF!$B$29:$AQ$29,Monthly_CF!$B$4:$AQ$4,B$4) -> 0 | C19: =SUMIFS(Monthly_CF!$B$29:$AQ$29,Monthly_CF!$B$4:$AQ$4,C$4) -> 34500 | D19: =SUMIFS(Monthly_CF!$B$29:$AQ$29,Monthly_CF!$B$4:$AQ$4,D$4) -> 158700 | E19: =SUMIFS(Monthly_CF!$B$29:$AQ$29,Monthly_CF!$B$4:$AQ$4,E$4) -> 354200 | F19: =SUM(B19:E19) -> 547400
A20: Overhead | B20: =SUMIFS(Monthly_CF!$B$30:$AQ$30,Monthly_CF!$B$4:$AQ$4,B$4) -> 5000 | C20: =SUMIFS(Monthly_CF!$B$30:$AQ$30,Monthly_CF!$B$4:$AQ$4,C$4) -> 24000 | D20: =SUMIFS(Monthly_CF!$B$30:$AQ$30,Monthly_CF!$B$4:$AQ$4,D$4) -> 45000 | E20: =SUMIFS(Monthly_CF!$B$30:$AQ$30,Monthly_CF!$B$4:$AQ$4,E$4) -> 70000 | F20: =SUM(B20:E20) -> 144000
A21: EBITDA | B21: =SUMIFS(Monthly_CF!$B$31:$AQ$31,Monthly_CF!$B$4:$AQ$4,B$4) -> 4931.0125 | C21: =SUMIFS(Monthly_CF!$B$31:$AQ$31,Monthly_CF!$B$4:$AQ$4,C$4) -> 16473.38 | D21: =SUMIFS(Monthly_CF!$B$31:$AQ$31,Monthly_CF!$B$4:$AQ$4,D$4) -> -5966.145 | E21: =SUMIFS(Monthly_CF!$B$31:$AQ$31,Monthly_CF!$B$4:$AQ$4,E$4) -> -10411.965 | F21: =SUM(B21:E21) -> 5026.2824
A22: EBITDA margin % | B22: =IF(B12=0,0,B21/B12) -> 0.41000481 | C22: =IF(C12=0,0,C21/C12) -> 0.19548786 | D22: =IF(D12=0,0,D21/D12) -> -0.027280345 | E22: =IF(E12=0,0,E21/E12) -> -0.022898421 | F22: =IF(F12=0,0,F21/F12) -> 0.0065302292
A23: Tax | B23: =SUMIFS(Monthly_CF!$B$32:$AQ$32,Monthly_CF!$B$4:$AQ$4,B$4) -> 986.2025 | C23: =SUMIFS(Monthly_CF!$B$32:$AQ$32,Monthly_CF!$B$4:$AQ$4,C$4) -> 3294.676 | D23: =SUMIFS(Monthly_CF!$B$32:$AQ$32,Monthly_CF!$B$4:$AQ$4,D$4) -> 0 | E23: =SUMIFS(Monthly_CF!$B$32:$AQ$32,Monthly_CF!$B$4:$AQ$4,E$4) -> 0 | F23: =SUM(B23:E23) -> 4280.8785
A24: Net income | B24: =SUMIFS(Monthly_CF!$B$33:$AQ$33,Monthly_CF!$B$4:$AQ$4,B$4) -> 3944.81 | C24: =SUMIFS(Monthly_CF!$B$33:$AQ$33,Monthly_CF!$B$4:$AQ$4,C$4) -> 13178.704 | D24: =SUMIFS(Monthly_CF!$B$33:$AQ$33,Monthly_CF!$B$4:$AQ$4,D$4) -> -5966.145 | E24: =SUMIFS(Monthly_CF!$B$33:$AQ$33,Monthly_CF!$B$4:$AQ$4,E$4) -> -10411.965 | F24: =SUM(B24:E24) -> 745.4039
A25: Cumulative net income | B25: =B24 -> 3944.81 | C25: =B25+C24 -> 17123.514 | D25: =C25+D24 -> 11157.369 | E25: =D25+E24 -> 745.4039 | F25: =E25 -> 745.4039
A27: KPIs (whole horizon, active scenario)
A28: Sustainable break-even month (first month after the last negative-EBITDA month) | B28: =IF(MAX(Monthly_CF!$B$48:$AQ$48)>=Monthly_CF!$AQ$3,"Not reached in horizon",EDATE(MAX(Monthly_CF!$B$48:$AQ$48),1)) -> 47331
A29: Active clients at break-even | B29: =IF(ISNUMBER(B28),INDEX(Monthly_CF!$B$10:$AQ$10,MATCH(B28,Monthly_CF!$B$3:$AQ$3,0)),"n/a") -> 29
A30: Deck claim to test: break-even at ~6–8 clients (slides 6/7, v13 open item 3). It holds only while the founder draw is near zero — raise Assumptions row 40 and watch this row.
A31: Lowest closing cash in horizon (CHF) | B31: =MIN(Monthly_CF!$B$44:$AQ$44) -> -31925.902
A32: Month of lowest cash | B32: =INDEX(Monthly_CF!$B$3:$AQ$3,MATCH(B31,Monthly_CF!$B$44:$AQ$44,0)) -> 47331
A33: Peak external funding need (CHF) — 0 means the plan self-funds | B33: =MAX(0,-B31) -> 31925.902
A34: Year-end cash (CHF) | B34: =INDEX(Monthly_CF!$B$44:$AQ$44,MATCH(DATE(B$4,12,1),Monthly_CF!$B$3:$AQ$3,0)) -> 30995.07 | C34: =INDEX(Monthly_CF!$B$44:$AQ$44,MATCH(DATE(C$4,12,1),Monthly_CF!$B$3:$AQ$3,0)) -> 37466.598 | D34: =INDEX(Monthly_CF!$B$44:$AQ$44,MATCH(DATE(D$4,12,1),Monthly_CF!$B$3:$AQ$3,0)) -> 17633.379 | E34: =INDEX(Monthly_CF!$B$44:$AQ$44,MATCH(DATE(E$4,12,1),Monthly_CF!$B$3:$AQ$3,0)) -> -16685.002
A36: Reference — deck slide 7 ARR band (indicative): 2027 ~50–120k · 2028 ~120–300k · 2029 ~240–600k. Compare with row 13.

Sheet Balance_Sheet
A1: Year-end balance sheet & capital structure — active scenario
A2: Simplified: no fixed assets, no accruals beyond receivables; tax paid in-year. Check row must be zero.
A3: 31 December | B3: 2026 | C3: 2027 | D3: 2028 | E3: 2029
A4: year key | B4: 2026 | C4: 2027 | D4: 2028 | E4: 2029
A5: ASSETS
A6: Cash | B6: =INDEX(Monthly_CF!$B$44:$AQ$44,MATCH(DATE(B$4,12,1),Monthly_CF!$B$3:$AQ$3,0)) -> 30995.07 | C6: =INDEX(Monthly_CF!$B$44:$AQ$44,MATCH(DATE(C$4,12,1),Monthly_CF!$B$3:$AQ$3,0)) -> 37466.598 | D6: =INDEX(Monthly_CF!$B$44:$AQ$44,MATCH(DATE(D$4,12,1),Monthly_CF!$B$3:$AQ$3,0)) -> 17633.379 | E6: =INDEX(Monthly_CF!$B$44:$AQ$44,MATCH(DATE(E$4,12,1),Monthly_CF!$B$3:$AQ$3,0)) -> -16685.002
A7: Trade receivables | B7: =INDEX(Monthly_CF!$B$35:$AQ$35,MATCH(DATE(B$4,12,1),Monthly_CF!$B$3:$AQ$3,0)) -> 2949.7396 | C7: =INDEX(Monthly_CF!$B$35:$AQ$35,MATCH(DATE(C$4,12,1),Monthly_CF!$B$3:$AQ$3,0)) -> 9656.9159 | D7: =INDEX(Monthly_CF!$B$35:$AQ$35,MATCH(DATE(D$4,12,1),Monthly_CF!$B$3:$AQ$3,0)) -> 23523.99 | E7: =INDEX(Monthly_CF!$B$35:$AQ$35,MATCH(DATE(E$4,12,1),Monthly_CF!$B$3:$AQ$3,0)) -> 47430.406
A8: Total assets | B8: =B6+B7 -> 33944.81 | C8: =C6+C7 -> 47123.514 | D8: =D6+D7 -> 41157.369 | E8: =E6+E7 -> 30745.404
A10: LIABILITIES
A11: Bank / start-up loans outstanding | B11: =SUMIFS(Financing_Plan!$E$5:$E$11,Financing_Plan!$D$5:$D$11,"Debt",Financing_Plan!$F$5:$F$11,1,Financing_Plan!$B$5:$B$11,"<="&DATE(B$4,12,1))-SUMIFS(Financing_Plan!$E$5:$E$11,Financing_Plan!$D$5:$D$11,"Repayment",Financing_Plan!$F$5:$F$11,1,Financing_Plan!$B$5:$B$11,"<="&DATE(B$4,12,1)) -> 0 | C11: =SUMIFS(Financing_Plan!$E$5:$E$11,Financing_Plan!$D$5:$D$11,"Debt",Financing_Plan!$F$5:$F$11,1,Financing_Plan!$B$5:$B$11,"<="&DATE(C$4,12,1))-SUMIFS(Financing_Plan!$E$5:$E$11,Financing_Plan!$D$5:$D$11,"Repayment",Financing_Plan!$F$5:$F$11,1,Financing_Plan!$B$5:$B$11,"<="&DATE(C$4,12,1)) -> 0 | D11: =SUMIFS(Financing_Plan!$E$5:$E$11,Financing_Plan!$D$5:$D$11,"Debt",Financing_Plan!$F$5:$F$11,1,Financing_Plan!$B$5:$B$11,"<="&DATE(D$4,12,1))-SUMIFS(Financing_Plan!$E$5:$E$11,Financing_Plan!$D$5:$D$11,"Repayment",Financing_Plan!$F$5:$F$11,1,Financing_Plan!$B$5:$B$11,"<="&DATE(D$4,12,1)) -> 0 | E11: =SUMIFS(Financing_Plan!$E$5:$E$11,Financing_Plan!$D$5:$D$11,"Debt",Financing_Plan!$F$5:$F$11,1,Financing_Plan!$B$5:$B$11,"<="&DATE(E$4,12,1))-SUMIFS(Financing_Plan!$E$5:$E$11,Financing_Plan!$D$5:$D$11,"Repayment",Financing_Plan!$F$5:$F$11,1,Financing_Plan!$B$5:$B$11,"<="&DATE(E$4,12,1)) -> 0
A12: Total liabilities | B12: =B11 -> 0 | C12: =C11 -> 0 | D12: =D11 -> 0 | E12: =E11 -> 0
A14: EQUITY
A15: Share capital & paid-in (cumulative equity in) | B15: =SUMIFS(Financing_Plan!$E$5:$E$11,Financing_Plan!$D$5:$D$11,"Equity",Financing_Plan!$F$5:$F$11,1,Financing_Plan!$B$5:$B$11,"<="&DATE(B$4,12,1)) -> 30000 | C15: =SUMIFS(Financing_Plan!$E$5:$E$11,Financing_Plan!$D$5:$D$11,"Equity",Financing_Plan!$F$5:$F$11,1,Financing_Plan!$B$5:$B$11,"<="&DATE(C$4,12,1)) -> 30000 | D15: =SUMIFS(Financing_Plan!$E$5:$E$11,Financing_Plan!$D$5:$D$11,"Equity",Financing_Plan!$F$5:$F$11,1,Financing_Plan!$B$5:$B$11,"<="&DATE(D$4,12,1)) -> 30000 | E15: =SUMIFS(Financing_Plan!$E$5:$E$11,Financing_Plan!$D$5:$D$11,"Equity",Financing_Plan!$F$5:$F$11,1,Financing_Plan!$B$5:$B$11,"<="&DATE(E$4,12,1)) -> 30000
A16: Grants received (reserve) | B16: =SUMIFS(Financing_Plan!$E$5:$E$11,Financing_Plan!$D$5:$D$11,"Grant",Financing_Plan!$F$5:$F$11,1,Financing_Plan!$B$5:$B$11,"<="&DATE(B$4,12,1)) -> 0 | C16: =SUMIFS(Financing_Plan!$E$5:$E$11,Financing_Plan!$D$5:$D$11,"Grant",Financing_Plan!$F$5:$F$11,1,Financing_Plan!$B$5:$B$11,"<="&DATE(C$4,12,1)) -> 0 | D16: =SUMIFS(Financing_Plan!$E$5:$E$11,Financing_Plan!$D$5:$D$11,"Grant",Financing_Plan!$F$5:$F$11,1,Financing_Plan!$B$5:$B$11,"<="&DATE(D$4,12,1)) -> 0 | E16: =SUMIFS(Financing_Plan!$E$5:$E$11,Financing_Plan!$D$5:$D$11,"Grant",Financing_Plan!$F$5:$F$11,1,Financing_Plan!$B$5:$B$11,"<="&DATE(E$4,12,1)) -> 0
A17: Retained earnings (cumulative net income) | B17: =SUMIFS(Monthly_CF!$B$33:$AQ$33,Monthly_CF!$B$4:$AQ$4,"<="&B$4) -> 3944.81 | C17: =SUMIFS(Monthly_CF!$B$33:$AQ$33,Monthly_CF!$B$4:$AQ$4,"<="&C$4) -> 17123.514 | D17: =SUMIFS(Monthly_CF!$B$33:$AQ$33,Monthly_CF!$B$4:$AQ$4,"<="&D$4) -> 11157.369 | E17: =SUMIFS(Monthly_CF!$B$33:$AQ$33,Monthly_CF!$B$4:$AQ$4,"<="&E$4) -> 745.4039
A18: Total equity | B18: =SUM(B15:B17) -> 33944.81 | C18: =SUM(C15:C17) -> 47123.514 | D18: =SUM(D15:D17) -> 41157.369 | E18: =SUM(E15:E17) -> 30745.404
A20: Total liabilities & equity | B20: =B12+B18 -> 33944.81 | C20: =C12+C18 -> 47123.514 | D20: =D12+D18 -> 41157.369 | E20: =E12+E18 -> 30745.404
A22: CHECKS & RATIOS
A24: Balance check (assets − liabilities − equity) → must be 0 | B24: =B8-B12-B18 -> 0 | C24: =C8-C12-C18 -> 0 | D24: =D8-D12-D18 -> 0 | E24: =E8-E12-E18 -> 0
A25: Equity ratio (equity / total assets) | B25: =IF(B8=0,0,B18/B8) -> 1 | C25: =IF(C8=0,0,C18/C8) -> 1 | D25: =IF(D8=0,0,D18/D8) -> 1 | E25: =IF(E8=0,0,E18/E8) -> 1
A26: Debt / equity | B26: =IF(B18<=0,0,B11/B18) -> 0 | C26: =IF(C18<=0,0,C11/C18) -> 0 | D26: =IF(D18<=0,0,D11/D18) -> 0 | E26: =IF(E18<=0,0,E11/E18) -> 0
A27: Cash / annual overhead (months of overhead covered) | B27: =IF(Assumptions!B$55=0,0,B6/(Assumptions!B$55/12)) -> 37.194085 | C27: =IF(Assumptions!C$55=0,0,C6/(Assumptions!C$55/12)) -> 18.733299 | D27: =IF(Assumptions!D$55=0,0,D6/(Assumptions!D$55/12)) -> 4.7022345 | E27: =IF(Assumptions!E$55=0,0,E6/(Assumptions!E$55/12)) -> -2.8602861
A29: Capital structure today: 100% founder-owned; no debt. Any round or loan is a toggle on Financing_Plan (see Cap_Table for dilution).

Sheet Cap_Table
A1: Cap table — ownership by stage (indicative)
A2: Stages: founding → technical co-founder equity (2027) → option pool → angel round (2028, optional). Percentages; share counts assume new shares issued at each step.
A4: INPUTS
A5: Founding share capital (CHF) | B5: =Financing_Plan!E5 -> 20000
A6: Nominal value per share (CHF) | B6: 1
A7: Founding shares | B7: =B5/B6 -> 20000
A8: Technical co-founder equity % (vesting 4 yrs, 1-yr cliff) | B8: 0.2 | F8: Placeholder. Team slide v13: 'equity, not salary'. Typical late-joining technical co-founder: 10–25%, always with vesting.
A9: Option pool created pre-round (% post-pool) | B9: 0.1 | F9: Placeholder. For key hires (client success, sales). Set 0 if none.
A10: Angel round investment (CHF) | B10: =Financing_Plan!E8 -> 150000
A11: Pre-money valuation at round (CHF) | B11: =Valuation!B40 -> 459565.04
A12: Post-money valuation (CHF) | B12: =B11+B10 -> 609565.04
A13: New investor share of company | B13: =IF(B12=0,0,B10/B12) -> 0.24607711
A15: Holder | B15: 1 · Founding | C15: 2 · Post co-founder | D15: 3 · Post option pool | E15: 4 · Post angel round | F15: Note
A16: Total (check = 100%) | B16: =SUM(B17:B20) -> 1 | C16: =SUM(C17:C20) -> 1 | D16: =SUM(D17:D20) -> 1 | E16: =SUM(E17:E20) -> 1
A17: Maciek Szczech (founder) | B17: 1 | C17: =B17*(1-$B$8) -> 0.8 | D17: =C17*(1-$B$9) -> 0.72 | E17: =D17*(1-$B$13) -> 0.54282448 | F17: Founder keeps control at every stage while > 50% (TalkingPoints v15: control-first).
A18: Technical co-founder | B18: 0 | C18: =$B$8 -> 0.2 | D18: =C18*(1-$B$9) -> 0.18 | E18: =D18*(1-$B$13) -> 0.13570612
A19: Option pool | B19: 0 | C19: =B19 -> 0 | D19: =$B$9 -> 0.1 | E19: =D19*(1-$B$13) -> 0.075392289
A20: Angel investors | B20: 0 | C20: =B20 -> 0 | D20: =C20 -> 0 | E20: =$B$13 -> 0.24607711 | F20: Round is a toggle on Financing_Plan; if Include = 0 the stage-4 column is a what-if only.
A22: IMPLIED SHARE COUNTS (new shares issued at each stage)
A23: Total shares outstanding | B23: =IF(B17=0,0,$B$7*$B$17/B17) -> 20000 | C23: =IF(C17=0,0,$B$7*$B$17/C17) -> 25000 | D23: =IF(D17=0,0,$B$7*$B$17/D17) -> 27777.778 | E23: =IF(E17=0,0,$B$7*$B$17/E17) -> 36844.322
A24: Maciek Szczech (founder) | B24: =B23*B17 -> 20000 | C24: =C23*C17 -> 20000 | D24: =D23*D17 -> 20000 | E24: =E23*E17 -> 20000
A25: Technical co-founder | B25: =B23*B18 -> 0 | C25: =C23*C18 -> 5000 | D25: =D23*D18 -> 5000 | E25: =E23*E18 -> 5000
A26: Option pool | B26: =B23*B19 -> 0 | C26: =C23*C19 -> 0 | D26: =D23*D19 -> 2777.7778 | E26: =E23*E19 -> 2777.7778
A27: Angel investors | B27: =B23*B20 -> 0 | C27: =C23*C20 -> 0 | D27: =D23*D20 -> 0 | E27: =E23*E20 -> 9066.5441
A29: Implied price per share at the round (CHF) | B29: =IF(D23=0,0,B11/D23) -> 16.544341
A31: Founder control check (> 50% after round) | B31: =IF(E17>0.5,"OK — founder keeps majority","CHECK — founder below 50%") -> OK — founder keeps majority

Sheet Use_of_Funds
A1: Use of funds — if the optional round is raised
A2: Amount links to Financing_Plan row 8 (angel / pre-seed). Allocation % are placeholders — deck slide 11 names: earlier delivery hire, faster CH → EU.
A4: Planned raise (CHF) | B4: =Financing_Plan!E8 -> 150000
A5: Included in cash flow? | B5: =IF(Financing_Plan!F8=1,"Yes — in Monthly_CF","No — what-if only") -> No — what-if only
A7: Use | B7: Share % | C7: Amount CHF | D7: What it buys | E7: Links to
A8: Delivery capacity — technical hire / co-founder salary | B8: 0.4 | C8: =$B$4*B8 -> 60000 | D8: 12–18 months of a delivery engineer so the founder stops being the build bottleneck | E8: Team slide v13 role 01
A9: Go-to-market & DACH/EU entry | B9: 0.2 | C9: =$B$4*B9 -> 30000 | D9: Sales hire earlier, partner channels, first EU pilots, events | E9: Roadmap 2028 'CH → EU'
A10: Product / reusable workflow (IP) library | B10: 0.15 | C10: =$B$4*B10 -> 22500 | D10: Productise the 5 packages; documentation; licence-ready blueprints | E10: Slide 7 licence model
A11: Working-capital buffer | B11: 0.15 | C11: =$B$4*B11 -> 22500 | D11: ~6 months of overhead so pilots can be priced for proof, not survival | E11: Balance_Sheet row 27
A12: Legal, IP & data-protection | B12: 0.05 | C12: =$B$4*B12 -> 7500 | D12: Licence agreements, data agreements, term sheet, trademark | E12: Team slide 'bought in, not hired'
A13: Contingency | B13: 0.05 | C13: =$B$4*B13 -> 7500 | D13: Unallocated | E13: —
A14: Total | B14: =SUM(B8:B13) -> 1 | C14: =SUM(C8:C13) -> 150000
A16: WHAT THE RAISE BUYS IN TIME
A17: Average monthly net cash flow in 2028 without the raise (CHF) | B17: =SUMIFS(Monthly_CF!$B$37:$AQ$37,Monthly_CF!$B$4:$AQ$4,2028)/12 -> -1652.7682
A18: Months of 2028 operating burn covered by the raise | B18: =IF(B17>=0,"n/a — 2028 is cash-positive operationally",B4/-B17) -> 90.756827
A19: Peak funding need without any raise (from PnL) | B19: =PnL!B33 -> 31925.902
A20: Raise vs. need | B20: =IF(B19=0,"Plan self-funds — raise is acceleration only",IF(B4>=B19,"Raise covers the gap","Raise smaller than the gap")) -> Raise covers the gap

Sheet Funding_Sources
A1: Funding source matrix — Swiss options vs. fit for VortexDeep
A2: Indicative, from general knowledge of the Swiss ecosystem — verify current programmes, amounts and eligibility before Day 5. Fit is the founder's call.
A4: Source | B4: Type | C4: Dilution | D4: Typical size CHF | E4: Stage fit | F4: Time to close | G4: Control impact | H4: Fit for VD | I4: Why / conditions
A5: Bootstrap — setup fees fund builds | B5: Revenue | C5: None | D5: 5–30k per client | E5: Now | F5: Immediate | G5: None | H5: High | I5: Core model (TalkingPoints v15). Setup fee is invoiced at kickoff; keeps 100% ownership.
A6: Founder capital / shareholder loan | B6: Equity or loan | C6: None | D6: 20–50k | E6: Formation | F6: Immediate | G6: None | H6: High | I6: GmbH minimum CHF 20k; any extra as paid-in or documented loan.
A7: Design-partner prepayment / paid pilot | B7: Revenue | C7: None | D7: 5–15k | E7: 2026–27 | F7: 1–3 months | G7: None | H7: High | I7: Deck slide 11 ask. Best signal to a jury: someone paid.
A8: Innosuisse Start-up Coaching (Core Coaching) | B8: Non-dilutive services | C8: None | D8: Coaching, not cash | E8: 2026–27 | F8: 3–6 months | G8: None | H8: Medium | I8: Coaching and network; funds coach hours, not the company. Verify current programme.
A9: Innosuisse Innovation Cheque / project | B9: Non-dilutive grant | C9: None | D9: ~15k cheque; larger projects | E9: 2027 | F9: 3–6 months | G9: None | H9: Medium–Low | I9: Requires a Swiss research partner (e.g. FH/ETH) — fits only if the workflow library becomes an R&D project. Verify.
A10: Cantonal / regional start-up loans (e.g. cantonal bank programmes, technology-park loans) | B10: Debt (soft) | C10: None | D10: 50–150k | E10: 2028+ | F10: 2–4 months | G10: Covenants | H10: Medium | I10: Usually needs a track record or guarantee; verify canton Zürich options.
A11: Bank SME credit line | B11: Debt | C11: None | D11: 20–100k | E11: 2028+ | F11: 1–3 months | G11: Covenants | H11: Medium | I11: Needs ~2 years of accounts and recurring revenue; personal guarantee likely.
A12: Business angels / angel networks (e.g. SICTIC) | B12: Equity | C12: 10–25% | D12: 150–500k | E12: 2028 (optional) | F12: 3–6 months | G12: Board seat / information rights | H12: Medium | I12: Only to accelerate (delivery hire, EU). Managed-service businesses are not a classic angel case; need a productised/licensing story.
A13: Venture Kick / Swiss start-up competitions | B13: Non-dilutive prize | C13: None | D13: up to ~150k in stages | E13: 2027 | F13: 3–9 months | G13: None | H13: Low–Medium | I13: Favours scalable tech and university spin-offs; verify eligibility for a services model.
A14: Revenue-based financing | B14: Quasi-debt | C14: None | D14: 50–200k | E14: 2028+ | F14: 1–2 months | G14: Revenue share until cap | H14: Low–Medium | I14: Needs stable recurring revenue; expensive if growth is slow.
A15: Crowdfunding / crowdlending | B15: Debt or equity | C15: 0–15% | D15: 50–200k | E15: 2028+ | F15: 2–4 months | G15: Many small holders | H15: Low | I15: Marketing effort high; weak fit for a B2B managed service.
... A17: Strategic partner (IT services firm, Treuhand network, automation platform) | B17: Equity or commercial | C17: 0–20% | D17: Varies | E17: 2028–29 | F17: 3–9 months | G17: Exclusivity risk | H17: Medium | I17: Distribution + credibility; also an exit path (see Exit sheet).

Sheet Valuation
A1: Valuation — three indicative methods (pre-money, CHF)
A2: None of these is a forecast. They bracket what a 2028 angel conversation could start from. Selected method feeds Cap_Table.
A4: METHOD 1 — ARR MULTIPLE, EXIT-BACK (what a buyer might pay in 2029, discounted to today)
A5: 2029 ARR run-rate (CHF, from PnL) | B5: =PnL!E13 -> 457237.5
A6: ARR multiple at exit | B6: 3 | F6: Placeholder. Managed IT / automation services typically 1–3× ARR; productised recurring software 4–8×. VD sits between until the IP library is licensed.
A7: Implied enterprise value 2029 (CHF) | B7: =B5*B6 -> 1371712.5
A8: Discount rate (early-stage risk) | B8: 0.4 | F8: Placeholder. Angels/VC typically discount 30–60% p.a. at pre-seed.
A9: Years from today to 2029 exit | B9: 3.25
A10: Present value today (CHF) | B10: =B7/(1+B8)^B9 -> 459565.04
A12: METHOD 2 — SCORECARD (adjust a regional pre-seed benchmark by qualitative factors)
A13: Benchmark pre-money for comparable Swiss pre-seed services/AI companies (CHF) | B13: 1500000 | F13: Placeholder — verify with SICTIC / Swiss angel data; services businesses sit at the low end of typical pre-seed ranges.
A14: Factor | B14: Weight | C14: Score vs. benchmark (1.0 = average) | D14: Weighted | F14: Rationale
A15: Team (founder + gaps) | B15: 0.3 | C15: 0.9 | D15: =B15*C15 -> 0.27 | F15: 20+ yrs industrial ops (strength); solo founder without technical co-founder (gap) — team slide v13.
A16: Market size & timing | B16: 0.25 | C16: 1 | D16: =B16*C16 -> 0.25 | F16: ~50k Swiss SMEs in SAM; AI-assisted admin is timely.
A17: Product / traction | B17: 0.15 | C17: 0.7 | D17: =B17*C17 -> 0.105 | F17: Unpaid pilot only; pre-revenue (deck slide 10).
A18: Competition / defensibility | B18: 0.1 | C18: 0.9 | D18: =B18*C18 -> 0.09 | F18: Managed + human-in-the-loop positioning; IP library not yet proven.
A19: Sales channels & partnerships | B19: 0.1 | C19: 0.8 | D19: =B19*C19 -> 0.08 | F19: No channel yet; Fit Check is the front door.
A20: Need for further funding | B20: 0.05 | C20: 1.1 | D20: =B20*C20 -> 0.055 | F20: Bootstrap-first — low capital need is a plus.
A21: Other (governance, legal readiness) | B21: 0.05 | C21: 1 | D21: =B21*C21 -> 0.05 | F21: Legal/IP counsel bought in; no board yet.
A22: Total weight / weighted score | B22: =SUM(B15:B21) -> 1 | D22: =SUM(D15:D21) -> 0.9
A23: Scorecard pre-money (CHF) | B23: =B13*D22 -> 1350000
A25: METHOD 3 — FORWARD REVENUE MULTIPLE (next-12-month revenue × multiple)
A26: 2027 total revenue (CHF, from PnL) | B26: =PnL!C12 -> 84268.045
A27: Forward revenue multiple | B27: 2 | F27: Placeholder. Small services firms 0.5–1.5×; recurring-heavy models 2–4×.
A28: Forward-revenue pre-money (CHF) | B28: =B26*B27 -> 168536.09
A30: SUMMARY
A31: Method | B31: Pre-money CHF | F31: Use
A32: 1 · ARR multiple, exit-back | B32: =B10 -> 459565.04 | F32: Investor logic: what is the 2029 business worth, discounted for risk.
A33: 2 · Scorecard | B33: =B23 -> 1350000 | F33: Angel-network logic at pre-seed.
A34: 3 · Forward revenue multiple | B34: =B28 -> 168536.09 | F34: Floor-type view for a services business.
A35: Average of the three | B35: =AVERAGE(B32:B34) -> 659367.04
A36: Lowest / highest | B36: =MIN(B32:B34) -> 168536.09 | C36: =MAX(B32:B34) -> 1350000
A38: Method used for Cap_Table (1, 2, 3 or 4 = average) | B38: 1 | F38: Default = method 1 (most conservative and most defensible for a jury).
A40: SELECTED PRE-MONEY VALUATION (CHF) | B40: =INDEX(B32:B35,B38) -> 459565.04
A42: Reminder: valuation only matters if the optional round on Financing_Plan is switched on. Bootstrap-first means this sheet is a negotiation aid, not a plan.

Sheet Exit
A1: Exit strategy — options, drivers and prerequisites (minor area)
A2: For a bootstrap-first managed-service business the default 'exit' is a cash-flow business the founder keeps. The others are options to keep open, not the plan.
A4: Reference values (active scenario)
A5: 2029 ARR run-rate (CHF) | B5: =PnL!E13 -> 457237.5
A6: 2029 EBITDA (CHF) | B6: =PnL!E21 -> -10411.965
A7: Indicative 2029 enterprise value at the ARR multiple (CHF) | B7: =Valuation!B7 -> 1371712.5
A8: EBITDA multiple cross-check (× 2029 EBITDA) | B8: 5 | C8: =MAX(0,B6)*B8 -> 0 | D8: Placeholder: small profitable services firms 3–6× EBITDA.
A10: Option | B10: What it is | C10: When plausible | D10: Value driver | E10: Prerequisites | F10: Likelihood | G10: Founder outcome
A11: Hold & harvest | B11: Keep VortexDeep as a profitable, founder-owned managed-service business | C11: 2029+ | D11: EBITDA, low capital need | E11: Break-even sustained; team of 3–4 covering Build/Sell/Run | F11: High | G11: Income + optionality; no dilution
A12: Strategic sale to Swiss IT services / MSP | B12: Acquirer buys the client base, recurring contracts and the workflow library | C12: 2029–2031 | D12: ARR × multiple; retention; documented processes | E12: ≥30 managed clients; contracts assignable; founder-independent delivery | F12: Medium | G12: Cash at ARR multiple; earn-out likely
A13: Sale to Treuhand / accounting or ERP network | B13: Distribution-led buyer that wants automation for its SME base | C13: 2029–2031 | D13: Repeatable packages; DACH-ready | E13: Productised offers; partner pilot proves channel | F13: Medium | G13: Cash + role as head of automation
A14: Acqui-hire by automation platform / AI vendor | B14: Team and know-how bought, clients secondary | C14: 2028–2030 | D14: Team, reusable IP, case studies | E14: Technical co-founder on board; IP owned cleanly by the company | F14: Low–Medium | G14: Salary + retention equity; lower cash
