Workbook

Sheet START HERE
A1: Phase 5 — Testing / Validation
A2: Purpose: validate that the MVP built in Phase 4 is safe, reliable, and ready for go-live.
A4: Step | B4: What to do | C4: Output
A5: 1 | B5: Copy approved MVP modules from Phase 4 into the handoff sheet. | C5: Clear list of items to test.
A6: 2 | B6: Create test cases covering normal, edge, risk, and failure scenarios. | C6: Test Case Matrix completed.
A7: 3 | B7: Run each test and record actual result, pass/fail, defect, owner, and fix notes. | C7: Evidence-based validation.
A8: 4 | B8: Review AI classification quality separately: category, confidence, fallback, hallucination risk. | C8: AI Validation completed.
A9: 5 | B9: Review approval, escalation, audit, error handling, and security behavior. | C9: Safety checks completed.
A10: 6 | B10: Only approve go-live if critical issues are closed and success criteria are met. | C10: Go / No-Go decision.
A14: We planned this PM flow:
A16: Phase 1 — Discovery / Analysis
A17: Understand client needs, channels, risks, pain points, possible package direction.
A19: Phase 2 — Scope Definition / MVP Design
A20: Convert discovery answers into a clear first project scope.
A22: Phase 3 — Solution Blueprint
A23: Design workflow logic, tools, data fields, routing, approvals, security.
A25: Phase 4 — MVP Build
A26: Build the first safe automation version.
A28: Phase 5 — Testing / Validation
A29: Test real cases, edge cases, errors, wrong classifications, approvals.
A31: Phase 6 — Go-live / Managed Service
... A36: Test Case Matrix — by Pass/Fail
A37: Status | B37: Meaning | C37: Count
A38: Pass | B38: Test passed. | C38: =COUNTIF('Test Case Matrix'!J5:J60,"Pass") -> 0
A39: Fail | B39: Test failed. | C39: =COUNTIF('Test Case Matrix'!J5:J60,"Fail") -> 0
A40: Partial | B40: Partial pass — close but not exact. | C40: =COUNTIF('Test Case Matrix'!J5:J60,"Partial") -> 0
A41: Not Tested | B41: Not yet run. | C41: =COUNTIF('Test Case Matrix'!J5:J60,"Not Tested") -> 0
A42: Blocked | B42: Cannot test. | C42: =COUNTIF('Test Case Matrix'!J5:J60,"Blocked") -> 0
A44: Approval Escalation Tests — by Pass/Fail
A45: Status | B45: Meaning | C45: Count
A46: Pass | B46: Approval/escalation behavior correct. | C46: =COUNTIF('Approval Escalation Tests'!E5:E40,"Pass") -> 0
A47: Fail | B47: Failed — risky behavior detected. | C47: =COUNTIF('Approval Escalation Tests'!E5:E40,"Fail") -> 0
A48: Partial | B48: Partial pass. | C48: =COUNTIF('Approval Escalation Tests'!E5:E40,"Partial") -> 0
A49: Not Tested | B49: Not yet run. | C49: =COUNTIF('Approval Escalation Tests'!E5:E40,"Not Tested") -> 0
A51: Error Monitoring Tests — by Pass/Fail
A52: Status | B52: Meaning | C52: Count
A53: Pass | B53: Fallback behaved correctly. | C53: =COUNTIF('Error Monitoring Tests'!E5:E40,"Pass") -> 0
A54: Fail | B54: Fallback failed. | C54: =COUNTIF('Error Monitoring Tests'!E5:E40,"Fail") -> 0
A55: Partial | B55: Partial pass. | C55: =COUNTIF('Error Monitoring Tests'!E5:E40,"Partial") -> 0
A56: Not Tested | B56: Not yet run. | C56: =COUNTIF('Error Monitoring Tests'!E5:E40,"Not Tested") -> 0
...

Sheet Test Result Triage Helper
A1: Test Result Triage Helper — one test, one verdict
A2: Use this AFTER running a single test, before recording Pass/Fail on the Test Case Matrix. Fill the 6 yellow inputs; the blue cells suggest verdict, severity, whether a defect is needed, go-live blocker status, and recommended next action. PM judgment still final.
A4: INPUTS — about this one test run
A5: # | B5: Question | C5: Allowed values | D5: Answer
A6: Q1 | B6: Q1. Did the actual result match the expected? | C6: Exactly / Close (minor differences) / Partially / No / Errored before completion | D6: Exactly
A7: Q2 | B7: Q2. Type of mismatch (if any) | C7: None / Wrong category / Wrong action / Wrong route / Unsafe behavior / Other | D7: None
A8: Q3 | B8: Q3. Reproducibility | C8: Always / Sometimes / Once (could not reproduce) | D8: Always
A9: Q4 | B9: Q4. Safety / privacy impact if this bug ships | C9: None / Minor / Major / Critical (data loss, sensitive harm, legal) | D9: None
A10: Q5 | B10: Q5. Affected scope | C10: Single test / Single category / Whole workflow / Multiple workflows | D10: Single test
A11: Q6 | B11: Q6. Test scenario type | C11: Normal / Edge / Risk / Failure / Error simulation | D11: Normal
A13: SUGGESTED VERDICT (auto-calculated)
A14: # | B14: Indicator | C14: Suggested Value (formula) | D14: Reasoning hint
A15: O1 | B15: Verdict (Pass/Fail) | C15: =IF(D6="Errored","Re-run needed (errored before completing)",IF(D7="Unsafe behavior","Fail (unsafe)",IF(D6="Exactly","Pass",IF(D6="Close","Pass (with note)",IF(D6="Partially","Partial","Fail"))))) -> Pass | D15: Exactly match → Pass. Unsafe behavior → Fail regardless. Partial → Partial.
A16: O2 | B16: Severity (if defect) | C16: =IF(D6="Exactly","None",IF(D9="Critical","Critical",IF(D9="Major","High",IF(OR(D7="Wrong action",D7="Wrong route",D7="Unsafe behavior"),"High",IF(D7="Wrong category","Medium",IF(D6="Close","Low","Low")))))) -> None | D16: Critical safety → Critical. Wrong action/route → High. Wrong category → Medium.
A17: O3 | B17: Defect needed? | C17: =IF(D6="Exactly","No",IF(D6="Close","Maybe (log a note)",IF(D6="Errored",IF(D8="Once","Maybe (try once more first)","Yes"),"Yes"))) -> No | D17: Exact pass → No. Close → Maybe (log only). Otherwise → Yes.
A18: O4 | B18: Go-live blocker? | C18: =IF(D9="Critical","YES — critical safety issue.",IF(D7="Unsafe behavior","YES — unsafe behavior must be fixed.",IF(AND(D10="Whole workflow",D6<>"Exactly"),"YES — affects whole workflow.",IF(AND(D10="Multiple workflows",D6<>"Exactly"),"YES — affects multiple workflows.",IF(AND(OR(D11="Risk",D11="Failure",D11="Error simulation"),D6="No"),"YES — risk/failure scenario failed.",IF(D6="Exactly","No",IF(D9="None","No (low severity)","Conditional — depends on fix difficulty and client tolerance."))))))) -> No | D18: Critical safety always blocks. Risk/Failure scenarios that fail block. Whole-workflow scope blocks.
A19: O5 | B19: Recommended next action | C19: =IF(D6="Errored",IF(D8="Once","Re-run the test once; if still errors, file defect.","File defect; capture error trace; do not pass."),IF(D6="Exactly","Mark Pass; move to next test.",IF(D7="Unsafe behavior","Stop further testing in this area; file high-severity defect; review safety design.",IF(D9="Critical","Escalate to PM/client now; file critical defect; pause go-live discussion.",IF(D8="Sometimes","File defect with reproduction notes; flag flaky behavior.",IF(D6="Close","Note difference in test row; decide later if defect needed.","File defect; assign owner; schedule retest.")))))) -> Mark Pass; move to next test. | D19: Single concrete next step based on the combination.
A22: How to use this with the Test Case Matrix:
A23: 1) Run one test (TC-### row on Test Case Matrix).
A24: 2) Fill the 6 yellow inputs here.
A25: 3) Read the 5 blue suggestions; record the Pass/Fail on the matrix.
A26: 4) If a defect is needed → open a Defect Log row with the suggested severity and blocker status.
A28: Caveat: this is decision support. PM judgment overrides — especially for 'Conditional' go-live blocker calls.

Sheet Phase4 to Phase5 Handoff
A1: Phase4 to Phase5 Handoff
A2: Transfer the built MVP components and expected behavior from Phase 4.
A4: Build Component | B4: Expected Behavior | C4: Source from Phase4 | D4: Test Priority | E4: Risk Level | F4: Ready for Test? | G4: Notes | H4: Owner
A5: Trigger / Intake | B5: Receives only intended trigger inputs (messages, documents, events, or data records). | C5: Phase4 Module Build Plan | D5: High | E5: Medium
A6: Data Normalization | B6: Maps source input fields into standard format correctly (channel, type, content, timestamp, source_id). | C6: Phase4 Data Map | D6: High | E6: Medium
A7: AI Classifier | B7: Returns valid JSON with category, confidence, reason, action. | C7: Phase4 AI Prompt Config | D7: High | E7: High
A8: Router | B8: Routes each classification to the correct branch. | C8: Phase4 Module Build Plan | D8: High | E8: Medium
A9: CRM / Log | B9: Creates correct record with status and audit fields. | C9: Phase4 Build Backlog | D9: Medium | E9: Medium
A10: Human Approval | B10: Drafts or actions are held for approval where required. | C10: Phase4 Approval Design | D10: High | E10: High
A11: Error Handling | B11: Failed modules create error status and alert owner. | C11: Phase4 Error Build | D11: High | E11: High

Sheet Test Case Matrix
A1: Test Case Matrix
A2: Main testing sheet: define cases, run tests, record evidence, defects, and decisions.
A4: Test ID | B4: Scenario Type | C4: Input Channel | D4: Test Input / Message | E4: Expected Classification | F4: Expected Action | G4: Human Approval Required? | H4: Expected Output / Evidence | I4: Actual Result | J4: Pass/Fail | K4: Defect ID | L4: Severity | M4: Owner | N4: Fix / Retest Notes | O4: Retest Result | P4: Completeness Status (AUTO)
A5: TC-001 | B5: Normal | C5: Website form | D5: Customer asks where to buy product in Switzerland. | E5: LEAD | F5: Create CRM item, move email to Leads, no auto-send. | G5: Yes | H5: CRM item + folder move + audit log | P5: =IF(COUNTA(A5,B5,D5,E5,F5,I5,J5)=0,"Empty",IF(COUNTA(A5,B5,D5,E5,F5,I5,J5)<7,"Partial","Complete")) -> Partial
A6: TC-002 | B6: Out-of-scope | C6: Website form | D6: Distributor request for Bangladesh. | E6: SEEKER | F6: Create SEEKER record, use approved short reply draft or no reply depending policy. | G6: Yes | H6: SEEKER status + audit log | P6: =IF(COUNTA(A6,B6,D6,E6,F6,I6,J6)=0,"Empty",IF(COUNTA(A6,B6,D6,E6,F6,I6,J6)<7,"Partial","Complete")) -> Partial
A7: TC-003 | B7: Spam | C7: Website form | D7: Generic SEO offer with suspicious links. | E7: SPAM | F7: Move to spam-review folder, do not delete. | G7: No | H7: Email moved + audit log | P7: =IF(COUNTA(A7,B7,D7,E7,F7,I7,J7)=0,"Empty",IF(COUNTA(A7,B7,D7,E7,F7,I7,J7)<7,"Partial","Complete")) -> Partial
A8: TC-004 | B8: Sensitive | C8: Gmail | D8: Client asks for personal medical/therapy advice. | E8: SENSITIVE / HUMAN_REVIEW | F8: Escalate to human, no AI advice. | G8: Yes | H8: Human review alert | P8: =IF(COUNTA(A8,B8,D8,E8,F8,I8,J8)=0,"Empty",IF(COUNTA(A8,B8,D8,E8,F8,I8,J8)<7,"Partial","Complete")) -> Partial
A9: TC-005 | B9: Error | C9: Gmail | D9: Force AI API failure or invalid JSON response. | E9: ERROR | F9: Stop action, log error, notify owner. | G9: Yes | H9: Error log + notification | P9: =IF(COUNTA(A9,B9,D9,E9,F9,I9,J9)=0,"Empty",IF(COUNTA(A9,B9,D9,E9,F9,I9,J9)<7,"Partial","Complete")) -> Partial
A10: TC-D01 | B10: Non-normal | C10: Document upload (email attachment) | D10: [Invoice PDF] Supplier: ABC GmbH, CHF 4'850, due 2026-07-15 | E10: INVOICE / EXTRACT | F10: Extract all required fields → validate → log to accounting tool; flag mismatches for review. | G10: Yes | H10: Extracted data logged; mismatch → exception alert sent | L10: Medium | P10: =IF(COUNTA(A10,B10,D10,E10,F10,I10,J10)=0,"Empty",IF(COUNTA(A10,B10,D10,E10,F10,I10,J10)<7,"Partial","Complete")) -> Partial
A11: TC-D02 | B11: Non-normal | C11: Approval request form submission | D11: [Purchase request] CHF 1'200 office equipment — route to manager for approval | E11: APPROVAL_REQUEST | F11: Route to approver → send notification and log; reminder if no response within 24h. | G11: Yes | H11: Notification sent; request logged; reminder scheduled at +24h | L11: Low | P11: =IF(COUNTA(A11,B11,D11,E11,F11,I11,J11)=0,"Empty",IF(COUNTA(A11,B11,D11,E11,F11,I11,J11)<7,"Partial","Complete")) -> Partial
P12: =IF(COUNTA(A12,B12,D12,E12,F12,I12,J12)=0,"Empty",IF(COUNTA(A12,B12,D12,E12,F12,I12,J12)<7,"Partial","Complete")) -> Empty
P13: =IF(COUNTA(A13,B13,D13,E13,F13,I13,J13)=0,"Empty",IF(COUNTA(A13,B13,D13,E13,F13,I13,J13)<7,"Partial","Complete")) -> Empty
P14: =IF(COUNTA(A14,B14,D14,E14,F14,I14,J14)=0,"Empty",IF(COUNTA(A14,B14,D14,E14,F14,I14,J14)<7,"Partial","Complete")) -> Empty
P15: =IF(COUNTA(A15,B15,D15,E15,F15,I15,J15)=0,"Empty",IF(COUNTA(A15,B15,D15,E15,F15,I15,J15)<7,"Partial","Complete")) -> Empty
P16: =IF(COUNTA(A16,B16,D16,E16,F16,I16,J16)=0,"Empty",IF(COUNTA(A16,B16,D16,E16,F16,I16,J16)<7,"Partial","Complete")) -> Empty
P17: =IF(COUNTA(A17,B17,D17,E17,F17,I17,J17)=0,"Empty",IF(COUNTA(A17,B17,D17,E17,F17,I17,J17)<7,"Partial","Complete")) -> Empty
P18: =IF(COUNTA(A18,B18,D18,E18,F18,I18,J18)=0,"Empty",IF(COUNTA(A18,B18,D18,E18,F18,I18,J18)<7,"Partial","Complete")) -> Empty
P19: =IF(COUNTA(A19,B19,D19,E19,F19,I19,J19)=0,"Empty",IF(COUNTA(A19,B19,D19,E19,F19,I19,J19)<7,"Partial","Complete")) -> Empty
P20: =IF(COUNTA(A20,B20,D20,E20,F20,I20,J20)=0,"Empty",IF(COUNTA(A20,B20,D20,E20,F20,I20,J20)<7,"Partial","Complete")) -> Empty
P21: =IF(COUNTA(A21,B21,D21,E21,F21,I21,J21)=0,"Empty",IF(COUNTA(A21,B21,D21,E21,F21,I21,J21)<7,"Partial","Complete")) -> Empty
P22: =IF(COUNTA(A22,B22,D22,E22,F22,I22,J22)=0,"Empty",IF(COUNTA(A22,B22,D22,E22,F22,I22,J22)<7,"Partial","Complete")) -> Empty
P23: =IF(COUNTA(A23,B23,D23,E23,F23,I23,J23)=0,"Empty",IF(COUNTA(A23,B23,D23,E23,F23,I23,J23)<7,"Partial","Complete")) -> Empty
... P60: =IF(COUNTA(A60,B60,D60,E60,F60,I60,J60)=0,"Empty",IF(COUNTA(A60,B60,D60,E60,F60,I60,J60)<7,"Partial","Complete")) -> Empty

Sheet AI Validation
A1: AI Validation
A2: Validate AI behavior separately from workflow execution.
A4: Test ID | B4: Message | C4: Expected Category | D4: AI Category | E4: Confidence | F4: Reason Quality | G4: JSON Valid? | H4: Fallback Triggered? | I4: Hallucination / Unsafe Content? | J4: Decision | K4: Notes
A5: AI-001 | B5: Booking request / product purchase question. | C5: LEAD or BOOKING
A6: AI-002 | B6: Distributor / reseller request outside target country. | C6: SEEKER
A7: AI-003 | B7: Complaint or angry message. | C7: COMPLAINT / HUMAN_REVIEW
A8: AI-004 | B8: Sensitive therapy or medical question. | C8: SENSITIVE / HUMAN_REVIEW
A9: AI-005 | B9: Empty or unclear message. | C9: UNKNOWN / HUMAN_REVIEW
A10: AI-D01 | B10: [Invoice PDF] Supplier ABC GmbH, CHF 4'850, due 2026-07-15 | C10: INVOICE / EXTRACT — fields: supplier, amount, due_date, currency
A11: AI-D02 | B11: Source blog post (800 words) submitted for repurposing to Instagram and LinkedIn | C11: CONTENT_REPURPOSE — drafts per platform; never auto-publish

Sheet Approval Escalation Tests
A1: Approval & Escalation Tests
A2: Validate that human control works where required.
A4: Rule / Case | B4: Expected Behavior | C4: Test Input | D4: Actual Behavior | E4: Pass/Fail | F4: Risk if Failed | G4: Fix Required | H4: Owner
A5: AI draft reply | B5: Draft is created but not sent automatically. | F5: Wrong message may be sent.
A6: Sensitive case | B6: Escalates to human review and no advice is generated. | F6: Client safety/privacy risk.
A7: Complaint | B7: Marked urgent or human review. | F7: Reputation risk.
A8: Low confidence | B8: Routes to Human Review. | F8: Misclassification risk.
A9: Agentic action | B9: No calendar/CRM action without allowed rule and approval. | F9: Uncontrolled action risk.

Sheet Error Monitoring Tests
A1: Error & Monitoring Tests
A2: Validate failure behavior before go-live.
A4: Failure Scenario | B4: Expected Fallback | C4: How to Simulate | D4: Actual Result | E4: Pass/Fail | F4: Alert Sent? | G4: Audit Log Created? | H4: Severity | I4: Fix Notes
A5: AI API unavailable | B5: Stop workflow, no wrong action, notify owner. | C5: Disable key / use test bad endpoint. | H5: High
A6: Invalid AI JSON | B6: Route to error/human review. | C6: Force malformed response. | H6: High
A7: CRM/Notion unavailable | B7: Do not lose message; create error notification. | C7: Disconnect CRM temporarily. | H7: High
A8: Duplicate message | B8: Avoid duplicate CRM item or mark duplicate. | C8: Send same message twice. | H8: Medium
A9: Wrong/empty required field | B9: Human review or error status. | C9: Submit empty email/message. | H9: Medium

Sheet Defect Log
A1: Defect Log
A2: Track all issues found during testing until closed.
A4: Defect ID | B4: Found In Test ID | C4: Description | D4: Severity | E4: Status | F4: Owner | G4: Root Cause | H4: Fix Action | I4: Retest Date | J4: Retest Result | K4: Go-live Blocker?
A5: D-001 | D5: High | E5: Open
A6: D-002 | D6: Medium | E6: Open

Sheet Go No-Go Checklist
A1: Go / No-Go Checklist
A2: Final validation gate before Phase 6 go-live.
A4: Gate | B4: Criteria | C4: Status | D4: Evidence / Notes | E4: Owner
A5: Scope | B5: All MVP in-scope items tested.
A6: Critical Defects | B6: No open critical/high go-live blockers.
A7: AI Safety | B7: Sensitive/low-confidence cases route to human review.
A8: Approval | B8: No risky auto-send or autonomous action without approval.
A9: Error Handling | B9: Errors generate notifications and audit logs.
A10: Security | B10: No exposed API keys or hardcoded secrets.
A11: Client Review | B11: Client reviewed and accepted MVP behavior.
A12: Go-live Decision | B12: GO / NO-GO / GO WITH LIMITATIONS
A32: Go-Live Readiness Summary (auto-computed)
A33: Test cases defined | E33: =COUNTA('Test Case Matrix'!A5:A60) -> 7
A34: Test cases — Pass | E34: =COUNTIF('Test Case Matrix'!J5:J60,"Pass") -> 0
A35: Test cases — Fail | E35: =COUNTIF('Test Case Matrix'!J5:J60,"Fail") -> 0
A36: Test cases — Not Tested | E36: =COUNTIF('Test Case Matrix'!J5:J60,"Not Tested") -> 0
A37: Defects logged | E37: =COUNTA('Defect Log'!A5:A40) -> 2
A38: Defects — Open or In Progress | E38: =COUNTIF('Defect Log'!E5:E40,"Open")+COUNTIF('Defect Log'!E5:E40,"In Progress") -> 2
A39: Defects — Closed / Accepted Risk | E39: =COUNTIF('Defect Log'!E5:E40,"Closed")+COUNTIF('Defect Log'!E5:E40,"Accepted Risk") -> 0
A40: Go-live blockers (col K = Yes) | E40: =COUNTIF('Defect Log'!K5:K40,"Yes") -> 0
A41: Approval/Escalation tests — Pass | E41: =COUNTIF('Approval Escalation Tests'!E5:E40,"Pass") -> 0
A42: Error/Monitoring tests — Pass | E42: =COUNTIF('Error Monitoring Tests'!E5:E40,"Pass") -> 0
A43: Go No-Go gates — Pass | E43: =COUNTIF('Go No-Go Checklist'!C5:C30,"Pass") -> 0

Sheet Lists
A1: PassFail | B1: Severity | C1: Status | D1: RiskLevel | E1: MVPRelevant | F1: Package
A2: Pass | B2: Critical | C2: Open | D2: Low | E2: Yes | F2: Basic
A3: Fail | B3: High | C3: In Progress | D3: Medium | E3: No | F3: Pro
A4: Partial | B4: Medium | C4: Retest | D4: High | E4: Later | F4: Managed
A5: Not Tested | B5: Low | C5: Closed | F5: Agentic
A6: Blocked | C6: Accepted Risk | F6: Mixed
