Workbook

Sheet START HERE
A1: Project Retrospective
A2: Run this within 1-2 weeks of project go-live (or wrap-up). Real ROI emerges after your 3rd-5th retro when patterns become visible: pricing benchmarks, scope-creep triggers, which client signals predict difficult projects, etc.
A4: Recommended workflow
A5: 1. Open the Retrospective sheet. Fill it within 1-2 weeks of project completion. Don't wait — details fade.
A6: 2. Time budget: 30-45 minutes for thorough retro; 15 minutes if quickly.
A7: 3. After filling: copy the summary row into Retrospective Archive (one row per project).
A8: 4. Save this file per project (e.g. "Retro_AcmeCo_2026-11.xlsx") AND maintain a separate "Retros Archive" file aggregating all.
A9: 5. Quarterly: open Patterns at a Glance. Look for recurring themes in "didn't work" and pricing benchmarks.
A11: Why retros matter
A12: Area | B12: Why
A13: Pricing accuracy | B13: After 3-5 retros, you know if you're over/underestimating by package type. Adjust before the next quote.
A14: Scope creep patterns | B14: Specific triggers become visible — e.g. "client always requests additional data sources or channels after blueprint sign-off", "document format scope expands mid-project", "client adds approval steps not agreed in Phase 2". Pre-empt in the next discovery.
A15: Bad-fit signals | B15: Which Fit Check signals correlated with difficult projects? Adjust the fit-check thresholds.
A16: Framework improvements | B16: What was missing? What was awkward? Each retro can spawn 1-2 small improvements to the toolkit.
A17: Client repeat business | B17: Tracking outcome → repeat rate tells you which packages and engagement types build durable client relationships.

Sheet Retrospective
A1: Project Retrospective
A2: One project's worth. Fill in fields below. Yellow = your input. Blue = auto-derived. The summary at the bottom is the row you'll copy into the Archive.
A4: Project metadata
A5: Client name | C5: Full name.
A6: Project name | C6: Internal identifier.
A7: Package delivered | C7: Final package — not the initial guess.
A8: Project start date | C8: YYYY-MM-DD.
A9: Project go-live date | C9: YYYY-MM-DD.
A10: Project duration | C10: Calculated externally or rough estimate.
A11: Final setup price (CHF) | C11: Actual amount invoiced.
A12: Final monthly price (CHF) | C12: If managed service, monthly amount.
A14: Outcome assessment
A15: Overall outcome | C15: Successful = met all goals. Mixed = some goals missed. Difficult = met but with significant friction.
A16: Profitability | C16: Net of all costs including your time at target hourly rate.
A17: Estimation accuracy | C17: Did the actual effort match the quote?
A18: Client relationship outcome | C18: Where does the relationship stand now?
A19: Repeat business potential | C19: Likelihood of more work with this client.
A20: Scope creep observed | C20: Yes/No + brief description if yes.
A22: What worked / what didn't
A23: What worked well (3-5 specific items) | C23: Specific outcomes, decisions, or patterns. Avoid vague 'good communication'.
A24: What didn't work (3-5 specific items) | C24: Specific friction points. Each should be actionable for next time.
A25: What surprised you | C25: Things you didn't expect — positive or negative.
A27: Lessons & forward-looking
A28: Top lesson learned | C28: If you only remember one thing from this project, it's...
A29: Pricing adjustment for similar future projects | C29: Concrete: 'Charge 20% more for Pro packages with sensitive content,' etc.
A30: Framework improvement suggestions | C30: Specific changes to add to the toolkit (helper sheet that would have helped, etc.).
A31: Discovery process changes | C31: Questions to add/remove for next discovery. Often the biggest source of avoidable problems.
A32: Anything to do differently in Phase 1-6 | C32: Phase-specific lessons.
A35: Archive Row (copy these cells to Retrospective Archive)
A36: Copy the values below into a new row in the Retrospective Archive sheet (paste as VALUES, not formulas).
A37: Client name | B37: =B5 -> 0
A38: Project name | B38: =B6 -> 0
A39: Package delivered | B39: =B7 -> 0
A40: Start date | B40: =B8 -> 0
A41: Go-live date | B41: =B9 -> 0
A42: Setup price (CHF) | B42: =B11 -> 0
A43: Monthly price (CHF) | B43: =B12 -> 0
A44: Overall outcome | B44: =B15 -> 0
A45: Profitability | B45: =B16 -> 0
A46: Estimation accuracy | B46: =B17 -> 0
...

Sheet Retrospective Archive
A1: Retrospective Archive
A2: One row per completed project. Append a new row whenever you complete a retrospective. Patterns emerge after 5+ entries.
A4: Client name | B4: Project name | C4: Package | D4: Start date | E4: Go-live date | F4: Setup CHF | G4: Monthly CHF | H4: Outcome | I4: Profitability | J4: Estimation | K4: Relationship | L4: Repeat | M4: Scope creep | N4: Top lesson | O4: Pricing adjustment | P4: Framework improvement

Sheet Patterns at a Glance
A1: Patterns at a Glance (auto-computed from Archive)
A2: Cross-project pattern analysis. Counts from the Retrospective Archive. Most useful after 5+ entries — small samples can mislead.
A4: Project counts
A5: Category | B5: Meaning | C5: Count / Value
A6: Projects completed | B6: Total in archive. | C6: =COUNTA('Retrospective Archive'!A5:A34) -> 0
A8: Outcome distribution
A9: Category | B9: Meaning | C9: Count / Value
A10: Successful | B10: Met all goals. | C10: =COUNTIF('Retrospective Archive'!H5:H34,"Successful") -> 0
A11: Mixed | B11: Some goals missed. | C11: =COUNTIF('Retrospective Archive'!H5:H34,"Mixed") -> 0
A12: Difficult | B12: Met but with friction. | C12: =COUNTIF('Retrospective Archive'!H5:H34,"Difficult") -> 0
A13: Failed | B13: Did not deliver. | C13: =COUNTIF('Retrospective Archive'!H5:H34,"Failed") -> 0
A14: Cancelled | B14: Stopped mid-project. | C14: =COUNTIF('Retrospective Archive'!H5:H34,"Cancelled") -> 0
A16: Profitability
A17: Category | B17: Meaning | C17: Count / Value
A18: Profitable | B18: Net positive. | C18: =COUNTIF('Retrospective Archive'!I5:I34,"Profitable") -> 0
A19: Break-even | B19: No profit, no loss. | C19: =COUNTIF('Retrospective Archive'!I5:I34,"Break-even") -> 0
A20: Loss | B20: Net negative. | C20: =COUNTIF('Retrospective Archive'!I5:I34,"Loss") -> 0
A21: Not yet measured | B21: Pending measurement. | C21: =COUNTIF('Retrospective Archive'!I5:I34,"Not yet measured") -> 0
A23: Estimation accuracy
A24: Category | B24: Meaning | C24: Count / Value
A25: Pricing right | B25: Quote matched effort. | C25: =COUNTIF('Retrospective Archive'!J5:J34,"Pricing right") -> 0
A26: Underestimated (lost money) | B26: Quoted too low. | C26: =COUNTIF('Retrospective Archive'!J5:J34,"Underestimated (lost money)") -> 0
A27: Overestimated (good margin) | B27: Quoted high; healthy margin. | C27: =COUNTIF('Retrospective Archive'!J5:J34,"Overestimated (good margin)") -> 0
A28: Significantly off | B28: Way off either direction. | C28: =COUNTIF('Retrospective Archive'!J5:J34,"Significantly off") -> 0
A30: Client relationship outcomes
A31: Category | B31: Meaning | C31: Count / Value
A32: Strong — active referrer | B32: Sending you leads. | C32: =COUNTIF('Retrospective Archive'!K5:K34,"Strong - active referrer") -> 0
A33: Good — might return | B33: Open to next project. | C33: =COUNTIF('Retrospective Archive'!K5:K34,"Good - might return") -> 0
A34: OK — delivered cleanly | B34: Transactional success. | C34: =COUNTIF('Retrospective Archive'!K5:K34,"OK - delivered cleanly") -> 0
A35: Strained | B35: Tension remains. | C35: =COUNTIF('Retrospective Archive'!K5:K34,"Strained") -> 0
A36: Lost | B36: Won't work with them again. | C36: =COUNTIF('Retrospective Archive'!K5:K34,"Lost") -> 0
A38: Repeat business potential
A39: Category | B39: Meaning | C39: Count / Value
A40: High — already discussing | B40: Next project in flight. | C40: =COUNTIF('Retrospective Archive'!L5:L34,"High - already discussing") -> 0
A41: Possible — good rapport | B41: Possible later. | C41: =COUNTIF('Retrospective Archive'!L5:L34,"Possible - good rapport") -> 0
A42: Unlikely | B42: One and done. | C42: =COUNTIF('Retrospective Archive'!L5:L34,"Unlikely") -> 0
A43: No | B43: Confirmed no repeat. | C43: =COUNTIF('Retrospective Archive'!L5:L34,"No") -> 0
A45: Scope creep frequency
A46: Category | B46: Meaning | C46: Count / Value
A47: No creep | B47: Scope held. | C47: =COUNTIF('Retrospective Archive'!M5:M34,"No") -> 0
...
