Workbook

Sheet START HERE
A1: Phase 3 — Solution Blueprint
A2: Purpose: convert Phase 2 MVP scope into a concrete automation design before building anything in Make, Zapier, n8n, CRM, Gmail, Meta, OpenAI, etc.
A4: Step | B4: What to do | C4: Main sheet
A5: 1 | B5: Copy final MVP decisions from Phase 2. | C5: Phase2 to Phase3 Handoff
A6: 2 | B6: Design the automation flow step-by-step. | C6: Workflow Blueprint
A7: 3 | B7: Define which data fields move through the system. | C7: Data Field Map
A8: 4 | B8: Define routing logic for each classification/category. | C8: Routing Rules
A9: 5 | B9: Choose tools and account ownership. | C9: Tool Stack
A10: 6 | B10: Define human approval, escalation, and safety boundaries. | C10: Approval & Escalation
A11: 7 | B11: Define credentials, access, logging, retention, and privacy rules. | C11: Security & Access
A12: 8 | B12: Define monitoring, errors, retries, and fallback behavior. | C12: Error & Monitoring
A13: 9 | B13: Summarize final blueprint before Phase 4 build. | C13: Final Blueprint Summary
A15: Color logic: Grey = fixed guidance, Green = fill during design workshop, Blue = PM/technical decision, Yellow = warning/boundary notes.
A18: We planned this PM flow:
A20: Phase 1 — Discovery / Analysis
A21: Understand client needs, channels, risks, pain points, possible package direction.
A23: Phase 2 — Scope Definition / MVP Design
A24: Convert discovery answers into a clear first project scope.
A26: Phase 3 — Solution Blueprint
A27: Design workflow logic, tools, data fields, routing, approvals, security.
A29: Phase 4 — MVP Build
A30: Build the first safe automation version.
A32: Phase 5 — Testing / Validation
A33: Test real cases, edge cases, errors, wrong classifications, approvals.
... A40: Workflow Blueprint — by Build Status
A41: Status | B41: Meaning | C41: Count
A42: Draft | B42: Designed but not yet approved. | C42: =COUNTIF('Workflow Blueprint'!K5:K40,"Draft") -> 22
A43: Approved | B43: Approved and ready for build. | C43: =COUNTIF('Workflow Blueprint'!K5:K40,"Approved") -> 0
A44: Later | B44: Deferred to a later phase. | C44: =COUNTIF('Workflow Blueprint'!K5:K40,"Later") -> 0
A45: Blocked | B45: Blocked — needs resolution. | C45: =COUNTIF('Workflow Blueprint'!K5:K40,"Blocked") -> 0
A46: Done | B46: Build complete. | C46: =COUNTIF('Workflow Blueprint'!K5:K40,"Done") -> 0
A48: Workflow Blueprint — by Completeness (col L)
A49: Status | B49: Meaning | C49: Count
A50: Empty | B50: No fields filled. | C50: =COUNTIF('Workflow Blueprint'!L5:L40,"Empty") -> 14
A51: Partial | B51: Some required fields still missing. | C51: =COUNTIF('Workflow Blueprint'!L5:L40,"Partial") -> 0
A52: Complete | B52: All required fields filled. | C52: =COUNTIF('Workflow Blueprint'!L5:L40,"Complete") -> 22
A54: Security & Access — Required Before Build
A55: Status | B55: Meaning | C55: Count
A56: Yes | B56: Decision finalized. | C56: =COUNTIF('Security & Access'!F5:F40,"Yes") -> 7
A57: No | B57: Not required to lock before build. | C57: =COUNTIF('Security & Access'!F5:F40,"No") -> 0
...

Sheet Workflow Step Designer
A1: Workflow Step Designer — one step at a time
A2: Use this when designing a single workflow step on the Workflow Blueprint and you're unsure about automation type, tool, approval rule, or risk. Fill the 6 yellow inputs; the blue cells suggest the design choices. PM judgment still final.
A4: INPUTS — about this one step
A5: # | B5: Question | C5: Allowed values | D5: Answer
A6: Q1 | B6: Q1. Step purpose | C6: Intake / Normalize / Classify / Route / Log / Draft reply / Send / Escalate / Monitor / Extract / Validate / Enrich / Generate content / Publish / Approve / Other | D6: Classify
A7: Q2 | B7: Q2. Involves sensitive data? (health/legal/financial/emotional) | C7: Yes / No / Sometimes | D7: No
A8: Q3 | B8: Q3. Consequence if this step fails or acts wrongly | C8: Low (annoyance) / Medium (lost lead) / High (legal/trust) | D8: Medium
A9: Q4 | B9: Q4. AI involvement in this step | C9: None / Classify only / Generate content / Take action | D9: Classify only
A10: Q5 | B10: Q5. Reversibility of the action | C10: Reversible / One-way (cannot undo) | D10: Reversible
A11: Q6 | B11: Q6. Expected volume / frequency | C11: Low / Medium / High | D11: Medium
A13: SUGGESTED DESIGN (auto-calculated)
A14: # | B14: Indicator | C14: Suggested Value (formula) | D14: Reasoning hint
A15: O1 | B15: Suggested Automation Type | C15: =IF(D6="Monitor","Managed",IF(D9="None","Traditional",IF(D9="Take action","Agentic","AI"))) -> AI | D15: Take action → Agentic; Monitor → Managed; None → Traditional; otherwise AI.
A16: O2 | B16: Suggested Tool Family | C16: =IF(D6="Intake","Webhook / Gmail / Form connector",IF(D6="Normalize","Data formatter (Make tools / parser)",IF(D6="Classify","AI API (OpenAI / Anthropic / Make AI)",IF(D6="Route","Router module (Make / n8n)",IF(D6="Log","CRM (Notion / Airtable / HubSpot)",IF(D6="Draft reply","AI API + Gmail/CRM draft module",IF(D6="Send","Email / Messaging connector",IF(D6="Escalate","Notification (Email / Slack / SMS)",IF(D6="Monitor","Logger + dashboard / audit log",IF(D6="Extract","AI API (document parser / OCR / field extractor)",IF(D6="Validate","Validation module (Make / n8n / custom rule logic)",IF(D6="Enrich","CRM + AI API (data enrichment / lookup)",IF(D6="Generate content","AI API (OpenAI / Anthropic / Make AI)",IF(D6="Publish","CMS / Social / Newsletter connector (scheduling tool)",IF(D6="Approve","Approval workflow (email / Slack / CRM status gate)","PM to define"))))))))))))))) -> AI API (OpenAI / Anthropic / Make AI) | D16: Lookup by step purpose. Names match the Tool Stack sheet conventions.
A17: O3 | B17: Suggested Approval Rule | C17: =IF(OR(D7="Yes",D8="High",D10="One-way"),"Always (every action approved)",IF(D9="None","Not required",IF(OR(D6="Send",D6="Escalate"),"Required (human approves before send)",IF(D9="Take action","Always (every action approved)",IF(D9="Classify only","Optional (review when confidence low)","Required (human reviews drafts)"))))) -> Optional (review when confidence low) | D17: Sensitive / High consequence / One-way → Always. Send/Escalate → Required.
A18: O4 | B18: Risk Level | C18: =IF(OR(D7="Yes",D8="High"),"High",IF(AND(D10="One-way",D9<>"None"),"High",IF(OR(D8="Medium",D9="Take action"),"Medium","Low"))) -> Medium | D18: Sensitive or High-consequence elevate. One-way + AI = High.
A19: O5 | B19: Top Boundary Note | C19: =IF(AND(D7="Yes",D9="Generate content"),"Sensitive + AI content: human approval mandatory; no AI advice.",IF(AND(D10="One-way",D9="Take action"),"Irreversible AI action: require allow-list + audit log + kill-switch.",IF(D6="Publish","Publishing step: human approval required before any content goes live; log post ID and timestamp.",IF(D6="Extract","Extraction step: validate all required fields before downstream write; error route mandatory.",IF(D6="Approve","Approval step: define timeout rule — what happens if approver does not respond in time?",IF(D7="Yes","Sensitive route: classify + escalate only; never auto-act.",IF(AND(D11="High",D9<>"None"),"High volume + AI: add rate limit + cost monitor + fallback to human.",IF(D6="Monitor","Log run_id, status, error; alert on silent failures.","Standard: log inputs and outputs; fall back to Human Review on uncertainty.")))))))) -> Standard: log inputs and outputs; fall back to Human Review on uncertainty. | D19: The single biggest caution to record in the Workflow Blueprint Risk/Boundary column.
A22: How to use this with the Workflow Blueprint:
A23: 1) Fill the 6 yellow inputs for ONE step you're designing.
A24: 2) Read the 5 blue suggestions.
A25: 3) Transfer the values into the matching row of Workflow Blueprint (Automation Type → col E; Tool → col D; Approval → col H; Risk → col J).
A26: 4) Use Routing Rules + Approval & Escalation sheets for category-level rules afterwards.
A28: Caveat: this is decision support. Local context (client constraints, existing tools, contractual scope) overrides whenever it changes the picture.

Sheet Phase2 to Phase3 Handoff
A1: Phase 2 → Phase 3 Handoff
A2: Use this sheet to transfer the final MVP scope and decisions into the blueprint design phase.
A4: Item | B4: Phase 2 Decision / Input (EDIT) | C4: Blueprint Impact (POST) | D4: Open Question | E4: Owner | F4: Status
A5: MVP goal | B5: Classify Gmail + website inquiries, route them, log in CRM, prepare human-approved drafts. | C5: Determines core workflow modules. | E5: PM | F5: Draft
A6: Included channels | B6: Gmail, website form | C6: Only these channels designed in MVP workflow. | E6: PM | F6: Draft
A7: Excluded / later channels | B7: Instagram later | C7: Do not build Meta API in Phase 4 MVP. | D7: Check API feasibility later. | E7: PM | F7: Later
A8: Included categories | B8: Booking, price question, lead, spam, complaint | C8: Routing rules needed for each category. | E8: PM | F8: Draft
A9: Human approval rule | B9: All replies require approval. | C9: Draft only; no automatic send module. | E9: PM | F9: Draft
A10: Risk boundary | B10: Sensitive content escalated; AI gives no advice. | C10: Escalation route + safety prompt needed. | E10: PM | F10: Draft
A11: Package direction | B11: Basic / Pro mix | C11: Simple build with AI classification and drafts. | E11: PM | F11: Draft

Sheet Workflow Blueprint
A1: Workflow Blueprint
A2: Design the exact automation flow. This is the main Phase 3 working sheet.
A4: Step No. | B4: Process Step | C4: Trigger / Input | D4: Tool / Module Candidate | E4: Traditional / AI / Agentic | F4: Action Logic | G4: Data Used / Created | H4: Human Control | I4: Output | J4: Risk / Boundary | K4: Build Status | L4: Completeness Status (AUTO)
A5: 1 | B5: Receive inquiry | C5: Website form submitted or email received | D5: Webhook / Gmail / IMAP | E5: Traditional | F5: Capture message and metadata. | G5: sender, subject, message, timestamp, message_id | H5: None | I5: Normalized inquiry object | J5: Do not lose original message. | K5: Draft | L5: =IF(COUNTA(B5,C5,D5,E5,F5,I5,K5)=0,"Empty",IF(COUNTA(B5,C5,D5,E5,F5,I5,K5)<7,"Partial","Complete")) -> Complete
A6: 2 | B6: Normalize data | C6: Raw email/form payload | D6: Make tools / formatter | E6: Traditional | F6: Map fields into standard format. | G6: channel, sender, content, source_id | H6: None | I6: Clean input object | J6: Missing fields go to error route. | K6: Draft | L6: =IF(COUNTA(B6,C6,D6,E6,F6,I6,K6)=0,"Empty",IF(COUNTA(B6,C6,D6,E6,F6,I6,K6)<7,"Partial","Complete")) -> Complete
A7: 3 | B7: Classify message | C7: Normalized inquiry | D7: OpenAI / Make AI tools | E7: AI | F7: Classify into approved taxonomy with confidence and reason. | G7: classification, confidence, urgency | H7: Review if low confidence. | I7: Classification JSON | J7: No advice; classify only. | K7: Draft | L7: =IF(COUNTA(B7,C7,D7,E7,F7,I7,K7)=0,"Empty",IF(COUNTA(B7,C7,D7,E7,F7,I7,K7)<7,"Partial","Complete")) -> Complete
A8: 4 | B8: Route by category | C8: Classification result | D8: Router | E8: Traditional | F8: Send message to matching route. | G8: classification, urgency | H8: Human review for sensitive cases. | I8: Selected route | J8: Unknown category goes to Human Review. | K8: Draft | L8: =IF(COUNTA(B8,C8,D8,E8,F8,I8,K8)=0,"Empty",IF(COUNTA(B8,C8,D8,E8,F8,I8,K8)<7,"Partial","Complete")) -> Complete
A9: 5 | B9: Log in CRM | C9: Routed inquiry | D9: Notion/Airtable/HubSpot | E9: Traditional | F9: Create or update record. | G9: all key fields + status | H9: Owner assigned | I9: CRM record | J9: Store minimum needed data. | K9: Draft | L9: =IF(COUNTA(B9,C9,D9,E9,F9,I9,K9)=0,"Empty",IF(COUNTA(B9,C9,D9,E9,F9,I9,K9)<7,"Partial","Complete")) -> Complete
A10: 6 | B10: Prepare draft reply | C10: Safe categories only | D10: OpenAI / Gmail draft | E10: AI | F10: Generate short reply draft from approved rules/FAQ. | G10: message, category, business rules | H10: Human approval required | I10: Draft email/message | J10: No automatic sending in MVP. | K10: Draft | L10: =IF(COUNTA(B10,C10,D10,E10,F10,I10,K10)=0,"Empty",IF(COUNTA(B10,C10,D10,E10,F10,I10,K10)<7,"Partial","Complete")) -> Complete
A11: 7 | B11: Escalate sensitive/urgent | C11: Urgency or sensitive flag | D11: Email/Slack/SMS notification | E11: Traditional | F11: Notify owner immediately. | G11: classification, reason, source link | H11: Human must handle | I11: Escalation notification | J11: No AI advice. | K11: Draft | L11: =IF(COUNTA(B11,C11,D11,E11,F11,I11,K11)=0,"Empty",IF(COUNTA(B11,C11,D11,E11,F11,I11,K11)<7,"Partial","Complete")) -> Complete
A12: 8 | B12: Monitor result | C12: Scenario completed or failed | D12: Make logs / audit table | E12: Managed | F12: Write action log and notify on errors. | G12: run_id, status, error | H12: PM/service owner checks | I12: Audit record | J12: No silent failures. | K12: Draft | L12: =IF(COUNTA(B12,C12,D12,E12,F12,I12,K12)=0,"Empty",IF(COUNTA(B12,C12,D12,E12,F12,I12,K12)<7,"Partial","Complete")) -> Complete
B13: [Doc Processing] Receive document | C13: Document arrives by email or upload (PDF / form / attachment) | D13: Email connector / file handler / webhook | E13: Traditional | F13: Capture document and sender metadata; store original unmodified. | G13: document_id, sender, filename, format, received_at | H13: None | I13: Raw document object with metadata | J13: Preserve original; do not transform before extraction step. | K13: Draft | L13: =IF(COUNTA(B13,C13,D13,E13,F13,I13,K13)=0,"Empty",IF(COUNTA(B13,C13,D13,E13,F13,I13,K13)<7,"Partial","Complete")) -> Complete
B14: [Doc Processing] Extract structured fields | C14: Raw document (PDF / image / form) | D14: AI API (document parser / OCR / field extractor) | E14: AI | F14: Extract defined fields (e.g., invoice total, date, supplier name, line items). | G14: extracted_fields, confidence_score, document_id | H14: Flag low-confidence extractions for human review. | I14: Structured data object | J14: Define expected fields before build; mandatory error route for missing required fields. | K14: Draft | L14: =IF(COUNTA(B14,C14,D14,E14,F14,I14,K14)=0,"Empty",IF(COUNTA(B14,C14,D14,E14,F14,I14,K14)<7,"Partial","Complete")) -> Complete
B15: [Doc Processing] Validate extracted data | C15: Structured data object from extraction step | D15: Validation module (Make / n8n / custom rule logic) | E15: Traditional | F15: Check required fields present, format valid, values within expected range. | G15: validation_result, error_list, document_id | H15: Human review required for all validation failures. | I15: Validated record or flagged exception | J15: Never post a failed record to downstream system without human confirmation. | K15: Draft | L15: =IF(COUNTA(B15,C15,D15,E15,F15,I15,K15)=0,"Empty",IF(COUNTA(B15,C15,D15,E15,F15,I15,K15)<7,"Partial","Complete")) -> Complete
B16: [Doc Processing] Log to destination system | C16: Validated record | D16: CRM / Spreadsheet / Accounting connector | E16: Traditional | F16: Write confirmed record to target system; update status. | G16: all extracted fields, validation_status, write_timestamp | H16: Human confirms before posting financial data. | I16: Logged entry in target system | J16: Confirm before any financial write; log write result for audit. | K16: Draft | L16: =IF(COUNTA(B16,C16,D16,E16,F16,I16,K16)=0,"Empty",IF(COUNTA(B16,C16,D16,E16,F16,I16,K16)<7,"Partial","Complete")) -> Complete
B17: [Doc Processing] Notify on exceptions | C17: Validation failure or extraction error | D17: Email / Slack notification | E17: Traditional | F17: Alert owner of failed extractions, missing fields, or data mismatches. | G17: document_id, error_list, exception_type, sender | H17: Human must resolve all exceptions before data is used. | I17: Exception notification sent | J17: No silent failures; every exception logged and notified. | K17: Draft | L17: =IF(COUNTA(B17,C17,D17,E17,F17,I17,K17)=0,"Empty",IF(COUNTA(B17,C17,D17,E17,F17,I17,K17)<7,"Partial","Complete")) -> Complete
B18: [Content & Mktg] Receive source content | C18: Client submits long-form post, article, or raw transcript | D18: Email / form / shared drive connector | E18: Traditional | F18: Capture source text and context (platform targets, tone guide reference). | G18: source_text, target_platforms, tone_guide_ref, content_id | H18: None | I18: Source content object | J18: Validate source content is present and non-empty before triggering AI steps. | K18: Draft | L18: =IF(COUNTA(B18,C18,D18,E18,F18,I18,K18)=0,"Empty",IF(COUNTA(B18,C18,D18,E18,F18,I18,K18)<7,"Partial","Complete")) -> Complete
B19: [Content & Mktg] Generate platform-specific drafts | C19: Source content object + tone guide | D19: AI API (OpenAI / Anthropic / Make AI) | E19: AI | F19: Generate adapted draft for each target platform respecting character limits and tone guide. | G19: source_text, platform, tone_guide, character_limits, content_id | H19: Human reviews all drafts before any publishing action. | I19: Draft posts per platform | J19: No auto-publish; generate only; human must approve every post before it goes live. | K19: Draft | L19: =IF(COUNTA(B19,C19,D19,E19,F19,I19,K19)=0,"Empty",IF(COUNTA(B19,C19,D19,E19,F19,I19,K19)<7,"Partial","Complete")) -> Complete
B20: [Content & Mktg] Human review and approval | C20: Draft posts per platform | D20: CRM / email draft / approval channel | E20: Traditional | F20: Present drafts to owner for review; record approval or edit request per draft. | G20: draft_id, review_status, reviewer, edited_content | H20: Owner must explicitly approve or reject each draft before proceeding. | I20: Approval decision per draft | J20: Never proceed to publish without explicit approval; track rejection reasons. | K20: Draft | L20: =IF(COUNTA(B20,C20,D20,E20,F20,I20,K20)=0,"Empty",IF(COUNTA(B20,C20,D20,E20,F20,I20,K20)<7,"Partial","Complete")) -> Complete
B21: [Content & Mktg] Publish approved content | C21: Approved draft + scheduling metadata | D21: CMS / Social / Newsletter connector (scheduling tool) | E21: Traditional | F21: Publish or schedule approved content to target platform at specified time. | G21: draft_id, platform, scheduled_at, published_at | H21: Post-publish confirmation recommended. | I21: Published post reference | J21: Log post ID and timestamp; alert immediately on publish failure. | K21: Draft | L21: =IF(COUNTA(B21,C21,D21,E21,F21,I21,K21)=0,"Empty",IF(COUNTA(B21,C21,D21,E21,F21,I21,K21)<7,"Partial","Complete")) -> Complete
B22: [Content & Mktg] Log to content calendar | C22: Published post reference | D22: CRM / Spreadsheet / Content calendar tool | E22: Traditional | F22: Record published content in content calendar with full metadata. | G22: post_id, platform, published_at, topic, status, content_id | H22: None | I22: Content calendar entry | J22: Maintain complete audit trail for all published content. | K22: Draft | L22: =IF(COUNTA(B22,C22,D22,E22,F22,I22,K22)=0,"Empty",IF(COUNTA(B22,C22,D22,E22,F22,I22,K22)<7,"Partial","Complete")) -> Complete
B23: [Finance & Admin] Trigger from accounting data source | C23: Scheduled export from accounting tool (Bexio / Banana / CSV file) | D23: Email / file connector / API polling | E23: Traditional | F23: Receive periodic data export; parse overdue or pending records. | G23: export_date, record_id, amount, due_date, client_ref, status | H23: None | I23: Parsed record list | J23: Validate file format and expected fields before processing; reject malformed exports. | K23: Draft | L23: =IF(COUNTA(B23,C23,D23,E23,F23,I23,K23)=0,"Empty",IF(COUNTA(B23,C23,D23,E23,F23,I23,K23)<7,"Partial","Complete")) -> Complete
B24: [Finance & Admin] Identify actionable records | C24: Parsed record list | D24: Filter / router module (Make / n8n) | E24: Traditional | F24: Apply business rules to flag overdue invoices, missing data, or exception conditions. | G24: record_id, days_overdue, exception_type, action_required | H24: PM reviews and approves rule set before automation runs. | I24: Filtered action list | J24: Business rules must be approved before automation runs; define edge cases explicitly. | K24: Draft | L24: =IF(COUNTA(B24,C24,D24,E24,F24,I24,K24)=0,"Empty",IF(COUNTA(B24,C24,D24,E24,F24,I24,K24)<7,"Partial","Complete")) -> Complete
... B26: [Finance & Admin] Log action and result | C26: Reminder sent or exception flagged | D26: CRM / Spreadsheet / Audit log connector | E26: Traditional | F26: Record action taken, result, and any follow-up required. | G26: record_id, action_taken, result, timestamp, follow_up_needed | H26: None | I26: Audit log entry | J26: Maintain complete record of all finance-related automation actions. | K26: Draft | L26: =IF(COUNTA(B26,C26,D26,E26,F26,I26,K26)=0,"Empty",IF(COUNTA(B26,C26,D26,E26,F26,I26,K26)<7,"Partial","Complete")) -> Complete
L27: =IF(COUNTA(B27,C27,D27,E27,F27,I27,K27)=0,"Empty",IF(COUNTA(B27,C27,D27,E27,F27,I27,K27)<7,"Partial","Complete")) -> Empty
L28: =IF(COUNTA(B28,C28,D28,E28,F28,I28,K28)=0,"Empty",IF(COUNTA(B28,C28,D28,E28,F28,I28,K28)<7,"Partial","Complete")) -> Empty
L29: =IF(COUNTA(B29,C29,D29,E29,F29,I29,K29)=0,"Empty",IF(COUNTA(B29,C29,D29,E29,F29,I29,K29)<7,"Partial","Complete")) -> Empty
L30: =IF(COUNTA(B30,C30,D30,E30,F30,I30,K30)=0,"Empty",IF(COUNTA(B30,C30,D30,E30,F30,I30,K30)<7,"Partial","Complete")) -> Empty
L31: =IF(COUNTA(B31,C31,D31,E31,F31,I31,K31)=0,"Empty",IF(COUNTA(B31,C31,D31,E31,F31,I31,K31)<7,"Partial","Complete")) -> Empty
L32: =IF(COUNTA(B32,C32,D32,E32,F32,I32,K32)=0,"Empty",IF(COUNTA(B32,C32,D32,E32,F32,I32,K32)<7,"Partial","Complete")) -> Empty
L33: =IF(COUNTA(B33,C33,D33,E33,F33,I33,K33)=0,"Empty",IF(COUNTA(B33,C33,D33,E33,F33,I33,K33)<7,"Partial","Complete")) -> Empty
L34: =IF(COUNTA(B34,C34,D34,E34,F34,I34,K34)=0,"Empty",IF(COUNTA(B34,C34,D34,E34,F34,I34,K34)<7,"Partial","Complete")) -> Empty
L35: =IF(COUNTA(B35,C35,D35,E35,F35,I35,K35)=0,"Empty",IF(COUNTA(B35,C35,D35,E35,F35,I35,K35)<7,"Partial","Complete")) -> Empty
L36: =IF(COUNTA(B36,C36,D36,E36,F36,I36,K36)=0,"Empty",IF(COUNTA(B36,C36,D36,E36,F36,I36,K36)<7,"Partial","Complete")) -> Empty
L37: =IF(COUNTA(B37,C37,D37,E37,F37,I37,K37)=0,"Empty",IF(COUNTA(B37,C37,D37,E37,F37,I37,K37)<7,"Partial","Complete")) -> Empty
L38: =IF(COUNTA(B38,C38,D38,E38,F38,I38,K38)=0,"Empty",IF(COUNTA(B38,C38,D38,E38,F38,I38,K38)<7,"Partial","Complete")) -> Empty
... L40: =IF(COUNTA(B40,C40,D40,E40,F40,I40,K40)=0,"Empty",IF(COUNTA(B40,C40,D40,E40,F40,I40,K40)<7,"Partial","Complete")) -> Empty

Sheet Data Field Map
A1: Data Field Map
A2: Define the fields that must be captured, created, transformed, stored, or passed to tools.
A4: Field Name | B4: Source | C4: Example Value | D4: Required? | E4: Used By | F4: Stored Where | G4: Retention / Privacy Note | H4: Owner / Decision
A5: source_channel | B5: Webhook/Gmail | C5: gmail / website_form | D5: Yes | E5: Routing, CRM, reports | F5: CRM + audit log | G5: Non-sensitive operational field.
A6: source_message_id | B6: Gmail/Form | C6: email UID or form submission ID | D6: Yes | E6: Correlation, audit, deduplication | F6: CRM + audit log | G6: Important to avoid moving wrong email.
A7: sender_name | B7: Message payload | C7: Anna Müller | D7: Optional | E7: CRM, draft reply | F7: CRM | G7: Personal data; store only if needed.
A8: sender_email | B8: Message payload | C8: anna@example.com | D8: Yes for email | E8: Reply, CRM | F8: CRM | G8: Personal data; limit access.
A9: subject | B9: Email/form | C9: Booking request | D9: Optional | E9: Classification, CRM | F9: CRM | G9: May contain personal data.
A10: message_body | B10: Email/form | C10: I would like to book... | D10: Yes | E10: Classification, draft | F10: CRM or limited log | G10: Potentially sensitive; define retention.
A11: classification | B11: AI output | C11: BOOKING_REQUEST | D11: Yes | E11: Router, reports | F11: CRM + audit log | G11: Internal processing field.
A12: confidence | B12: AI output | C12: 0.87 | D12: Yes | E12: Fallback rule | F12: CRM + audit log | G12: Use threshold for review.
A13: urgency | B13: AI output/rules | C13: normal / urgent | D13: Yes | E13: Escalation | F13: CRM + audit log | G13: Urgent must notify human.
A14: status | B14: Workflow | C14: Pending Approval | D14: Yes | E14: CRM workflow | F14: CRM | G14: Operational status.

Sheet Routing Rules
A1: Routing Rules
A2: Define what happens to each category/classification.
A4: Category | B4: Definition | C4: Example Message | D4: Allowed Automation | E4: Human Approval? | F4: Destination / Status | G4: Auto Reply Allowed? | H4: Fallback Rule | I4: Notes
A5: BOOKING_REQUEST | B5: User wants to book appointment/service. | C5: Do you have free time next week? | D5: Classify + draft reply + create CRM item | E5: Yes | F5: Pending Approval | G5: No in MVP | H5: If unclear → Human Review
A6: PRICE_QUESTION | B6: User asks price/cost/package. | C6: How much does it cost? | D6: Classify + draft approved FAQ reply | E6: Yes | F6: Pending Approval | G6: No in MVP | H6: If service unclear → Human Review
A7: LEAD | B7: Potential business opportunity/customer. | C7: I want to buy/use your service. | D7: Classify + CRM item + notify owner | E7: Yes | F7: Lead Review | G7: No in MVP | H7: If uncertain → Human Review
A8: COMPLAINT | B8: Negative feedback or issue. | C8: I am not satisfied... | D8: Classify + escalate | E8: Yes | F8: Escalated | G8: No | H8: Always human
A9: SENSITIVE | B9: Health/legal/financial/private issue. | C9: I feel very bad and need advice... | D9: Classify + urgent/human route only | E9: Yes | F9: Human Review / Urgent | G9: No | H9: No AI advice
A10: SPAM | B10: Marketing, scam, irrelevant. | C10: Buy followers now | D10: Classify + move to spam-review | E10: No, but review initially | F10: Spam Review | G10: No | H10: Never delete in MVP
A11: TEST | B11: Internal testing. | C11: test message | D11: Classify + move test folder | E11: No | F11: Test | G11: No | H11: Keep test log

Sheet Tool Stack
A1: Tool Stack
A2: Define tools, ownership, credentials, and purpose. This supports safe implementation in Phase 4.
A4: Function | B4: Preferred Tool | C4: Alternative Tool | D4: Account Owner | E4: Credential Storage | F4: Used For | G4: MVP Required? | H4: Risk / Note
A5: Workflow orchestration | B5: Make.com | C5: n8n / Zapier | D5: You or client workspace | E5: Make connections/keychain | F5: Scenario logic | G5: Yes | H5: Avoid hardcoded secrets.
A6: Email intake | B6: Gmail / IMAP | C6: Outlook | D6: Client | E6: OAuth/IMAP connection | F6: Receive and route emails | G6: Yes | H6: Client should own mailbox.
A7: Website form intake | B7: Webhook | C7: Form plugin | D7: Client/site owner | E7: Webhook URL | F7: Receive form submissions | G7: Yes | H7: Use correlation ID.
A8: AI classification | B8: OpenAI | C8: Make AI / Anthropic | D8: You/service account or client | E8: Connection/secret, not raw header | F8: Classify and draft | G8: Yes | H8: Rotate exposed keys.
A9: CRM/logging | B9: Notion | C9: Airtable / HubSpot | D9: Client or shared workspace | E9: OAuth connection | F9: Track inquiries | G9: Yes | H9: Access control needed.
A10: Booking | B10: Calendly / Google Calendar | C10: Acuity | D10: Client | E10: OAuth connection | F10: Booking link/slots | G10: Later/Maybe | H10: Agentic actions need approval.
A11: Notifications | B11: Email / Slack | C11: Telegram | D11: Client/team | E11: Connection | F11: Escalations/errors | G11: Yes | H11: Urgent route must work.

Sheet Approval & Escalation
A1: Approval & Escalation
A2: Define where human control is mandatory and how escalations are handled.
A4: Situation | B4: AI Allowed? | C4: Draft Allowed? | D4: Auto-send Allowed? | E4: Human Owner | F4: Approval Channel | G4: Escalation Time | H4: Final Rule
A5: Normal booking request | B5: Yes, classify | C5: Yes | D5: No in MVP | E5: Business owner | F5: CRM/Gmail draft | G5: Same day | H5: Human approves before send.
A6: Price/FAQ question | B6: Yes, classify | C6: Yes, from approved FAQ | D6: No in MVP | E6: Business owner | F6: CRM/Gmail draft | G6: Same day | H6: Human approves before send.
A7: Complaint | B7: Classification only | C7: No or very limited | D7: No | E7: Business owner | F7: Email/phone alert | G7: Immediate/priority | H7: Human handles.
A8: Sensitive personal content | B8: Classification only | C8: No advice | D8: No | E8: Business owner | F8: Urgent alert | G8: Immediate | H8: Escalate; no AI advice.
A9: Low confidence classification | B9: Yes | C9: No until reviewed | D9: No | E9: Business owner/PM | F9: Human Review queue | G9: Next review cycle | H9: Fallback to human review.
A10: Automation error | B10: No | C10: No | D10: No | E10: Service owner | F10: Error notification | G10: Immediate/next business hour | H10: Stop risky action; log error.

Sheet Security & Access
A1: Security & Access
A2: Define access, credentials, privacy, logging, and retention before build.
A4: Control Area | B4: Design Decision | C4: Recommended Rule | D4: Client Decision / Notes (EDIT) | E4: Risk Level | F4: Required Before Build?
A5: API keys | B5: No hardcoded keys in scenarios/exports. | C5: Use Make connections/keychain or secure backend. | E5: High | F5: Yes
A6: Client accounts | B6: Client owns Gmail, calendar, social accounts. | C6: Use granted access/OAuth where possible. | E6: High | F6: Yes
A7: Scenario access | B7: Limit who can edit production scenarios. | C7: Only service owner/admins. | E7: Medium | F7: Yes
A8: Data minimization | B8: Store only necessary fields. | C8: Avoid storing sensitive message body unless needed. | E8: High | F8: Yes
A9: Retention | B9: Define how long logs/messages stay in CRM. | C9: Set client-specific retention rule. | E9: Medium | F9: Yes
A10: Exports | B10: Do not export/share blueprints with secrets. | C10: Sanitize before sharing. | E10: High | F10: Yes
A11: Audit log | B11: Track actions taken by automation. | C11: Write run_id, action, status, error. | E11: Medium | F11: Yes

Sheet Error & Monitoring
A1: Error & Monitoring
A2: Design fallback behavior so automation does not fail silently or take wrong action.
A4: Failure / Edge Case | B4: Detection Method | C4: Fallback Action | D4: Notify Whom? | E4: Log What? | F4: Severity | G4: Build Requirement
A5: AI API error | B5: HTTP error / timeout | C5: Send item to Human Review; retry if safe | D5: Service owner | E5: run_id, payload id, error | F5: High | G5: Error route
A6: Invalid JSON from AI | B6: Parse error | C6: Human Review; do not route automatically | D6: Service owner | E6: raw response + message id | F6: High | G6: JSON validation
A7: Low confidence | B7: confidence < threshold | C7: Human Review | D7: Business owner | E7: classification + confidence | F7: Medium | G7: Threshold rule
A8: Unknown category | B8: classification not in list | C8: Human Review | D8: Service owner | E8: category returned | F8: Medium | G8: Validation list
A9: Duplicate message | B9: same source_message_id | C9: Skip or update existing record | D9: None unless repeated | E9: dedupe decision | F9: Medium | G9: Correlation ID
A10: CRM write failure | B10: API error | C10: Retry; email notification | D10: Service owner | E10: record fields + error | F10: High | G10: Retry/error route
A11: Email move failure | B11: module error | C11: Do not mark complete; notify | D11: Service owner | E11: email id + destination | F11: Medium | G11: Error route

Sheet Final Blueprint Summary
A1: Final Phase 3 Blueprint Summary
A2: Complete this before starting Phase 4 build.
A4: Section | B4: Final Decision / Summary (EDIT) | C4: Open Issue | D4: Approved?
A5: Workflow goal | D5: No
A6: Included channels | D6: No
A7: Core automation steps | D7: No
A8: Classification taxonomy | D8: No
A9: Routing rules | D9: No
A10: CRM/logging design | D10: No
A11: Human approval rules | D11: No
A12: Security/access decisions | D12: No
A13: Error/fallback handling | D13: No
A14: Ready for Phase 4 build? | D14: No
A32: Blueprint at a Glance (auto-computed)
A33: Workflow steps designed | D33: =COUNTA('Workflow Blueprint'!B5:B40) -> 22
A34: Workflow steps — Approved | D34: =COUNTIF('Workflow Blueprint'!K5:K40,"Approved") -> 0
A35: Workflow steps — Done | D35: =COUNTIF('Workflow Blueprint'!K5:K40,"Done") -> 0
A36: Data fields mapped | D36: =COUNTA('Data Field Map'!A5:A50) -> 10
A37: Routing categories defined | D37: =COUNTA('Routing Rules'!A5:A50) -> 7
A38: Tools selected as MVP-required | D38: =COUNTIF('Tool Stack'!G5:G40,"Yes") -> 6
A39: Tools deferred (Later/Maybe) | D39: =COUNTIF('Tool Stack'!G5:G40,"Later")+COUNTIF('Tool Stack'!G5:G40,"Maybe") -> 0
A40: Approval rules defined | D40: =COUNTA('Approval & Escalation'!A5:A40) -> 6
A41: Security controls — locked (Required=Yes) | D41: =COUNTIF('Security & Access'!F5:F40,"Yes") -> 7
A42: Error cases handled | D42: =COUNTA('Error & Monitoring'!A5:A40) -> 7
A43: Total summary sections approved | D43: =COUNTIF('Final Blueprint Summary'!D5:D30,"Yes") -> 0

Sheet Lists
A1: Dropdown Lists
A2: Internal lists used for consistent wording.
A4: MVP Required? | B4: Yes
B5: No
B6: Later
B7: Maybe
A8: Status | B8: Draft
B9: Approved
B10: Later
B11: Blocked
B12: Done
A13: Risk Level | B13: Low
B14: Medium
B15: High
A16: Automation Type | B16: Traditional
B17: AI
B18: Managed
B19: Agentic
A20: Package | B20: Basic
B21: Pro
B22: Managed
B23: Agentic
B24: Mixed
