Workbook
Name Datenschnitt_C: #N/A
Name Datenschnitt_C_L: #N/A
Name Datenschnitt_Off_Status: #N/A
Name Datenschnitt_P_L: #N/A
Name Datenschnitt_PM: #N/A
Name ostatus: 'AT-Listv2'!$B$3:$B$17
Name pick: 'AT-Listsv1'!$D$3:$D$8
Name pm: 'AT-Listsv1'!$E$3:$E$9
Name priority: 'AT-Listsv1'!$C$3:$C$7
Name status: 'AT-Listsv1'!$B$3:$B$11

Sheet 2024_old
B2: Year | C2: Mon | J2: Work hours | AC2: Summ | AE2: Summ | AG2: A | AI2: Overtime | AJ2: F -Leave | AK2: K - Compens | AL2: FT - Frei | AN2: Work | AO2: Work | AU2: Work | BB2: Privat
D3: KW | E3: Day | F3: Year | G3: Month | H3: Day | I3: Data | J3: In | L3: Break | N3: Break | P3: Out | R3: Break | T3: Break | AC3: must | AE3: is | AG3: F | AN3: Days | AO3: Days | AP3: Day | AS3: Project | AT3: Where | AU3: What | AW3: Day | AZ3: Project | BA3: Where | BB3: What
I4: Sa;So | J4: 0 | K4: 0 | L4: 0 | M4: 0 | N4: 0 | O4: 0 | P4: 0 | Q4: 0 | AC4: 0 | AE4: 0 | AG4: FT | AN4: Effective | AO4: Sum
F5: 2035 | G5: 1 | H5: 1 | J5: 7 | K5: 0 | L5: 13 | M5: 0 | N5: 13 | O5: 30 | P5: 15 | Q5: 55 | AC5: 8 | AE5: 25 | AG5: HO | AN5: A | AO5: Sa
AG6: HT
D7: [ - ] | E7: [ - ] | F7: [ - ] | G7: [ - ] | H7: [ - ] | I7: [ - ] | J7: [h] | K7: [m] | L7: [h] | M7: [m] | N7: [h] | O7: [m] | P7: [h] | Q7: [m] | AC7: [h] | AE7: [m] | AG7: K | AN7: HO | AO7: So | AP7: [ - ] | AQ7: [h] | AR7: [m] | AS7: [ - ] | AT7: [ - ] | AU7: [ - ] | AW7: [ - ] | AX7: [h] | AY7: [m] | AZ7: [ - ] | BA7: [ - ] | BB7: [ - ]
AI8: 0 | AJ8: 0 | AK8: 0 | AL8: 0
B9: =$F$5 -> 2035 | C9: =TEXT(I10,"MMM") -> Jan
A10: =$G$5 -> 1 | D10: =IF(E10="Mo",WEEKNUM(I10),"") -> 1 | E10: =TEXT(I10,"TTT") -> Mo | F10: =$F$5 -> 2035 | G10: =$A$10 -> 1 | H10: =$H$5 -> 1 | I10: =DATE(F10,G10,H10) -> 47848 | J10: =IF(OR($E10="Sa",$E10="So"),J$4,J$5) -> 7 | K10: =IF(OR($E10="Sa",$E10="So"),K$4,K$5) -> 0 | L10: =IF(OR($E10="Sa",$E10="So"),L$4,L$5) -> 13 | M10: =IF(OR($E10="Sa",$E10="So"),M$4,M$5) -> 0 | N10: =IF(OR($E10="Sa",$E10="So"),N$4,N$5) -> 13 | O10: =IF(OR($E10="Sa",$E10="So"),O$4,O$5) -> 30 | P10: =IF(OR($E10="Sa",$E10="So"),P$4,P$5) -> 15 | Q10: =IF(OR($E10="Sa",$E10="So"),Q$4,Q$5) -> 55 | R10: =P10 -> 15 | S10: =Q10 -> 55 | T10: =R10 -> 15 | U10: =S10 -> 55 | V10: =TIME(J10,K10,0) -> 0.29166667 | W10: =TIME(L10,M10,0) -> 0.54166667 | X10: =TIME(N10,O10,0) -> 0.5625 | Y10: =TIME(P10,Q10,0) -> 0.66319444 | Z10: =TIME(R10,S10,0) -> 0.66319444 | AA10: =TIME(T10,U10,0) -> 0.66319444 | AC10: =IF(OR(E10="Sa",E10="So"),TIME($AC$4,$AE$4,0),TIME($AC$5,$AE$5,0)) -> 0.35069444 | AE10: =IF(OR(E10="Sa",E10="So"),TIME($AC$4,$AE$4,0),(Y10-V10-(X10-W10)+(AA10-Z10))) -> 0.35069444 | AJ10: =IF(AG10=$AG$3,1,0) -> 0 | AK10: =IF(AG10=$AG$7,1,0) -> 0 | AL10: =IF(AH10=$AG$4,1,0) -> 0 | AN10: =IF(OR(AG10=$AG$2,AG10=$AG$5),1,IF(AG10=$AG$6,0.5,0)) -> 0 | AO10: =IF(OR(E10="Sa",E10="So"),0,1) -> 1
D11: =IF(E11="Mo",WEEKNUM(I11),"") | E11: =TEXT(I11,"TTT") -> Di | F11: =$F$5 -> 2035 | G11: =$A$10 -> 1 | H11: =H10+1 -> 2 | I11: =DATE(F11,G11,H11) -> 47849 | J11: =IF(OR($E11="Sa",$E11="So"),J$4,J$5) -> 7 | K11: =IF(OR($E11="Sa",$E11="So"),K$4,K$5) -> 0 | L11: =IF(OR($E11="Sa",$E11="So"),L$4,L$5) -> 13 | M11: =IF(OR($E11="Sa",$E11="So"),M$4,M$5) -> 0 | N11: =IF(OR($E11="Sa",$E11="So"),N$4,N$5) -> 13 | O11: =IF(OR($E11="Sa",$E11="So"),O$4,O$5) -> 30 | P11: =IF(OR($E11="Sa",$E11="So"),P$4,P$5) -> 15 | Q11: =IF(OR($E11="Sa",$E11="So"),Q$4,Q$5) -> 55 | R11: =P11 -> 15 | S11: =Q11 -> 55 | T11: =R11 -> 15 | U11: =S11 -> 55 | V11: =TIME(J11,K11,0) -> 0.29166667 | W11: =TIME(L11,M11,0) -> 0.54166667 | X11: =TIME(N11,O11,0) -> 0.5625 | Y11: =TIME(P11,Q11,0) -> 0.66319444 | Z11: =TIME(R11,S11,0) -> 0.66319444 | AA11: =TIME(T11,U11,0) -> 0.66319444 | AC11: =IF(OR(E11="Sa",E11="So"),TIME($AC$4,$AE$4,0),TIME($AC$5,$AE$5,0)) -> 0.35069444 | AE11: =IF(OR(E11="Sa",E11="So"),TIME($AC$4,$AE$4,0),(Y11-V11-(X11-W11)+(AA11-Z11))) -> 0.35069444 | AJ11: =IF(AG11=$AG$3,1,0) -> 0 | AK11: =IF(AG11=$AG$7,1,0) -> 0 | AL11: =IF(AH11=$AG$4,1,0) -> 0 | AN11: =IF(OR(AG11=$AG$2,AG11=$AG$5),1,IF(AG11=$AG$6,0.5,0)) -> 0 | AO11: =IF(OR(E11="Sa",E11="So"),0,1) -> 1
D12: =IF(E12="Mo",WEEKNUM(I12),"") | E12: =TEXT(I12,"TTT") -> Mi | F12: =$F$5 -> 2035 | G12: =$A$10 -> 1 | H12: =H11+1 -> 3 | I12: =DATE(F12,G12,H12) -> 47850 | J12: =IF(OR($E12="Sa",$E12="So"),J$4,J$5) -> 7 | K12: =IF(OR($E12="Sa",$E12="So"),K$4,K$5) -> 0 | L12: =IF(OR($E12="Sa",$E12="So"),L$4,L$5) -> 13 | M12: =IF(OR($E12="Sa",$E12="So"),M$4,M$5) -> 0 | N12: =IF(OR($E12="Sa",$E12="So"),N$4,N$5) -> 13 | O12: =IF(OR($E12="Sa",$E12="So"),O$4,O$5) -> 30 | P12: =IF(OR($E12="Sa",$E12="So"),P$4,P$5) -> 15 | Q12: =IF(OR($E12="Sa",$E12="So"),Q$4,Q$5) -> 55 | R12: =P12 -> 15 | S12: =Q12 -> 55 | T12: =R12 -> 15 | U12: =S12 -> 55 | V12: =TIME(J12,K12,0) -> 0.29166667 | W12: =TIME(L12,M12,0) -> 0.54166667 | X12: =TIME(N12,O12,0) -> 0.5625 | Y12: =TIME(P12,Q12,0) -> 0.66319444 | Z12: =TIME(R12,S12,0) -> 0.66319444 | AA12: =TIME(T12,U12,0) -> 0.66319444 | AC12: =IF(OR(E12="Sa",E12="So"),TIME($AC$4,$AE$4,0),TIME($AC$5,$AE$5,0)) -> 0.35069444 | AE12: =IF(OR(E12="Sa",E12="So"),TIME($AC$4,$AE$4,0),(Y12-V12-(X12-W12)+(AA12-Z12))) -> 0.35069444 | AJ12: =IF(AG12=$AG$3,1,0) -> 0 | AK12: =IF(AG12=$AG$7,1,0) -> 0 | AL12: =IF(AH12=$AG$4,1,0) -> 0 | AN12: =IF(OR(AG12=$AG$2,AG12=$AG$5),1,IF(AG12=$AG$6,0.5,0)) -> 0 | AO12: =IF(OR(E12="Sa",E12="So"),0,1) -> 1
D13: =IF(E13="Mo",WEEKNUM(I13),"") | E13: =TEXT(I13,"TTT") -> Do | F13: =$F$5 -> 2035 | G13: =$A$10 -> 1 | H13: =H12+1 -> 4 | I13: =DATE(F13,G13,H13) -> 47851 | J13: =IF(OR($E13="Sa",$E13="So"),J$4,J$5) -> 7 | K13: =IF(OR($E13="Sa",$E13="So"),K$4,K$5) -> 0 | L13: =IF(OR($E13="Sa",$E13="So"),L$4,L$5) -> 13 | M13: =IF(OR($E13="Sa",$E13="So"),M$4,M$5) -> 0 | N13: =IF(OR($E13="Sa",$E13="So"),N$4,N$5) -> 13 | O13: =IF(OR($E13="Sa",$E13="So"),O$4,O$5) -> 30 | P13: =IF(OR($E13="Sa",$E13="So"),P$4,P$5) -> 15 | Q13: =IF(OR($E13="Sa",$E13="So"),Q$4,Q$5) -> 55 | R13: =P13 -> 15 | S13: =Q13 -> 55 | T13: =R13 -> 15 | U13: =S13 -> 55 | V13: =TIME(J13,K13,0) -> 0.29166667 | W13: =TIME(L13,M13,0) -> 0.54166667 | X13: =TIME(N13,O13,0) -> 0.5625 | Y13: =TIME(P13,Q13,0) -> 0.66319444 | Z13: =TIME(R13,S13,0) -> 0.66319444 | AA13: =TIME(T13,U13,0) -> 0.66319444 | AC13: =IF(OR(E13="Sa",E13="So"),TIME($AC$4,$AE$4,0),TIME($AC$5,$AE$5,0)) -> 0.35069444 | AE13: =IF(OR(E13="Sa",E13="So"),TIME($AC$4,$AE$4,0),(Y13-V13-(X13-W13)+(AA13-Z13))) -> 0.35069444 | AJ13: =IF(AG13=$AG$3,1,0) -> 0 | AK13: =IF(AG13=$AG$7,1,0) -> 0 | AL13: =IF(AH13=$AG$4,1,0) -> 0 | AN13: =IF(OR(AG13=$AG$2,AG13=$AG$5),1,IF(AG13=$AG$6,0.5,0)) -> 0 | AO13: =IF(OR(E13="Sa",E13="So"),0,1) -> 1
D14: =IF(E14="Mo",WEEKNUM(I14),"") | E14: =TEXT(I14,"TTT") -> Fr | F14: =$F$5 -> 2035 | G14: =$A$10 -> 1 | H14: =H13+1 -> 5 | I14: =DATE(F14,G14,H14) -> 47852 | J14: =IF(OR($E14="Sa",$E14="So"),J$4,J$5) -> 7 | K14: =IF(OR($E14="Sa",$E14="So"),K$4,K$5) -> 0 | L14: =IF(OR($E14="Sa",$E14="So"),L$4,L$5) -> 13 | M14: =IF(OR($E14="Sa",$E14="So"),M$4,M$5) -> 0 | N14: =IF(OR($E14="Sa",$E14="So"),N$4,N$5) -> 13 | O14: =IF(OR($E14="Sa",$E14="So"),O$4,O$5) -> 30 | P14: =IF(OR($E14="Sa",$E14="So"),P$4,P$5) -> 15 | Q14: =IF(OR($E14="Sa",$E14="So"),Q$4,Q$5) -> 55 | R14: =P14 -> 15 | S14: =Q14 -> 55 | T14: =R14 -> 15 | U14: =S14 -> 55 | V14: =TIME(J14,K14,0) -> 0.29166667 | W14: =TIME(L14,M14,0) -> 0.54166667 | X14: =TIME(N14,O14,0) -> 0.5625 | Y14: =TIME(P14,Q14,0) -> 0.66319444 | Z14: =TIME(R14,S14,0) -> 0.66319444 | AA14: =TIME(T14,U14,0) -> 0.66319444 | AC14: =IF(OR(E14="Sa",E14="So"),TIME($AC$4,$AE$4,0),TIME($AC$5,$AE$5,0)) -> 0.35069444 | AE14: =IF(OR(E14="Sa",E14="So"),TIME($AC$4,$AE$4,0),(Y14-V14-(X14-W14)+(AA14-Z14))) -> 0.35069444 | AJ14: =IF(AG14=$AG$3,1,0) -> 0 | AK14: =IF(AG14=$AG$7,1,0) -> 0 | AL14: =IF(AH14=$AG$4,1,0) -> 0 | AN14: =IF(OR(AG14=$AG$2,AG14=$AG$5),1,IF(AG14=$AG$6,0.5,0)) -> 0 | AO14: =IF(OR(E14="Sa",E14="So"),0,1) -> 1
D15: =IF(E15="Mo",WEEKNUM(I15),"") | E15: =TEXT(I15,"TTT") -> Sa | F15: =$F$5 -> 2035 | G15: =$A$10 -> 1 | H15: =H14+1 -> 6 | I15: =DATE(F15,G15,H15) -> 47853 | J15: =IF(OR($E15="Sa",$E15="So"),J$4,J$5) -> 0 | K15: =IF(OR($E15="Sa",$E15="So"),K$4,K$5) -> 0 | L15: =IF(OR($E15="Sa",$E15="So"),L$4,L$5) -> 0 | M15: =IF(OR($E15="Sa",$E15="So"),M$4,M$5) -> 0 | N15: =IF(OR($E15="Sa",$E15="So"),N$4,N$5) -> 0 | O15: =IF(OR($E15="Sa",$E15="So"),O$4,O$5) -> 0 | P15: =IF(OR($E15="Sa",$E15="So"),P$4,P$5) -> 0 | Q15: =IF(OR($E15="Sa",$E15="So"),Q$4,Q$5) -> 0 | R15: =P15 -> 0 | S15: =Q15 -> 0 | T15: =R15 -> 0 | U15: =S15 -> 0 | V15: =TIME(J15,K15,0) -> 0 | W15: =TIME(L15,M15,0) -> 0 | X15: =TIME(N15,O15,0) -> 0 | Y15: =TIME(P15,Q15,0) -> 0 | Z15: =TIME(R15,S15,0) -> 0 | AA15: =TIME(T15,U15,0) -> 0 | AC15: =IF(OR(E15="Sa",E15="So"),TIME($AC$4,$AE$4,0),TIME($AC$5,$AE$5,0)) -> 0 | AE15: =IF(OR(E15="Sa",E15="So"),TIME($AC$4,$AE$4,0),(Y15-V15-(X15-W15)+(AA15-Z15))) -> 0 | AJ15: =IF(AG15=$AG$3,1,0) -> 0 | AK15: =IF(AG15=$AG$7,1,0) -> 0 | AL15: =IF(AH15=$AG$4,1,0) -> 0 | AN15: =IF(OR(AG15=$AG$2,AG15=$AG$5),1,IF(AG15=$AG$6,0.5,0)) -> 0 | AO15: =IF(OR(E15="Sa",E15="So"),0,1) -> 0
D16: =IF(E16="Mo",WEEKNUM(I16),"") | E16: =TEXT(I16,"TTT") -> So | F16: =$F$5 -> 2035 | G16: =$A$10 -> 1 | H16: =H15+1 -> 7 | I16: =DATE(F16,G16,H16) -> 47854 | J16: =IF(OR($E16="Sa",$E16="So"),J$4,J$5) -> 0 | K16: =IF(OR($E16="Sa",$E16="So"),K$4,K$5) -> 0 | L16: =IF(OR($E16="Sa",$E16="So"),L$4,L$5) -> 0 | M16: =IF(OR($E16="Sa",$E16="So"),M$4,M$5) -> 0 | N16: =IF(OR($E16="Sa",$E16="So"),N$4,N$5) -> 0 | O16: =IF(OR($E16="Sa",$E16="So"),O$4,O$5) -> 0 | P16: =IF(OR($E16="Sa",$E16="So"),P$4,P$5) -> 0 | Q16: =IF(OR($E16="Sa",$E16="So"),Q$4,Q$5) -> 0 | R16: =P16 -> 0 | S16: =Q16 -> 0 | T16: =R16 -> 0 | U16: =S16 -> 0 | V16: =TIME(J16,K16,0) -> 0 | W16: =TIME(L16,M16,0) -> 0 | X16: =TIME(N16,O16,0) -> 0 | Y16: =TIME(P16,Q16,0) -> 0 | Z16: =TIME(R16,S16,0) -> 0 | AA16: =TIME(T16,U16,0) -> 0 | AC16: =IF(OR(E16="Sa",E16="So"),TIME($AC$4,$AE$4,0),TIME($AC$5,$AE$5,0)) -> 0 | AE16: =IF(OR(E16="Sa",E16="So"),TIME($AC$4,$AE$4,0),(Y16-V16-(X16-W16)+(AA16-Z16))) -> 0 | AJ16: =IF(AG16=$AG$3,1,0) -> 0 | AK16: =IF(AG16=$AG$7,1,0) -> 0 | AL16: =IF(AH16=$AG$4,1,0) -> 0 | AN16: =IF(OR(AG16=$AG$2,AG16=$AG$5),1,IF(AG16=$AG$6,0.5,0)) -> 0 | AO16: =IF(OR(E16="Sa",E16="So"),0,1) -> 0
D17: =IF(E17="Mo",WEEKNUM(I17),"") -> 2 | E17: =TEXT(I17,"TTT") -> Mo | F17: =$F$5 -> 2035 | G17: =$A$10 -> 1 | H17: =H16+1 -> 8 | I17: =DATE(F17,G17,H17) -> 47855 | J17: =IF(OR($E17="Sa",$E17="So"),J$4,J$5) -> 7 | K17: =IF(OR($E17="Sa",$E17="So"),K$4,K$5) -> 0 | L17: =IF(OR($E17="Sa",$E17="So"),L$4,L$5) -> 13 | M17: =IF(OR($E17="Sa",$E17="So"),M$4,M$5) -> 0 | N17: =IF(OR($E17="Sa",$E17="So"),N$4,N$5) -> 13 | O17: =IF(OR($E17="Sa",$E17="So"),O$4,O$5) -> 30 | P17: =IF(OR($E17="Sa",$E17="So"),P$4,P$5) -> 15 | Q17: =IF(OR($E17="Sa",$E17="So"),Q$4,Q$5) -> 55 | R17: =P17 -> 15 | S17: =Q17 -> 55 | T17: =R17 -> 15 | U17: =S17 -> 55 | V17: =TIME(J17,K17,0) -> 0.29166667 | W17: =TIME(L17,M17,0) -> 0.54166667 | X17: =TIME(N17,O17,0) -> 0.5625 | Y17: =TIME(P17,Q17,0) -> 0.66319444 | Z17: =TIME(R17,S17,0) -> 0.66319444 | AA17: =TIME(T17,U17,0) -> 0.66319444 | AC17: =IF(OR(E17="Sa",E17="So"),TIME($AC$4,$AE$4,0),TIME($AC$5,$AE$5,0)) -> 0.35069444 | AE17: =IF(OR(E17="Sa",E17="So"),TIME($AC$4,$AE$4,0),(Y17-V17-(X17-W17)+(AA17-Z17))) -> 0.35069444 | AJ17: =IF(AG17=$AG$3,1,0) -> 0 | AK17: =IF(AG17=$AG$7,1,0) -> 0 | AL17: =IF(AH17=$AG$4,1,0) -> 0 | AN17: =IF(OR(AG17=$AG$2,AG17=$AG$5),1,IF(AG17=$AG$6,0.5,0)) -> 0 | AO17: =IF(OR(E17="Sa",E17="So"),0,1) -> 1
D18: =IF(E18="Mo",WEEKNUM(I18),"") | E18: =TEXT(I18,"TTT") -> Di | F18: =$F$5 -> 2035 | G18: =$A$10 -> 1 | H18: =H17+1 -> 9 | I18: =DATE(F18,G18,H18) -> 47856 | J18: =IF(OR($E18="Sa",$E18="So"),J$4,J$5) -> 7 | K18: =IF(OR($E18="Sa",$E18="So"),K$4,K$5) -> 0 | L18: =IF(OR($E18="Sa",$E18="So"),L$4,L$5) -> 13 | M18: =IF(OR($E18="Sa",$E18="So"),M$4,M$5) -> 0 | N18: =IF(OR($E18="Sa",$E18="So"),N$4,N$5) -> 13 | O18: =IF(OR($E18="Sa",$E18="So"),O$4,O$5) -> 30 | P18: =IF(OR($E18="Sa",$E18="So"),P$4,P$5) -> 15 | Q18: =IF(OR($E18="Sa",$E18="So"),Q$4,Q$5) -> 55 | R18: =P18 -> 15 | S18: =Q18 -> 55 | T18: =R18 -> 15 | U18: =S18 -> 55 | V18: =TIME(J18,K18,0) -> 0.29166667 | W18: =TIME(L18,M18,0) -> 0.54166667 | X18: =TIME(N18,O18,0) -> 0.5625 | Y18: =TIME(P18,Q18,0) -> 0.66319444 | Z18: =TIME(R18,S18,0) -> 0.66319444 | AA18: =TIME(T18,U18,0) -> 0.66319444 | AC18: =IF(OR(E18="Sa",E18="So"),TIME($AC$4,$AE$4,0),TIME($AC$5,$AE$5,0)) -> 0.35069444 | AE18: =IF(OR(E18="Sa",E18="So"),TIME($AC$4,$AE$4,0),(Y18-V18-(X18-W18)+(AA18-Z18))) -> 0.35069444 | AJ18: =IF(AG18=$AG$3,1,0) -> 0 | AK18: =IF(AG18=$AG$7,1,0) -> 0 | AL18: =IF(AH18=$AG$4,1,0) -> 0 | AN18: =IF(OR(AG18=$AG$2,AG18=$AG$5),1,IF(AG18=$AG$6,0.5,0)) -> 0 | AO18: =IF(OR(E18="Sa",E18="So"),0,1) -> 1
D19: =IF(E19="Mo",WEEKNUM(I19),"") | E19: =TEXT(I19,"TTT") -> Mi | F19: =$F$5 -> 2035 | G19: =$A$10 -> 1 | H19: =H18+1 -> 10 | I19: =DATE(F19,G19,H19) -> 47857 | J19: =IF(OR($E19="Sa",$E19="So"),J$4,J$5) -> 7 | K19: =IF(OR($E19="Sa",$E19="So"),K$4,K$5) -> 0 | L19: =IF(OR($E19="Sa",$E19="So"),L$4,L$5) -> 13 | M19: =IF(OR($E19="Sa",$E19="So"),M$4,M$5) -> 0 | N19: =IF(OR($E19="Sa",$E19="So"),N$4,N$5) -> 13 | O19: =IF(OR($E19="Sa",$E19="So"),O$4,O$5) -> 30 | P19: =IF(OR($E19="Sa",$E19="So"),P$4,P$5) -> 15 | Q19: =IF(OR($E19="Sa",$E19="So"),Q$4,Q$5) -> 55 | R19: =P19 -> 15 | S19: =Q19 -> 55 | T19: =R19 -> 15 | U19: =S19 -> 55 | V19: =TIME(J19,K19,0) -> 0.29166667 | W19: =TIME(L19,M19,0) -> 0.54166667 | X19: =TIME(N19,O19,0) -> 0.5625 | Y19: =TIME(P19,Q19,0) -> 0.66319444 | Z19: =TIME(R19,S19,0) -> 0.66319444 | AA19: =TIME(T19,U19,0) -> 0.66319444 | AC19: =IF(OR(E19="Sa",E19="So"),TIME($AC$4,$AE$4,0),TIME($AC$5,$AE$5,0)) -> 0.35069444 | AE19: =IF(OR(E19="Sa",E19="So"),TIME($AC$4,$AE$4,0),(Y19-V19-(X19-W19)+(AA19-Z19))) -> 0.35069444 | AJ19: =IF(AG19=$AG$3,1,0) -> 0 | AK19: =IF(AG19=$AG$7,1,0) -> 0 | AL19: =IF(AH19=$AG$4,1,0) -> 0 | AN19: =IF(OR(AG19=$AG$2,AG19=$AG$5),1,IF(AG19=$AG$6,0.5,0)) -> 0 | AO19: =IF(OR(E19="Sa",E19="So"),0,1) -> 1
D20: =IF(E20="Mo",WEEKNUM(I20),"") | E20: =TEXT(I20,"TTT") -> Do | F20: =$F$5 -> 2035 | G20: =$A$10 -> 1 | H20: =H19+1 -> 11 | I20: =DATE(F20,G20,H20) -> 47858 | J20: =IF(OR($E20="Sa",$E20="So"),J$4,J$5) -> 7 | K20: =IF(OR($E20="Sa",$E20="So"),K$4,K$5) -> 0 | L20: =IF(OR($E20="Sa",$E20="So"),L$4,L$5) -> 13 | M20: =IF(OR($E20="Sa",$E20="So"),M$4,M$5) -> 0 | N20: =IF(OR($E20="Sa",$E20="So"),N$4,N$5) -> 13 | O20: =IF(OR($E20="Sa",$E20="So"),O$4,O$5) -> 30 | P20: =IF(OR($E20="Sa",$E20="So"),P$4,P$5) -> 15 | Q20: =IF(OR($E20="Sa",$E20="So"),Q$4,Q$5) -> 55 | R20: =P20 -> 15 | S20: =Q20 -> 55 | T20: =R20 -> 15 | U20: =S20 -> 55 | V20: =TIME(J20,K20,0) -> 0.29166667 | W20: =TIME(L20,M20,0) -> 0.54166667 | X20: =TIME(N20,O20,0) -> 0.5625 | Y20: =TIME(P20,Q20,0) -> 0.66319444 | Z20: =TIME(R20,S20,0) -> 0.66319444 | AA20: =TIME(T20,U20,0) -> 0.66319444 | AC20: =IF(OR(E20="Sa",E20="So"),TIME($AC$4,$AE$4,0),TIME($AC$5,$AE$5,0)) -> 0.35069444 | AE20: =IF(OR(E20="Sa",E20="So"),TIME($AC$4,$AE$4,0),(Y20-V20-(X20-W20)+(AA20-Z20))) -> 0.35069444 | AJ20: =IF(AG20=$AG$3,1,0) -> 0 | AK20: =IF(AG20=$AG$7,1,0) -> 0 | AL20: =IF(AH20=$AG$4,1,0) -> 0 | AN20: =IF(OR(AG20=$AG$2,AG20=$AG$5),1,IF(AG20=$AG$6,0.5,0)) -> 0 | AO20: =IF(OR(E20="Sa",E20="So"),0,1) -> 1
D21: =IF(E21="Mo",WEEKNUM(I21),"") | E21: =TEXT(I21,"TTT") -> Fr | F21: =$F$5 -> 2035 | G21: =$A$10 -> 1 | H21: =H20+1 -> 12 | I21: =DATE(F21,G21,H21) -> 47859 | J21: =IF(OR($E21="Sa",$E21="So"),J$4,J$5) -> 7 | K21: =IF(OR($E21="Sa",$E21="So"),K$4,K$5) -> 0 | L21: =IF(OR($E21="Sa",$E21="So"),L$4,L$5) -> 13 | M21: =IF(OR($E21="Sa",$E21="So"),M$4,M$5) -> 0 | N21: =IF(OR($E21="Sa",$E21="So"),N$4,N$5) -> 13 | O21: =IF(OR($E21="Sa",$E21="So"),O$4,O$5) -> 30 | P21: =IF(OR($E21="Sa",$E21="So"),P$4,P$5) -> 15 | Q21: =IF(OR($E21="Sa",$E21="So"),Q$4,Q$5) -> 55 | R21: =P21 -> 15 | S21: =Q21 -> 55 | T21: =R21 -> 15 | U21: =S21 -> 55 | V21: =TIME(J21,K21,0) -> 0.29166667 | W21: =TIME(L21,M21,0) -> 0.54166667 | X21: =TIME(N21,O21,0) -> 0.5625 | Y21: =TIME(P21,Q21,0) -> 0.66319444 | Z21: =TIME(R21,S21,0) -> 0.66319444 | AA21: =TIME(T21,U21,0) -> 0.66319444 | AC21: =IF(OR(E21="Sa",E21="So"),TIME($AC$4,$AE$4,0),TIME($AC$5,$AE$5,0)) -> 0.35069444 | AE21: =IF(OR(E21="Sa",E21="So"),TIME($AC$4,$AE$4,0),(Y21-V21-(X21-W21)+(AA21-Z21))) -> 0.35069444 | AJ21: =IF(AG21=$AG$3,1,0) -> 0 | AK21: =IF(AG21=$AG$7,1,0) -> 0 | AL21: =IF(AH21=$AG$4,1,0) -> 0 | AN21: =IF(OR(AG21=$AG$2,AG21=$AG$5),1,IF(AG21=$AG$6,0.5,0)) -> 0 | AO21: =IF(OR(E21="Sa",E21="So"),0,1) -> 1
D22: =IF(E22="Mo",WEEKNUM(I22),"") | E22: =TEXT(I22,"TTT") -> Sa | F22: =$F$5 -> 2035 | G22: =$A$10 -> 1 | H22: =H21+1 -> 13 | I22: =DATE(F22,G22,H22) -> 47860 | J22: =IF(OR($E22="Sa",$E22="So"),J$4,J$5) -> 0 | K22: =IF(OR($E22="Sa",$E22="So"),K$4,K$5) -> 0 | L22: =IF(OR($E22="Sa",$E22="So"),L$4,L$5) -> 0 | M22: =IF(OR($E22="Sa",$E22="So"),M$4,M$5) -> 0 | N22: =IF(OR($E22="Sa",$E22="So"),N$4,N$5) -> 0 | O22: =IF(OR($E22="Sa",$E22="So"),O$4,O$5) -> 0 | P22: =IF(OR($E22="Sa",$E22="So"),P$4,P$5) -> 0 | Q22: =IF(OR($E22="Sa",$E22="So"),Q$4,Q$5) -> 0 | R22: =P22 -> 0 | S22: =Q22 -> 0 | T22: =R22 -> 0 | U22: =S22 -> 0 | V22: =TIME(J22,K22,0) -> 0 | W22: =TIME(L22,M22,0) -> 0 | X22: =TIME(N22,O22,0) -> 0 | Y22: =TIME(P22,Q22,0) -> 0 | Z22: =TIME(R22,S22,0) -> 0 | AA22: =TIME(T22,U22,0) -> 0 | AC22: =IF(OR(E22="Sa",E22="So"),TIME($AC$4,$AE$4,0),TIME($AC$5,$AE$5,0)) -> 0 | AE22: =IF(OR(E22="Sa",E22="So"),TIME($AC$4,$AE$4,0),(Y22-V22-(X22-W22)+(AA22-Z22))) -> 0 | AJ22: =IF(AG22=$AG$3,1,0) -> 0 | AK22: =IF(AG22=$AG$7,1,0) -> 0 | AL22: =IF(AH22=$AG$4,1,0) -> 0 | AN22: =IF(OR(AG22=$AG$2,AG22=$AG$5),1,IF(AG22=$AG$6,0.5,0)) -> 0 | AO22: =IF(OR(E22="Sa",E22="So"),0,1) -> 0
... D40: =IF(E40="Mo",WEEKNUM(I40),"") | E40: =TEXT(I40,"TTT") -> Mi | F40: =$F$5 -> 2035 | G40: =$A$10 -> 1 | H40: =H39+1 -> 31 | I40: =DATE(F40,G40,H40) -> 47878 | J40: =IF(OR($E40="Sa",$E40="So"),J$4,J$5) -> 7 | K40: =IF(OR($E40="Sa",$E40="So"),K$4,K$5) -> 0 | L40: =IF(OR($E40="Sa",$E40="So"),L$4,L$5) -> 13 | M40: =IF(OR($E40="Sa",$E40="So"),M$4,M$5) -> 0 | N40: =IF(OR($E40="Sa",$E40="So"),N$4,N$5) -> 13 | O40: =IF(OR($E40="Sa",$E40="So"),O$4,O$5) -> 30 | P40: =IF(OR($E40="Sa",$E40="So"),P$4,P$5) -> 15 | Q40: =IF(OR($E40="Sa",$E40="So"),Q$4,Q$5) -> 55 | R40: =P40 -> 15 | S40: =Q40 -> 55 | T40: =R40 -> 15 | U40: =S40 -> 55 | V40: =TIME(J40,K40,0) -> 0.29166667 | W40: =TIME(L40,M40,0) -> 0.54166667 | X40: =TIME(N40,O40,0) -> 0.5625 | Y40: =TIME(P40,Q40,0) -> 0.66319444 | Z40: =TIME(R40,S40,0) -> 0.66319444 | AA40: =TIME(T40,U40,0) -> 0.66319444 | AC40: =IF(OR(E40="Sa",E40="So"),TIME($AC$4,$AE$4,0),TIME($AC$5,$AE$5,0)) -> 0.35069444 | AE40: =IF(OR(E40="Sa",E40="So"),TIME($AC$4,$AE$4,0),(Y40-V40-(X40-W40)+(AA40-Z40))) -> 0.35069444 | AJ40: =IF(AG40=$AG$3,1,0) -> 0 | AK40: =IF(AG40=$AG$7,1,0) -> 0 | AL40: =IF(AH40=$AG$4,1,0) -> 0 | AN40: =IF(OR(AG40=$AG$2,AG40=$AG$5),1,IF(AG40=$AG$6,0.5,0)) -> 0 | AO40: =IF(OR(E40="Sa",E40="So"),0,1) -> 1
D41: EM | P41: Summ | AC41: =SUM(AC10:AC40) -> 8.0659722 | AE41: =SUM(AE10:AE40) -> 8.0659722 | AI41: =IF(AE41-AC41<0,AC41-AE41,AE41-AC41) -> 3.5527137e-15 | AJ41: =8.425*SUM(AJ10:AJ40)/24 -> 0 | AK41: =8.425*SUM(AK10:AK40)/24 -> 0 | AL41: =8.425*SUM(AL10:AL40)/24 -> 0 | AN41: =SUM(AN10:AN40) -> 0 | AO41: =SUM(AO10:AO40) -> 23
AI42: =AI8+AI41 -> 3.5527137e-15 | AJ42: =AJ8+SUM(AJ9:AJ40) -> 0 | AK42: =AK8+SUM(AK9:AK40) -> 0 | AL42: =AL8+SUM(AL9:AL40) -> 0 | AN42: =AN41*8 -> 0 | AO42: =AO41*8 -> 184
B43: =$F$5 -> 2035 | C43: =TEXT(I44,"MMM") -> Feb
A44: =A10+1 -> 2 | D44: =IF(E44="Mo",WEEKNUM(I44),"") | E44: =TEXT(I44,"TTT") -> Do | F44: =$F$5 -> 2035 | G44: =$A$44 -> 2 | H44: =$H$5 -> 1 | I44: =DATE(F44,G44,H44) -> 47879 | J44: =IF(OR($E44="Sa",$E44="So"),J$4,J$5) -> 7 | K44: =IF(OR($E44="Sa",$E44="So"),K$4,K$5) -> 0 | L44: =IF(OR($E44="Sa",$E44="So"),L$4,L$5) -> 13 | M44: =IF(OR($E44="Sa",$E44="So"),M$4,M$5) -> 0 | N44: =IF(OR($E44="Sa",$E44="So"),N$4,N$5) -> 13 | O44: =IF(OR($E44="Sa",$E44="So"),O$4,O$5) -> 30 | P44: =IF(OR($E44="Sa",$E44="So"),P$4,P$5) -> 15 | Q44: =IF(OR($E44="Sa",$E44="So"),Q$4,Q$5) -> 55 | R44: =P44 -> 15 | S44: =Q44 -> 55 | T44: =R44 -> 15 | U44: =S44 -> 55 | V44: =TIME(J44,K44,0) -> 0.29166667 | W44: =TIME(L44,M44,0) -> 0.54166667 | X44: =TIME(N44,O44,0) -> 0.5625 | Y44: =TIME(P44,Q44,0) -> 0.66319444 | Z44: =TIME(R44,S44,0) -> 0.66319444 | AA44: =TIME(T44,U44,0) -> 0.66319444 | AC44: =IF(OR(E44="Sa",E44="So"),TIME($AC$4,$AE$4,0),TIME($AC$5,$AE$5,0)) -> 0.35069444 | AE44: =IF(OR(E44="Sa",E44="So"),TIME($AC$4,$AE$4,0),(Y44-V44-(X44-W44)+(AA44-Z44))) -> 0.35069444 | AJ44: =IF(AG44=$AG$3,1,0) -> 0 | AK44: =IF(AG44=$AG$7,1,0) -> 0 | AL44: =IF(AH44=$AG$4,1,0) -> 0 | AN44: =IF(OR(AG44=$AG$2,AG44=$AG$5),1,IF(AG44=$AG$6,0.5,0)) -> 0 | AO44: =IF(OR(E44="Sa",E44="So"),0,1) -> 1
D45: =IF(E45="Mo",WEEKNUM(I45),"") | E45: =TEXT(I45,"TTT") -> Fr | F45: =$F$5 -> 2035 | G45: =$A$44 -> 2 | H45: =H44+1 -> 2 | I45: =DATE(F45,G45,H45) -> 47880 | J45: =IF(OR($E45="Sa",$E45="So"),J$4,J$5) -> 7 | K45: =IF(OR($E45="Sa",$E45="So"),K$4,K$5) -> 0 | L45: =IF(OR($E45="Sa",$E45="So"),L$4,L$5) -> 13 | M45: =IF(OR($E45="Sa",$E45="So"),M$4,M$5) -> 0 | N45: =IF(OR($E45="Sa",$E45="So"),N$4,N$5) -> 13 | O45: =IF(OR($E45="Sa",$E45="So"),O$4,O$5) -> 30 | P45: =IF(OR($E45="Sa",$E45="So"),P$4,P$5) -> 15 | Q45: =IF(OR($E45="Sa",$E45="So"),Q$4,Q$5) -> 55 | R45: =P45 -> 15 | S45: =Q45 -> 55 | T45: =R45 -> 15 | U45: =S45 -> 55 | V45: =TIME(J45,K45,0) -> 0.29166667 | W45: =TIME(L45,M45,0) -> 0.54166667 | X45: =TIME(N45,O45,0) -> 0.5625 | Y45: =TIME(P45,Q45,0) -> 0.66319444 | Z45: =TIME(R45,S45,0) -> 0.66319444 | AA45: =TIME(T45,U45,0) -> 0.66319444 | AC45: =IF(OR(E45="Sa",E45="So"),TIME($AC$4,$AE$4,0),TIME($AC$5,$AE$5,0)) -> 0.35069444 | AE45: =IF(OR(E45="Sa",E45="So"),TIME($AC$4,$AE$4,0),(Y45-V45-(X45-W45)+(AA45-Z45))) -> 0.35069444 | AJ45: =IF(AG45=$AG$3,1,0) -> 0 | AK45: =IF(AG45=$AG$7,1,0) -> 0 | AL45: =IF(AH45=$AG$4,1,0) -> 0 | AN45: =IF(OR(AG45=$AG$2,AG45=$AG$5),1,IF(AG45=$AG$6,0.5,0)) -> 0 | AO45: =IF(OR(E45="Sa",E45="So"),0,1) -> 1
D46: =IF(E46="Mo",WEEKNUM(I46),"") | E46: =TEXT(I46,"TTT") -> Sa | F46: =$F$5 -> 2035 | G46: =$A$44 -> 2 | H46: =H45+1 -> 3 | I46: =DATE(F46,G46,H46) -> 47881 | J46: =IF(OR($E46="Sa",$E46="So"),J$4,J$5) -> 0 | K46: =IF(OR($E46="Sa",$E46="So"),K$4,K$5) -> 0 | L46: =IF(OR($E46="Sa",$E46="So"),L$4,L$5) -> 0 | M46: =IF(OR($E46="Sa",$E46="So"),M$4,M$5) -> 0 | N46: =IF(OR($E46="Sa",$E46="So"),N$4,N$5) -> 0 | O46: =IF(OR($E46="Sa",$E46="So"),O$4,O$5) -> 0 | P46: =IF(OR($E46="Sa",$E46="So"),P$4,P$5) -> 0 | Q46: =IF(OR($E46="Sa",$E46="So"),Q$4,Q$5) -> 0 | R46: =P46 -> 0 | S46: =Q46 -> 0 | T46: =R46 -> 0 | U46: =S46 -> 0 | V46: =TIME(J46,K46,0) -> 0 | W46: =TIME(L46,M46,0) -> 0 | X46: =TIME(N46,O46,0) -> 0 | Y46: =TIME(P46,Q46,0) -> 0 | Z46: =TIME(R46,S46,0) -> 0 | AA46: =TIME(T46,U46,0) -> 0 | AC46: =IF(OR(E46="Sa",E46="So"),TIME($AC$4,$AE$4,0),TIME($AC$5,$AE$5,0)) -> 0 | AE46: =IF(OR(E46="Sa",E46="So"),TIME($AC$4,$AE$4,0),(Y46-V46-(X46-W46)+(AA46-Z46))) -> 0 | AJ46: =IF(AG46=$AG$3,1,0) -> 0 | AK46: =IF(AG46=$AG$7,1,0) -> 0 | AL46: =IF(AH46=$AG$4,1,0) -> 0 | AN46: =IF(OR(AG46=$AG$2,AG46=$AG$5),1,IF(AG46=$AG$6,0.5,0)) -> 0 | AO46: =IF(OR(E46="Sa",E46="So"),0,1) -> 0
D47: =IF(E47="Mo",WEEKNUM(I47),"") | E47: =TEXT(I47,"TTT") -> So | F47: =$F$5 -> 2035 | G47: =$A$44 -> 2 | H47: =H46+1 -> 4 | I47: =DATE(F47,G47,H47) -> 47882 | J47: =IF(OR($E47="Sa",$E47="So"),J$4,J$5) -> 0 | K47: =IF(OR($E47="Sa",$E47="So"),K$4,K$5) -> 0 | L47: =IF(OR($E47="Sa",$E47="So"),L$4,L$5) -> 0 | M47: =IF(OR($E47="Sa",$E47="So"),M$4,M$5) -> 0 | N47: =IF(OR($E47="Sa",$E47="So"),N$4,N$5) -> 0 | O47: =IF(OR($E47="Sa",$E47="So"),O$4,O$5) -> 0 | P47: =IF(OR($E47="Sa",$E47="So"),P$4,P$5) -> 0 | Q47: =IF(OR($E47="Sa",$E47="So"),Q$4,Q$5) -> 0 | R47: =P47 -> 0 | S47: =Q47 -> 0 | T47: =R47 -> 0 | U47: =S47 -> 0 | V47: =TIME(J47,K47,0) -> 0 | W47: =TIME(L47,M47,0) -> 0 | X47: =TIME(N47,O47,0) -> 0 | Y47: =TIME(P47,Q47,0) -> 0 | Z47: =TIME(R47,S47,0) -> 0 | AA47: =TIME(T47,U47,0) -> 0 | AC47: =IF(OR(E47="Sa",E47="So"),TIME($AC$4,$AE$4,0),TIME($AC$5,$AE$5,0)) -> 0 | AE47: =IF(OR(E47="Sa",E47="So"),TIME($AC$4,$AE$4,0),(Y47-V47-(X47-W47)+(AA47-Z47))) -> 0 | AJ47: =IF(AG47=$AG$3,1,0) -> 0 | AK47: =IF(AG47=$AG$7,1,0) -> 0 | AL47: =IF(AH47=$AG$4,1,0) -> 0 | AN47: =IF(OR(AG47=$AG$2,AG47=$AG$5),1,IF(AG47=$AG$6,0.5,0)) -> 0 | AO47: =IF(OR(E47="Sa",E47="So"),0,1) -> 0
D48: =IF(E48="Mo",WEEKNUM(I48),"") -> 6 | E48: =TEXT(I48,"TTT") -> Mo | F48: =$F$5 -> 2035 | G48: =$A$44 -> 2 | H48: =H47+1 -> 5 | I48: =DATE(F48,G48,H48) -> 47883 | J48: =IF(OR($E48="Sa",$E48="So"),J$4,J$5) -> 7 | K48: =IF(OR($E48="Sa",$E48="So"),K$4,K$5) -> 0 | L48: =IF(OR($E48="Sa",$E48="So"),L$4,L$5) -> 13 | M48: =IF(OR($E48="Sa",$E48="So"),M$4,M$5) -> 0 | N48: =IF(OR($E48="Sa",$E48="So"),N$4,N$5) -> 13 | O48: =IF(OR($E48="Sa",$E48="So"),O$4,O$5) -> 30 | P48: =IF(OR($E48="Sa",$E48="So"),P$4,P$5) -> 15 | Q48: =IF(OR($E48="Sa",$E48="So"),Q$4,Q$5) -> 55 | R48: =P48 -> 15 | S48: =Q48 -> 55 | T48: =R48 -> 15 | U48: =S48 -> 55 | V48: =TIME(J48,K48,0) -> 0.29166667 | W48: =TIME(L48,M48,0) -> 0.54166667 | X48: =TIME(N48,O48,0) -> 0.5625 | Y48: =TIME(P48,Q48,0) -> 0.66319444 | Z48: =TIME(R48,S48,0) -> 0.66319444 | AA48: =TIME(T48,U48,0) -> 0.66319444 | AC48: =IF(OR(E48="Sa",E48="So"),TIME($AC$4,$AE$4,0),TIME($AC$5,$AE$5,0)) -> 0.35069444 | AE48: =IF(OR(E48="Sa",E48="So"),TIME($AC$4,$AE$4,0),(Y48-V48-(X48-W48)+(AA48-Z48))) -> 0.35069444 | AJ48: =IF(AG48=$AG$3,1,0) -> 0 | AK48: =IF(AG48=$AG$7,1,0) -> 0 | AL48: =IF(AH48=$AG$4,1,0) -> 0 | AN48: =IF(OR(AG48=$AG$2,AG48=$AG$5),1,IF(AG48=$AG$6,0.5,0)) -> 0 | AO48: =IF(OR(E48="Sa",E48="So"),0,1) -> 1
D49: =IF(E49="Mo",WEEKNUM(I49),"") | E49: =TEXT(I49,"TTT") -> Di | F49: =$F$5 -> 2035 | G49: =$A$44 -> 2 | H49: =H48+1 -> 6 | I49: =DATE(F49,G49,H49) -> 47884 | J49: =IF(OR($E49="Sa",$E49="So"),J$4,J$5) -> 7 | K49: =IF(OR($E49="Sa",$E49="So"),K$4,K$5) -> 0 | L49: =IF(OR($E49="Sa",$E49="So"),L$4,L$5) -> 13 | M49: =IF(OR($E49="Sa",$E49="So"),M$4,M$5) -> 0 | N49: =IF(OR($E49="Sa",$E49="So"),N$4,N$5) -> 13 | O49: =IF(OR($E49="Sa",$E49="So"),O$4,O$5) -> 30 | P49: =IF(OR($E49="Sa",$E49="So"),P$4,P$5) -> 15 | Q49: =IF(OR($E49="Sa",$E49="So"),Q$4,Q$5) -> 55 | R49: =P49 -> 15 | S49: =Q49 -> 55 | T49: =R49 -> 15 | U49: =S49 -> 55 | V49: =TIME(J49,K49,0) -> 0.29166667 | W49: =TIME(L49,M49,0) -> 0.54166667 | X49: =TIME(N49,O49,0) -> 0.5625 | Y49: =TIME(P49,Q49,0) -> 0.66319444 | Z49: =TIME(R49,S49,0) -> 0.66319444 | AA49: =TIME(T49,U49,0) -> 0.66319444 | AC49: =IF(OR(E49="Sa",E49="So"),TIME($AC$4,$AE$4,0),TIME($AC$5,$AE$5,0)) -> 0.35069444 | AE49: =IF(OR(E49="Sa",E49="So"),TIME($AC$4,$AE$4,0),(Y49-V49-(X49-W49)+(AA49-Z49))) -> 0.35069444 | AJ49: =IF(AG49=$AG$3,1,0) -> 0 | AK49: =IF(AG49=$AG$7,1,0) -> 0 | AL49: =IF(AH49=$AG$4,1,0) -> 0 | AN49: =IF(OR(AG49=$AG$2,AG49=$AG$5),1,IF(AG49=$AG$6,0.5,0)) -> 0 | AO49: =IF(OR(E49="Sa",E49="So"),0,1) -> 1
D50: =IF(E50="Mo",WEEKNUM(I50),"") | E50: =TEXT(I50,"TTT") -> Mi | F50: =$F$5 -> 2035 | G50: =$A$44 -> 2 | H50: =H49+1 -> 7 | I50: =DATE(F50,G50,H50) -> 47885 | J50: =IF(OR($E50="Sa",$E50="So"),J$4,J$5) -> 7 | K50: =IF(OR($E50="Sa",$E50="So"),K$4,K$5) -> 0 | L50: =IF(OR($E50="Sa",$E50="So"),L$4,L$5) -> 13 | M50: =IF(OR($E50="Sa",$E50="So"),M$4,M$5) -> 0 | N50: =IF(OR($E50="Sa",$E50="So"),N$4,N$5) -> 13 | O50: =IF(OR($E50="Sa",$E50="So"),O$4,O$5) -> 30 | P50: =IF(OR($E50="Sa",$E50="So"),P$4,P$5) -> 15 | Q50: =IF(OR($E50="Sa",$E50="So"),Q$4,Q$5) -> 55 | R50: =P50 -> 15 | S50: =Q50 -> 55 | T50: =R50 -> 15 | U50: =S50 -> 55 | V50: =TIME(J50,K50,0) -> 0.29166667 | W50: =TIME(L50,M50,0) -> 0.54166667 | X50: =TIME(N50,O50,0) -> 0.5625 | Y50: =TIME(P50,Q50,0) -> 0.66319444 | Z50: =TIME(R50,S50,0) -> 0.66319444 | AA50: =TIME(T50,U50,0) -> 0.66319444 | AC50: =IF(OR(E50="Sa",E50="So"),TIME($AC$4,$AE$4,0),TIME($AC$5,$AE$5,0)) -> 0.35069444 | AE50: =IF(OR(E50="Sa",E50="So"),TIME($AC$4,$AE$4,0),(Y50-V50-(X50-W50)+(AA50-Z50))) -> 0.35069444 | AJ50: =IF(AG50=$AG$3,1,0) -> 0 | AK50: =IF(AG50=$AG$7,1,0) -> 0 | AL50: =IF(AH50=$AG$4,1,0) -> 0 | AN50: =IF(OR(AG50=$AG$2,AG50=$AG$5),1,IF(AG50=$AG$6,0.5,0)) -> 0 | AO50: =IF(OR(E50="Sa",E50="So"),0,1) -> 1
D51: =IF(E51="Mo",WEEKNUM(I51),"") | E51: =TEXT(I51,"TTT") -> Do | F51: =$F$5 -> 2035 | G51: =$A$44 -> 2 | H51: =H50+1 -> 8 | I51: =DATE(F51,G51,H51) -> 47886 | J51: =IF(OR($E51="Sa",$E51="So"),J$4,J$5) -> 7 | K51: =IF(OR($E51="Sa",$E51="So"),K$4,K$5) -> 0 | L51: =IF(OR($E51="Sa",$E51="So"),L$4,L$5) -> 13 | M51: =IF(OR($E51="Sa",$E51="So"),M$4,M$5) -> 0 | N51: =IF(OR($E51="Sa",$E51="So"),N$4,N$5) -> 13 | O51: =IF(OR($E51="Sa",$E51="So"),O$4,O$5) -> 30 | P51: =IF(OR($E51="Sa",$E51="So"),P$4,P$5) -> 15 | Q51: =IF(OR($E51="Sa",$E51="So"),Q$4,Q$5) -> 55 | R51: =P51 -> 15 | S51: =Q51 -> 55 | T51: =R51 -> 15 | U51: =S51 -> 55 | V51: =TIME(J51,K51,0) -> 0.29166667 | W51: =TIME(L51,M51,0) -> 0.54166667 | X51: =TIME(N51,O51,0) -> 0.5625 | Y51: =TIME(P51,Q51,0) -> 0.66319444 | Z51: =TIME(R51,S51,0) -> 0.66319444 | AA51: =TIME(T51,U51,0) -> 0.66319444 | AC51: =IF(OR(E51="Sa",E51="So"),TIME($AC$4,$AE$4,0),TIME($AC$5,$AE$5,0)) -> 0.35069444 | AE51: =IF(OR(E51="Sa",E51="So"),TIME($AC$4,$AE$4,0),(Y51-V51-(X51-W51)+(AA51-Z51))) -> 0.35069444 | AJ51: =IF(AG51=$AG$3,1,0) -> 0 | AK51: =IF(AG51=$AG$7,1,0) -> 0 | AL51: =IF(AH51=$AG$4,1,0) -> 0 | AN51: =IF(OR(AG51=$AG$2,AG51=$AG$5),1,IF(AG51=$AG$6,0.5,0)) -> 0 | AO51: =IF(OR(E51="Sa",E51="So"),0,1) -> 1
D52: =IF(E52="Mo",WEEKNUM(I52),"") | E52: =TEXT(I52,"TTT") -> Fr | F52: =$F$5 -> 2035 | G52: =$A$44 -> 2 | H52: =H51+1 -> 9 | I52: =DATE(F52,G52,H52) -> 47887 | J52: =IF(OR($E52="Sa",$E52="So"),J$4,J$5) -> 7 | K52: =IF(OR($E52="Sa",$E52="So"),K$4,K$5) -> 0 | L52: =IF(OR($E52="Sa",$E52="So"),L$4,L$5) -> 13 | M52: =IF(OR($E52="Sa",$E52="So"),M$4,M$5) -> 0 | N52: =IF(OR($E52="Sa",$E52="So"),N$4,N$5) -> 13 | O52: =IF(OR($E52="Sa",$E52="So"),O$4,O$5) -> 30 | P52: =IF(OR($E52="Sa",$E52="So"),P$4,P$5) -> 15 | Q52: =IF(OR($E52="Sa",$E52="So"),Q$4,Q$5) -> 55 | R52: =P52 -> 15 | S52: =Q52 -> 55 | T52: =R52 -> 15 | U52: =S52 -> 55 | V52: =TIME(J52,K52,0) -> 0.29166667 | W52: =TIME(L52,M52,0) -> 0.54166667 | X52: =TIME(N52,O52,0) -> 0.5625 | Y52: =TIME(P52,Q52,0) -> 0.66319444 | Z52: =TIME(R52,S52,0) -> 0.66319444 | AA52: =TIME(T52,U52,0) -> 0.66319444 | AC52: =IF(OR(E52="Sa",E52="So"),TIME($AC$4,$AE$4,0),TIME($AC$5,$AE$5,0)) -> 0.35069444 | AE52: =IF(OR(E52="Sa",E52="So"),TIME($AC$4,$AE$4,0),(Y52-V52-(X52-W52)+(AA52-Z52))) -> 0.35069444 | AJ52: =IF(AG52=$AG$3,1,0) -> 0 | AK52: =IF(AG52=$AG$7,1,0) -> 0 | AL52: =IF(AH52=$AG$4,1,0) -> 0 | AN52: =IF(OR(AG52=$AG$2,AG52=$AG$5),1,IF(AG52=$AG$6,0.5,0)) -> 0 | AO52: =IF(OR(E52="Sa",E52="So"),0,1) -> 1
D53: =IF(E53="Mo",WEEKNUM(I53),"") | E53: =TEXT(I53,"TTT") -> Sa | F53: =$F$5 -> 2035 | G53: =$A$44 -> 2 | H53: =H52+1 -> 10 | I53: =DATE(F53,G53,H53) -> 47888 | J53: =IF(OR($E53="Sa",$E53="So"),J$4,J$5) -> 0 | K53: =IF(OR($E53="Sa",$E53="So"),K$4,K$5) -> 0 | L53: =IF(OR($E53="Sa",$E53="So"),L$4,L$5) -> 0 | M53: =IF(OR($E53="Sa",$E53="So"),M$4,M$5) -> 0 | N53: =IF(OR($E53="Sa",$E53="So"),N$4,N$5) -> 0 | O53: =IF(OR($E53="Sa",$E53="So"),O$4,O$5) -> 0 | P53: =IF(OR($E53="Sa",$E53="So"),P$4,P$5) -> 0 | Q53: =IF(OR($E53="Sa",$E53="So"),Q$4,Q$5) -> 0 | R53: =P53 -> 0 | S53: =Q53 -> 0 | T53: =R53 -> 0 | U53: =S53 -> 0 | V53: =TIME(J53,K53,0) -> 0 | W53: =TIME(L53,M53,0) -> 0 | X53: =TIME(N53,O53,0) -> 0 | Y53: =TIME(P53,Q53,0) -> 0 | Z53: =TIME(R53,S53,0) -> 0 | AA53: =TIME(T53,U53,0) -> 0 | AC53: =IF(OR(E53="Sa",E53="So"),TIME($AC$4,$AE$4,0),TIME($AC$5,$AE$5,0)) -> 0 | AE53: =IF(OR(E53="Sa",E53="So"),TIME($AC$4,$AE$4,0),(Y53-V53-(X53-W53)+(AA53-Z53))) -> 0 | AJ53: =IF(AG53=$AG$3,1,0) -> 0 | AK53: =IF(AG53=$AG$7,1,0) -> 0 | AL53: =IF(AH53=$AG$4,1,0) -> 0 | AN53: =IF(OR(AG53=$AG$2,AG53=$AG$5),1,IF(AG53=$AG$6,0.5,0)) -> 0 | AO53: =IF(OR(E53="Sa",E53="So"),0,1) -> 0
D54: =IF(E54="Mo",WEEKNUM(I54),"") | E54: =TEXT(I54,"TTT") -> So | F54: =$F$5 -> 2035 | G54: =$A$44 -> 2 | H54: =H53+1 -> 11 | I54: =DATE(F54,G54,H54) -> 47889 | J54: =IF(OR($E54="Sa",$E54="So"),J$4,J$5) -> 0 | K54: =IF(OR($E54="Sa",$E54="So"),K$4,K$5) -> 0 | L54: =IF(OR($E54="Sa",$E54="So"),L$4,L$5) -> 0 | M54: =IF(OR($E54="Sa",$E54="So"),M$4,M$5) -> 0 | N54: =IF(OR($E54="Sa",$E54="So"),N$4,N$5) -> 0 | O54: =IF(OR($E54="Sa",$E54="So"),O$4,O$5) -> 0 | P54: =IF(OR($E54="Sa",$E54="So"),P$4,P$5) -> 0 | Q54: =IF(OR($E54="Sa",$E54="So"),Q$4,Q$5) -> 0 | R54: =P54 -> 0 | S54: =Q54 -> 0 | T54: =R54 -> 0 | U54: =S54 -> 0 | V54: =TIME(J54,K54,0) -> 0 | W54: =TIME(L54,M54,0) -> 0 | X54: =TIME(N54,O54,0) -> 0 | Y54: =TIME(P54,Q54,0) -> 0 | Z54: =TIME(R54,S54,0) -> 0 | AA54: =TIME(T54,U54,0) -> 0 | AC54: =IF(OR(E54="Sa",E54="So"),TIME($AC$4,$AE$4,0),TIME($AC$5,$AE$5,0)) -> 0 | AE54: =IF(OR(E54="Sa",E54="So"),TIME($AC$4,$AE$4,0),(Y54-V54-(X54-W54)+(AA54-Z54))) -> 0 | AJ54: =IF(AG54=$AG$3,1,0) -> 0 | AK54: =IF(AG54=$AG$7,1,0) -> 0 | AL54: =IF(AH54=$AG$4,1,0) -> 0 | AN54: =IF(OR(AG54=$AG$2,AG54=$AG$5),1,IF(AG54=$AG$6,0.5,0)) -> 0 | AO54: =IF(OR(E54="Sa",E54="So"),0,1) -> 0
D55: =IF(E55="Mo",WEEKNUM(I55),"") -> 7 | E55: =TEXT(I55,"TTT") -> Mo | F55: =$F$5 -> 2035 | G55: =$A$44 -> 2 | H55: =H54+1 -> 12 | I55: =DATE(F55,G55,H55) -> 47890 | J55: =IF(OR($E55="Sa",$E55="So"),J$4,J$5) -> 7 | K55: =IF(OR($E55="Sa",$E55="So"),K$4,K$5) -> 0 | L55: =IF(OR($E55="Sa",$E55="So"),L$4,L$5) -> 13 | M55: =IF(OR($E55="Sa",$E55="So"),M$4,M$5) -> 0 | N55: =IF(OR($E55="Sa",$E55="So"),N$4,N$5) -> 13 | O55: =IF(OR($E55="Sa",$E55="So"),O$4,O$5) -> 30 | P55: =IF(OR($E55="Sa",$E55="So"),P$4,P$5) -> 15 | Q55: =IF(OR($E55="Sa",$E55="So"),Q$4,Q$5) -> 55 | R55: =P55 -> 15 | S55: =Q55 -> 55 | T55: =R55 -> 15 | U55: =S55 -> 55 | V55: =TIME(J55,K55,0) -> 0.29166667 | W55: =TIME(L55,M55,0) -> 0.54166667 | X55: =TIME(N55,O55,0) -> 0.5625 | Y55: =TIME(P55,Q55,0) -> 0.66319444 | Z55: =TIME(R55,S55,0) -> 0.66319444 | AA55: =TIME(T55,U55,0) -> 0.66319444 | AC55: =IF(OR(E55="Sa",E55="So"),TIME($AC$4,$AE$4,0),TIME($AC$5,$AE$5,0)) -> 0.35069444 | AE55: =IF(OR(E55="Sa",E55="So"),TIME($AC$4,$AE$4,0),(Y55-V55-(X55-W55)+(AA55-Z55))) -> 0.35069444 | AJ55: =IF(AG55=$AG$3,1,0) -> 0 | AK55: =IF(AG55=$AG$7,1,0) -> 0 | AL55: =IF(AH55=$AG$4,1,0) -> 0 | AN55: =IF(OR(AG55=$AG$2,AG55=$AG$5),1,IF(AG55=$AG$6,0.5,0)) -> 0 | AO55: =IF(OR(E55="Sa",E55="So"),0,1) -> 1
D56: =IF(E56="Mo",WEEKNUM(I56),"") | E56: =TEXT(I56,"TTT") -> Di | F56: =$F$5 -> 2035 | G56: =$A$44 -> 2 | H56: =H55+1 -> 13 | I56: =DATE(F56,G56,H56) -> 47891 | J56: =IF(OR($E56="Sa",$E56="So"),J$4,J$5) -> 7 | K56: =IF(OR($E56="Sa",$E56="So"),K$4,K$5) -> 0 | L56: =IF(OR($E56="Sa",$E56="So"),L$4,L$5) -> 13 | M56: =IF(OR($E56="Sa",$E56="So"),M$4,M$5) -> 0 | N56: =IF(OR($E56="Sa",$E56="So"),N$4,N$5) -> 13 | O56: =IF(OR($E56="Sa",$E56="So"),O$4,O$5) -> 30 | P56: =IF(OR($E56="Sa",$E56="So"),P$4,P$5) -> 15 | Q56: =IF(OR($E56="Sa",$E56="So"),Q$4,Q$5) -> 55 | R56: =P56 -> 15 | S56: =Q56 -> 55 | T56: =R56 -> 15 | U56: =S56 -> 55 | V56: =TIME(J56,K56,0) -> 0.29166667 | W56: =TIME(L56,M56,0) -> 0.54166667 | X56: =TIME(N56,O56,0) -> 0.5625 | Y56: =TIME(P56,Q56,0) -> 0.66319444 | Z56: =TIME(R56,S56,0) -> 0.66319444 | AA56: =TIME(T56,U56,0) -> 0.66319444 | AC56: =IF(OR(E56="Sa",E56="So"),TIME($AC$4,$AE$4,0),TIME($AC$5,$AE$5,0)) -> 0.35069444 | AE56: =IF(OR(E56="Sa",E56="So"),TIME($AC$4,$AE$4,0),(Y56-V56-(X56-W56)+(AA56-Z56))) -> 0.35069444 | AJ56: =IF(AG56=$AG$3,1,0) -> 0 | AK56: =IF(AG56=$AG$7,1,0) -> 0 | AL56: =IF(AH56=$AG$4,1,0) -> 0 | AN56: =IF(OR(AG56=$AG$2,AG56=$AG$5),1,IF(AG56=$AG$6,0.5,0)) -> 0 | AO56: =IF(OR(E56="Sa",E56="So"),0,1) -> 1
... D74: =IF(E74="Mo",WEEKNUM(I74),"") | E74: =TEXT(I74,"TTT") -> Sa | F74: =$F$5 -> 2035 | G74: =$A$44 -> 2 | H74: =H73+1 -> 31 | I74: =DATE(F74,G74,H74) -> 47909 | J74: =IF(OR($E74="Sa",$E74="So"),J$4,J$5) -> 0 | K74: =IF(OR($E74="Sa",$E74="So"),K$4,K$5) -> 0 | L74: =IF(OR($E74="Sa",$E74="So"),L$4,L$5) -> 0 | M74: =IF(OR($E74="Sa",$E74="So"),M$4,M$5) -> 0 | N74: =IF(OR($E74="Sa",$E74="So"),N$4,N$5) -> 0 | O74: =IF(OR($E74="Sa",$E74="So"),O$4,O$5) -> 0 | P74: =IF(OR($E74="Sa",$E74="So"),P$4,P$5) -> 0 | Q74: =IF(OR($E74="Sa",$E74="So"),Q$4,Q$5) -> 0 | R74: =P74 -> 0 | S74: =Q74 -> 0 | T74: =R74 -> 0 | U74: =S74 -> 0 | V74: =TIME(J74,K74,0) -> 0 | W74: =TIME(L74,M74,0) -> 0 | X74: =TIME(N74,O74,0) -> 0 | Y74: =TIME(P74,Q74,0) -> 0 | Z74: =TIME(R74,S74,0) -> 0 | AA74: =TIME(T74,U74,0) -> 0 | AC74: =IF(OR(E74="Sa",E74="So"),TIME($AC$4,$AE$4,0),TIME($AC$5,$AE$5,0)) -> 0 | AE74: =IF(OR(E74="Sa",E74="So"),TIME($AC$4,$AE$4,0),(Y74-V74-(X74-W74)+(AA74-Z74))) -> 0 | AJ74: =IF(AG74=$AG$3,1,0) -> 0 | AK74: =IF(AG74=$AG$7,1,0) -> 0 | AL74: =IF(AH74=$AG$4,1,0) -> 0 | AN74: =IF(OR(AG74=$AG$2,AG74=$AG$5),1,IF(AG74=$AG$6,0.5,0)) -> 0 | AO74: =IF(OR(E74="Sa",E74="So"),0,1) -> 0
D75: EM | P75: Summ | AC75: =SUM(AC44:AC74) -> 7.7152778 | AE75: =SUM(AE44:AE74) -> 7.7152778 | AI75: =IF(AE75-AC75<0,AC75-AE75,AE75-AC75) -> 2.6645353e-15 | AJ75: =8.425*SUM(AJ44:AJ74)/24 -> 0 | AK75: =8.425*SUM(AK44:AK74)/24 -> 0 | AL75: =8.425*SUM(AL44:AL74)/24 -> 0 | AN75: =SUM(AN44:AN74) -> 0 | AO75: =SUM(AO44:AO74) -> 22
...

Sheet 2025
BG1: WHA | BH1: WAH | BI1: ECO | BJ1: ECO | BL1: WHA | BM1: WAH | BN1: ECO | BO1: ECO
B2: Year | C2: Mon | K2: Work hours | AD2: Summ | AF2: Summ | AH2: A | AJ2: Overtime | AK2: F -Leave | AL2: K - Compens | AM2: FT - Frei | AO2: Work | AP2: Work | AV2: Work | BC2: Privat | BF2: WGTST | BG2: 80.9 | BH2: 1h 10min
D3: KW | E3: Day | F3: Year | G3: Month | H3: Day | I3: Data | K3: In | M3: Break | O3: Break | Q3: Out | S3: Break | U3: Break | AD3: must | AF3: is | AH3: F | AO3: Days | AP3: Days | AQ3: Day | AT3: Project | AU3: Where | AV3: What | AX3: Day | BA3: Project | BB3: Where | BC3: What | BF3: WGKWT | BG3: 68.5 | BH3: 1h 02min
I4: Sa;So | K4: 0 | L4: 0 | M4: 0 | N4: 0 | O4: 0 | P4: 0 | Q4: 0 | R4: 0 | AD4: 0 | AF4: 0 | AH4: FT | AO4: Effective | AP4: Sum | BF4: WGMLFT | BG4: 67.8 | BH4: 1h 09min
F5: 2025 | G5: 1 | H5: 1 | K5: 7 | L5: 0 | M5: 13 | N5: 0 | O5: 13 | P5: 30 | Q5: 15 | R5: 55 | AD5: 8 | AF5: 25 | AH5: HO | AO5: A | AP5: Sa | BF5: WGMWT | BG5: 72.2 | BH5: 1h 03min
AH6: HT | BF6: WLSLHT | BG6: 67.3 | BH6: 1h 13min
D7: [ - ] | E7: [ - ] | F7: [ - ] | G7: [ - ] | H7: [ - ] | I7: [ - ] | K7: [h] | L7: [m] | M7: [h] | N7: [m] | O7: [h] | P7: [m] | Q7: [h] | R7: [m] | AD7: [h] | AF7: [m] | AH7: K | AO7: HO | AP7: So | AQ7: [ - ] | AR7: [h] | AS7: [m] | AT7: [ - ] | AU7: [ - ] | AV7: [ - ] | AX7: [ - ] | AY7: [h] | AZ7: [m] | BA7: [ - ] | BB7: [ - ] | BC7: [ - ] | BF7: WLSFT | BG7: 72.3 | BH7: 1h 12min | BL7: km | BM7: km
AJ8: 0 | AK8: 0 | AL8: 0 | AM8: 0 | BF8: WLSWT | BG8: 77.4 | BH8: 1h 09min | BL8: WGTST | BN8: ECO | BO8: ECO
B9: =$F$5 -> 2025 | C9: =TEXT(I10,"MMM") -> Jan | BL9: =INDEX($BF$2:$BG$8,MATCH(BL8,$BF$2:$BF$8,0),2) -> 80.9 | BM9: =INDEX($BF$2:$BG$8,MATCH(BL8,$BF$2:$BF$8,0),2) -> 80.9 | BN9: 15 | BO9: 15
A10: =$G$5 -> 1 | D10: =IF(E10="Mo",WEEKNUM(I10),"") | E10: =TEXT(I10,"TTT") -> Mi | F10: =$F$5 -> 2025 | G10: =$A$10 -> 1 | H10: =$H$5 -> 1 | I10: =DATE(F10,G10,H10) -> 44196 | J10: =IF(OR(G10="",G10=MONTH(I10)),1,0) -> 1 | K10: =IF(OR($E10="Sa",$E10="So",$J10=0),K$4,K$5) -> 7 | L10: =IF(OR($E10="Sa",$E10="So",$J10=0),L$4,L$5) -> 0 | M10: =IF(OR($E10="Sa",$E10="So",$J10=0),M$4,M$5) -> 13 | N10: =IF(OR($E10="Sa",$E10="So",$J10=0),N$4,N$5) -> 0 | O10: =IF(OR($E10="Sa",$E10="So",$J10=0),O$4,O$5) -> 13 | P10: =IF(OR($E10="Sa",$E10="So",$J10=0),P$4,P$5) -> 30 | Q10: =IF(OR($E10="Sa",$E10="So",$J10=0),Q$4,Q$5) -> 15 | R10: =IF(OR($E10="Sa",$E10="So",$J10=0),R$4,R$5) -> 55 | S10: =Q10 -> 15 | T10: =R10 -> 55 | U10: =S10 -> 15 | V10: =T10 -> 55 | W10: =TIME(K10,L10,0) -> 0.29166667 | X10: =TIME(M10,N10,0) -> 0.54166667 | Y10: =TIME(O10,P10,0) -> 0.5625 | Z10: =TIME(Q10,R10,0) -> 0.66319444 | AA10: =TIME(S10,T10,0) -> 0.66319444 | AB10: =TIME(U10,V10,0) -> 0.66319444 | AD10: =IF(J10=0,0,IF(OR(E10="Sa",E10="So"),TIME($AD$4,$AF$4,0),TIME($AD$5,$AF$5,0))) -> 0.35069444 | AF10: =IF(J10=0,0,Z10-W10-(Y10-X10)) -> 0.35069444 | AK10: =IF(AH10=$AH$3,1,0) -> 0 | AL10: =IF(AH10=$AH$7,1,0) -> 0 | AM10: =IF(AI10=$AH$4,1,0) -> 0 | AO10: =IF(OR(AH10=$AH$2,AH10=$AH$5),1,IF(AH10=$AH$6,0.5,0)) -> 0 | AP10: =IF(OR(E10="Sa",E10="So",E10="",J10=0,AH10="FT"),0,1) -> 1 | BL10: =BL9 -> 80.9 | BM10: =BM9 -> 80.9 | BN10: =BN9 -> 15 | BO10: =BN10+BO9 -> 30
D11: =IF(E11="Mo",WEEKNUM(I11),"") | E11: =TEXT(I11,"TTT") -> Do | F11: =$F$5 -> 2025 | G11: =$A$10 -> 1 | H11: =H10+1 -> 2 | I11: =DATE(F11,G11,H11) -> 44197 | J11: =IF(OR(G11="",G11=MONTH(I11)),1,0) -> 1 | K11: =IF(OR($E11="Sa",$E11="So",$J11=0),K$4,K$5) -> 7 | L11: =IF(OR($E11="Sa",$E11="So",$J11=0),L$4,L$5) -> 0 | M11: =IF(OR($E11="Sa",$E11="So",$J11=0),M$4,M$5) -> 13 | N11: =IF(OR($E11="Sa",$E11="So",$J11=0),N$4,N$5) -> 0 | O11: =IF(OR($E11="Sa",$E11="So",$J11=0),O$4,O$5) -> 13 | P11: =IF(OR($E11="Sa",$E11="So",$J11=0),P$4,P$5) -> 30 | Q11: =IF(OR($E11="Sa",$E11="So",$J11=0),Q$4,Q$5) -> 15 | R11: =IF(OR($E11="Sa",$E11="So",$J11=0),R$4,R$5) -> 55 | S11: =Q11 -> 15 | T11: =R11 -> 55 | U11: =S11 -> 15 | V11: =T11 -> 55 | W11: =TIME(K11,L11,0) -> 0.29166667 | X11: =TIME(M11,N11,0) -> 0.54166667 | Y11: =TIME(O11,P11,0) -> 0.5625 | Z11: =TIME(Q11,R11,0) -> 0.66319444 | AA11: =TIME(S11,T11,0) -> 0.66319444 | AB11: =TIME(U11,V11,0) -> 0.66319444 | AD11: =IF(J11=0,0,IF(OR(E11="Sa",E11="So"),TIME($AD$4,$AF$4,0),TIME($AD$5,$AF$5,0))) -> 0.35069444 | AF11: =IF(J11=0,0,Z11-W11-(Y11-X11)) -> 0.35069444 | AK11: =IF(AH11=$AH$3,1,0) -> 0 | AL11: =IF(AH11=$AH$7,1,0) -> 0 | AM11: =IF(AI11=$AH$4,1,0) -> 0 | AO11: =IF(OR(AH11=$AH$2,AH11=$AH$5),1,IF(AH11=$AH$6,0.5,0)) -> 0 | AP11: =IF(OR(E11="Sa",E11="So",E11="",J11=0,AH11="FT"),0,1) -> 1 | BL11: =BL9 -> 80.9 | BM11: =BM9 -> 80.9 | BN11: =BO10+BN9 -> 45 | BO11: =BN11+BO9 -> 60
D12: =IF(E12="Mo",WEEKNUM(I12),"") | E12: =TEXT(I12,"TTT") -> Fr | F12: =$F$5 -> 2025 | G12: =$A$10 -> 1 | H12: =H11+1 -> 3 | I12: =DATE(F12,G12,H12) -> 44198 | J12: =IF(OR(G12="",G12=MONTH(I12)),1,0) -> 1 | K12: =IF(OR($E12="Sa",$E12="So",$J12=0),K$4,K$5) -> 7 | L12: =IF(OR($E12="Sa",$E12="So",$J12=0),L$4,L$5) -> 0 | M12: =IF(OR($E12="Sa",$E12="So",$J12=0),M$4,M$5) -> 13 | N12: =IF(OR($E12="Sa",$E12="So",$J12=0),N$4,N$5) -> 0 | O12: =IF(OR($E12="Sa",$E12="So",$J12=0),O$4,O$5) -> 13 | P12: =IF(OR($E12="Sa",$E12="So",$J12=0),P$4,P$5) -> 30 | Q12: =IF(OR($E12="Sa",$E12="So",$J12=0),Q$4,Q$5) -> 15 | R12: =IF(OR($E12="Sa",$E12="So",$J12=0),R$4,R$5) -> 55 | S12: =Q12 -> 15 | T12: =R12 -> 55 | U12: =S12 -> 15 | V12: =T12 -> 55 | W12: =TIME(K12,L12,0) -> 0.29166667 | X12: =TIME(M12,N12,0) -> 0.54166667 | Y12: =TIME(O12,P12,0) -> 0.5625 | Z12: =TIME(Q12,R12,0) -> 0.66319444 | AA12: =TIME(S12,T12,0) -> 0.66319444 | AB12: =TIME(U12,V12,0) -> 0.66319444 | AD12: =IF(J12=0,0,IF(OR(E12="Sa",E12="So"),TIME($AD$4,$AF$4,0),TIME($AD$5,$AF$5,0))) -> 0.35069444 | AF12: =IF(J12=0,0,Z12-W12-(Y12-X12)) -> 0.35069444 | AK12: =IF(AH12=$AH$3,1,0) -> 0 | AL12: =IF(AH12=$AH$7,1,0) -> 0 | AM12: =IF(AI12=$AH$4,1,0) -> 0 | AO12: =IF(OR(AH12=$AH$2,AH12=$AH$5),1,IF(AH12=$AH$6,0.5,0)) -> 0 | AP12: =IF(OR(E12="Sa",E12="So",E12="",J12=0,AH12="FT"),0,1) -> 1 | BL12: =BL9 -> 80.9 | BM12: =BM9 -> 80.9 | BN12: =BO11+BN9 -> 75 | BO12: =BN12+BO9 -> 90
D13: =IF(E13="Mo",WEEKNUM(I13),"") | E13: =TEXT(I13,"TTT") -> Sa | F13: =$F$5 -> 2025 | G13: =$A$10 -> 1 | H13: =H12+1 -> 4 | I13: =DATE(F13,G13,H13) -> 44199 | J13: =IF(OR(G13="",G13=MONTH(I13)),1,0) -> 1 | K13: =IF(OR($E13="Sa",$E13="So",$J13=0),K$4,K$5) -> 0 | L13: =IF(OR($E13="Sa",$E13="So",$J13=0),L$4,L$5) -> 0 | M13: =IF(OR($E13="Sa",$E13="So",$J13=0),M$4,M$5) -> 0 | N13: =IF(OR($E13="Sa",$E13="So",$J13=0),N$4,N$5) -> 0 | O13: =IF(OR($E13="Sa",$E13="So",$J13=0),O$4,O$5) -> 0 | P13: =IF(OR($E13="Sa",$E13="So",$J13=0),P$4,P$5) -> 0 | Q13: =IF(OR($E13="Sa",$E13="So",$J13=0),Q$4,Q$5) -> 0 | R13: =IF(OR($E13="Sa",$E13="So",$J13=0),R$4,R$5) -> 0 | S13: =Q13 -> 0 | T13: =R13 -> 0 | U13: =S13 -> 0 | V13: =T13 -> 0 | W13: =TIME(K13,L13,0) -> 0 | X13: =TIME(M13,N13,0) -> 0 | Y13: =TIME(O13,P13,0) -> 0 | Z13: =TIME(Q13,R13,0) -> 0 | AA13: =TIME(S13,T13,0) -> 0 | AB13: =TIME(U13,V13,0) -> 0 | AD13: =IF(J13=0,0,IF(OR(E13="Sa",E13="So"),TIME($AD$4,$AF$4,0),TIME($AD$5,$AF$5,0))) -> 0 | AF13: =IF(J13=0,0,Z13-W13-(Y13-X13)) -> 0 | AK13: =IF(AH13=$AH$3,1,0) -> 0 | AL13: =IF(AH13=$AH$7,1,0) -> 0 | AM13: =IF(AI13=$AH$4,1,0) -> 0 | AO13: =IF(OR(AH13=$AH$2,AH13=$AH$5),1,IF(AH13=$AH$6,0.5,0)) -> 0 | AP13: =IF(OR(E13="Sa",E13="So",E13="",J13=0,AH13="FT"),0,1) -> 0 | BL13: =BL9 -> 80.9 | BM13: =BM9 -> 80.9 | BN13: =BO12+BN9 -> 105 | BO13: =BN13+BO9 -> 120
D14: =IF(E14="Mo",WEEKNUM(I14),"") | E14: =TEXT(I14,"TTT") -> So | F14: =$F$5 -> 2025 | G14: =$A$10 -> 1 | H14: =H13+1 -> 5 | I14: =DATE(F14,G14,H14) -> 44200 | J14: =IF(OR(G14="",G14=MONTH(I14)),1,0) -> 1 | K14: =IF(OR($E14="Sa",$E14="So",$J14=0),K$4,K$5) -> 0 | L14: =IF(OR($E14="Sa",$E14="So",$J14=0),L$4,L$5) -> 0 | M14: =IF(OR($E14="Sa",$E14="So",$J14=0),M$4,M$5) -> 0 | N14: =IF(OR($E14="Sa",$E14="So",$J14=0),N$4,N$5) -> 0 | O14: =IF(OR($E14="Sa",$E14="So",$J14=0),O$4,O$5) -> 0 | P14: =IF(OR($E14="Sa",$E14="So",$J14=0),P$4,P$5) -> 0 | Q14: =IF(OR($E14="Sa",$E14="So",$J14=0),Q$4,Q$5) -> 0 | R14: =IF(OR($E14="Sa",$E14="So",$J14=0),R$4,R$5) -> 0 | S14: =Q14 -> 0 | T14: =R14 -> 0 | U14: =S14 -> 0 | V14: =T14 -> 0 | W14: =TIME(K14,L14,0) -> 0 | X14: =TIME(M14,N14,0) -> 0 | Y14: =TIME(O14,P14,0) -> 0 | Z14: =TIME(Q14,R14,0) -> 0 | AA14: =TIME(S14,T14,0) -> 0 | AB14: =TIME(U14,V14,0) -> 0 | AD14: =IF(J14=0,0,IF(OR(E14="Sa",E14="So"),TIME($AD$4,$AF$4,0),TIME($AD$5,$AF$5,0))) -> 0 | AF14: =IF(J14=0,0,Z14-W14-(Y14-X14)) -> 0 | AK14: =IF(AH14=$AH$3,1,0) -> 0 | AL14: =IF(AH14=$AH$7,1,0) -> 0 | AM14: =IF(AI14=$AH$4,1,0) -> 0 | AO14: =IF(OR(AH14=$AH$2,AH14=$AH$5),1,IF(AH14=$AH$6,0.5,0)) -> 0 | AP14: =IF(OR(E14="Sa",E14="So",E14="",J14=0,AH14="FT"),0,1) -> 0 | BL14: =BL9 -> 80.9 | BM14: =BM9 -> 80.9 | BN14: =BO13+BN9 -> 135 | BO14: =BN14+BO9 -> 150
D15: =IF(E15="Mo",WEEKNUM(I15),"") -> 2 | E15: =TEXT(I15,"TTT") -> Mo | F15: =$F$5 -> 2025 | G15: =$A$10 -> 1 | H15: =H14+1 -> 6 | I15: =DATE(F15,G15,H15) -> 44201 | J15: =IF(OR(G15="",G15=MONTH(I15)),1,0) -> 1 | K15: =IF(OR($E15="Sa",$E15="So",$J15=0),K$4,K$5) -> 7 | L15: =IF(OR($E15="Sa",$E15="So",$J15=0),L$4,L$5) -> 0 | M15: =IF(OR($E15="Sa",$E15="So",$J15=0),M$4,M$5) -> 13 | N15: =IF(OR($E15="Sa",$E15="So",$J15=0),N$4,N$5) -> 0 | O15: =IF(OR($E15="Sa",$E15="So",$J15=0),O$4,O$5) -> 13 | P15: =IF(OR($E15="Sa",$E15="So",$J15=0),P$4,P$5) -> 30 | Q15: =IF(OR($E15="Sa",$E15="So",$J15=0),Q$4,Q$5) -> 15 | R15: =IF(OR($E15="Sa",$E15="So",$J15=0),R$4,R$5) -> 55 | S15: =Q15 -> 15 | T15: =R15 -> 55 | U15: =S15 -> 15 | V15: =T15 -> 55 | W15: =TIME(K15,L15,0) -> 0.29166667 | X15: =TIME(M15,N15,0) -> 0.54166667 | Y15: =TIME(O15,P15,0) -> 0.5625 | Z15: =TIME(Q15,R15,0) -> 0.66319444 | AA15: =TIME(S15,T15,0) -> 0.66319444 | AB15: =TIME(U15,V15,0) -> 0.66319444 | AD15: =IF(J15=0,0,IF(OR(E15="Sa",E15="So"),TIME($AD$4,$AF$4,0),TIME($AD$5,$AF$5,0))) -> 0.35069444 | AF15: =IF(J15=0,0,Z15-W15-(Y15-X15)) -> 0.35069444 | AK15: =IF(AH15=$AH$3,1,0) -> 0 | AL15: =IF(AH15=$AH$7,1,0) -> 0 | AM15: =IF(AI15=$AH$4,1,0) -> 0 | AO15: =IF(OR(AH15=$AH$2,AH15=$AH$5),1,IF(AH15=$AH$6,0.5,0)) -> 0 | AP15: =IF(OR(E15="Sa",E15="So",E15="",J15=0,AH15="FT"),0,1) -> 1 | BL15: WGTST | BM15: =SUM(BL10:BL14)+SUM(BM10:BM14) -> 809 | BN15: ECO | BO15: ECO
D16: =IF(E16="Mo",WEEKNUM(I16),"") | E16: =TEXT(I16,"TTT") -> Di | F16: =$F$5 -> 2025 | G16: =$A$10 -> 1 | H16: =H15+1 -> 7 | I16: =DATE(F16,G16,H16) -> 44202 | J16: =IF(OR(G16="",G16=MONTH(I16)),1,0) -> 1 | K16: =IF(OR($E16="Sa",$E16="So",$J16=0),K$4,K$5) -> 7 | L16: =IF(OR($E16="Sa",$E16="So",$J16=0),L$4,L$5) -> 0 | M16: =IF(OR($E16="Sa",$E16="So",$J16=0),M$4,M$5) -> 13 | N16: =IF(OR($E16="Sa",$E16="So",$J16=0),N$4,N$5) -> 0 | O16: =IF(OR($E16="Sa",$E16="So",$J16=0),O$4,O$5) -> 13 | P16: =IF(OR($E16="Sa",$E16="So",$J16=0),P$4,P$5) -> 30 | Q16: =IF(OR($E16="Sa",$E16="So",$J16=0),Q$4,Q$5) -> 15 | R16: =IF(OR($E16="Sa",$E16="So",$J16=0),R$4,R$5) -> 55 | S16: =Q16 -> 15 | T16: =R16 -> 55 | U16: =S16 -> 15 | V16: =T16 -> 55 | W16: =TIME(K16,L16,0) -> 0.29166667 | X16: =TIME(M16,N16,0) -> 0.54166667 | Y16: =TIME(O16,P16,0) -> 0.5625 | Z16: =TIME(Q16,R16,0) -> 0.66319444 | AA16: =TIME(S16,T16,0) -> 0.66319444 | AB16: =TIME(U16,V16,0) -> 0.66319444 | AD16: =IF(J16=0,0,IF(OR(E16="Sa",E16="So"),TIME($AD$4,$AF$4,0),TIME($AD$5,$AF$5,0))) -> 0.35069444 | AF16: =IF(J16=0,0,Z16-W16-(Y16-X16)) -> 0.35069444 | AK16: =IF(AH16=$AH$3,1,0) -> 0 | AL16: =IF(AH16=$AH$7,1,0) -> 0 | AM16: =IF(AI16=$AH$4,1,0) -> 0 | AO16: =IF(OR(AH16=$AH$2,AH16=$AH$5),1,IF(AH16=$AH$6,0.5,0)) -> 0 | AP16: =IF(OR(E16="Sa",E16="So",E16="",J16=0,AH16="FT"),0,1) -> 1 | BL16: =INDEX($BF$2:$BG$8,MATCH(BL15,$BF$2:$BF$8,0),2) -> 80.9 | BM16: =INDEX($BF$2:$BG$8,MATCH(BL15,$BF$2:$BF$8,0),2) -> 80.9 | BN16: 15 | BO16: 15
D17: =IF(E17="Mo",WEEKNUM(I17),"") | E17: =TEXT(I17,"TTT") -> Mi | F17: =$F$5 -> 2025 | G17: =$A$10 -> 1 | H17: =H16+1 -> 8 | I17: =DATE(F17,G17,H17) -> 44203 | J17: =IF(OR(G17="",G17=MONTH(I17)),1,0) -> 1 | K17: =IF(OR($E17="Sa",$E17="So",$J17=0),K$4,K$5) -> 7 | L17: =IF(OR($E17="Sa",$E17="So",$J17=0),L$4,L$5) -> 0 | M17: =IF(OR($E17="Sa",$E17="So",$J17=0),M$4,M$5) -> 13 | N17: =IF(OR($E17="Sa",$E17="So",$J17=0),N$4,N$5) -> 0 | O17: =IF(OR($E17="Sa",$E17="So",$J17=0),O$4,O$5) -> 13 | P17: =IF(OR($E17="Sa",$E17="So",$J17=0),P$4,P$5) -> 30 | Q17: =IF(OR($E17="Sa",$E17="So",$J17=0),Q$4,Q$5) -> 15 | R17: =IF(OR($E17="Sa",$E17="So",$J17=0),R$4,R$5) -> 55 | S17: =Q17 -> 15 | T17: =R17 -> 55 | U17: =S17 -> 15 | V17: =T17 -> 55 | W17: =TIME(K17,L17,0) -> 0.29166667 | X17: =TIME(M17,N17,0) -> 0.54166667 | Y17: =TIME(O17,P17,0) -> 0.5625 | Z17: =TIME(Q17,R17,0) -> 0.66319444 | AA17: =TIME(S17,T17,0) -> 0.66319444 | AB17: =TIME(U17,V17,0) -> 0.66319444 | AD17: =IF(J17=0,0,IF(OR(E17="Sa",E17="So"),TIME($AD$4,$AF$4,0),TIME($AD$5,$AF$5,0))) -> 0.35069444 | AF17: =IF(J17=0,0,Z17-W17-(Y17-X17)) -> 0.35069444 | AK17: =IF(AH17=$AH$3,1,0) -> 0 | AL17: =IF(AH17=$AH$7,1,0) -> 0 | AM17: =IF(AI17=$AH$4,1,0) -> 0 | AO17: =IF(OR(AH17=$AH$2,AH17=$AH$5),1,IF(AH17=$AH$6,0.5,0)) -> 0 | AP17: =IF(OR(E17="Sa",E17="So",E17="",J17=0,AH17="FT"),0,1) -> 1 | BL17: =BL16 -> 80.9 | BM17: =BM16 -> 80.9 | BN17: =BN16 -> 15 | BO17: =BN17+BO16 -> 30
D18: =IF(E18="Mo",WEEKNUM(I18),"") | E18: =TEXT(I18,"TTT") -> Do | F18: =$F$5 -> 2025 | G18: =$A$10 -> 1 | H18: =H17+1 -> 9 | I18: =DATE(F18,G18,H18) -> 44204 | J18: =IF(OR(G18="",G18=MONTH(I18)),1,0) -> 1 | K18: =IF(OR($E18="Sa",$E18="So",$J18=0),K$4,K$5) -> 7 | L18: =IF(OR($E18="Sa",$E18="So",$J18=0),L$4,L$5) -> 0 | M18: =IF(OR($E18="Sa",$E18="So",$J18=0),M$4,M$5) -> 13 | N18: =IF(OR($E18="Sa",$E18="So",$J18=0),N$4,N$5) -> 0 | O18: =IF(OR($E18="Sa",$E18="So",$J18=0),O$4,O$5) -> 13 | P18: =IF(OR($E18="Sa",$E18="So",$J18=0),P$4,P$5) -> 30 | Q18: =IF(OR($E18="Sa",$E18="So",$J18=0),Q$4,Q$5) -> 15 | R18: =IF(OR($E18="Sa",$E18="So",$J18=0),R$4,R$5) -> 55 | S18: =Q18 -> 15 | T18: =R18 -> 55 | U18: =S18 -> 15 | V18: =T18 -> 55 | W18: =TIME(K18,L18,0) -> 0.29166667 | X18: =TIME(M18,N18,0) -> 0.54166667 | Y18: =TIME(O18,P18,0) -> 0.5625 | Z18: =TIME(Q18,R18,0) -> 0.66319444 | AA18: =TIME(S18,T18,0) -> 0.66319444 | AB18: =TIME(U18,V18,0) -> 0.66319444 | AD18: =IF(J18=0,0,IF(OR(E18="Sa",E18="So"),TIME($AD$4,$AF$4,0),TIME($AD$5,$AF$5,0))) -> 0.35069444 | AF18: =IF(J18=0,0,Z18-W18-(Y18-X18)) -> 0.35069444 | AK18: =IF(AH18=$AH$3,1,0) -> 0 | AL18: =IF(AH18=$AH$7,1,0) -> 0 | AM18: =IF(AI18=$AH$4,1,0) -> 0 | AO18: =IF(OR(AH18=$AH$2,AH18=$AH$5),1,IF(AH18=$AH$6,0.5,0)) -> 0 | AP18: =IF(OR(E18="Sa",E18="So",E18="",J18=0,AH18="FT"),0,1) -> 1 | BL18: =BL16 -> 80.9 | BM18: =BM16 -> 80.9 | BN18: =BO17+BN16 -> 45 | BO18: =BN18+BO16 -> 60
D19: =IF(E19="Mo",WEEKNUM(I19),"") | E19: =TEXT(I19,"TTT") -> Fr | F19: =$F$5 -> 2025 | G19: =$A$10 -> 1 | H19: =H18+1 -> 10 | I19: =DATE(F19,G19,H19) -> 44205 | J19: =IF(OR(G19="",G19=MONTH(I19)),1,0) -> 1 | K19: =IF(OR($E19="Sa",$E19="So",$J19=0),K$4,K$5) -> 7 | L19: =IF(OR($E19="Sa",$E19="So",$J19=0),L$4,L$5) -> 0 | M19: =IF(OR($E19="Sa",$E19="So",$J19=0),M$4,M$5) -> 13 | N19: =IF(OR($E19="Sa",$E19="So",$J19=0),N$4,N$5) -> 0 | O19: =IF(OR($E19="Sa",$E19="So",$J19=0),O$4,O$5) -> 13 | P19: =IF(OR($E19="Sa",$E19="So",$J19=0),P$4,P$5) -> 30 | Q19: =IF(OR($E19="Sa",$E19="So",$J19=0),Q$4,Q$5) -> 15 | R19: =IF(OR($E19="Sa",$E19="So",$J19=0),R$4,R$5) -> 55 | S19: =Q19 -> 15 | T19: =R19 -> 55 | U19: =S19 -> 15 | V19: =T19 -> 55 | W19: =TIME(K19,L19,0) -> 0.29166667 | X19: =TIME(M19,N19,0) -> 0.54166667 | Y19: =TIME(O19,P19,0) -> 0.5625 | Z19: =TIME(Q19,R19,0) -> 0.66319444 | AA19: =TIME(S19,T19,0) -> 0.66319444 | AB19: =TIME(U19,V19,0) -> 0.66319444 | AD19: =IF(J19=0,0,IF(OR(E19="Sa",E19="So"),TIME($AD$4,$AF$4,0),TIME($AD$5,$AF$5,0))) -> 0.35069444 | AF19: =IF(J19=0,0,Z19-W19-(Y19-X19)) -> 0.35069444 | AK19: =IF(AH19=$AH$3,1,0) -> 0 | AL19: =IF(AH19=$AH$7,1,0) -> 0 | AM19: =IF(AI19=$AH$4,1,0) -> 0 | AO19: =IF(OR(AH19=$AH$2,AH19=$AH$5),1,IF(AH19=$AH$6,0.5,0)) -> 0 | AP19: =IF(OR(E19="Sa",E19="So",E19="",J19=0,AH19="FT"),0,1) -> 1 | BL19: =BL16 -> 80.9 | BM19: =BM16 -> 80.9 | BN19: =BO18+BN16 -> 75 | BO19: =BN19+BO16 -> 90
D20: =IF(E20="Mo",WEEKNUM(I20),"") | E20: =TEXT(I20,"TTT") -> Sa | F20: =$F$5 -> 2025 | G20: =$A$10 -> 1 | H20: =H19+1 -> 11 | I20: =DATE(F20,G20,H20) -> 44206 | J20: =IF(OR(G20="",G20=MONTH(I20)),1,0) -> 1 | K20: =IF(OR($E20="Sa",$E20="So",$J20=0),K$4,K$5) -> 0 | L20: =IF(OR($E20="Sa",$E20="So",$J20=0),L$4,L$5) -> 0 | M20: =IF(OR($E20="Sa",$E20="So",$J20=0),M$4,M$5) -> 0 | N20: =IF(OR($E20="Sa",$E20="So",$J20=0),N$4,N$5) -> 0 | O20: =IF(OR($E20="Sa",$E20="So",$J20=0),O$4,O$5) -> 0 | P20: =IF(OR($E20="Sa",$E20="So",$J20=0),P$4,P$5) -> 0 | Q20: =IF(OR($E20="Sa",$E20="So",$J20=0),Q$4,Q$5) -> 0 | R20: =IF(OR($E20="Sa",$E20="So",$J20=0),R$4,R$5) -> 0 | S20: =Q20 -> 0 | T20: =R20 -> 0 | U20: =S20 -> 0 | V20: =T20 -> 0 | W20: =TIME(K20,L20,0) -> 0 | X20: =TIME(M20,N20,0) -> 0 | Y20: =TIME(O20,P20,0) -> 0 | Z20: =TIME(Q20,R20,0) -> 0 | AA20: =TIME(S20,T20,0) -> 0 | AB20: =TIME(U20,V20,0) -> 0 | AD20: =IF(J20=0,0,IF(OR(E20="Sa",E20="So"),TIME($AD$4,$AF$4,0),TIME($AD$5,$AF$5,0))) -> 0 | AF20: =IF(J20=0,0,Z20-W20-(Y20-X20)) -> 0 | AK20: =IF(AH20=$AH$3,1,0) -> 0 | AL20: =IF(AH20=$AH$7,1,0) -> 0 | AM20: =IF(AI20=$AH$4,1,0) -> 0 | AO20: =IF(OR(AH20=$AH$2,AH20=$AH$5),1,IF(AH20=$AH$6,0.5,0)) -> 0 | AP20: =IF(OR(E20="Sa",E20="So",E20="",J20=0,AH20="FT"),0,1) -> 0 | BL20: =BL16 -> 80.9 | BM20: =BM16 -> 80.9 | BN20: =BO19+BN16 -> 105 | BO20: =BN20+BO16 -> 120
D21: =IF(E21="Mo",WEEKNUM(I21),"") | E21: =TEXT(I21,"TTT") -> So | F21: =$F$5 -> 2025 | G21: =$A$10 -> 1 | H21: =H20+1 -> 12 | I21: =DATE(F21,G21,H21) -> 44207 | J21: =IF(OR(G21="",G21=MONTH(I21)),1,0) -> 1 | K21: =IF(OR($E21="Sa",$E21="So",$J21=0),K$4,K$5) -> 0 | L21: =IF(OR($E21="Sa",$E21="So",$J21=0),L$4,L$5) -> 0 | M21: =IF(OR($E21="Sa",$E21="So",$J21=0),M$4,M$5) -> 0 | N21: =IF(OR($E21="Sa",$E21="So",$J21=0),N$4,N$5) -> 0 | O21: =IF(OR($E21="Sa",$E21="So",$J21=0),O$4,O$5) -> 0 | P21: =IF(OR($E21="Sa",$E21="So",$J21=0),P$4,P$5) -> 0 | Q21: =IF(OR($E21="Sa",$E21="So",$J21=0),Q$4,Q$5) -> 0 | R21: =IF(OR($E21="Sa",$E21="So",$J21=0),R$4,R$5) -> 0 | S21: =Q21 -> 0 | T21: =R21 -> 0 | U21: =S21 -> 0 | V21: =T21 -> 0 | W21: =TIME(K21,L21,0) -> 0 | X21: =TIME(M21,N21,0) -> 0 | Y21: =TIME(O21,P21,0) -> 0 | Z21: =TIME(Q21,R21,0) -> 0 | AA21: =TIME(S21,T21,0) -> 0 | AB21: =TIME(U21,V21,0) -> 0 | AD21: =IF(J21=0,0,IF(OR(E21="Sa",E21="So"),TIME($AD$4,$AF$4,0),TIME($AD$5,$AF$5,0))) -> 0 | AF21: =IF(J21=0,0,Z21-W21-(Y21-X21)) -> 0 | AK21: =IF(AH21=$AH$3,1,0) -> 0 | AL21: =IF(AH21=$AH$7,1,0) -> 0 | AM21: =IF(AI21=$AH$4,1,0) -> 0 | AO21: =IF(OR(AH21=$AH$2,AH21=$AH$5),1,IF(AH21=$AH$6,0.5,0)) -> 0 | AP21: =IF(OR(E21="Sa",E21="So",E21="",J21=0,AH21="FT"),0,1) -> 0 | BL21: =BL16 -> 80.9 | BM21: =BM16 -> 80.9 | BN21: =BO20+BN16 -> 135 | BO21: =BN21+BO16 -> 150
D22: =IF(E22="Mo",WEEKNUM(I22),"") -> 3 | E22: =TEXT(I22,"TTT") -> Mo | F22: =$F$5 -> 2025 | G22: =$A$10 -> 1 | H22: =H21+1 -> 13 | I22: =DATE(F22,G22,H22) -> 44208 | J22: =IF(OR(G22="",G22=MONTH(I22)),1,0) -> 1 | K22: =IF(OR($E22="Sa",$E22="So",$J22=0),K$4,K$5) -> 7 | L22: =IF(OR($E22="Sa",$E22="So",$J22=0),L$4,L$5) -> 0 | M22: =IF(OR($E22="Sa",$E22="So",$J22=0),M$4,M$5) -> 13 | N22: =IF(OR($E22="Sa",$E22="So",$J22=0),N$4,N$5) -> 0 | O22: =IF(OR($E22="Sa",$E22="So",$J22=0),O$4,O$5) -> 13 | P22: =IF(OR($E22="Sa",$E22="So",$J22=0),P$4,P$5) -> 30 | Q22: =IF(OR($E22="Sa",$E22="So",$J22=0),Q$4,Q$5) -> 15 | R22: =IF(OR($E22="Sa",$E22="So",$J22=0),R$4,R$5) -> 55 | S22: =Q22 -> 15 | T22: =R22 -> 55 | U22: =S22 -> 15 | V22: =T22 -> 55 | W22: =TIME(K22,L22,0) -> 0.29166667 | X22: =TIME(M22,N22,0) -> 0.54166667 | Y22: =TIME(O22,P22,0) -> 0.5625 | Z22: =TIME(Q22,R22,0) -> 0.66319444 | AA22: =TIME(S22,T22,0) -> 0.66319444 | AB22: =TIME(U22,V22,0) -> 0.66319444 | AD22: =IF(J22=0,0,IF(OR(E22="Sa",E22="So"),TIME($AD$4,$AF$4,0),TIME($AD$5,$AF$5,0))) -> 0.35069444 | AF22: =IF(J22=0,0,Z22-W22-(Y22-X22)) -> 0.35069444 | AK22: =IF(AH22=$AH$3,1,0) -> 0 | AL22: =IF(AH22=$AH$7,1,0) -> 0 | AM22: =IF(AI22=$AH$4,1,0) -> 0 | AO22: =IF(OR(AH22=$AH$2,AH22=$AH$5),1,IF(AH22=$AH$6,0.5,0)) -> 0 | AP22: =IF(OR(E22="Sa",E22="So",E22="",J22=0,AH22="FT"),0,1) -> 1 | BG22: WGTST | BI22: ECO | BJ22: ECO | BL22: 60 | BM22: =SUM(BL17:BL21)+SUM(BM17:BM21) -> 809
D23: =IF(E23="Mo",WEEKNUM(I23),"") | E23: =TEXT(I23,"TTT") -> Di | F23: =$F$5 -> 2025 | G23: =$A$10 -> 1 | H23: =H22+1 -> 14 | I23: =DATE(F23,G23,H23) -> 44209 | J23: =IF(OR(G23="",G23=MONTH(I23)),1,0) -> 1 | K23: =IF(OR($E23="Sa",$E23="So",$J23=0),K$4,K$5) -> 7 | L23: =IF(OR($E23="Sa",$E23="So",$J23=0),L$4,L$5) -> 0 | M23: =IF(OR($E23="Sa",$E23="So",$J23=0),M$4,M$5) -> 13 | N23: =IF(OR($E23="Sa",$E23="So",$J23=0),N$4,N$5) -> 0 | O23: =IF(OR($E23="Sa",$E23="So",$J23=0),O$4,O$5) -> 13 | P23: =IF(OR($E23="Sa",$E23="So",$J23=0),P$4,P$5) -> 30 | Q23: =IF(OR($E23="Sa",$E23="So",$J23=0),Q$4,Q$5) -> 15 | R23: =IF(OR($E23="Sa",$E23="So",$J23=0),R$4,R$5) -> 55 | S23: =Q23 -> 15 | T23: =R23 -> 55 | U23: =S23 -> 15 | V23: =T23 -> 55 | W23: =TIME(K23,L23,0) -> 0.29166667 | X23: =TIME(M23,N23,0) -> 0.54166667 | Y23: =TIME(O23,P23,0) -> 0.5625 | Z23: =TIME(Q23,R23,0) -> 0.66319444 | AA23: =TIME(S23,T23,0) -> 0.66319444 | AB23: =TIME(U23,V23,0) -> 0.66319444 | AD23: =IF(J23=0,0,IF(OR(E23="Sa",E23="So"),TIME($AD$4,$AF$4,0),TIME($AD$5,$AF$5,0))) -> 0.35069444 | AF23: =IF(J23=0,0,Z23-W23-(Y23-X23)) -> 0.35069444 | AK23: =IF(AH23=$AH$3,1,0) -> 0 | AL23: =IF(AH23=$AH$7,1,0) -> 0 | AM23: =IF(AI23=$AH$4,1,0) -> 0 | AO23: =IF(OR(AH23=$AH$2,AH23=$AH$5),1,IF(AH23=$AH$6,0.5,0)) -> 0 | AP23: =IF(OR(E23="Sa",E23="So",E23="",J23=0,AH23="FT"),0,1) -> 1 | BG23: =INDEX($BF$2:$BG$8,MATCH(BG22,$BF$2:$BF$8,0),2) -> 80.9 | BH23: =INDEX($BF$2:$BG$8,MATCH(BG22,$BF$2:$BF$8,0),2) -> 80.9 | BI23: 15 | BJ23: 15 | BL23: =BM23/BL22 -> 26.966667 | BM23: =SUM(BM15,BM22) -> 1618
